# Ancient Warfare Structure Template File
# Auto-generated structure template file. created on: 3/15/2024 at: 23:45:57
# Lines beginning with # denote comments

header:
version=2.11
name=SarkonidFarmFlaxHarvestcraft
mods=harvestcraft
size=37,19,30
offset=10,5,29
:endheader

#### VALIDATION ####
validation:
type=ground
structureAuthor=TheOddlySeagull
survival=false
worldGenEnabled=true
unique=false
preserveBlocks=false
preventNaturalHostileSpawns=true
selectionWeight=35
clusterValue=50
minDuplicateDistance=1000
dimensionWhiteList=true
dimensionList=0
biomeGroupList=sarkonid
biomeWhiteList=true
biomeList=environs:sandstone_ranges,nt:sahel,minecraft:desert,minecraft:mutated_desert,minecraft:desert_hills
leveling=10
fill=10
border=6
blockSwap=false
territoryName=sarkonid
biomeReplacement=minecraft:
minGenerationHeight=0
maxGenerationHeight=255
:endvalidation

#### LAYERS ####
layer: 0
1,1,1,1,1,1,1,1,1,1,1,1,1,1,1,1,1,1,1,1,1,1,1,1,1,1,1,1,1,1,1,1,1,1,1,1,1
1,1,1,1,1,1,1,1,1,1,1,1,1,1,1,1,1,1,1,1,1,1,1,1,1,1,1,1,1,1,1,1,1,1,1,1,1
1,1,1,1,1,1,1,1,1,1,1,1,1,1,1,1,1,1,1,1,1,1,1,1,1,1,1,1,1,1,1,1,1,1,1,1,1
1,1,1,1,1,1,1,1,1,1,1,1,1,1,1,1,1,1,1,1,1,1,1,1,1,1,1,1,1,1,1,1,1,1,1,1,1
1,1,1,1,1,1,1,1,1,1,1,1,1,1,1,1,1,1,1,1,1,1,1,1,1,1,1,1,1,1,1,1,1,1,1,1,1
1,1,1,1,1,1,1,1,1,1,1,1,1,1,1,1,1,1,1,1,1,1,1,1,1,1,1,1,1,1,1,1,1,1,1,1,1
1,1,1,1,1,1,1,1,1,1,1,1,1,1,1,1,1,1,1,1,1,1,1,1,1,1,1,1,1,1,1,1,1,1,1,1,1
1,1,1,1,1,1,1,1,1,1,1,1,1,1,1,1,1,1,1,1,1,1,1,1,1,1,1,1,1,1,1,1,1,1,1,1,1
1,1,1,1,1,1,1,1,1,1,1,1,1,1,1,1,1,1,1,1,1,1,1,1,1,1,1,1,1,1,1,1,1,1,1,1,1
1,1,1,1,1,1,1,1,1,1,1,1,1,1,1,1,1,1,1,1,1,1,1,1,1,1,1,1,1,1,1,1,1,1,1,1,1
1,1,1,1,1,1,1,1,1,1,1,1,1,1,1,1,1,1,1,1,1,1,1,1,1,1,1,1,1,1,1,1,1,1,1,1,1
1,1,1,1,1,1,1,1,1,1,1,1,1,1,1,1,1,1,1,1,1,1,1,1,1,1,1,1,1,1,1,1,1,1,1,1,1
1,1,1,1,1,1,1,1,1,1,1,1,1,1,1,1,1,1,1,1,1,1,1,1,1,1,1,1,1,1,1,1,1,1,1,1,1
1,1,1,1,1,1,1,1,1,1,1,1,1,1,1,1,1,1,1,1,1,1,1,1,1,1,1,1,1,1,1,1,1,1,1,1,1
1,1,1,1,1,1,1,1,1,1,1,1,1,1,1,1,1,1,1,1,1,1,1,1,1,1,1,1,1,1,1,1,1,1,1,1,1
1,1,1,1,1,1,1,1,1,1,1,1,1,1,1,1,1,1,1,1,1,1,1,1,1,1,1,1,1,1,1,1,1,1,1,1,1
1,1,1,1,1,1,1,1,1,1,1,1,1,1,1,1,1,1,1,1,1,1,1,1,1,1,1,1,1,1,1,1,1,1,1,1,1
1,1,1,1,1,1,1,1,1,1,1,1,1,1,1,1,1,1,1,1,1,1,1,1,1,1,1,1,1,1,1,1,1,1,1,1,1
1,1,1,1,1,1,1,1,1,1,1,1,1,1,1,1,1,1,1,1,1,1,1,1,1,1,1,1,1,1,1,1,1,1,1,1,1
1,1,1,1,1,1,1,1,1,1,1,1,1,1,1,1,1,1,1,1,1,1,1,1,1,1,1,1,1,1,1,1,1,1,1,1,1
1,1,1,1,1,1,1,1,1,1,1,1,1,1,1,1,1,1,1,1,1,1,1,1,1,1,1,1,1,1,1,1,1,1,1,1,1
1,1,1,1,1,1,1,1,1,1,1,1,1,1,1,1,1,1,1,1,1,1,1,1,1,1,1,1,1,1,1,1,1,1,1,1,1
1,1,1,1,1,1,1,1,1,1,1,1,1,1,1,1,1,1,1,1,1,1,1,1,1,1,1,1,1,1,1,1,1,1,1,1,1
1,1,1,1,1,1,1,1,1,1,1,1,1,1,1,1,1,1,1,1,1,1,1,1,1,1,1,1,1,1,1,1,1,1,1,1,1
1,1,1,1,1,1,1,1,1,1,1,1,1,1,1,1,1,1,1,1,1,1,1,1,1,1,1,1,1,1,1,1,1,1,1,1,1
1,1,1,1,1,1,1,1,1,1,1,1,1,1,1,1,1,1,1,1,1,1,1,1,1,1,1,1,1,1,1,1,1,1,1,1,1
1,1,1,1,1,1,1,1,1,1,1,1,1,1,1,1,1,1,1,1,1,1,1,1,1,1,1,1,1,1,1,1,1,1,1,1,1
1,1,1,1,1,1,1,1,1,1,1,1,1,1,1,1,1,1,1,1,1,1,1,1,1,1,1,1,1,1,1,1,1,1,1,1,1
1,1,1,1,1,1,1,1,1,1,1,1,1,1,1,1,1,1,1,1,1,1,1,1,1,1,1,1,1,1,1,1,1,1,1,1,1
1,1,1,1,1,1,1,1,1,1,1,1,1,1,1,1,1,1,1,1,1,1,1,1,1,1,1,1,1,1,1,1,1,1,1,1,1
:endlayer
layer: 1
1,1,1,1,1,1,1,1,1,1,1,1,1,1,1,1,1,1,1,1,1,1,1,1,1,1,1,1,1,1,1,1,1,1,1,1,1
1,1,1,1,1,1,1,1,1,1,1,1,1,1,1,1,1,1,1,1,1,1,1,1,1,1,1,1,1,1,1,1,1,1,1,1,1
1,1,1,1,1,1,1,1,1,1,1,1,1,1,1,1,1,1,1,1,1,1,1,1,1,1,1,1,1,1,1,1,1,1,1,1,1
1,1,1,1,1,1,1,1,1,1,1,1,1,1,1,1,1,1,1,1,1,1,1,1,1,1,1,1,1,1,1,1,1,1,1,1,1
1,1,1,1,1,1,1,1,1,1,1,1,1,1,1,1,1,1,1,1,1,1,1,1,1,1,1,1,1,1,1,1,1,1,1,1,1
1,1,1,1,1,1,1,1,1,1,1,1,1,1,1,1,1,1,1,1,1,1,1,1,1,1,1,1,1,1,1,1,1,1,1,1,1
1,1,1,1,1,1,1,1,1,1,1,1,1,1,1,1,1,1,1,1,1,1,1,1,1,1,1,1,1,1,1,1,1,1,1,1,1
1,1,1,1,1,1,1,1,1,1,1,1,1,1,1,1,1,1,1,1,1,1,1,1,1,1,1,1,1,1,1,1,1,1,1,1,1
1,1,1,1,1,1,1,1,1,1,1,1,1,1,1,1,1,1,1,1,1,1,1,1,1,1,1,1,1,1,1,1,1,1,1,1,1
1,1,1,1,1,1,1,1,1,1,1,1,1,1,1,1,1,1,1,1,1,0,0,1,1,1,1,1,1,1,1,1,1,1,1,1,1
1,1,1,1,1,1,1,1,1,1,1,1,1,1,1,1,1,1,1,1,1,0,0,1,1,1,1,1,1,1,1,1,1,1,1,1,1
1,1,1,1,1,1,1,1,1,1,1,1,1,1,1,1,1,1,1,1,1,1,1,1,1,1,1,1,1,1,1,1,1,1,1,1,1
1,1,1,1,1,1,1,1,1,1,1,1,1,1,1,1,1,1,1,1,1,1,1,1,1,1,1,1,1,1,1,1,1,1,1,1,1
1,1,1,1,1,1,1,1,1,1,1,1,1,1,1,1,1,1,1,1,1,1,1,1,1,1,1,1,1,1,1,1,1,1,1,1,1
1,1,1,1,1,1,1,1,1,1,1,1,1,1,1,1,1,1,1,1,1,1,1,1,1,1,1,1,1,1,1,1,1,1,1,1,1
1,1,1,1,1,1,1,1,1,1,1,1,1,1,1,1,1,1,1,1,1,1,1,1,1,1,1,1,1,1,1,1,1,1,1,1,1
1,1,1,1,1,1,1,1,1,1,1,1,1,1,1,1,1,1,1,1,1,1,1,1,1,1,1,1,1,1,1,1,1,1,1,1,1
1,1,1,1,1,1,1,1,1,1,1,1,1,1,1,1,1,1,1,1,1,1,1,1,1,1,1,1,1,1,1,1,1,1,1,1,1
1,1,1,1,1,1,1,1,1,1,1,1,1,1,1,1,1,1,1,1,1,1,1,1,1,1,1,1,1,1,1,1,1,1,1,1,1
1,1,1,1,1,1,1,1,1,1,1,1,1,1,1,1,1,1,1,1,1,1,1,1,1,1,1,1,1,1,1,1,1,1,1,1,1
1,1,1,1,1,1,1,1,1,1,1,1,1,1,1,1,1,1,1,1,1,1,1,1,1,1,1,1,1,1,1,1,1,1,1,1,1
1,1,1,1,1,1,1,1,1,1,1,1,1,1,1,1,1,1,1,1,1,1,1,1,1,1,1,1,1,1,1,1,1,1,1,1,1
1,1,1,1,1,1,1,1,1,1,1,1,1,1,1,1,1,1,1,1,1,1,1,1,1,1,1,1,1,1,1,1,1,1,1,1,1
1,1,1,1,1,1,1,1,1,1,1,1,1,1,1,1,1,1,1,1,1,1,1,1,1,1,1,1,1,1,1,1,1,1,1,1,1
1,1,1,1,1,1,1,1,1,1,1,1,1,1,1,1,1,1,1,1,1,1,1,1,1,1,1,1,1,1,1,1,1,1,1,1,1
1,1,1,1,1,1,1,1,1,1,1,1,1,1,1,1,1,1,1,1,1,1,1,1,1,1,1,1,1,1,1,1,1,1,1,1,1
1,1,1,1,1,1,1,1,1,1,1,1,1,1,1,1,1,1,1,1,1,1,1,1,1,1,1,1,1,1,1,1,1,1,1,1,1
1,1,1,1,1,1,1,1,1,1,1,1,1,1,1,1,1,1,1,1,1,1,1,1,1,1,1,1,1,1,1,1,1,1,1,1,1
1,1,1,1,1,1,1,1,1,1,1,1,1,1,1,1,1,1,1,1,1,1,1,1,1,1,1,1,1,1,1,1,1,1,1,1,1
1,1,1,1,1,1,1,1,1,1,1,1,1,1,1,1,1,1,1,1,1,1,1,1,1,1,1,1,1,1,1,1,1,1,1,1,1
:endlayer
layer: 2
1,1,1,1,1,1,1,1,1,1,1,1,1,1,1,1,1,1,1,1,1,1,1,1,1,1,1,1,1,1,1,1,1,1,1,1,1
1,1,1,1,1,1,1,1,1,1,1,1,1,1,1,1,1,1,1,1,1,1,1,1,1,1,1,1,1,1,1,1,1,1,1,1,1
1,1,1,1,1,1,1,1,1,1,1,1,1,1,1,1,1,1,1,1,1,1,1,1,1,1,1,1,1,1,1,1,1,1,1,1,1
1,1,1,1,1,1,1,1,1,1,1,1,1,1,1,1,1,1,1,1,1,1,1,1,1,1,1,1,1,1,1,1,1,1,1,1,1
1,1,1,1,1,1,1,1,1,1,1,1,1,1,1,1,1,1,1,1,1,1,1,1,1,1,1,1,1,1,1,1,1,1,1,1,1
1,1,1,1,1,1,1,1,1,1,1,1,1,1,1,1,1,1,1,1,1,1,1,1,1,1,1,1,1,1,1,1,1,1,1,1,1
1,1,1,1,1,1,1,1,1,1,1,1,1,1,1,1,1,1,1,1,1,1,1,1,1,1,1,1,1,1,1,1,1,1,1,1,1
1,1,1,1,1,1,1,1,1,1,1,1,1,1,1,1,1,1,1,1,1,1,1,1,1,1,1,1,1,1,1,1,1,1,1,1,1
1,1,1,1,1,1,1,1,1,1,1,1,1,1,1,1,1,1,1,1,1,1,1,1,1,1,1,1,1,1,1,1,1,1,1,1,1
1,1,1,1,1,1,1,1,1,1,1,1,1,1,1,1,1,1,1,1,1,0,0,1,1,1,1,1,1,1,1,1,1,1,1,1,1
1,1,1,1,1,1,1,1,1,1,1,1,1,1,1,1,1,1,1,1,1,0,0,1,1,1,1,1,1,1,1,1,1,1,1,1,1
1,1,1,1,1,1,1,1,1,1,1,1,1,1,1,1,1,1,1,1,1,1,1,1,1,1,1,1,1,1,1,1,1,1,1,1,1
1,1,1,1,1,1,1,1,1,1,1,1,1,1,1,1,1,1,1,1,1,1,1,1,1,1,1,1,1,1,1,1,1,1,1,1,1
1,1,1,1,1,1,1,1,1,1,1,1,1,1,1,1,1,1,1,1,1,1,1,1,1,1,1,1,1,1,1,1,1,1,1,1,1
1,1,1,1,1,1,1,1,1,1,1,1,1,1,1,1,1,1,1,1,1,1,1,1,1,1,1,1,1,1,1,1,1,1,1,1,1
1,1,1,1,1,1,1,1,1,1,1,1,1,1,1,1,1,1,1,1,1,1,1,1,1,1,1,1,1,1,1,1,1,1,1,1,1
1,1,1,1,1,1,1,1,1,1,1,1,1,1,1,1,1,1,1,1,1,1,1,1,1,1,1,1,1,1,1,1,1,1,1,1,1
1,1,1,1,1,1,1,1,1,1,1,1,1,1,1,1,1,1,1,1,1,1,1,1,1,1,1,1,1,1,1,1,1,1,1,1,1
1,1,1,1,1,1,1,1,1,1,1,1,1,1,1,1,1,1,1,1,1,1,1,1,1,1,1,1,1,1,1,1,1,1,1,1,1
1,1,1,1,1,1,1,1,1,1,1,1,1,1,1,1,1,1,1,1,1,1,1,1,1,1,1,1,1,1,1,1,1,1,1,1,1
1,1,1,1,1,1,1,1,1,1,1,1,1,1,1,1,1,1,1,1,1,1,1,1,1,1,1,1,1,1,1,1,1,1,1,1,1
1,1,1,1,1,1,1,1,1,1,1,1,1,1,1,1,1,1,1,1,1,1,1,1,1,1,1,1,1,1,1,1,1,1,1,1,1
1,1,1,1,1,1,1,1,1,1,1,1,1,1,1,1,1,1,1,1,1,1,1,1,1,1,1,1,1,1,1,1,1,1,1,1,1
1,1,1,1,1,1,1,1,1,1,1,1,1,1,1,1,1,1,1,1,1,1,1,1,1,1,1,1,1,1,1,1,1,1,1,1,1
1,1,1,1,1,1,1,1,1,1,1,1,1,1,1,1,1,1,1,1,1,1,1,1,1,1,1,1,1,1,1,1,1,1,1,1,1
1,1,1,1,1,1,1,1,1,1,1,1,1,1,1,1,1,1,1,1,1,1,1,1,1,1,1,1,1,1,1,1,1,1,1,1,1
1,1,1,1,1,1,1,1,1,1,1,1,1,1,1,1,1,1,1,1,1,1,1,1,1,1,1,1,1,1,1,1,1,1,1,1,1
1,1,1,1,1,1,1,1,1,1,1,1,1,1,1,1,1,1,1,1,1,1,1,1,1,1,1,1,1,1,1,1,1,1,1,1,1
1,1,1,1,1,1,1,1,1,1,1,1,1,1,1,1,1,1,1,1,1,1,1,1,1,1,1,1,1,1,1,1,1,1,1,1,1
1,1,1,1,1,1,1,1,1,1,1,1,1,1,1,1,1,1,1,1,1,1,1,1,1,1,1,1,1,1,1,1,1,1,1,1,1
:endlayer
layer: 3
2,2,2,2,2,2,2,2,2,2,2,2,2,2,2,2,2,2,2,2,2,2,2,2,2,2,2,2,2,2,2,2,2,2,2,2,2
2,2,2,2,2,2,2,2,2,2,2,2,2,2,2,2,2,2,2,2,2,2,2,2,2,2,2,2,2,2,2,2,2,2,2,2,2
2,2,2,2,2,2,2,2,2,2,2,2,2,2,2,2,2,2,2,2,2,2,2,2,2,2,2,2,2,2,2,2,2,2,2,2,2
2,2,2,2,2,2,2,2,2,2,2,2,2,2,2,2,2,2,2,2,2,2,2,2,2,2,2,2,2,2,2,2,2,2,2,2,2
2,2,2,2,2,2,2,2,2,2,2,2,2,2,2,2,2,2,2,2,2,2,2,2,2,2,2,2,2,2,2,2,2,2,2,2,2
2,2,2,2,2,2,2,2,2,2,2,2,2,2,2,2,2,2,2,2,2,2,2,2,2,2,2,2,1,1,1,1,2,2,2,2,2
2,2,2,2,2,2,2,2,2,2,2,2,2,2,2,2,2,2,2,2,2,2,2,2,2,2,2,2,1,2,2,1,2,2,2,2,2
2,2,2,2,2,2,2,2,2,2,2,2,2,2,2,2,2,2,2,2,2,2,2,2,2,2,2,2,1,2,2,1,2,2,2,2,2
2,2,2,3,2,2,2,2,2,2,2,2,2,2,2,2,2,2,2,2,1,1,1,1,2,2,2,2,1,1,1,1,2,2,2,2,2
2,2,2,1,2,2,2,2,2,2,2,2,2,2,2,2,2,2,2,2,1,0,0,1,2,2,2,2,1,2,2,1,2,2,2,2,2
2,2,2,1,2,2,2,2,2,2,2,2,2,2,2,2,2,2,2,2,1,0,0,1,2,2,2,2,1,2,2,1,2,2,2,2,2
2,2,2,1,2,2,2,2,2,2,2,2,2,2,2,2,2,2,2,2,1,1,1,1,2,2,2,2,1,1,1,1,2,2,2,2,2
2,2,2,1,2,2,2,2,2,2,2,2,2,2,2,2,2,2,2,2,2,2,2,2,2,2,2,2,1,2,2,2,2,2,2,2,2
2,2,2,1,2,2,2,2,2,2,2,2,2,2,2,2,2,2,2,2,2,2,2,2,2,2,2,2,1,2,2,2,2,2,2,2,2
2,2,2,3,2,2,2,2,2,2,2,2,2,2,2,2,2,2,2,2,2,2,2,2,2,2,2,2,1,2,2,2,2,2,2,2,2
2,2,2,2,2,2,2,2,2,2,2,2,2,2,2,2,2,2,2,2,2,2,1,1,1,1,1,1,1,2,2,2,2,2,2,2,2
2,2,2,2,2,2,2,2,2,2,2,2,2,2,2,2,2,2,2,2,2,2,1,2,2,2,2,2,1,2,2,2,2,2,2,2,2
2,2,2,2,2,2,2,2,2,2,2,2,2,2,2,2,2,2,2,2,2,2,1,2,2,2,2,2,1,2,2,2,2,2,2,2,2
2,2,2,3,2,2,2,2,2,2,2,2,2,2,2,2,2,2,2,2,2,2,1,2,2,2,2,2,1,2,2,2,2,2,2,2,2
2,2,1,1,1,1,1,1,2,2,2,2,2,2,2,2,1,1,1,1,1,1,1,2,2,2,2,2,1,1,1,1,1,2,2,2,2
2,2,1,2,2,2,2,1,2,2,2,2,2,2,2,2,1,2,2,2,2,2,2,2,2,2,2,2,2,2,2,2,1,2,2,2,2
2,2,1,2,2,2,2,1,2,2,2,2,2,2,2,2,1,2,2,2,2,2,2,2,2,2,2,2,2,2,2,2,1,2,2,2,2
2,2,1,2,2,2,2,1,2,2,2,2,2,2,2,2,1,2,2,2,2,2,2,2,2,2,2,2,2,2,2,2,1,2,2,2,2
2,2,1,2,2,2,2,1,2,2,2,2,2,2,2,2,1,2,2,2,2,2,2,2,2,2,2,2,2,2,1,1,1,1,1,2,2
2,2,1,2,2,2,2,1,2,2,2,2,2,2,2,2,1,2,2,2,2,2,2,2,2,2,2,2,2,2,1,2,2,2,1,2,2
2,2,1,2,2,2,2,1,2,2,2,2,2,2,2,2,1,1,1,1,1,1,1,2,2,2,2,2,2,2,1,2,2,2,1,2,2
2,2,1,2,2,2,2,1,2,2,2,2,2,2,2,2,2,2,2,2,2,2,1,2,2,2,2,2,2,2,1,2,2,2,1,2,2
2,2,1,1,1,1,1,1,2,2,2,2,2,2,2,2,2,2,2,2,2,2,1,1,1,1,1,1,1,1,1,1,1,1,1,2,2
2,2,2,2,2,2,2,2,2,2,2,2,2,2,2,2,2,2,2,2,2,2,2,2,2,2,2,2,2,2,2,2,2,2,2,2,2
2,2,2,2,2,2,2,2,2,2,2,2,2,2,2,2,2,2,2,2,2,2,2,2,2,2,2,2,2,2,2,2,2,2,2,2,2
:endlayer
layer: 4
2,2,2,2,2,2,2,2,2,2,2,2,2,2,2,2,2,2,2,2,2,2,2,2,2,2,2,2,2,2,2,2,2,2,2,2,2
2,2,2,2,2,2,2,2,2,2,2,2,2,2,2,2,2,2,2,2,2,2,2,2,2,2,2,2,2,2,2,2,2,2,2,2,2
2,2,2,2,2,2,2,2,2,2,2,2,2,2,2,2,2,2,2,2,2,2,2,2,2,2,2,2,2,2,2,2,2,2,2,2,2
2,2,2,2,2,2,2,2,2,2,2,2,2,2,2,2,2,2,2,2,2,2,2,2,2,2,2,2,2,2,2,2,2,2,2,2,2
2,2,2,2,2,2,2,2,2,2,2,2,2,2,2,2,2,2,2,2,2,2,2,2,2,2,2,2,2,2,2,2,2,2,2,2,2
2,2,2,2,2,2,2,2,2,2,2,2,2,2,2,2,2,2,2,2,2,2,2,2,2,2,2,2,1,1,1,1,2,2,2,2,2
2,2,2,2,2,2,2,2,2,2,2,2,2,2,2,2,2,1,2,2,1,2,1,1,1,1,1,1,1,2,2,1,2,2,2,2,2
2,2,2,2,2,2,2,2,2,2,2,2,2,2,2,2,2,1,2,1,1,2,1,2,2,1,2,2,1,2,2,1,2,2,2,2,2
2,2,2,3,2,2,2,2,2,2,2,2,2,2,2,2,2,1,2,2,1,1,1,1,2,1,1,1,1,1,1,1,2,2,2,2,2
2,2,2,1,2,2,2,2,2,2,2,2,2,2,2,2,2,2,2,2,1,0,0,1,2,1,2,2,1,2,2,1,2,2,2,2,2
2,2,2,1,2,2,2,2,2,2,2,2,2,2,2,2,2,2,2,2,1,0,0,1,1,1,2,2,1,2,2,1,2,2,2,2,2
2,2,2,1,2,2,2,2,2,2,2,2,2,2,2,2,2,1,2,1,1,1,1,1,1,2,1,2,1,1,1,1,2,2,2,2,2
2,2,2,1,2,2,2,2,2,2,2,2,2,2,2,2,2,1,2,1,1,2,1,2,1,2,1,2,1,2,2,1,1,2,2,2,1
2,2,2,1,2,2,2,2,2,2,2,2,2,2,2,2,2,1,2,2,1,1,1,2,2,1,1,2,1,2,1,2,1,2,2,1,2
2,2,2,3,2,1,1,1,2,1,1,1,2,1,1,1,1,1,1,1,1,2,1,1,2,1,1,2,1,1,1,2,1,2,2,1,2
2,2,2,1,1,2,2,2,1,2,2,1,2,2,1,1,2,2,2,2,2,1,1,1,1,1,1,1,1,2,2,2,2,2,2,2,2
2,2,2,1,2,1,2,1,1,1,1,2,2,2,1,2,1,1,2,2,2,1,1,1,1,1,1,1,1,2,2,2,2,2,2,2,2
2,2,2,1,2,2,2,2,1,1,1,2,1,1,2,1,1,1,2,1,2,1,1,1,1,1,1,1,1,2,2,2,2,2,2,2,2
2,2,2,3,1,1,1,1,1,2,2,2,2,2,2,2,2,1,2,1,2,1,1,1,1,1,1,1,1,2,2,2,2,2,2,2,2
2,2,1,1,1,1,1,1,2,1,2,2,2,2,2,2,1,1,1,1,1,1,1,1,1,1,1,1,1,1,1,1,1,2,2,2,2
2,2,1,2,1,1,2,1,1,2,1,1,2,2,2,2,1,1,1,1,1,1,1,1,1,1,1,1,1,1,1,1,1,2,2,2,2
2,2,1,4,4,1,1,1,2,2,2,1,2,2,2,2,1,1,1,1,1,1,1,1,1,1,1,1,1,1,1,1,1,2,2,2,2
2,2,1,4,4,4,4,1,2,1,1,1,1,2,2,2,1,1,1,1,1,1,1,1,1,1,1,1,1,1,1,1,1,2,2,2,2
2,2,1,1,2,1,4,1,1,2,1,1,2,2,2,2,1,1,1,1,1,1,1,1,1,1,1,1,1,1,1,1,1,1,1,2,2
2,2,1,2,4,1,2,1,2,2,2,2,1,2,2,2,1,1,1,1,1,1,1,1,1,1,1,1,1,1,1,1,1,1,1,2,2
2,2,1,2,4,4,2,1,2,1,1,2,2,2,2,2,1,1,1,1,1,1,1,1,1,1,1,1,1,1,1,1,1,1,1,2,2
2,2,1,1,4,1,1,1,2,2,2,1,2,1,1,1,1,2,2,2,2,2,1,1,1,1,1,1,1,1,1,1,1,1,1,2,2
2,2,1,1,1,1,1,1,1,1,2,1,2,2,2,2,1,2,2,2,2,2,1,1,1,1,1,1,1,1,1,1,1,1,1,2,2
2,2,2,2,2,2,2,2,2,1,1,2,1,2,2,2,2,2,2,2,2,2,2,2,2,2,2,2,2,2,2,2,2,2,2,2,2
2,2,2,2,2,2,2,2,1,1,1,1,2,2,2,2,2,2,2,2,2,2,2,2,2,2,2,2,2,2,2,2,2,2,2,2,2
:endlayer
layer: 5
0,0,0,0,0,0,0,0,0,0,0,0,0,0,0,0,0,0,0,0,0,0,0,0,0,0,0,0,0,0,0,0,0,0,0,0,0
0,0,0,0,0,0,1,1,1,1,1,40,1,1,1,1,1,0,44,0,0,34,0,24,0,24,0,24,0,0,0,0,0,0,0,0,0
0,0,0,9,0,0,1,51,51,51,51,1,51,51,51,51,1,0,0,0,0,0,0,0,0,0,0,0,0,0,0,0,0,0,0,0,0
0,0,0,0,0,0,1,51,51,51,51,1,51,51,51,51,1,0,0,11,0,24,0,24,0,24,0,24,0,9,0,0,0,10,0,0,0
0,0,0,0,24,0,1,51,51,51,51,1,51,51,51,51,1,0,0,0,0,0,0,0,0,0,0,0,0,0,0,0,0,0,0,0,0
0,9,0,0,0,0,1,51,51,51,51,61,51,51,51,51,1,0,0,0,0,34,0,24,0,24,0,0,1,1,1,1,0,0,0,0,0
0,0,24,0,24,0,1,51,51,51,51,1,51,51,51,51,1,0,45,0,0,0,0,0,0,0,0,0,20,0,0,1,0,0,0,0,0
0,0,0,0,0,0,1,51,51,51,51,1,51,51,51,51,1,0,0,0,0,0,0,0,0,0,0,0,20,0,0,1,0,0,0,0,0
0,0,0,3,0,0,1,51,51,51,51,1,51,51,51,51,1,0,0,0,3,31,31,3,0,0,0,0,1,1,1,1,0,9,0,0,0
0,0,0,1,0,0,1,51,51,51,51,61,51,51,51,51,1,0,0,0,31,0,0,31,0,0,0,0,20,16,0,1,0,0,0,0,0
0,0,0,1,0,0,1,51,51,51,51,1,51,51,51,51,1,0,0,0,31,0,0,31,0,0,0,0,20,0,0,1,0,0,9,0,0
0,0,0,1,0,0,1,51,51,51,51,1,51,51,51,51,1,0,0,0,3,31,31,3,0,0,0,0,1,1,1,1,0,0,0,0,0
0,0,0,1,0,0,1,51,51,51,51,1,51,51,51,51,1,0,0,0,0,0,0,0,0,0,0,0,0,0,0,0,0,0,0,0,0
0,0,0,1,0,0,1,1,1,1,1,62,1,1,1,1,1,0,0,0,0,35,0,0,0,0,27,0,0,0,0,0,0,0,0,0,0
0,0,0,3,0,0,0,0,0,0,0,0,0,0,0,0,0,0,0,0,0,0,0,0,0,0,0,0,0,0,0,0,0,0,0,5,0
0,0,0,0,0,0,0,0,0,0,0,0,0,0,56,0,0,48,0,0,0,36,1,1,29,1,1,1,1,0,0,0,0,0,0,0,0
0,0,0,75,0,0,0,0,0,0,63,0,0,0,0,0,0,0,0,0,0,1,1,32,0,0,14,13,1,0,0,0,0,11,0,6,0
0,0,0,0,0,0,0,0,0,0,0,0,0,0,0,0,0,0,0,0,0,37,1,33,0,0,14,13,1,0,0,0,0,0,0,0,0
0,0,0,3,73,71,1,1,65,0,0,0,0,58,0,0,0,0,0,0,0,38,1,32,0,0,0,23,1,0,0,0,0,0,0,0,0
0,0,1,1,1,1,1,1,0,0,0,0,0,59,0,52,1,1,46,1,40,1,1,3,30,0,0,3,1,1,1,1,1,0,0,0,0
0,0,1,76,0,72,69,1,0,0,0,0,0,60,0,53,1,49,0,32,33,32,3,0,0,0,0,0,21,17,0,0,1,0,0,0,0
0,0,1,77,0,0,0,66,0,0,0,0,0,60,32,0,50,0,0,32,33,32,0,0,0,22,22,22,22,18,0,0,12,0,0,0,0
0,0,1,78,0,0,0,67,0,0,0,0,0,60,57,0,50,0,0,0,0,0,0,0,0,22,22,22,22,0,14,13,1,0,0,0,0
0,0,1,78,0,0,0,68,0,0,0,0,0,60,32,0,1,0,0,42,0,0,0,0,0,22,22,22,22,0,1,1,1,1,1,0,0
0,0,1,24,74,0,0,1,0,0,0,6,0,60,0,54,1,47,47,43,41,39,3,0,0,0,0,0,0,0,15,1,1,1,1,6,0
0,0,1,24,24,0,0,1,0,0,0,0,0,59,55,55,1,1,1,1,1,1,1,25,25,0,25,25,0,0,15,1,1,1,1,7,0
0,0,1,24,24,24,70,1,0,0,0,0,0,0,0,0,0,0,0,0,0,0,1,26,26,28,26,26,23,19,1,1,1,1,1,8,0
0,0,1,1,1,1,1,1,0,0,64,0,0,0,0,0,0,0,0,0,9,0,1,1,1,1,1,1,1,1,1,1,1,1,1,6,0
0,0,0,0,0,0,0,0,0,0,0,0,0,0,6,0,0,0,0,0,0,0,0,0,0,0,0,0,0,0,0,0,0,0,0,0,0
0,0,0,0,0,0,0,0,0,0,0,0,0,0,0,0,0,0,0,0,0,0,0,0,0,0,0,0,0,0,0,0,0,0,0,0,0
:endlayer
layer: 6
0,0,0,0,0,0,0,0,0,0,0,0,0,0,0,0,0,0,0,0,0,0,0,0,0,0,0,0,0,0,0,0,0,0,0,0,0
0,0,0,0,0,0,3,31,31,31,3,0,3,31,31,31,3,0,0,0,0,96,0,92,0,88,0,86,0,0,0,0,0,0,0,0,0
0,0,0,9,0,0,31,104,103,103,106,0,103,103,103,103,31,0,0,0,0,0,0,0,0,0,0,0,0,0,0,0,0,0,0,0,0
0,0,0,0,0,0,31,106,103,103,103,79,103,103,103,104,31,0,0,11,0,97,0,93,0,89,0,87,0,9,0,0,0,0,0,0,0
0,0,0,0,120,0,31,104,103,103,103,111,103,103,103,104,31,0,0,0,0,0,0,0,0,0,0,0,0,0,0,0,0,0,0,0,0
0,9,0,0,0,0,3,103,103,103,103,0,103,103,103,103,3,0,0,0,0,98,0,94,0,90,0,0,1,6,1,1,0,0,0,0,0
0,0,126,0,121,0,31,103,106,103,106,0,103,103,103,103,31,0,0,0,0,0,0,0,0,0,0,0,0,0,0,1,0,0,0,0,0
0,0,0,0,0,0,31,103,103,104,103,79,106,106,103,104,31,0,0,0,0,0,0,0,0,0,0,0,0,0,0,1,0,0,0,0,0
0,0,0,3,0,0,31,104,103,106,103,0,103,103,103,103,31,0,0,0,6,0,0,6,0,0,0,0,1,6,1,1,0,9,0,0,0
0,0,0,1,0,0,3,103,103,103,113,0,103,103,103,103,3,0,0,0,0,0,0,0,0,0,0,0,0,0,0,1,0,0,0,0,0
0,0,0,1,0,0,31,106,104,104,103,0,104,103,106,103,31,0,0,0,0,0,0,0,0,0,0,0,0,0,0,1,0,0,9,0,0
0,0,0,1,0,0,31,104,106,103,106,79,104,103,103,103,31,0,0,0,6,0,0,6,0,0,0,0,1,1,1,1,0,0,0,0,0
0,0,0,1,0,0,31,103,104,103,104,112,104,103,103,104,31,0,0,0,0,0,0,0,0,0,0,0,0,0,0,0,0,0,0,0,0
0,0,0,1,0,0,3,31,31,31,3,0,3,31,31,31,3,0,0,0,0,0,0,0,0,0,0,0,0,0,0,0,0,0,0,0,0
0,0,0,3,0,0,0,0,0,0,0,0,0,0,0,0,0,0,0,0,0,0,0,0,0,0,0,0,0,0,0,0,0,0,0,0,0
0,0,0,0,0,0,0,0,0,0,0,0,0,0,0,0,0,0,0,0,0,0,1,1,83,1,6,1,1,0,0,0,0,0,0,0,0
0,0,0,0,0,0,0,0,0,0,0,0,0,0,0,0,0,0,0,0,0,36,1,0,0,0,0,0,1,0,0,0,0,11,0,79,0
0,0,0,0,0,0,0,0,0,0,0,0,0,0,0,0,0,0,0,0,0,99,1,95,0,0,0,0,6,0,0,0,0,0,0,0,0
0,0,0,3,0,0,1,65,0,0,0,0,0,0,0,0,0,0,0,0,0,100,1,0,0,0,0,0,1,0,0,0,0,0,0,0,0
0,0,1,1,1,1,1,1,0,0,0,0,0,6,0,0,1,1,101,1,6,1,1,3,0,0,0,3,1,1,6,1,1,0,0,0,0
0,0,1,117,117,117,117,1,0,0,0,0,0,108,0,0,1,0,0,0,0,0,3,0,0,0,0,0,0,0,0,0,1,0,0,0,0
0,0,1,0,0,0,0,114,0,0,0,0,0,0,0,0,101,0,0,0,0,0,0,0,0,0,0,0,0,0,0,0,83,0,0,0,0
0,0,1,123,0,0,0,115,0,0,0,0,0,0,0,0,83,0,0,0,0,0,0,0,0,0,0,0,0,0,0,0,1,0,0,0,0
0,0,1,124,0,0,0,116,0,0,0,0,0,109,0,0,1,0,0,0,0,0,0,0,0,0,0,0,0,0,1,1,1,1,1,0,0
0,0,1,125,0,0,0,1,0,0,0,79,0,110,0,0,6,102,0,0,0,0,3,0,0,0,0,0,0,0,0,0,0,0,1,6,0
0,0,1,24,122,0,0,1,0,0,0,0,0,6,107,105,1,1,6,1,6,1,1,0,0,0,0,0,0,0,0,31,3,0,1,80,0
0,0,1,24,24,119,118,1,0,0,0,0,0,0,0,0,0,0,0,0,0,0,1,0,0,91,0,0,0,0,1,85,84,82,1,81,0
0,0,1,1,1,1,1,1,0,0,0,0,0,0,0,0,0,0,0,0,9,0,1,1,6,1,6,1,6,1,1,1,1,1,1,6,0
0,0,0,0,0,0,0,0,0,0,0,0,0,0,79,0,0,0,0,0,0,0,0,0,0,0,0,0,0,0,0,0,0,0,0,0,0
0,0,0,0,0,0,0,0,0,0,0,0,0,0,0,0,0,0,0,0,0,0,0,0,0,0,0,0,0,0,0,0,0,0,0,0,0
:endlayer
layer: 7
0,0,0,0,0,0,0,0,0,0,0,0,0,0,0,0,0,0,0,0,0,0,0,0,0,0,0,0,0,0,0,0,0,0,0,0,0
0,0,0,0,0,0,79,0,0,0,79,0,79,0,0,0,79,0,0,0,0,0,0,0,0,0,0,0,0,0,0,0,0,0,0,0,0
0,0,0,9,0,0,0,0,0,0,0,0,0,0,0,0,0,0,0,0,0,0,0,0,0,0,0,0,0,0,0,0,0,0,0,0,0
0,0,0,0,0,0,0,0,0,0,0,0,0,0,0,0,0,0,0,11,0,0,0,0,0,0,0,0,0,9,0,0,0,0,0,0,0
0,0,0,0,0,0,0,0,0,0,0,0,0,0,0,0,0,0,0,0,0,0,0,0,0,0,0,0,0,0,0,0,0,0,0,0,0
0,9,0,0,0,0,79,0,0,0,0,0,0,0,0,0,79,0,0,0,0,0,0,0,0,0,0,130,1,1,1,1,127,0,0,0,0
0,0,0,0,0,0,0,0,0,0,0,0,0,0,0,0,0,0,0,0,0,0,0,0,0,0,0,0,0,0,0,1,0,0,0,0,0
0,0,0,58,0,0,0,0,0,0,0,0,0,0,0,0,0,0,0,0,0,0,0,0,0,0,0,0,0,0,0,1,0,0,0,0,0
0,0,130,3,127,0,0,0,0,0,0,0,0,0,0,0,0,0,0,0,6,0,0,6,0,0,0,130,1,1,1,1,127,9,0,0,0
0,0,0,31,0,0,79,0,0,0,0,0,0,0,0,0,79,0,0,0,0,0,0,0,0,0,0,0,0,0,0,1,0,0,0,0,0
0,0,0,31,0,0,0,0,0,0,0,0,0,0,0,0,0,0,0,0,0,0,0,0,0,0,0,0,0,0,0,1,0,0,9,0,0
0,0,0,31,0,0,0,0,0,0,0,0,0,0,0,0,0,0,0,0,6,0,0,6,0,0,0,130,1,1,1,1,127,0,0,0,0
0,0,0,31,0,0,0,0,0,0,0,0,0,0,0,0,0,0,0,0,0,0,0,0,0,0,0,0,99,0,0,0,0,0,0,0,0
0,0,0,31,0,0,79,0,0,0,79,0,79,0,0,0,79,0,0,0,0,0,0,0,0,0,0,0,0,0,0,0,0,0,0,0,0
0,0,130,3,0,0,0,0,0,0,0,0,0,0,0,0,0,0,0,0,0,0,58,0,0,0,0,0,100,0,0,0,0,0,0,0,0
0,0,0,0,0,0,0,0,0,0,0,0,0,0,0,0,0,0,0,0,0,130,1,1,1,1,6,1,1,127,0,0,0,0,0,0,0
0,0,0,0,0,0,0,0,0,0,0,0,0,0,0,0,0,0,0,0,0,0,1,0,0,128,0,0,1,0,0,0,0,11,0,0,0
0,0,0,0,0,0,0,0,0,0,0,0,0,0,0,0,0,0,0,0,0,36,1,0,0,0,0,0,6,0,0,0,0,0,0,0,0
0,0,130,3,141,139,65,0,0,0,0,0,0,0,0,0,58,0,0,0,0,1,1,0,0,0,0,0,1,0,0,0,58,0,0,0,0
0,130,1,1,1,1,1,1,127,0,0,0,0,6,0,130,1,1,40,1,6,1,1,3,132,85,131,3,1,1,6,1,1,127,0,0,0
0,0,1,144,142,140,138,1,0,0,0,0,0,0,0,0,1,127,0,0,0,130,3,128,0,0,0,128,0,0,0,0,1,0,0,0,0
0,0,6,0,0,0,0,135,0,0,0,0,0,0,0,0,1,0,0,0,0,0,133,0,0,0,0,0,0,0,0,0,129,0,0,0,0
0,0,1,0,0,0,0,136,0,0,0,0,0,0,0,0,1,0,0,0,0,0,85,0,0,0,0,0,0,0,58,0,1,0,58,0,0
0,0,6,0,0,0,0,137,0,0,0,0,0,0,0,0,1,127,0,0,0,0,134,0,0,0,0,0,0,130,1,1,1,1,1,127,0
0,0,1,0,0,0,0,1,0,0,0,0,0,0,0,0,1,0,0,0,0,130,3,127,0,0,0,0,0,0,0,0,0,0,1,6,0
0,0,6,145,0,0,0,6,0,0,0,0,0,6,0,130,1,1,6,1,6,1,1,0,0,0,0,0,0,0,0,0,3,0,1,0,0
0,0,1,24,143,0,0,1,0,0,0,0,0,0,0,0,128,0,0,0,0,0,1,0,0,58,0,58,0,0,1,0,31,85,1,0,0
0,130,1,1,6,6,1,1,127,0,0,0,0,0,0,0,0,0,0,0,9,130,1,1,6,1,6,1,6,1,1,6,1,1,1,6,0
0,0,128,0,0,0,0,128,0,0,0,0,0,0,0,0,0,0,0,0,0,0,128,0,0,0,0,0,0,0,128,0,0,0,128,0,0
0,0,0,0,0,0,0,0,0,0,0,0,0,0,0,0,0,0,0,0,0,0,0,0,0,0,0,0,0,0,0,0,0,0,0,0,0
:endlayer
layer: 8
0,0,0,0,0,0,0,0,0,0,0,0,0,0,0,0,0,0,0,0,0,0,0,0,0,0,0,0,0,0,0,0,0,0,0,0,0
0,0,0,0,0,0,0,0,0,0,0,0,0,0,0,0,0,0,0,0,0,0,0,0,0,0,0,0,0,0,0,0,0,0,0,0,0
0,0,0,0,0,0,0,0,0,0,0,0,0,0,0,0,0,0,0,0,0,0,0,0,0,0,0,0,0,0,0,0,0,0,0,0,0
0,0,0,0,0,0,0,0,0,0,0,0,0,0,0,0,0,0,0,0,0,0,0,0,0,0,0,0,0,0,0,0,0,0,0,0,0
0,0,0,0,0,0,0,0,0,0,0,0,0,0,0,0,0,0,11,0,0,0,0,0,0,0,0,0,0,0,0,0,0,0,0,0,0
0,0,0,0,0,0,0,0,0,0,0,0,0,0,0,0,0,0,0,0,0,0,0,0,0,0,0,0,146,146,146,146,0,0,0,0,0
0,0,0,0,0,0,0,0,0,0,0,0,0,0,0,0,0,0,0,0,0,0,0,0,0,0,0,0,6,31,31,146,0,0,0,0,0
0,0,0,0,0,0,0,0,0,0,0,0,0,0,0,0,0,0,0,0,0,0,0,0,0,0,0,0,6,31,31,146,0,0,0,0,0
0,0,0,31,0,0,0,0,0,0,0,0,0,0,0,0,0,0,0,0,31,31,31,31,0,0,0,0,146,146,146,146,0,9,0,0,0
0,0,0,0,0,0,0,0,0,0,0,0,0,0,0,0,0,0,0,0,31,1,1,31,0,0,0,0,6,31,31,146,0,0,0,0,0
0,0,0,0,0,0,0,0,0,0,0,0,0,0,0,0,0,0,0,0,31,1,1,31,0,0,0,0,6,31,31,146,0,0,0,0,0
0,0,0,0,0,0,0,0,0,0,0,0,0,0,0,0,0,0,0,0,31,31,31,31,0,0,0,0,146,146,146,146,0,0,0,0,0
0,0,0,0,0,0,0,0,0,0,0,0,0,0,0,0,0,0,0,0,0,0,0,0,0,0,0,0,146,0,0,0,0,0,0,0,0
0,0,0,0,0,0,0,0,0,0,0,0,0,0,0,0,0,0,0,0,0,0,0,0,0,0,0,0,146,0,0,0,0,0,0,0,0
0,0,0,3,0,0,0,0,0,0,0,0,0,0,0,0,0,0,0,0,0,0,0,147,147,147,147,147,146,0,0,0,0,0,0,0,0
0,0,0,133,0,0,0,0,0,0,0,0,0,0,0,0,0,0,0,0,0,0,146,146,146,146,146,146,146,0,0,0,0,0,0,0,0
0,0,0,85,0,0,0,0,0,0,0,0,0,0,0,0,0,0,0,0,0,0,146,1,1,1,1,1,146,0,0,0,11,0,0,0,0
0,0,0,134,0,0,0,0,0,0,0,0,0,0,0,0,0,0,0,0,0,0,146,1,1,1,1,1,146,0,0,0,0,0,0,0,0
0,0,0,3,1,65,0,0,0,0,0,0,0,0,0,0,0,0,0,0,0,36,146,1,1,1,1,1,146,0,0,0,0,0,0,0,0
0,0,1,1,1,1,1,1,0,0,0,0,0,148,148,148,1,1,134,1,134,1,1,1,1,1,1,1,1,1,134,1,1,0,0,0,0
0,0,1,0,151,0,0,1,0,0,0,0,0,148,149,149,1,85,85,85,85,85,1,85,85,85,85,85,85,85,85,85,1,0,0,0,0
0,0,1,0,0,0,0,1,0,0,0,0,0,148,150,150,1,85,0,0,0,85,1,85,0,0,0,0,0,0,0,85,132,0,0,0,0
0,0,1,0,0,0,130,1,0,0,0,0,0,148,149,149,1,85,0,0,0,85,1,85,0,0,0,0,0,85,85,85,1,0,0,0,0
0,0,1,0,0,0,0,1,0,0,0,0,0,148,150,150,1,85,0,0,0,85,1,85,0,0,0,0,0,85,1,1,1,1,1,0,0
0,0,1,127,0,0,0,1,0,0,0,0,0,148,149,149,1,85,85,85,85,85,1,85,0,0,0,0,0,85,99,0,0,85,1,31,0
0,0,1,0,0,0,0,1,0,0,0,0,0,148,148,148,1,1,133,1,133,1,1,85,0,0,0,0,0,85,100,0,3,31,1,31,0
0,0,1,152,0,0,0,1,0,0,0,0,0,0,0,0,0,0,0,0,0,0,1,85,85,85,85,85,85,85,1,0,0,0,1,31,0
0,0,1,1,1,1,1,1,0,0,0,0,0,0,0,0,0,0,0,0,0,0,1,1,133,1,133,1,133,1,1,1,1,1,1,31,0
0,0,0,0,0,0,0,0,0,0,0,0,0,0,0,0,0,0,0,0,0,0,0,0,0,0,0,0,0,0,0,0,0,0,0,0,0
0,0,0,0,0,0,0,0,0,0,0,0,0,0,0,0,0,0,0,0,0,0,0,0,0,0,0,0,0,0,0,0,0,0,0,0,0
:endlayer
layer: 9
0,0,0,0,0,0,0,0,0,0,0,0,0,0,0,0,0,0,0,0,0,0,0,0,0,0,0,0,0,0,0,0,0,0,0,0,0
0,0,0,0,0,0,0,0,0,0,0,0,0,0,0,0,0,0,0,0,0,0,0,0,0,0,0,0,0,0,0,0,0,0,0,0,0
0,0,0,0,0,0,0,0,0,0,0,0,0,0,0,0,0,0,0,0,0,0,0,0,0,0,0,0,0,0,0,0,0,0,0,0,0
0,0,0,0,0,0,0,0,0,0,0,0,0,0,0,0,0,0,0,0,0,0,0,0,0,0,0,0,0,0,0,0,0,0,0,0,0
0,0,0,0,0,0,0,0,0,0,0,0,0,0,0,0,0,0,11,0,0,0,0,0,0,0,0,0,0,0,0,0,0,0,0,0,0
0,0,0,0,0,0,0,0,0,0,0,0,0,0,0,0,0,0,0,0,0,0,0,0,0,0,0,0,31,0,0,31,0,0,0,0,0
0,0,0,0,0,0,0,0,0,0,0,0,0,0,0,0,0,0,0,0,0,0,0,0,0,0,0,0,0,0,0,0,0,0,0,0,0
0,0,0,0,0,0,0,0,0,0,0,0,0,0,0,0,0,0,0,0,0,0,0,0,0,0,0,0,0,0,0,0,0,0,0,0,0
0,0,0,0,0,0,0,0,0,0,0,0,0,0,0,0,0,0,0,0,0,0,0,0,0,0,0,0,31,0,0,31,0,0,0,0,0
0,0,0,0,0,0,0,0,0,0,0,0,0,0,0,0,0,0,0,0,0,79,0,0,0,0,0,0,0,0,0,0,0,0,0,0,0
0,0,0,0,0,0,0,0,0,0,0,0,0,0,0,0,0,0,0,0,0,0,79,0,0,0,0,0,0,0,0,0,0,0,0,0,0
0,0,0,0,0,0,0,0,0,0,0,0,0,0,0,0,0,0,0,0,0,0,0,0,0,0,0,0,3,0,0,31,0,0,0,0,0
0,0,0,0,0,0,0,0,0,0,0,0,0,0,0,0,0,0,0,0,0,0,0,0,0,0,0,0,31,0,0,0,0,0,0,0,0
0,0,0,0,0,0,0,0,0,0,0,0,0,0,0,0,0,0,0,0,0,0,0,0,0,0,0,0,31,0,0,0,0,0,0,0,0
0,0,0,146,0,0,0,0,0,0,0,0,0,0,0,0,0,0,0,0,0,0,0,0,0,0,0,0,31,0,0,0,0,0,0,0,0
0,0,0,146,0,0,0,0,0,0,0,0,0,0,0,0,0,0,0,0,0,0,3,31,31,31,31,31,3,0,0,0,0,0,0,0,0
0,0,0,146,0,0,0,0,0,0,0,0,0,0,0,0,0,0,0,0,0,0,31,0,0,0,0,0,31,0,0,0,11,0,0,0,0
0,0,0,146,0,0,0,0,0,0,0,0,0,0,0,0,0,0,0,0,0,0,31,0,0,0,0,0,31,0,0,0,0,0,0,0,0
0,0,0,146,65,0,0,0,0,0,0,0,0,0,0,0,0,0,0,0,0,0,31,0,0,0,0,0,31,0,0,0,0,0,0,0,0
0,0,146,146,146,146,146,146,0,0,0,0,0,0,0,0,153,153,153,153,153,153,153,153,153,40,153,153,153,153,153,153,153,0,0,0,0
0,0,146,1,1,1,1,146,0,0,0,0,0,0,0,0,153,1,1,1,1,1,153,1,1,1,1,1,1,1,1,1,153,0,0,0,0
0,0,146,1,1,1,1,146,0,0,0,0,0,0,0,0,153,1,1,1,1,1,153,1,1,1,1,1,1,1,1,1,153,0,0,0,0
0,0,146,1,1,1,1,146,0,0,0,0,0,0,0,0,153,1,1,1,1,1,153,1,1,1,1,1,1,1,1,1,153,0,0,0,0
0,0,146,1,1,1,1,146,0,0,0,0,0,0,0,0,153,1,1,1,1,1,153,1,1,1,1,1,1,1,153,153,153,153,153,0,0
0,0,146,1,1,1,1,146,0,0,0,0,0,0,0,0,153,1,1,1,1,1,153,1,1,1,1,1,1,1,153,85,31,0,153,0,0
0,0,146,1,1,1,1,146,0,0,0,0,0,0,0,0,153,153,153,153,153,153,153,1,1,1,1,1,1,1,153,0,3,0,153,0,0
0,0,146,1,1,1,1,146,0,0,0,0,0,0,0,0,0,0,0,0,0,0,153,1,1,1,1,1,1,1,153,127,0,0,153,0,0
0,0,146,146,146,146,146,146,0,0,0,0,0,0,0,0,0,0,0,0,0,0,153,153,153,153,153,153,153,153,153,153,153,153,153,0,0
0,0,0,0,0,0,0,0,0,0,0,0,0,0,0,0,0,0,0,0,0,0,0,0,147,147,147,147,147,0,0,0,0,0,0,0,0
0,0,0,0,0,0,0,0,0,0,0,0,0,0,0,0,0,0,0,0,0,0,0,0,0,0,0,0,0,0,0,0,0,0,0,0,0
:endlayer
layer: 10
0,0,0,0,0,0,0,0,0,0,0,0,0,0,0,0,0,0,0,0,0,0,0,0,0,0,0,0,0,0,0,0,0,0,0,0,0
0,0,0,0,0,0,0,0,0,0,0,0,0,0,0,0,0,0,0,0,0,0,0,0,0,0,0,0,0,0,0,0,0,0,0,0,0
0,0,0,0,0,0,0,0,0,0,0,0,0,0,0,0,0,0,0,0,0,0,0,0,0,0,0,0,0,0,0,0,0,0,0,0,0
0,0,0,0,0,0,0,0,0,0,0,0,0,0,0,0,0,0,0,0,0,0,0,0,0,0,0,0,0,0,0,0,0,0,0,0,0
0,0,0,0,0,0,0,0,0,0,0,0,0,0,0,0,0,0,11,0,0,0,0,0,0,0,0,0,0,0,0,0,0,0,0,0,0
0,0,0,0,0,0,0,0,0,0,0,0,0,0,0,0,0,0,0,0,0,0,0,0,0,0,0,0,0,0,0,0,0,0,0,0,0
0,0,0,0,0,0,0,0,0,0,0,0,0,0,0,0,0,0,0,0,0,0,0,0,0,0,0,0,0,0,0,0,0,0,0,0,0
0,0,0,0,0,0,0,0,0,0,0,0,0,0,0,0,0,0,0,0,0,0,0,0,0,0,0,0,0,0,0,0,0,0,0,0,0
0,0,0,0,0,0,0,0,0,0,0,0,0,0,0,0,0,0,0,0,0,0,0,0,0,0,0,0,0,0,0,0,0,0,0,0,0
0,0,0,0,0,0,0,0,0,0,0,0,0,0,0,0,0,0,0,0,0,0,0,0,0,0,0,0,0,0,0,0,0,0,0,0,0
0,0,0,0,0,0,0,0,0,0,0,0,0,0,0,0,0,0,0,0,0,0,0,0,0,0,0,0,0,0,0,0,0,0,0,0,0
0,0,0,0,0,0,0,0,0,0,0,0,0,0,0,0,0,0,0,0,0,0,0,0,0,0,0,0,0,0,0,0,0,0,0,0,0
0,0,0,0,0,0,0,0,0,0,0,0,0,0,0,0,0,0,0,0,0,0,0,0,0,0,0,0,0,0,0,0,34,0,0,0,0
0,0,0,0,0,0,0,0,0,0,0,0,0,0,0,0,0,0,0,0,0,0,0,0,0,0,0,0,0,154,0,0,34,0,0,154,0
0,0,0,1,0,0,0,0,0,0,0,0,0,0,0,0,0,0,0,0,0,0,0,0,0,0,0,0,0,0,154,0,0,0,154,0,0
0,0,0,165,0,0,0,0,0,0,0,0,0,0,0,0,0,0,0,0,0,0,0,0,0,155,0,0,0,0,0,0,0,0,0,0,0
0,0,0,165,0,0,0,0,0,0,0,0,0,0,0,0,0,0,0,0,0,0,0,0,0,0,0,0,34,34,0,0,11,0,0,34,34
0,0,0,165,0,0,0,0,0,0,0,0,0,0,0,0,0,0,0,0,0,0,0,0,0,0,0,0,0,0,0,0,0,0,0,0,0
0,0,0,1,0,0,0,0,0,0,0,0,0,0,0,0,0,0,85,85,85,0,0,0,0,0,0,0,0,0,34,0,0,0,154,0,0
0,0,3,31,31,31,31,3,0,0,0,0,0,0,0,0,1,1,1,1,1,1,1,31,3,0,3,31,3,31,3,31,3,0,0,154,0
0,0,31,166,0,0,0,31,0,0,0,0,0,0,0,0,1,162,160,159,0,23,1,0,0,0,0,0,0,0,0,0,31,0,0,0,0
0,0,31,0,0,0,0,31,0,0,0,0,0,0,0,85,1,162,160,159,0,0,12,0,0,0,32,32,0,0,0,0,3,0,0,0,0
0,0,31,0,0,0,0,31,0,0,0,0,0,0,0,85,1,163,0,0,0,0,1,36,0,0,33,33,0,0,0,0,31,0,0,0,0
0,0,31,0,0,0,0,31,0,0,0,0,0,0,0,85,1,25,0,32,25,25,1,1,0,0,32,32,0,0,1,1,1,1,1,0,0
0,0,31,0,0,0,0,31,0,0,0,0,0,0,0,0,1,26,161,33,26,26,1,157,0,156,0,0,0,0,50,0,0,0,1,85,0
0,0,31,0,0,0,0,31,0,0,0,0,0,0,0,0,1,1,1,1,1,1,1,158,0,0,0,0,0,0,1,0,3,0,1,85,0
0,0,31,0,0,0,164,31,0,0,0,0,0,0,0,0,0,0,85,85,85,0,1,1,0,0,0,0,0,0,1,0,0,0,1,85,0
0,0,3,31,31,31,31,3,0,0,0,0,0,0,0,0,0,0,0,0,0,0,3,31,3,31,3,31,3,31,1,1,1,1,1,0,0
0,0,0,0,0,0,0,0,0,0,0,0,0,0,0,0,0,0,0,0,0,0,0,0,0,0,0,0,0,0,0,85,85,85,0,0,0
0,0,0,0,0,0,0,0,0,0,0,0,0,0,0,0,0,0,0,0,0,0,0,0,0,0,0,0,0,0,0,0,0,0,0,0,0
:endlayer
layer: 11
0,0,0,0,0,0,0,0,0,0,0,0,0,0,0,0,0,0,0,0,0,0,0,0,0,0,0,0,0,0,0,0,0,0,0,0,0
0,0,0,0,0,0,0,0,0,0,0,0,0,0,0,0,0,0,0,0,0,0,0,0,0,0,0,0,0,0,0,0,0,0,0,0,0
0,0,0,0,0,0,0,0,0,0,0,0,0,0,0,0,0,0,0,0,0,0,0,0,0,0,0,0,0,0,0,0,0,0,0,0,0
0,0,0,0,0,0,0,0,0,0,0,0,0,0,0,0,0,0,0,0,0,0,0,0,0,0,0,0,0,0,0,0,0,0,0,0,0
0,0,0,0,0,0,0,0,0,0,0,0,0,0,0,0,0,0,0,0,0,0,0,0,0,0,0,0,0,0,0,0,0,0,0,0,0
0,0,0,0,0,0,0,0,0,0,0,0,0,0,0,0,0,0,11,0,0,0,0,0,0,0,0,0,0,0,0,0,0,0,0,0,0
0,0,0,0,0,0,0,0,0,0,0,0,0,0,0,0,0,0,0,0,0,0,0,0,0,0,0,0,0,0,0,0,0,0,0,0,0
0,0,0,0,0,0,0,0,0,0,0,0,0,0,0,0,0,0,0,0,0,0,0,0,0,0,0,0,0,0,0,0,0,0,0,0,0
0,0,0,0,0,0,0,0,0,0,0,0,0,0,0,0,0,0,0,0,0,0,0,0,0,0,0,0,0,0,0,0,0,0,0,0,0
0,0,0,0,0,0,0,0,0,0,0,0,0,0,0,0,0,0,0,0,0,0,0,0,0,0,0,0,0,0,0,0,0,0,0,0,0
0,0,0,0,0,0,0,0,0,0,0,0,0,0,0,0,0,0,0,0,0,0,0,0,0,0,0,0,0,0,0,0,0,0,0,0,0
0,0,0,0,0,0,0,0,0,0,0,0,0,0,0,0,0,0,0,0,0,0,0,0,0,0,0,0,0,0,0,0,0,0,0,0,0
0,0,0,0,0,0,0,0,0,0,0,0,0,0,0,0,0,0,0,0,0,0,0,0,0,0,0,0,0,0,0,0,0,0,0,0,0
0,0,0,0,0,0,0,0,0,0,0,0,0,0,0,0,0,0,0,0,0,0,0,0,0,0,0,0,0,0,0,0,154,0,0,0,0
0,0,0,0,0,0,0,0,0,0,0,0,0,0,0,0,0,0,0,0,0,0,0,0,0,0,0,0,0,0,154,0,154,0,154,0,0
0,0,0,0,0,0,0,0,0,0,0,0,0,0,0,0,0,0,0,0,0,0,0,0,0,0,0,0,0,0,0,154,154,154,0,0,0
0,0,0,0,0,0,0,0,0,0,0,0,0,0,0,0,0,0,0,0,0,0,0,0,0,0,0,0,0,154,154,154,34,154,154,154,0
0,0,0,0,0,0,0,0,0,0,0,0,0,0,0,0,0,0,0,0,0,0,0,0,0,0,0,0,0,0,0,154,34,154,0,0,0
0,0,0,0,0,0,0,0,0,0,0,0,0,0,0,0,0,0,0,0,0,0,0,0,0,0,0,0,0,0,154,0,34,0,154,0,0
0,0,79,0,0,0,0,79,0,0,0,0,0,0,0,0,1,1,6,1,6,1,1,0,79,0,79,0,0,0,0,0,34,0,0,0,0
0,0,0,0,0,0,0,0,0,0,0,0,0,0,0,0,1,0,0,0,0,95,1,0,0,0,0,0,0,0,0,0,0,0,0,0,0
0,0,0,0,0,0,0,0,0,0,0,0,0,0,0,105,6,0,0,0,0,0,83,0,0,0,0,0,0,0,0,0,0,0,0,0,0
0,0,0,0,0,0,0,0,0,0,0,0,0,0,0,0,1,0,0,0,0,0,1,0,0,0,91,0,0,0,0,0,0,0,0,0,0
0,0,0,0,0,0,0,0,0,0,0,0,0,0,0,0,6,0,0,0,0,0,1,36,0,0,0,0,0,0,1,6,1,6,1,0,0
0,0,0,0,0,0,0,0,0,0,0,0,0,0,0,0,1,0,0,0,0,0,1,99,0,0,0,0,0,0,83,0,0,0,6,0,0
0,0,0,0,0,0,0,0,0,0,0,0,0,0,0,0,1,1,6,1,6,1,1,100,0,0,0,0,0,0,1,0,3,0,1,0,0
0,0,0,0,0,0,0,0,0,0,0,0,0,0,0,0,0,0,0,0,0,0,1,1,0,0,0,0,0,0,6,0,0,0,6,0,0
0,0,79,0,0,0,0,79,0,0,0,0,0,0,0,0,0,0,0,0,0,0,0,0,0,0,0,167,0,0,1,6,1,6,1,0,0
0,0,0,0,0,0,0,0,0,0,0,0,0,0,0,0,0,0,0,0,0,0,0,0,0,0,0,0,0,0,0,0,0,0,0,0,0
0,0,0,0,0,0,0,0,0,0,0,0,0,0,0,0,0,0,0,0,0,0,0,0,0,0,0,0,0,0,0,0,0,0,0,0,0
:endlayer
layer: 12
0,0,0,0,0,0,0,0,0,0,0,0,0,0,0,0,0,0,0,0,0,0,0,0,0,0,0,0,0,0,0,0,0,0,0,0,0
0,0,0,0,0,0,0,0,0,0,0,0,0,0,0,0,0,0,154,0,0,0,0,0,0,0,0,0,0,0,0,0,0,0,0,0,0
0,0,0,0,0,0,0,0,0,0,0,0,0,0,0,154,0,0,154,0,0,154,0,0,0,0,0,0,0,0,0,0,0,0,0,0,0
0,0,0,0,0,0,0,0,0,0,0,0,0,0,0,0,154,0,0,0,154,0,0,0,0,0,0,0,0,0,0,0,0,0,0,0,0
0,0,0,0,0,0,0,0,0,0,0,0,0,0,0,0,0,0,0,0,0,0,0,0,0,0,0,0,0,0,0,0,0,0,0,0,0
0,0,0,0,0,0,0,0,0,0,0,0,0,0,154,154,0,0,11,0,0,154,154,0,0,0,0,0,0,0,0,0,0,0,0,0,0
0,0,0,0,0,0,0,0,0,0,0,0,0,0,0,0,0,0,0,0,0,0,0,0,0,0,0,0,0,0,0,0,0,0,0,0,0
0,0,0,0,0,0,0,0,0,0,0,0,0,0,0,0,154,0,0,0,154,0,0,0,0,0,0,0,0,0,0,0,0,0,0,0,0
0,0,0,0,0,0,0,0,0,0,0,0,0,0,0,154,0,0,154,0,0,154,0,0,0,0,0,0,0,0,0,0,0,0,0,0,0
0,0,0,0,0,0,0,0,0,0,0,0,0,0,0,0,0,0,34,0,0,0,0,0,0,0,0,0,0,0,0,0,0,0,0,0,0
0,0,0,0,0,0,0,0,0,0,0,0,0,0,0,0,0,0,0,0,0,0,0,0,0,0,0,0,0,0,0,0,0,0,0,0,0
0,0,0,0,0,0,0,0,0,0,0,0,0,0,0,0,0,0,0,0,0,0,0,0,0,0,0,0,0,0,0,0,0,0,0,0,0
0,0,0,0,0,0,0,0,0,0,0,0,0,0,0,0,0,0,0,0,0,0,0,0,0,0,0,0,0,0,0,0,0,0,0,0,0
0,0,0,0,0,0,0,0,0,0,0,0,0,0,0,0,0,0,0,0,0,0,0,0,0,0,0,0,0,0,0,0,0,0,0,0,0
0,0,0,0,0,0,0,0,0,0,0,0,0,0,0,0,0,0,0,0,0,0,0,0,0,0,0,0,0,0,0,0,0,0,0,0,0
0,0,0,0,0,0,0,0,0,0,0,0,0,0,0,0,0,0,0,0,0,0,0,0,0,0,0,0,0,0,0,0,0,0,0,0,0
0,0,0,0,0,0,0,0,0,0,0,0,0,0,0,0,0,0,0,0,0,0,0,0,0,0,0,0,0,0,0,0,34,0,0,0,0
0,0,0,0,0,0,0,0,0,0,0,0,0,0,0,0,0,0,0,0,0,0,0,0,0,0,0,0,0,0,0,0,0,0,0,0,0
0,0,0,0,0,0,0,0,0,0,0,0,0,0,0,0,0,0,0,0,0,0,0,0,0,0,0,0,0,0,0,0,0,0,0,0,0
0,0,0,0,0,0,0,0,0,0,0,0,0,0,0,0,1,1,6,1,6,1,1,0,0,0,0,0,0,0,0,0,0,0,0,0,0
0,0,0,0,0,0,0,0,0,0,0,0,0,0,0,0,1,0,0,0,0,0,1,0,0,0,0,0,0,0,0,0,0,0,0,0,0
0,0,0,0,0,0,0,0,0,0,0,0,0,0,0,0,6,0,0,0,0,0,129,0,0,0,0,0,0,0,0,0,0,0,0,0,0
0,0,0,0,0,0,0,0,0,0,0,0,0,0,0,0,1,0,0,0,0,0,1,0,0,0,0,0,0,0,58,0,0,0,0,0,0
0,0,0,0,0,0,0,0,0,0,0,0,0,0,0,0,6,0,0,0,0,0,1,0,0,0,0,0,0,130,1,6,1,6,1,0,0
0,0,0,0,0,0,0,0,0,0,0,0,0,0,0,0,1,0,0,0,0,0,1,36,0,0,0,0,0,0,1,0,0,0,6,0,0
0,0,0,0,0,0,0,0,0,0,0,0,0,0,0,0,1,1,6,1,6,1,1,1,127,0,0,0,0,0,1,0,3,0,1,0,0
0,0,0,0,0,0,0,0,0,0,0,0,0,0,0,0,0,0,0,0,0,0,1,1,0,0,0,0,0,0,6,0,0,0,6,0,0
0,0,0,0,0,0,0,0,0,0,0,0,0,0,0,0,0,0,0,0,0,0,0,0,0,0,0,0,0,0,1,6,1,6,1,0,0
0,0,0,0,0,0,0,0,0,0,0,0,0,0,0,0,0,0,0,0,0,0,0,0,0,0,0,0,0,0,0,0,0,0,0,0,0
0,0,0,0,0,0,0,0,0,0,0,0,0,0,0,0,0,0,0,0,0,0,0,0,0,0,0,0,0,0,0,0,0,0,0,0,0
:endlayer
layer: 13
0,0,0,0,0,0,0,0,0,0,0,0,0,0,0,0,0,0,0,0,0,0,0,0,0,0,0,0,0,0,0,0,0,0,0,0,0
0,0,0,0,0,0,0,0,0,0,0,0,0,0,0,0,0,0,0,0,0,0,0,0,0,0,0,0,0,0,0,0,0,0,0,0,0
0,0,0,0,0,0,0,0,0,0,0,0,0,0,0,0,0,0,154,0,0,0,0,0,0,0,0,0,0,0,0,0,0,0,0,0,0
0,0,0,0,0,0,0,0,0,0,0,0,0,0,0,0,154,0,154,0,154,0,0,0,0,0,0,0,0,0,0,0,0,0,0,0,0
0,0,0,0,0,0,0,0,0,0,0,0,0,0,0,0,0,154,154,154,0,0,0,0,0,0,0,0,0,0,0,0,0,0,0,0,0
0,0,0,0,0,0,0,0,0,0,0,0,0,0,0,154,154,154,154,154,154,154,0,0,0,0,0,0,0,0,0,0,0,0,0,0,0
0,0,0,0,0,0,0,0,0,0,0,0,0,0,0,0,0,154,154,154,0,0,0,0,0,0,0,0,0,0,0,0,0,0,0,0,0
0,0,0,0,0,0,0,0,0,0,0,0,0,0,0,0,154,0,154,0,154,0,0,0,0,0,0,0,0,0,0,0,0,0,0,0,0
0,0,0,0,0,0,0,0,0,0,0,0,0,0,0,0,0,0,154,0,0,0,0,0,0,0,0,0,0,0,0,0,0,0,0,0,0
0,0,0,0,0,0,0,0,0,0,0,0,0,0,0,0,0,0,0,0,0,0,0,0,0,0,0,0,0,0,0,0,0,0,0,0,0
0,0,0,0,0,0,0,0,0,0,0,0,0,0,0,0,0,0,0,0,0,0,0,0,0,0,0,0,0,0,0,0,0,0,0,0,0
0,0,0,0,0,0,0,0,0,0,0,0,0,0,0,0,0,0,0,0,0,0,0,0,0,0,0,0,0,0,0,0,0,0,0,0,0
0,0,0,0,0,0,0,0,0,0,0,0,0,0,0,0,0,0,0,0,0,0,0,0,0,0,0,0,0,0,0,0,0,0,0,0,0
0,0,0,0,0,0,0,0,0,0,0,0,0,0,0,0,0,0,0,0,0,0,0,0,0,0,0,0,0,0,0,0,0,0,0,0,0
0,0,0,0,0,0,0,0,0,0,0,0,0,0,0,0,0,0,0,0,0,0,0,0,0,0,0,0,0,0,0,0,0,0,0,0,0
0,0,0,0,0,0,0,0,0,0,0,0,0,0,0,0,0,0,0,0,0,0,0,0,0,0,0,0,0,0,0,0,0,0,0,0,0
0,0,0,0,0,0,0,0,0,0,0,0,0,0,0,0,0,0,0,0,0,0,0,0,0,0,0,0,0,0,0,0,0,0,0,0,0
0,0,0,0,0,0,0,0,0,0,0,0,0,0,0,0,0,0,0,0,0,0,0,0,0,0,0,0,0,0,0,0,0,0,0,0,0
0,0,0,0,0,0,0,0,0,0,0,0,0,0,0,0,0,0,0,0,0,0,0,0,0,0,0,0,0,0,0,0,0,0,0,0,0
0,0,0,0,0,0,0,0,0,0,0,0,0,0,0,0,1,1,134,1,134,1,1,0,0,0,0,0,0,0,0,0,0,0,0,0,0
0,0,0,0,0,0,0,0,0,0,0,0,0,0,0,0,1,128,0,0,0,128,1,0,0,0,0,0,0,0,0,0,0,0,0,0,0
0,0,0,0,0,0,0,0,0,0,0,0,0,0,0,0,131,0,0,0,0,0,132,0,0,0,0,0,0,0,0,0,0,0,0,0,0
0,0,0,0,0,0,0,0,0,0,0,0,0,0,0,0,1,0,0,0,0,0,1,0,0,0,0,0,0,0,0,85,0,85,0,0,0
0,0,0,0,0,0,0,0,0,0,0,0,0,0,0,0,131,0,0,0,0,0,1,0,0,0,0,0,0,0,153,153,153,153,153,0,0
0,0,0,0,0,0,0,0,0,0,0,0,0,0,0,0,1,58,0,0,0,58,1,0,0,0,0,0,0,85,153,1,1,1,153,85,0
0,0,0,0,0,0,0,0,0,0,0,0,0,0,0,0,1,1,133,1,133,1,1,36,0,0,0,0,0,0,153,1,1,1,153,0,0
0,0,0,0,0,0,0,0,0,0,0,0,0,0,0,0,0,0,0,0,0,139,1,1,0,0,0,0,0,85,153,1,1,1,153,85,0
0,0,0,0,0,0,0,0,0,0,0,0,0,0,0,0,0,0,0,0,0,0,0,0,0,0,0,0,0,0,153,153,153,153,153,0,0
0,0,0,0,0,0,0,0,0,0,0,0,0,0,0,0,0,0,0,0,0,0,0,0,0,0,0,0,0,0,0,85,0,85,0,0,0
0,0,0,0,0,0,0,0,0,0,0,0,0,0,0,0,0,0,0,0,0,0,0,0,0,0,0,0,0,0,0,0,0,0,0,0,0
:endlayer
layer: 14
0,0,0,0,0,0,0,0,0,0,0,0,0,0,0,0,0,0,0,0,0,0,0,0,0,0,0,0,0,0,0,0,0,0,0,0,0
0,0,0,0,0,0,0,0,0,0,0,0,0,0,0,0,0,0,0,0,0,0,0,0,0,0,0,0,0,0,0,0,0,0,0,0,0
0,0,0,0,0,0,0,0,0,0,0,0,0,0,0,0,0,0,0,0,0,0,0,0,0,0,0,0,0,0,0,0,0,0,0,0,0
0,0,0,0,0,0,0,0,0,0,0,0,0,0,0,0,0,0,0,0,0,0,0,0,0,0,0,0,0,0,0,0,0,0,0,0,0
0,0,0,0,0,0,0,0,0,0,0,0,0,0,0,0,0,0,0,0,0,0,0,0,0,0,0,0,0,0,0,0,0,0,0,0,0
0,0,0,0,0,0,0,0,0,0,0,0,0,0,0,0,0,0,154,0,0,0,0,0,0,0,0,0,0,0,0,0,0,0,0,0,0
0,0,0,0,0,0,0,0,0,0,0,0,0,0,0,0,0,0,0,0,0,0,0,0,0,0,0,0,0,0,0,0,0,0,0,0,0
0,0,0,0,0,0,0,0,0,0,0,0,0,0,0,0,0,0,0,0,0,0,0,0,0,0,0,0,0,0,0,0,0,0,0,0,0
0,0,0,0,0,0,0,0,0,0,0,0,0,0,0,0,0,0,0,0,0,0,0,0,0,0,0,0,0,0,0,0,0,0,0,0,0
0,0,0,0,0,0,0,0,0,0,0,0,0,0,0,0,0,0,0,0,0,0,0,0,0,0,0,0,0,0,0,0,0,0,0,0,0
0,0,0,0,0,0,0,0,0,0,0,0,0,0,0,0,0,0,0,0,0,0,0,0,0,0,0,0,0,0,0,0,0,0,0,0,0
0,0,0,0,0,0,0,0,0,0,0,0,0,0,0,0,0,0,0,0,0,0,0,0,0,0,0,0,0,0,0,0,0,0,0,0,0
0,0,0,0,0,0,0,0,0,0,0,0,0,0,0,0,0,0,0,0,0,0,0,0,0,0,0,0,0,0,0,0,0,0,0,0,0
0,0,0,0,0,0,0,0,0,0,0,0,0,0,0,0,0,0,0,0,0,0,0,0,0,0,0,0,0,0,0,0,0,0,0,0,0
0,0,0,0,0,0,0,0,0,0,0,0,0,0,0,0,0,0,0,0,0,0,0,0,0,0,0,0,0,0,0,0,0,0,0,0,0
0,0,0,0,0,0,0,0,0,0,0,0,0,0,0,0,0,0,0,0,0,0,0,0,0,0,0,0,0,0,0,0,0,0,0,0,0
0,0,0,0,0,0,0,0,0,0,0,0,0,0,0,0,0,0,0,0,0,0,0,0,0,0,0,0,0,0,0,0,0,0,0,0,0
0,0,0,0,0,0,0,0,0,0,0,0,0,0,0,0,0,0,0,0,0,0,0,0,0,0,0,0,0,0,0,0,0,0,0,0,0
0,0,0,0,0,0,0,0,0,0,0,0,0,0,0,0,0,147,147,147,147,147,0,0,0,0,0,0,0,0,0,0,0,0,0,0,0
0,0,0,0,0,0,0,0,0,0,0,0,0,0,0,0,153,153,153,153,153,153,153,0,0,0,0,0,0,0,0,0,0,0,0,0,0
0,0,0,0,0,0,0,0,0,0,0,0,0,0,0,147,153,1,1,1,1,1,153,0,0,0,0,0,0,0,0,0,0,0,0,0,0
0,0,0,0,0,0,0,0,0,0,0,0,0,0,0,147,153,1,1,1,1,1,153,0,0,0,0,0,0,0,0,0,0,0,0,0,0
0,0,0,0,0,0,0,0,0,0,0,0,0,0,0,147,153,1,1,1,1,1,153,0,0,0,0,0,0,0,0,0,0,0,0,0,0
0,0,0,0,0,0,0,0,0,0,0,0,0,0,0,147,153,1,1,1,1,1,153,0,0,0,0,0,0,0,1,165,165,165,1,0,0
0,0,0,0,0,0,0,0,0,0,0,0,0,0,0,147,153,1,1,1,1,1,153,0,0,0,0,0,0,0,165,0,0,0,165,0,0
0,0,0,0,0,0,0,0,0,0,0,0,0,0,0,0,153,153,153,153,153,153,153,0,0,0,0,0,0,0,165,0,79,0,165,0,0
0,0,0,0,0,0,0,0,0,0,0,0,0,0,0,0,0,147,147,147,1,1,65,0,0,0,0,0,0,0,165,0,0,0,165,0,0
0,0,0,0,0,0,0,0,0,0,0,0,0,0,0,0,0,0,0,0,0,0,0,0,0,0,0,0,0,0,1,165,165,165,1,0,0
0,0,0,0,0,0,0,0,0,0,0,0,0,0,0,0,0,0,0,0,0,0,0,0,0,0,0,0,0,0,0,0,0,0,0,0,0
0,0,0,0,0,0,0,0,0,0,0,0,0,0,0,0,0,0,0,0,0,0,0,0,0,0,0,0,0,0,0,0,0,0,0,0,0
:endlayer
layer: 15
0,0,0,0,0,0,0,0,0,0,0,0,0,0,0,0,0,0,0,0,0,0,0,0,0,0,0,0,0,0,0,0,0,0,0,0,0
0,0,0,0,0,0,0,0,0,0,0,0,0,0,0,0,0,0,0,0,0,0,0,0,0,0,0,0,0,0,0,0,0,0,0,0,0
0,0,0,0,0,0,0,0,0,0,0,0,0,0,0,0,0,0,0,0,0,0,0,0,0,0,0,0,0,0,0,0,0,0,0,0,0
0,0,0,0,0,0,0,0,0,0,0,0,0,0,0,0,0,0,0,0,0,0,0,0,0,0,0,0,0,0,0,0,0,0,0,0,0
0,0,0,0,0,0,0,0,0,0,0,0,0,0,0,0,0,0,0,0,0,0,0,0,0,0,0,0,0,0,0,0,0,0,0,0,0
0,0,0,0,0,0,0,0,0,0,0,0,0,0,0,0,0,0,0,0,0,0,0,0,0,0,0,0,0,0,0,0,0,0,0,0,0
0,0,0,0,0,0,0,0,0,0,0,0,0,0,0,0,0,0,0,0,0,0,0,0,0,0,0,0,0,0,0,0,0,0,0,0,0
0,0,0,0,0,0,0,0,0,0,0,0,0,0,0,0,0,0,0,0,0,0,0,0,0,0,0,0,0,0,0,0,0,0,0,0,0
0,0,0,0,0,0,0,0,0,0,0,0,0,0,0,0,0,0,0,0,0,0,0,0,0,0,0,0,0,0,0,0,0,0,0,0,0
0,0,0,0,0,0,0,0,0,0,0,0,0,0,0,0,0,0,0,0,0,0,0,0,0,0,0,0,0,0,0,0,0,0,0,0,0
0,0,0,0,0,0,0,0,0,0,0,0,0,0,0,0,0,0,0,0,0,0,0,0,0,0,0,0,0,0,0,0,0,0,0,0,0
0,0,0,0,0,0,0,0,0,0,0,0,0,0,0,0,0,0,0,0,0,0,0,0,0,0,0,0,0,0,0,0,0,0,0,0,0
0,0,0,0,0,0,0,0,0,0,0,0,0,0,0,0,0,0,0,0,0,0,0,0,0,0,0,0,0,0,0,0,0,0,0,0,0
0,0,0,0,0,0,0,0,0,0,0,0,0,0,0,0,0,0,0,0,0,0,0,0,0,0,0,0,0,0,0,0,0,0,0,0,0
0,0,0,0,0,0,0,0,0,0,0,0,0,0,0,0,0,0,0,0,0,0,0,0,0,0,0,0,0,0,0,0,0,0,0,0,0
0,0,0,0,0,0,0,0,0,0,0,0,0,0,0,0,0,0,0,0,0,0,0,0,0,0,0,0,0,0,0,0,0,0,0,0,0
0,0,0,0,0,0,0,0,0,0,0,0,0,0,0,0,0,0,0,0,0,0,0,0,0,0,0,0,0,0,0,0,0,0,0,0,0
0,0,0,0,0,0,0,0,0,0,0,0,0,0,0,0,0,0,0,0,0,0,0,0,0,0,0,0,0,0,0,0,0,0,0,0,0
0,0,0,0,0,0,0,0,0,0,0,0,0,0,0,0,0,0,0,0,0,0,0,0,0,0,0,0,0,0,0,0,0,0,0,0,0
0,0,0,0,0,0,0,0,0,0,0,0,0,0,0,0,3,31,31,31,31,31,3,0,0,0,0,0,0,0,0,0,0,0,0,0,0
0,0,0,0,0,0,0,0,0,0,0,0,0,0,0,0,31,6,168,0,0,6,31,0,0,0,0,0,0,0,0,0,0,0,0,0,0
0,0,0,0,0,0,0,0,0,0,0,0,0,0,0,0,31,159,33,33,159,0,31,0,0,0,0,0,0,0,0,0,0,0,0,0,0
0,0,0,0,0,0,0,0,0,0,0,0,0,0,0,0,31,159,33,33,159,0,31,0,0,0,0,0,0,0,0,0,0,0,0,0,0
0,0,0,0,0,0,0,0,0,0,0,0,0,0,0,0,31,159,33,33,159,0,31,0,0,0,0,0,0,0,0,0,0,0,0,0,0
0,0,0,0,0,0,0,0,0,0,0,0,0,0,0,0,31,6,0,0,0,6,31,0,0,0,0,0,0,0,0,0,0,0,0,0,0
0,0,0,0,0,0,0,0,0,0,0,0,0,0,0,0,3,31,31,31,31,31,3,0,0,0,0,0,0,0,0,0,0,0,0,0,0
0,0,0,0,0,0,0,0,0,0,0,0,0,0,0,0,0,0,0,0,0,0,0,0,0,0,0,0,0,0,0,0,0,0,0,0,0
0,0,0,0,0,0,0,0,0,0,0,0,0,0,0,0,0,0,0,0,0,0,0,0,0,0,0,0,0,0,0,0,0,0,0,0,0
0,0,0,0,0,0,0,0,0,0,0,0,0,0,0,0,0,0,0,0,0,0,0,0,0,0,0,0,0,0,0,0,0,0,0,0,0
0,0,0,0,0,0,0,0,0,0,0,0,0,0,0,0,0,0,0,0,0,0,0,0,0,0,0,0,0,0,0,0,0,0,0,0,0
:endlayer
layer: 16
0,0,0,0,0,0,0,0,0,0,0,0,0,0,0,0,0,0,0,0,0,0,0,0,0,0,0,0,0,0,0,0,0,0,0,0,0
0,0,0,0,0,0,0,0,0,0,0,0,0,0,0,0,0,0,0,0,0,0,0,0,0,0,0,0,0,0,0,0,0,0,0,0,0
0,0,0,0,0,0,0,0,0,0,0,0,0,0,0,0,0,0,0,0,0,0,0,0,0,0,0,0,0,0,0,0,0,0,0,0,0
0,0,0,0,0,0,0,0,0,0,0,0,0,0,0,0,0,0,0,0,0,0,0,0,0,0,0,0,0,0,0,0,0,0,0,0,0
0,0,0,0,0,0,0,0,0,0,0,0,0,0,0,0,0,0,0,0,0,0,0,0,0,0,0,0,0,0,0,0,0,0,0,0,0
0,0,0,0,0,0,0,0,0,0,0,0,0,0,0,0,0,0,0,0,0,0,0,0,0,0,0,0,0,0,0,0,0,0,0,0,0
0,0,0,0,0,0,0,0,0,0,0,0,0,0,0,0,0,0,0,0,0,0,0,0,0,0,0,0,0,0,0,0,0,0,0,0,0
0,0,0,0,0,0,0,0,0,0,0,0,0,0,0,0,0,0,0,0,0,0,0,0,0,0,0,0,0,0,0,0,0,0,0,0,0
0,0,0,0,0,0,0,0,0,0,0,0,0,0,0,0,0,0,0,0,0,0,0,0,0,0,0,0,0,0,0,0,0,0,0,0,0
0,0,0,0,0,0,0,0,0,0,0,0,0,0,0,0,0,0,0,0,0,0,0,0,0,0,0,0,0,0,0,0,0,0,0,0,0
0,0,0,0,0,0,0,0,0,0,0,0,0,0,0,0,0,0,0,0,0,0,0,0,0,0,0,0,0,0,0,0,0,0,0,0,0
0,0,0,0,0,0,0,0,0,0,0,0,0,0,0,0,0,0,0,0,0,0,0,0,0,0,0,0,0,0,0,0,0,0,0,0,0
0,0,0,0,0,0,0,0,0,0,0,0,0,0,0,0,0,0,0,0,0,0,0,0,0,0,0,0,0,0,0,0,0,0,0,0,0
0,0,0,0,0,0,0,0,0,0,0,0,0,0,0,0,0,0,0,0,0,0,0,0,0,0,0,0,0,0,0,0,0,0,0,0,0
0,0,0,0,0,0,0,0,0,0,0,0,0,0,0,0,0,0,0,0,0,0,0,0,0,0,0,0,0,0,0,0,0,0,0,0,0
0,0,0,0,0,0,0,0,0,0,0,0,0,0,0,0,0,0,0,0,0,0,0,0,0,0,0,0,0,0,0,0,0,0,0,0,0
0,0,0,0,0,0,0,0,0,0,0,0,0,0,0,0,0,0,0,0,0,0,0,0,0,0,0,0,0,0,0,0,0,0,0,0,0
0,0,0,0,0,0,0,0,0,0,0,0,0,0,0,0,0,0,0,0,0,0,0,0,0,0,0,0,0,0,0,0,0,0,0,0,0
0,0,0,0,0,0,0,0,0,0,0,0,0,0,0,0,0,0,0,0,0,0,0,0,0,0,0,0,0,0,0,0,0,0,0,0,0
0,0,0,0,0,0,0,0,0,0,0,0,0,0,0,0,79,0,0,0,0,0,79,0,0,0,0,0,0,0,0,0,0,0,0,0,0
0,0,0,0,0,0,0,0,0,0,0,0,0,0,0,0,0,6,0,0,0,6,0,0,0,0,0,0,0,0,0,0,0,0,0,0,0
0,0,0,0,0,0,0,0,0,0,0,0,0,0,0,0,0,0,91,0,0,0,0,0,0,0,0,0,0,0,0,0,0,0,0,0,0
0,0,0,0,0,0,0,0,0,0,0,0,0,0,0,0,0,0,0,0,0,0,0,0,0,0,0,0,0,0,0,0,0,0,0,0,0
0,0,0,0,0,0,0,0,0,0,0,0,0,0,0,0,0,0,0,0,0,0,0,0,0,0,0,0,0,0,0,0,0,0,0,0,0
0,0,0,0,0,0,0,0,0,0,0,0,0,0,0,0,0,6,0,0,0,6,0,0,0,0,0,0,0,0,0,0,0,0,0,0,0
0,0,0,0,0,0,0,0,0,0,0,0,0,0,0,0,79,0,169,0,0,0,79,0,0,0,0,0,0,0,0,0,0,0,0,0,0
0,0,0,0,0,0,0,0,0,0,0,0,0,0,0,0,0,0,0,0,0,0,0,0,0,0,0,0,0,0,0,0,0,0,0,0,0
0,0,0,0,0,0,0,0,0,0,0,0,0,0,0,0,0,0,0,0,0,0,0,0,0,0,0,0,0,0,0,0,0,0,0,0,0
0,0,0,0,0,0,0,0,0,0,0,0,0,0,0,0,0,0,0,0,0,0,0,0,0,0,0,0,0,0,0,0,0,0,0,0,0
0,0,0,0,0,0,0,0,0,0,0,0,0,0,0,0,0,0,0,0,0,0,0,0,0,0,0,0,0,0,0,0,0,0,0,0,0
:endlayer
layer: 17
0,0,0,0,0,0,0,0,0,0,0,0,0,0,0,0,0,0,0,0,0,0,0,0,0,0,0,0,0,0,0,0,0,0,0,0,0
0,0,0,0,0,0,0,0,0,0,0,0,0,0,0,0,0,0,0,0,0,0,0,0,0,0,0,0,0,0,0,0,0,0,0,0,0
0,0,0,0,0,0,0,0,0,0,0,0,0,0,0,0,0,0,0,0,0,0,0,0,0,0,0,0,0,0,0,0,0,0,0,0,0
0,0,0,0,0,0,0,0,0,0,0,0,0,0,0,0,0,0,0,0,0,0,0,0,0,0,0,0,0,0,0,0,0,0,0,0,0
0,0,0,0,0,0,0,0,0,0,0,0,0,0,0,0,0,0,0,0,0,0,0,0,0,0,0,0,0,0,0,0,0,0,0,0,0
0,0,0,0,0,0,0,0,0,0,0,0,0,0,0,0,0,0,0,0,0,0,0,0,0,0,0,0,0,0,0,0,0,0,0,0,0
0,0,0,0,0,0,0,0,0,0,0,0,0,0,0,0,0,0,0,0,0,0,0,0,0,0,0,0,0,0,0,0,0,0,0,0,0
0,0,0,0,0,0,0,0,0,0,0,0,0,0,0,0,0,0,0,0,0,0,0,0,0,0,0,0,0,0,0,0,0,0,0,0,0
0,0,0,0,0,0,0,0,0,0,0,0,0,0,0,0,0,0,0,0,0,0,0,0,0,0,0,0,0,0,0,0,0,0,0,0,0
0,0,0,0,0,0,0,0,0,0,0,0,0,0,0,0,0,0,0,0,0,0,0,0,0,0,0,0,0,0,0,0,0,0,0,0,0
0,0,0,0,0,0,0,0,0,0,0,0,0,0,0,0,0,0,0,0,0,0,0,0,0,0,0,0,0,0,0,0,0,0,0,0,0
0,0,0,0,0,0,0,0,0,0,0,0,0,0,0,0,0,0,0,0,0,0,0,0,0,0,0,0,0,0,0,0,0,0,0,0,0
0,0,0,0,0,0,0,0,0,0,0,0,0,0,0,0,0,0,0,0,0,0,0,0,0,0,0,0,0,0,0,0,0,0,0,0,0
0,0,0,0,0,0,0,0,0,0,0,0,0,0,0,0,0,0,0,0,0,0,0,0,0,0,0,0,0,0,0,0,0,0,0,0,0
0,0,0,0,0,0,0,0,0,0,0,0,0,0,0,0,0,0,0,0,0,0,0,0,0,0,0,0,0,0,0,0,0,0,0,0,0
0,0,0,0,0,0,0,0,0,0,0,0,0,0,0,0,0,0,0,0,0,0,0,0,0,0,0,0,0,0,0,0,0,0,0,0,0
0,0,0,0,0,0,0,0,0,0,0,0,0,0,0,0,0,0,0,0,0,0,0,0,0,0,0,0,0,0,0,0,0,0,0,0,0
0,0,0,0,0,0,0,0,0,0,0,0,0,0,0,0,0,0,0,0,0,0,0,0,0,0,0,0,0,0,0,0,0,0,0,0,0
0,0,0,0,0,0,0,0,0,0,0,0,0,0,0,0,0,0,0,0,0,0,0,0,0,0,0,0,0,0,0,0,0,0,0,0,0
0,0,0,0,0,0,0,0,0,0,0,0,0,0,0,0,0,0,0,0,0,0,0,0,0,0,0,0,0,0,0,0,0,0,0,0,0
0,0,0,0,0,0,0,0,0,0,0,0,0,0,0,0,0,6,0,0,0,6,0,0,0,0,0,0,0,0,0,0,0,0,0,0,0
0,0,0,0,0,0,0,0,0,0,0,0,0,0,0,0,0,0,0,0,0,0,0,0,0,0,0,0,0,0,0,0,0,0,0,0,0
0,0,0,0,0,0,0,0,0,0,0,0,0,0,0,0,0,0,0,0,0,0,0,0,0,0,0,0,0,0,0,0,0,0,0,0,0
0,0,0,0,0,0,0,0,0,0,0,0,0,0,0,0,0,0,0,0,0,0,0,0,0,0,0,0,0,0,0,0,0,0,0,0,0
0,0,0,0,0,0,0,0,0,0,0,0,0,0,0,0,0,6,0,0,0,6,0,0,0,0,0,0,0,0,0,0,0,0,0,0,0
0,0,0,0,0,0,0,0,0,0,0,0,0,0,0,0,0,0,0,0,0,0,0,0,0,0,0,0,0,0,0,0,0,0,0,0,0
0,0,0,0,0,0,0,0,0,0,0,0,0,0,0,0,0,0,0,0,0,0,0,0,0,0,0,0,0,0,0,0,0,0,0,0,0
0,0,0,0,0,0,0,0,0,0,0,0,0,0,0,0,0,0,0,0,0,0,0,0,0,0,0,0,0,0,0,0,0,0,0,0,0
0,0,0,0,0,0,0,0,0,0,0,0,0,0,0,0,0,0,0,0,0,0,0,0,0,0,0,0,0,0,0,0,0,0,0,0,0
0,0,0,0,0,0,0,0,0,0,0,0,0,0,0,0,0,0,0,0,0,0,0,0,0,0,0,0,0,0,0,0,0,0,0,0,0
:endlayer
layer: 18
0,0,0,0,0,0,0,0,0,0,0,0,0,0,0,0,0,0,0,0,0,0,0,0,0,0,0,0,0,0,0,0,0,0,0,0,0
0,0,0,0,0,0,0,0,0,0,0,0,0,0,0,0,0,0,0,0,0,0,0,0,0,0,0,0,0,0,0,0,0,0,0,0,0
0,0,0,0,0,0,0,0,0,0,0,0,0,0,0,0,0,0,0,0,0,0,0,0,0,0,0,0,0,0,0,0,0,0,0,0,0
0,0,0,0,0,0,0,0,0,0,0,0,0,0,0,0,0,0,0,0,0,0,0,0,0,0,0,0,0,0,0,0,0,0,0,0,0
0,0,0,0,0,0,0,0,0,0,0,0,0,0,0,0,0,0,0,0,0,0,0,0,0,0,0,0,0,0,0,0,0,0,0,0,0
0,0,0,0,0,0,0,0,0,0,0,0,0,0,0,0,0,0,0,0,0,0,0,0,0,0,0,0,0,0,0,0,0,0,0,0,0
0,0,0,0,0,0,0,0,0,0,0,0,0,0,0,0,0,0,0,0,0,0,0,0,0,0,0,0,0,0,0,0,0,0,0,0,0
0,0,0,0,0,0,0,0,0,0,0,0,0,0,0,0,0,0,0,0,0,0,0,0,0,0,0,0,0,0,0,0,0,0,0,0,0
0,0,0,0,0,0,0,0,0,0,0,0,0,0,0,0,0,0,0,0,0,0,0,0,0,0,0,0,0,0,0,0,0,0,0,0,0
0,0,0,0,0,0,0,0,0,0,0,0,0,0,0,0,0,0,0,0,0,0,0,0,0,0,0,0,0,0,0,0,0,0,0,0,0
0,0,0,0,0,0,0,0,0,0,0,0,0,0,0,0,0,0,0,0,0,0,0,0,0,0,0,0,0,0,0,0,0,0,0,0,0
0,0,0,0,0,0,0,0,0,0,0,0,0,0,0,0,0,0,0,0,0,0,0,0,0,0,0,0,0,0,0,0,0,0,0,0,0
0,0,0,0,0,0,0,0,0,0,0,0,0,0,0,0,0,0,0,0,0,0,0,0,0,0,0,0,0,0,0,0,0,0,0,0,0
0,0,0,0,0,0,0,0,0,0,0,0,0,0,0,0,0,0,0,0,0,0,0,0,0,0,0,0,0,0,0,0,0,0,0,0,0
0,0,0,0,0,0,0,0,0,0,0,0,0,0,0,0,0,0,0,0,0,0,0,0,0,0,0,0,0,0,0,0,0,0,0,0,0
0,0,0,0,0,0,0,0,0,0,0,0,0,0,0,0,0,0,0,0,0,0,0,0,0,0,0,0,0,0,0,0,0,0,0,0,0
0,0,0,0,0,0,0,0,0,0,0,0,0,0,0,0,0,0,0,0,0,0,0,0,0,0,0,0,0,0,0,0,0,0,0,0,0
0,0,0,0,0,0,0,0,0,0,0,0,0,0,0,0,0,0,0,0,0,0,0,0,0,0,0,0,0,0,0,0,0,0,0,0,0
0,0,0,0,0,0,0,0,0,0,0,0,0,0,0,0,0,0,0,0,0,0,0,0,0,0,0,0,0,0,0,0,0,0,0,0,0
0,0,0,0,0,0,0,0,0,0,0,0,0,0,0,0,0,0,0,0,0,0,0,0,0,0,0,0,0,0,0,0,0,0,0,0,0
0,0,0,0,0,0,0,0,0,0,0,0,0,0,0,0,0,148,148,148,148,148,0,0,0,0,0,0,0,0,0,0,0,0,0,0,0
0,0,0,0,0,0,0,0,0,0,0,0,0,0,0,0,0,148,150,150,150,148,0,0,0,0,0,0,0,0,0,0,0,0,0,0,0
0,0,0,0,0,0,0,0,0,0,0,0,0,0,0,0,0,148,149,149,149,148,0,0,0,0,0,0,0,0,0,0,0,0,0,0,0
0,0,0,0,0,0,0,0,0,0,0,0,0,0,0,0,0,148,150,150,150,148,0,0,0,0,0,0,0,0,0,0,0,0,0,0,0
0,0,0,0,0,0,0,0,0,0,0,0,0,0,0,0,0,148,148,148,148,148,0,0,0,0,0,0,0,0,0,0,0,0,0,0,0
0,0,0,0,0,0,0,0,0,0,0,0,0,0,0,0,0,0,0,0,0,0,0,0,0,0,0,0,0,0,0,0,0,0,0,0,0
0,0,0,0,0,0,0,0,0,0,0,0,0,0,0,0,0,0,0,0,0,0,0,0,0,0,0,0,0,0,0,0,0,0,0,0,0
0,0,0,0,0,0,0,0,0,0,0,0,0,0,0,0,0,0,0,0,0,0,0,0,0,0,0,0,0,0,0,0,0,0,0,0,0
0,0,0,0,0,0,0,0,0,0,0,0,0,0,0,0,0,0,0,0,0,0,0,0,0,0,0,0,0,0,0,0,0,0,0,0,0
0,0,0,0,0,0,0,0,0,0,0,0,0,0,0,0,0,0,0,0,0,0,0,0,0,0,0,0,0,0,0,0,0,0,0,0,0
:endlayer

#### RULES ####
rule:
plugin=vanillaBlocks
number=1
data:
JSON:{blockState:{blockName:"minecraft:sandstone",properties:{type:"sandstone"}}}
:enddata
:endrule

rule:
plugin=vanillaBlocks
number=2
data:
JSON:{blockState:{blockName:"minecraft:sand",properties:{variant:"sand"}}}
:enddata
:endrule

rule:
plugin=vanillaBlocks
number=3
data:
JSON:{blockState:{blockName:"minecraft:red_sandstone",properties:{type:"red_sandstone"}}}
:enddata
:endrule

rule:
plugin=vanillaBlocks
number=4
data:
JSON:{blockState:{blockName:"minecraft:dirt",properties:{variant:"coarse_dirt",snowy:"false"}}}
:enddata
:endrule

rule:
plugin=blockTile
number=5
data:
JSON:{blockState:{blockName:"ancientwarfarestructure:advanced_spawner",properties:{transparent:"true"}},teData:{id:"ancientwarfarestructure:advanced_spawner_tile",spawnerSettings:{minDelay:10,spawnDelay:9,lightSensitive:0b,spawnGroups:[{settingsList:[{remainingSpawnCount:1,hostile:1b,customTag:{ArmorDropChances:[0.085f,0.085f,0.085f,0.085f],hasCustomEquipment:0b,ArmorItems:[{},{},{},{}],skinSettings:{npcTypeName:"custom",skinTypeSelected:"default"},HandDropChances:[0.085f,0.085f],factionName:"sarkonid",HandItems:[{id:"ancientwarfarenpc:golden_lance",Count:1b,Damage:0s},{}]},maxToSpawn:1,entityId:"ancientwarfarenpc:faction.cavalry",minToSpawn:1}],groupWeight:1}],playerRange:16,respondToRedstone:0b,inventory:{Size:9,Items:[]},spawnRange:0,transparent:1b,maxDelay:10,spawnYOffset:0,xpToDrop:0,mobRange:0,debugMode:0b,maxNearbyMonsters:0}}}
:enddata
:endrule

rule:
plugin=vanillaBlocks
number=6
data:
JSON:{blockState:{blockName:"minecraft:birch_fence",properties:{east:"false",south:"false",north:"false",west:"false"}}}
:enddata
:endrule

rule:
plugin=blockTile
number=7
data:
JSON:{blockState:{blockName:"ancientwarfarestructure:advanced_loot_chest",properties:{facing:"east"}},teData:{lootSettings:{lootRolls:1,splashPotion:0b,hasMessage:0b,hasLoot:1b,lootTableName:"ancientwarfare:chests/compat/harvestcraft/harvestcraft_village_farm_flax",spawnEntity:0b},Items:[],id:"ancientwarfarestructure:advanced_loot_chest_tile",Lock:""}}
:enddata
:endrule

rule:
plugin=blockTile
number=8
data:
JSON:{blockState:{blockName:"ancientwarfarestructure:advanced_loot_chest",properties:{facing:"east"}},teData:{lootSettings:{lootRolls:1,splashPotion:0b,hasMessage:0b,hasLoot:1b,lootTableName:"ancientwarfare:chests/compat/harvestcraft/harvestcraft_village_farm_flax",spawnEntity:0b},Items:[],id:"ancientwarfarestructure:advanced_loot_chest_tile",Lock:""}}
:enddata
:endrule

rule:
plugin=vanillaBlocks
number=9
data:
JSON:{blockState:{blockName:"minecraft:cactus",properties:{age:"0"}}}
:enddata
:endrule

rule:
plugin=blockTile
number=10
data:
JSON:{blockState:{blockName:"ancientwarfarestructure:advanced_spawner",properties:{transparent:"true"}},teData:{id:"ancientwarfarestructure:advanced_spawner_tile",spawnerSettings:{minDelay:10,spawnDelay:4,lightSensitive:0b,spawnGroups:[{settingsList:[{remainingSpawnCount:1,hostile:1b,customTag:{ArmorDropChances:[0.085f,0.085f,0.085f,0.085f],hasCustomEquipment:0b,ArmorItems:[{},{},{},{}],skinSettings:{npcTypeName:"custom",skinTypeSelected:"default"},HandDropChances:[0.085f,0.085f],factionName:"sarkonid",HandItems:[{id:"ancientwarfarenpc:golden_spear",Count:1b,Damage:0s},{id:"ancientwarfarenpc:gold_shield",Count:1b,Damage:0s}]},maxToSpawn:1,entityId:"ancientwarfarenpc:faction.soldier",minToSpawn:1}],groupWeight:1}],playerRange:16,respondToRedstone:0b,inventory:{Size:9,Items:[]},spawnRange:0,transparent:1b,maxDelay:10,spawnYOffset:0,xpToDrop:0,mobRange:0,debugMode:0b,maxNearbyMonsters:0}}}
:enddata
:endrule

rule:
plugin=vanillaBlocks
number=11
data:
JSON:{blockState:{blockName:"minecraft:log",properties:{variant:"jungle",axis:"y"}}}
:enddata
:endrule

rule:
plugin=doors
number=12
data:
JSON:{blockState:{blockName:"minecraft:spruce_door",properties:{hinge:"left",half:"lower",powered:"false",facing:"west",open:"false"}}}
:enddata
:endrule

rule:
plugin=bed
number=13
data:
JSON:{blockState:{blockName:"minecraft:bed",properties:{part:"head",facing:"east",occupied:"false"}},bedColor:3}
:enddata
:endrule

rule:
plugin=bed
number=14
data:
JSON:{blockState:{blockName:"minecraft:bed",properties:{part:"foot",facing:"east",occupied:"false"}},bedColor:3}
:enddata
:endrule

rule:
plugin=vanillaBlocks
number=15
data:
JSON:{blockState:{blockName:"minecraft:sandstone_stairs",properties:{half:"bottom",shape:"straight",facing:"east"}}}
:enddata
:endrule

rule:
plugin=blockTile
number=16
data:
JSON:{blockState:{blockName:"ancientwarfarestructure:advanced_spawner",properties:{transparent:"true"}},teData:{id:"ancientwarfarestructure:advanced_spawner_tile",spawnerSettings:{minDelay:10,spawnDelay:6,lightSensitive:0b,spawnGroups:[{settingsList:[{remainingSpawnCount:1,hostile:0b,customTag:{ArmorDropChances:[0.085f,0.085f,0.085f,0.085f],ArmorItems:[{},{},{},{}],HandDropChances:[0.085f,0.085f],HandItems:[{},{}]},maxToSpawn:1,entityId:"minecraft:llama",minToSpawn:1}],groupWeight:1}],playerRange:16,respondToRedstone:0b,inventory:{Size:9,Items:[]},spawnRange:0,transparent:1b,maxDelay:10,spawnYOffset:0,xpToDrop:0,mobRange:0,debugMode:0b,maxNearbyMonsters:0}}}
:enddata
:endrule

rule:
plugin=blockTile
number=17
data:
JSON:{blockState:{blockName:"ancientwarfarestructure:advanced_loot_chest",properties:{facing:"south"}},teData:{lootSettings:{lootRolls:1,splashPotion:0b,hasMessage:0b,hasLoot:1b,lootTableName:"ancientwarfare:chests/citizen_medium_value",spawnEntity:0b,entity:"minecraft:"},Items:[],id:"ancientwarfarestructure:advanced_loot_chest_tile",Lock:""}}
:enddata
:endrule

rule:
plugin=blockTile
number=18
data:
JSON:{blockState:{blockName:"ancientwarfarestructure:advanced_spawner",properties:{transparent:"true"}},teData:{id:"ancientwarfarestructure:advanced_spawner_tile",spawnerSettings:{minDelay:10,spawnDelay:9,lightSensitive:0b,spawnGroups:[{settingsList:[{remainingSpawnCount:1,hostile:1b,customTag:{ArmorDropChances:[0.085f,0.085f,0.085f,0.085f],hasCustomEquipment:0b,ArmorItems:[{},{},{},{}],skinSettings:{npcTypeName:"custom",skinTypeSelected:"default"},HandDropChances:[0.085f,0.085f],factionName:"sarkonid",HandItems:[{},{}]},maxToSpawn:1,entityId:"ancientwarfarenpc:faction.civilian.male",minToSpawn:1}],groupWeight:1}],playerRange:16,respondToRedstone:0b,inventory:{Size:9,Items:[]},spawnRange:0,transparent:1b,maxDelay:10,spawnYOffset:0,xpToDrop:0,mobRange:0,debugMode:0b,maxNearbyMonsters:0}}}
:enddata
:endrule

rule:
plugin=blockTile
number=19
data:
JSON:{blockState:{blockName:"ancientwarfarestructure:advanced_loot_chest",properties:{facing:"north"}},teData:{lootSettings:{lootRolls:1,splashPotion:0b,hasMessage:0b,hasLoot:1b,lootTableName:"ancientwarfare:chests/sarkonid",spawnEntity:0b,entity:"minecraft:"},Items:[],id:"ancientwarfarestructure:advanced_loot_chest_tile",Lock:""}}
:enddata
:endrule

rule:
plugin=vanillaBlocks
number=20
data:
JSON:{blockState:{blockName:"minecraft:birch_fence_gate",properties:{in_wall:"false",powered:"false",facing:"east",open:"false"}}}
:enddata
:endrule

rule:
plugin=blockTile
number=21
data:
JSON:{blockState:{blockName:"ancientwarfarestructure:advanced_loot_chest",properties:{facing:"south"}},teData:{lootSettings:{lootRolls:1,splashPotion:0b,hasMessage:0b,hasLoot:1b,lootTableName:"ancientwarfare:chests/citizen_medium_value",spawnEntity:0b,entity:"minecraft:"},Items:[],id:"ancientwarfarestructure:advanced_loot_chest_tile",Lock:""}}
:enddata
:endrule

rule:
plugin=vanillaBlocks
number=22
data:
JSON:{blockState:{blockName:"minecraft:carpet",properties:{color:"yellow"}}}
:enddata
:endrule

rule:
plugin=vanillaBlocks
number=23
data:
JSON:{blockState:{blockName:"minecraft:crafting_table"}}
:enddata
:endrule

rule:
plugin=vanillaBlocks
number=24
data:
JSON:{blockState:{blockName:"minecraft:hay_block",properties:{axis:"y"}}}
:enddata
:endrule

rule:
plugin=bed
number=25
data:
JSON:{blockState:{blockName:"minecraft:bed",properties:{part:"foot",facing:"south",occupied:"false"}},bedColor:3}
:enddata
:endrule

rule:
plugin=bed
number=26
data:
JSON:{blockState:{blockName:"minecraft:bed",properties:{part:"head",facing:"south",occupied:"false"}},bedColor:3}
:enddata
:endrule

rule:
plugin=blockTile
number=27
data:
JSON:{blockState:{blockName:"ancientwarfarestructure:advanced_spawner",properties:{transparent:"true"}},teData:{id:"ancientwarfarestructure:advanced_spawner_tile",spawnerSettings:{minDelay:10,spawnDelay:7,lightSensitive:0b,spawnGroups:[{settingsList:[{remainingSpawnCount:1,hostile:1b,customTag:{ArmorDropChances:[0.085f,0.085f,0.085f,0.085f],hasCustomEquipment:0b,ArmorItems:[{},{},{},{}],skinSettings:{npcTypeName:"custom",skinTypeSelected:"default"},HandDropChances:[0.085f,0.085f],factionName:"sarkonid",HandItems:[{id:"ancientwarfarenpc:golden_lance",Count:1b,Damage:0s},{}]},maxToSpawn:1,entityId:"ancientwarfarenpc:faction.cavalry",minToSpawn:1}],groupWeight:1}],playerRange:16,respondToRedstone:0b,inventory:{Size:9,Items:[]},spawnRange:0,transparent:1b,maxDelay:10,spawnYOffset:0,xpToDrop:0,mobRange:0,debugMode:0b,maxNearbyMonsters:0}}}
:enddata
:endrule

rule:
plugin=vanillaBlocks
number=28
data:
JSON:{blockState:{blockName:"ancientwarfarestructure:table",properties:{leg_southwest:"true",leg_northwest:"true",variant:"spruce",leg_northeast:"true",leg_southeast:"true"}}}
:enddata
:endrule

rule:
plugin=doors
number=29
data:
JSON:{blockState:{blockName:"minecraft:spruce_door",properties:{hinge:"left",half:"lower",powered:"false",facing:"south",open:"false"}}}
:enddata
:endrule

rule:
plugin=blockTile
number=30
data:
JSON:{blockState:{blockName:"ancientwarfarestructure:advanced_spawner",properties:{transparent:"true"}},teData:{id:"ancientwarfarestructure:advanced_spawner_tile",spawnerSettings:{minDelay:10,spawnDelay:8,lightSensitive:0b,spawnGroups:[{settingsList:[{remainingSpawnCount:1,hostile:1b,customTag:{ArmorDropChances:[0.085f,0.085f,0.085f,0.085f],hasCustomEquipment:0b,ArmorItems:[{},{},{},{}],skinSettings:{npcTypeName:"custom",skinTypeSelected:"default"},HandDropChances:[0.085f,0.085f],factionName:"sarkonid",HandItems:[{id:"ancientwarfarenpc:golden_spear",Count:1b,Damage:0s},{id:"ancientwarfarenpc:gold_shield",Count:1b,Damage:0s}]},maxToSpawn:1,entityId:"ancientwarfarenpc:faction.soldier",minToSpawn:1}],groupWeight:1}],playerRange:16,respondToRedstone:0b,inventory:{Size:9,Items:[]},spawnRange:0,transparent:1b,maxDelay:10,spawnYOffset:0,xpToDrop:0,mobRange:0,debugMode:0b,maxNearbyMonsters:0}}}
:enddata
:endrule

rule:
plugin=vanillaBlocks
number=31
data:
JSON:{blockState:{blockName:"minecraft:stone_slab2",properties:{half:"bottom",variant:"red_sandstone"}}}
:enddata
:endrule

rule:
plugin=vanillaBlocks
number=32
data:
JSON:{blockState:{blockName:"ancientwarfarestructure:stool",properties:{variant:"oak"}}}
:enddata
:endrule

rule:
plugin=vanillaBlocks
number=33
data:
JSON:{blockState:{blockName:"ancientwarfarestructure:table",properties:{leg_southwest:"true",leg_northwest:"true",variant:"oak",leg_northeast:"true",leg_southeast:"true"}}}
:enddata
:endrule

rule:
plugin=vanillaBlocks
number=34
data:
JSON:{blockState:{blockName:"minecraft:leaves",properties:{check_decay:"false",decayable:"false",variant:"jungle"}}}
:enddata
:endrule

rule:
plugin=blockTile
number=35
data:
JSON:{blockState:{blockName:"ancientwarfarestructure:advanced_spawner",properties:{transparent:"true"}},teData:{id:"ancientwarfarestructure:advanced_spawner_tile",spawnerSettings:{minDelay:10,spawnDelay:3,lightSensitive:0b,spawnGroups:[{settingsList:[{remainingSpawnCount:1,hostile:1b,customTag:{ArmorDropChances:[0.085f,0.085f,0.085f,0.085f],hasCustomEquipment:0b,ArmorItems:[{},{},{},{}],skinSettings:{npcTypeName:"custom",skinTypeSelected:"default"},HandDropChances:[0.085f,0.085f],factionName:"sarkonid",HandItems:[{id:"ancientwarfarenpc:golden_spear",Count:1b,Damage:0s},{id:"ancientwarfarenpc:gold_shield",Count:1b,Damage:0s}]},maxToSpawn:1,entityId:"ancientwarfarenpc:faction.soldier",minToSpawn:1}],groupWeight:1}],playerRange:16,respondToRedstone:0b,inventory:{Size:9,Items:[]},spawnRange:0,transparent:1b,maxDelay:10,spawnYOffset:0,xpToDrop:0,mobRange:0,debugMode:0b,maxNearbyMonsters:0}}}
:enddata
:endrule

rule:
plugin=vanillaBlocks
number=36
data:
JSON:{blockState:{blockName:"minecraft:sandstone_stairs",properties:{half:"bottom",shape:"straight",facing:"south"}}}
:enddata
:endrule

rule:
plugin=blockTile
number=37
data:
JSON:{blockState:{blockName:"ancientwarfarestructure:advanced_loot_chest",properties:{facing:"west"}},teData:{lootSettings:{lootRolls:1,splashPotion:0b,hasMessage:0b,hasLoot:1b,lootTableName:"ancientwarfare:chests/compat/harvestcraft/harvestcraft_village_farm_flax",spawnEntity:0b},Items:[],id:"ancientwarfarestructure:advanced_loot_chest_tile",Lock:""}}
:enddata
:endrule

rule:
plugin=blockTile
number=38
data:
JSON:{blockState:{blockName:"ancientwarfarestructure:advanced_loot_chest",properties:{facing:"west"}},teData:{lootSettings:{lootRolls:1,splashPotion:0b,hasMessage:0b,hasLoot:1b,lootTableName:"ancientwarfare:chests/compat/harvestcraft/harvestcraft_village_farm_flax",spawnEntity:0b},Items:[],id:"ancientwarfarestructure:advanced_loot_chest_tile",Lock:""}}
:enddata
:endrule

rule:
plugin=inventory
number=39
data:
JSON:{blockState:{blockName:"minecraft:furnace",properties:{facing:"north"}},lootLevel:0,teData:{CookTime:0,BurnTime:0,Items:[],id:"minecraft:furnace",CookTimeTotal:0,Lock:""},inventoryData:{length:0,inventoryContents:[]},legacyFeatures:0b}
:enddata
:endrule

rule:
plugin=vanillaBlocks
number=40
data:
JSON:{blockState:{blockName:"minecraft:red_sandstone_stairs",properties:{half:"bottom",shape:"straight",facing:"south"}}}
:enddata
:endrule

rule:
plugin=inventory
number=41
data:
JSON:{blockState:{blockName:"minecraft:furnace",properties:{facing:"north"}},lootLevel:0,teData:{CookTime:0,BurnTime:0,Items:[],id:"minecraft:furnace",CookTimeTotal:0,Lock:""},inventoryData:{length:0,inventoryContents:[]},legacyFeatures:0b}
:enddata
:endrule

rule:
plugin=blockTile
number=42
data:
JSON:{blockState:{blockName:"ancientwarfarestructure:advanced_spawner",properties:{transparent:"true"}},teData:{id:"ancientwarfarestructure:advanced_spawner_tile",spawnerSettings:{minDelay:10,spawnDelay:10,lightSensitive:0b,spawnGroups:[{settingsList:[{remainingSpawnCount:1,hostile:1b,customTag:{ArmorDropChances:[0.085f,0.085f,0.085f,0.085f],hasCustomEquipment:0b,ArmorItems:[{},{},{},{}],skinSettings:{npcTypeName:"custom",skinTypeSelected:"default"},HandDropChances:[0.085f,0.085f],factionName:"sarkonid",HandItems:[{},{}]},maxToSpawn:1,entityId:"ancientwarfarenpc:faction.civilian.female",minToSpawn:1}],groupWeight:1}],playerRange:16,respondToRedstone:0b,inventory:{Size:9,Items:[]},spawnRange:0,transparent:1b,maxDelay:10,spawnYOffset:0,xpToDrop:0,mobRange:0,debugMode:0b,maxNearbyMonsters:0}}}
:enddata
:endrule

rule:
plugin=inventory
number=43
data:
JSON:{blockState:{blockName:"minecraft:furnace",properties:{facing:"north"}},lootLevel:0,teData:{CookTime:0,BurnTime:0,Items:[],id:"minecraft:furnace",CookTimeTotal:0,Lock:""},inventoryData:{length:0,inventoryContents:[]},legacyFeatures:0b}
:enddata
:endrule

rule:
plugin=blockTile
number=44
data:
JSON:{blockState:{blockName:"ancientwarfarestructure:advanced_spawner",properties:{transparent:"true"}},teData:{id:"ancientwarfarestructure:advanced_spawner_tile",spawnerSettings:{minDelay:10,spawnDelay:2,lightSensitive:0b,spawnGroups:[{settingsList:[{remainingSpawnCount:1,hostile:1b,customTag:{ArmorDropChances:[0.085f,0.085f,0.085f,0.085f],hasCustomEquipment:0b,ArmorItems:[{},{},{},{}],skinSettings:{npcTypeName:"custom",skinTypeSelected:"default"},HandDropChances:[0.085f,0.085f],factionName:"sarkonid",HandItems:[{id:"ancientwarfarenpc:golden_lance",Count:1b,Damage:0s},{}]},maxToSpawn:1,entityId:"ancientwarfarenpc:faction.cavalry",minToSpawn:1}],groupWeight:1}],playerRange:16,respondToRedstone:0b,inventory:{Size:9,Items:[]},spawnRange:0,transparent:1b,maxDelay:10,spawnYOffset:0,xpToDrop:0,mobRange:0,debugMode:0b,maxNearbyMonsters:0}}}
:enddata
:endrule

rule:
plugin=blockTile
number=45
data:
JSON:{blockState:{blockName:"ancientwarfarestructure:advanced_spawner",properties:{transparent:"true"}},teData:{id:"ancientwarfarestructure:advanced_spawner_tile",spawnerSettings:{minDelay:10,spawnDelay:10,lightSensitive:0b,spawnGroups:[{settingsList:[{remainingSpawnCount:1,hostile:1b,customTag:{ArmorDropChances:[0.085f,0.085f,0.085f,0.085f],hasCustomEquipment:0b,ArmorItems:[{},{},{},{}],skinSettings:{npcTypeName:"custom",skinTypeSelected:"default"},HandDropChances:[0.085f,0.085f],factionName:"sarkonid",HandItems:[{id:"ancientwarfarenpc:golden_spear",Count:1b,Damage:0s},{id:"ancientwarfarenpc:gold_shield",Count:1b,Damage:0s}]},maxToSpawn:1,entityId:"ancientwarfarenpc:faction.soldier",minToSpawn:1}],groupWeight:1}],playerRange:16,respondToRedstone:0b,inventory:{Size:9,Items:[]},spawnRange:0,transparent:1b,maxDelay:10,spawnYOffset:0,xpToDrop:0,mobRange:0,debugMode:0b,maxNearbyMonsters:0}}}
:enddata
:endrule

rule:
plugin=doors
number=46
data:
JSON:{blockState:{blockName:"minecraft:spruce_door",properties:{hinge:"left",half:"lower",powered:"false",facing:"south",open:"true"}}}
:enddata
:endrule

rule:
plugin=vanillaBlocks
number=47
data:
JSON:{blockState:{blockName:"minecraft:stone",properties:{variant:"smooth_andesite"}}}
:enddata
:endrule

rule:
plugin=blockTile
number=48
data:
JSON:{blockState:{blockName:"ancientwarfarestructure:advanced_spawner",properties:{transparent:"true"}},teData:{id:"ancientwarfarestructure:advanced_spawner_tile",spawnerSettings:{minDelay:10,spawnDelay:2,lightSensitive:0b,spawnGroups:[{settingsList:[{remainingSpawnCount:1,hostile:1b,customTag:{ArmorDropChances:[0.085f,0.085f,0.085f,0.085f],hasCustomEquipment:0b,ArmorItems:[{},{},{},{}],skinSettings:{npcTypeName:"custom",skinTypeSelected:"default"},HandDropChances:[0.085f,0.085f],factionName:"sarkonid",HandItems:[{id:"ancientwarfarenpc:golden_spear",Count:1b,Damage:0s},{id:"ancientwarfarenpc:gold_shield",Count:1b,Damage:0s}]},maxToSpawn:1,entityId:"ancientwarfarenpc:faction.soldier",minToSpawn:1}],groupWeight:1}],playerRange:16,respondToRedstone:0b,inventory:{Size:9,Items:[]},spawnRange:0,transparent:1b,maxDelay:10,spawnYOffset:0,xpToDrop:0,mobRange:0,debugMode:0b,maxNearbyMonsters:0}}}
:enddata
:endrule

rule:
plugin=blockTile
number=49
data:
JSON:{blockState:{blockName:"ancientwarfarestructure:urn"},teData:{lootSettings:{lootRolls:1,splashPotion:0b,hasMessage:0b,hasLoot:1b,lootTableName:"ancientwarfare:chests/compat/harvestcraft/harvestcraft_shop_spice",spawnEntity:0b,entity:"minecraft:"},id:"ancientwarfarestructure:urn_tile"}}
:enddata
:endrule

rule:
plugin=doors
number=50
data:
JSON:{blockState:{blockName:"minecraft:spruce_door",properties:{hinge:"left",half:"lower",powered:"false",facing:"east",open:"false"}}}
:enddata
:endrule

rule:
plugin=vanillaBlocks
number=51
data:
JSON:{blockState:{blockName:"minecraft:farmland",properties:{moisture:"7"}}}
:enddata
:endrule

rule:
plugin=blockTile
number=52
data:
JSON:{blockState:{blockName:"ancientwarfarestructure:advanced_loot_chest",properties:{facing:"west"}},teData:{lootSettings:{lootRolls:1,splashPotion:0b,hasMessage:0b,hasLoot:1b,lootTableName:"ancientwarfare:chests/compat/harvestcraft/harvestcraft_village_farm_flax",spawnEntity:0b,entity:"minecraft:"},Items:[],id:"ancientwarfarestructure:advanced_loot_chest_tile",Lock:""}}
:enddata
:endrule

rule:
plugin=inventory
number=53
data:
JSON:{blockState:{blockName:"ancientwarfarestructure:loot_basket",properties:{visible:"true",double:"true",facing:"west"}},lootLevel:0,teData:{lootSettings:{lootRolls:1,splashPotion:0b,hasMessage:0b,hasLoot:1b,lootTableName:"ancientwarfare:chests/compat/harvestcraft/harvestcraft_village_farm_flax",spawnEntity:0b},Items:[],id:"ancientwarfarestructure:loot_basket",Lock:""},legacyFeatures:0b}
:enddata
:endrule

rule:
plugin=vanillaBlocks
number=54
data:
JSON:{blockState:{blockName:"futuremc:loom",properties:{facing:"north"}}}
:enddata
:endrule

rule:
plugin=vanillaBlocks
number=55
data:
JSON:{blockState:{blockName:"minecraft:birch_stairs",properties:{half:"top",shape:"straight",facing:"north"}}}
:enddata
:endrule

rule:
plugin=blockTile
number=56
data:
JSON:{blockState:{blockName:"ancientwarfarestructure:advanced_spawner",properties:{transparent:"true"}},teData:{id:"ancientwarfarestructure:advanced_spawner_tile",spawnerSettings:{minDelay:10,spawnDelay:8,lightSensitive:0b,spawnGroups:[{settingsList:[{remainingSpawnCount:1,hostile:1b,customTag:{ArmorDropChances:[0.085f,0.085f,0.085f,0.085f],hasCustomEquipment:0b,ArmorItems:[{},{},{},{}],skinSettings:{npcTypeName:"custom",skinTypeSelected:"default"},HandDropChances:[0.085f,0.085f],factionName:"sarkonid",HandItems:[{},{}]},maxToSpawn:1,entityId:"ancientwarfarenpc:faction.civilian.male",minToSpawn:1}],groupWeight:1}],playerRange:16,respondToRedstone:0b,inventory:{Size:9,Items:[]},spawnRange:0,transparent:1b,maxDelay:10,spawnYOffset:0,xpToDrop:0,mobRange:0,debugMode:0b,maxNearbyMonsters:0}}}
:enddata
:endrule

rule:
plugin=blockTile
number=57
data:
JSON:{blockState:{blockName:"ancientwarfarestructure:advanced_spawner",properties:{transparent:"true"}},teData:{id:"ancientwarfarestructure:advanced_spawner_tile",spawnerSettings:{minDelay:10,spawnDelay:10,lightSensitive:0b,spawnGroups:[{settingsList:[{remainingSpawnCount:1,hostile:1b,customTag:{ArmorDropChances:[0.085f,0.085f,0.085f,0.085f],CustomName:"Flax Worker",hasCustomEquipment:1b,ArmorItems:[{},{},{},{}],skinSettings:{npcTypeName:"custom",skinTypeSelected:"default"},HandDropChances:[0.085f,0.085f],factionName:"sarkonid",tradeList:{tradeList:[{refillFrequency:6000,currentAvailable:5,inputItems:[{id:"harvestcraft:flaxseeditem",Count:16b,slot:4,Damage:0s}],outputItems:[{id:"ancientwarfarenpc:coin",Count:1b,tag:{metal:"silver"},slot:4,Damage:0s}],refillTime:-1L,maxAvailable:5},{refillFrequency:6000,currentAvailable:10,inputItems:[{id:"ancientwarfarenpc:coin",Count:4b,tag:{metal:"silver"},slot:4,Damage:0s}],outputItems:[{id:"biomesoplenty:double_plant",Count:16b,slot:4,Damage:0s}],refillTime:-1L,maxAvailable:10},{refillFrequency:6000,currentAvailable:20,inputItems:[{id:"ancientwarfarenpc:coin",Count:3b,tag:{metal:"silver"},slot:4,Damage:0s}],outputItems:[{id:"harvestcraft:flaxitem",Count:16b,slot:4,Damage:0s}],refillTime:-1L,maxAvailable:20},{refillFrequency:6000,currentAvailable:10,inputItems:[{id:"ancientwarfarenpc:coin",Count:2b,tag:{metal:"silver"},slot:4,Damage:0s}],outputItems:[{id:"minecraft:string",Count:16b,slot:4,Damage:0s}],refillTime:-1L,maxAvailable:10},{refillFrequency:6000,currentAvailable:10,inputItems:[{id:"ancientwarfarenpc:coin",Count:6b,tag:{metal:"silver"},slot:4,Damage:0s}],outputItems:[{id:"harvestcraft:wovencottonitem",Count:16b,slot:4,Damage:0s}],refillTime:-1L,maxAvailable:10},{refillFrequency:6000,currentAvailable:2,inputItems:[{id:"ancientwarfarenpc:coin",Count:4b,tag:{metal:"silver"},slot:4,Damage:0s}],outputItems:[{id:"minecraft:skull",Count:1b,tag:{SkullOwner:{Id:"4a842519-1cf4-48c5-ac2d-603e4dc4a243",Properties:{textures:[{Value:"eyJ0ZXh0dXJlcyI6eyJTS0lOIjp7InVybCI6Imh0dHA6Ly90ZXh0dXJlcy5taW5lY3JhZnQubmV0L3RleHR1cmUvNzhhNjhkZGI3ODIwMDUyNWI1YWFmNGRiMTc1MjgxNDFlNTg3NDU0Mzk1ZDg1ZTMzOWIwN2YzMTBhNDBiYTk1ZiJ9fX0="}]}},display:{Name:"Folded Fabric"}},slot:4,Damage:3s}],refillTime:-1L,maxAvailable:2}]},HandItems:[{id:"minecraft:shears",Count:1b,Damage:0s},{}]},maxToSpawn:1,entityId:"ancientwarfarenpc:faction.trader",minToSpawn:1}],groupWeight:1}],playerRange:16,respondToRedstone:0b,inventory:{Size:9,Items:[]},spawnRange:0,transparent:1b,maxDelay:10,spawnYOffset:0,xpToDrop:0,mobRange:0,debugMode:0b,maxNearbyMonsters:0}}}
:enddata
:endrule

rule:
plugin=vanillaBlocks
number=58
data:
JSON:{blockState:{blockName:"minecraft:torch",properties:{facing:"north"}}}
:enddata
:endrule

rule:
plugin=vanillaBlocks
number=59
data:
JSON:{blockState:{blockName:"minecraft:planks",properties:{variant:"birch"}}}
:enddata
:endrule

rule:
plugin=vanillaBlocks
number=60
data:
JSON:{blockState:{blockName:"minecraft:birch_stairs",properties:{half:"top",shape:"straight",facing:"east"}}}
:enddata
:endrule

rule:
plugin=fluid
number=61
data:
JSON:{blockState:{blockName:"minecraft:water",properties:{level:"0"}}}
:enddata
:endrule

rule:
plugin=vanillaBlocks
number=62
data:
JSON:{blockState:{blockName:"minecraft:red_sandstone_stairs",properties:{half:"bottom",shape:"straight",facing:"north"}}}
:enddata
:endrule

rule:
plugin=blockTile
number=63
data:
JSON:{blockState:{blockName:"ancientwarfarestructure:advanced_spawner",properties:{transparent:"true"}},teData:{id:"ancientwarfarestructure:advanced_spawner_tile",spawnerSettings:{minDelay:10,spawnDelay:10,lightSensitive:0b,spawnGroups:[{settingsList:[{remainingSpawnCount:1,hostile:1b,customTag:{ArmorDropChances:[0.085f,0.085f,0.085f,0.085f],hasCustomEquipment:0b,ArmorItems:[{},{},{},{}],skinSettings:{npcTypeName:"custom",skinTypeSelected:"default"},HandDropChances:[0.085f,0.085f],factionName:"sarkonid",HandItems:[{id:"ancientwarfarenpc:golden_spear",Count:1b,Damage:0s},{id:"ancientwarfarenpc:gold_shield",Count:1b,Damage:0s}]},maxToSpawn:1,entityId:"ancientwarfarenpc:faction.soldier",minToSpawn:1}],groupWeight:1}],playerRange:16,respondToRedstone:0b,inventory:{Size:9,Items:[]},spawnRange:0,transparent:1b,maxDelay:10,spawnYOffset:0,xpToDrop:0,mobRange:0,debugMode:0b,maxNearbyMonsters:0}}}
:enddata
:endrule

rule:
plugin=blockTile
number=64
data:
JSON:{blockState:{blockName:"ancientwarfarestructure:advanced_spawner",properties:{transparent:"true"}},teData:{id:"ancientwarfarestructure:advanced_spawner_tile",spawnerSettings:{minDelay:10,spawnDelay:7,lightSensitive:0b,spawnGroups:[{settingsList:[{remainingSpawnCount:1,hostile:1b,customTag:{ArmorDropChances:[0.085f,0.085f,0.085f,0.085f],hasCustomEquipment:0b,ArmorItems:[{},{},{},{}],skinSettings:{npcTypeName:"custom",skinTypeSelected:"default"},HandDropChances:[0.085f,0.085f],factionName:"sarkonid",HandItems:[{id:"ancientwarfarenpc:golden_lance",Count:1b,Damage:0s},{}]},maxToSpawn:1,entityId:"ancientwarfarenpc:faction.cavalry",minToSpawn:1}],groupWeight:1}],playerRange:16,respondToRedstone:0b,inventory:{Size:9,Items:[]},spawnRange:0,transparent:1b,maxDelay:10,spawnYOffset:0,xpToDrop:0,mobRange:0,debugMode:0b,maxNearbyMonsters:0}}}
:enddata
:endrule

rule:
plugin=vanillaBlocks
number=65
data:
JSON:{blockState:{blockName:"minecraft:sandstone_stairs",properties:{half:"bottom",shape:"straight",facing:"west"}}}
:enddata
:endrule

rule:
plugin=blockTile
number=66
data:
JSON:{blockState:{blockName:"ancientwarfarestructure:gate_proxy"},teData:{lsb:-6062094447113034482L,id:"ancientwarfarestructure:gate_proxy_tile",msb:-642925891553310447L,render:1b}}
:enddata
:endrule

rule:
plugin=blockTile
number=67
data:
JSON:{blockState:{blockName:"ancientwarfarestructure:gate_proxy"},teData:{lsb:-6062094447113034482L,id:"ancientwarfarestructure:gate_proxy_tile",msb:-642925891553310447L,render:0b}}
:enddata
:endrule

rule:
plugin=blockTile
number=68
data:
JSON:{blockState:{blockName:"ancientwarfarestructure:gate_proxy"},teData:{lsb:-6062094447113034482L,id:"ancientwarfarestructure:gate_proxy_tile",msb:-642925891553310447L,render:0b}}
:enddata
:endrule

rule:
plugin=blockTile
number=69
data:
JSON:{blockState:{blockName:"ancientwarfarestructure:advanced_loot_chest",properties:{facing:"south"}},teData:{lootSettings:{lootRolls:1,splashPotion:0b,hasMessage:0b,hasLoot:1b,lootTableName:"ancientwarfare:chests/sarkonid",spawnEntity:0b,entity:"minecraft:"},Items:[],id:"ancientwarfarestructure:advanced_loot_chest_tile",Lock:""}}
:enddata
:endrule

rule:
plugin=blockTile
number=70
data:
JSON:{blockState:{blockName:"ancientwarfarestructure:advanced_loot_chest",properties:{facing:"north"}},teData:{ForgeData:{},lootSettings:{lootRolls:1,splashPotion:0b,hasMessage:0b,hasLoot:1b,lootTableName:"ancientwarfare:chests/sarkonid",spawnEntity:0b,entity:"minecraft:"},Items:[],id:"ancientwarfarestructure:advanced_loot_chest_tile",Lock:""}}
:enddata
:endrule

rule:
plugin=blockTile
number=71
data:
JSON:{blockState:{blockName:"ancientwarfarestructure:advanced_loot_chest",properties:{facing:"north"}},teData:{lootSettings:{lootRolls:1,splashPotion:0b,hasMessage:0b,hasLoot:1b,lootTableName:"ancientwarfare:chests/compat/harvestcraft/harvestcraft_village_farm_flax",spawnEntity:0b,entity:"minecraft:"},Items:[],id:"ancientwarfarestructure:advanced_loot_chest_tile",Lock:""}}
:enddata
:endrule

rule:
plugin=blockTile
number=72
data:
JSON:{blockState:{blockName:"ancientwarfarestructure:advanced_loot_chest",properties:{facing:"south"}},teData:{lootSettings:{lootRolls:1,splashPotion:0b,hasMessage:0b,hasLoot:1b,lootTableName:"ancientwarfare:chests/sarkonid",spawnEntity:0b,entity:"minecraft:"},Items:[],id:"ancientwarfarestructure:advanced_loot_chest_tile",Lock:""}}
:enddata
:endrule

rule:
plugin=blockTile
number=73
data:
JSON:{blockState:{blockName:"ancientwarfarestructure:advanced_loot_chest",properties:{facing:"north"}},teData:{lootSettings:{lootRolls:1,splashPotion:0b,hasMessage:0b,hasLoot:1b,lootTableName:"ancientwarfare:chests/compat/harvestcraft/harvestcraft_village_farm_flax",spawnEntity:0b,entity:"minecraft:"},Items:[],id:"ancientwarfarestructure:advanced_loot_chest_tile",Lock:""}}
:enddata
:endrule

rule:
plugin=blockTile
number=74
data:
JSON:{blockState:{blockName:"ancientwarfarestructure:advanced_loot_chest",properties:{facing:"east"}},teData:{lootSettings:{lootRolls:1,splashPotion:0b,hasMessage:0b,hasLoot:1b,lootTableName:"ancientwarfare:chests/compat/harvestcraft/harvestcraft_village_farm_flax",spawnEntity:0b,entity:"minecraft:"},Items:[],id:"ancientwarfarestructure:advanced_loot_chest_tile",Lock:""}}
:enddata
:endrule

rule:
plugin=blockTile
number=75
data:
JSON:{blockState:{blockName:"ancientwarfarestructure:advanced_spawner",properties:{transparent:"true"}},teData:{id:"ancientwarfarestructure:advanced_spawner_tile",spawnerSettings:{minDelay:10,spawnDelay:6,lightSensitive:0b,spawnGroups:[{settingsList:[{remainingSpawnCount:1,hostile:1b,customTag:{ArmorDropChances:[0.085f,0.085f,0.085f,0.085f],hasCustomEquipment:0b,ArmorItems:[{},{},{},{}],skinSettings:{npcTypeName:"custom",skinTypeSelected:"default"},HandDropChances:[0.085f,0.085f],factionName:"sarkonid",HandItems:[{id:"ancientwarfarenpc:golden_lance",Count:1b,Damage:0s},{}]},maxToSpawn:1,entityId:"ancientwarfarenpc:faction.cavalry",minToSpawn:1}],groupWeight:1}],playerRange:16,respondToRedstone:0b,inventory:{Size:9,Items:[]},spawnRange:0,transparent:1b,maxDelay:10,spawnYOffset:0,xpToDrop:0,mobRange:0,debugMode:0b,maxNearbyMonsters:0}}}
:enddata
:endrule

rule:
plugin=vanillaSkull
number=76
data:
JSON:{blockState:{blockName:"minecraft:skull",properties:{nodrop:"false",facing:"up"}},skullRotation:4,teData:{Owner:{Id:"4a842519-1cf4-48c5-ac2d-603e4dc4a243",Properties:{textures:[{Value:"eyJ0ZXh0dXJlcyI6eyJTS0lOIjp7InVybCI6Imh0dHA6Ly90ZXh0dXJlcy5taW5lY3JhZnQubmV0L3RleHR1cmUvNzhhNjhkZGI3ODIwMDUyNWI1YWFmNGRiMTc1MjgxNDFlNTg3NDU0Mzk1ZDg1ZTMzOWIwN2YzMTBhNDBiYTk1ZiJ9fX0="}]}},Rot:0b,id:"minecraft:skull",SkullType:3b}}
:enddata
:endrule

rule:
plugin=vanillaSkull
number=77
data:
JSON:{blockState:{blockName:"minecraft:skull",properties:{nodrop:"false",facing:"up"}},skullRotation:5,teData:{Owner:{Id:"4a842519-1cf4-48c5-ac2d-603e4dc4a243",Properties:{textures:[{Value:"eyJ0ZXh0dXJlcyI6eyJTS0lOIjp7InVybCI6Imh0dHA6Ly90ZXh0dXJlcy5taW5lY3JhZnQubmV0L3RleHR1cmUvNzhhNjhkZGI3ODIwMDUyNWI1YWFmNGRiMTc1MjgxNDFlNTg3NDU0Mzk1ZDg1ZTMzOWIwN2YzMTBhNDBiYTk1ZiJ9fX0="}]}},Rot:1b,id:"minecraft:skull",SkullType:3b}}
:enddata
:endrule

rule:
plugin=vanillaBlocks
number=78
data:
JSON:{blockState:{blockName:"futuremc:loom",properties:{facing:"east"}}}
:enddata
:endrule

rule:
plugin=vanillaBlocks
number=79
data:
JSON:{blockState:{blockName:"minecraft:torch",properties:{facing:"up"}}}
:enddata
:endrule

rule:
plugin=blockTile
number=80
data:
JSON:{blockState:{blockName:"ancientwarfarestructure:advanced_loot_chest",properties:{facing:"east"}},teData:{lootSettings:{lootRolls:1,splashPotion:0b,hasMessage:0b,hasLoot:1b,lootTableName:"ancientwarfare:chests/compat/harvestcraft/harvestcraft_village_farm_flax",spawnEntity:0b},Items:[],id:"ancientwarfarestructure:advanced_loot_chest_tile",Lock:""}}
:enddata
:endrule

rule:
plugin=blockTile
number=81
data:
JSON:{blockState:{blockName:"ancientwarfarestructure:advanced_loot_chest",properties:{facing:"east"}},teData:{lootSettings:{lootRolls:1,splashPotion:0b,hasMessage:0b,hasLoot:1b,lootTableName:"ancientwarfare:chests/compat/harvestcraft/harvestcraft_village_farm_flax",spawnEntity:0b},Items:[],id:"ancientwarfarestructure:advanced_loot_chest_tile",Lock:""}}
:enddata
:endrule

rule:
plugin=blockTile
number=82
data:
JSON:{blockState:{blockName:"ancientwarfarestructure:advanced_loot_chest",properties:{facing:"north"}},teData:{lootSettings:{lootRolls:1,splashPotion:0b,hasMessage:0b,hasLoot:1b,lootTableName:"ancientwarfare:chests/sarkonid",spawnEntity:0b,entity:"minecraft:"},Items:[],id:"ancientwarfarestructure:advanced_loot_chest_tile",Lock:""}}
:enddata
:endrule

rule:
plugin=doors
number=83
data:
JSON:{blockState:{blockName:"minecraft:spruce_door",properties:{hinge:"right",half:"upper",powered:"false",facing:"east",open:"false"}}}
:enddata
:endrule

rule:
plugin=vanillaBlocks
number=84
data:
JSON:{blockState:{blockName:"minecraft:sand",properties:{variant:"red_sand"}}}
:enddata
:endrule

rule:
plugin=vanillaBlocks
number=85
data:
JSON:{blockState:{blockName:"minecraft:stone_slab2",properties:{half:"top",variant:"red_sandstone"}}}
:enddata
:endrule

rule:
plugin=vanillaSkull
number=86
data:
JSON:{blockState:{blockName:"minecraft:skull",properties:{nodrop:"false",facing:"up"}},skullRotation:8,teData:{Owner:{Id:"a76f5a5a-9855-4c8a-b9fa-44123e065585",Properties:{textures:[{Value:"eyJ0ZXh0dXJlcyI6eyJTS0lOIjp7InVybCI6Imh0dHA6Ly90ZXh0dXJlcy5taW5lY3JhZnQubmV0L3RleHR1cmUvMzVmNzViYWUxMzQ5NmI5N2Y1NWRjNDJmYzM3MjQyYTg4MTU4OTUyYjZjY2U5M2MwNTdhYjAyOGFjYmE4MGIyMCJ9fX0="}]}},Rot:4b,id:"minecraft:skull",SkullType:3b}}
:enddata
:endrule

rule:
plugin=vanillaSkull
number=87
data:
JSON:{blockState:{blockName:"minecraft:skull",properties:{nodrop:"false",facing:"up"}},skullRotation:9,teData:{Owner:{Id:"a76f5a5a-9855-4c8a-b9fa-44123e065585",Properties:{textures:[{Value:"eyJ0ZXh0dXJlcyI6eyJTS0lOIjp7InVybCI6Imh0dHA6Ly90ZXh0dXJlcy5taW5lY3JhZnQubmV0L3RleHR1cmUvMzVmNzViYWUxMzQ5NmI5N2Y1NWRjNDJmYzM3MjQyYTg4MTU4OTUyYjZjY2U5M2MwNTdhYjAyOGFjYmE4MGIyMCJ9fX0="}]}},Rot:5b,id:"minecraft:skull",SkullType:3b}}
:enddata
:endrule

rule:
plugin=vanillaSkull
number=88
data:
JSON:{blockState:{blockName:"minecraft:skull",properties:{nodrop:"false",facing:"up"}},skullRotation:5,teData:{Owner:{Id:"a76f5a5a-9855-4c8a-b9fa-44123e065585",Properties:{textures:[{Value:"eyJ0ZXh0dXJlcyI6eyJTS0lOIjp7InVybCI6Imh0dHA6Ly90ZXh0dXJlcy5taW5lY3JhZnQubmV0L3RleHR1cmUvMzVmNzViYWUxMzQ5NmI5N2Y1NWRjNDJmYzM3MjQyYTg4MTU4OTUyYjZjY2U5M2MwNTdhYjAyOGFjYmE4MGIyMCJ9fX0="}]}},Rot:1b,id:"minecraft:skull",SkullType:3b}}
:enddata
:endrule

rule:
plugin=vanillaSkull
number=89
data:
JSON:{blockState:{blockName:"minecraft:skull",properties:{nodrop:"false",facing:"up"}},skullRotation:10,teData:{Owner:{Id:"a76f5a5a-9855-4c8a-b9fa-44123e065585",Properties:{textures:[{Value:"eyJ0ZXh0dXJlcyI6eyJTS0lOIjp7InVybCI6Imh0dHA6Ly90ZXh0dXJlcy5taW5lY3JhZnQubmV0L3RleHR1cmUvMzVmNzViYWUxMzQ5NmI5N2Y1NWRjNDJmYzM3MjQyYTg4MTU4OTUyYjZjY2U5M2MwNTdhYjAyOGFjYmE4MGIyMCJ9fX0="}]}},Rot:6b,id:"minecraft:skull",SkullType:3b}}
:enddata
:endrule

rule:
plugin=vanillaSkull
number=90
data:
JSON:{blockState:{blockName:"minecraft:skull",properties:{nodrop:"false",facing:"up"}},skullRotation:8,teData:{Owner:{Id:"a76f5a5a-9855-4c8a-b9fa-44123e065585",Properties:{textures:[{Value:"eyJ0ZXh0dXJlcyI6eyJTS0lOIjp7InVybCI6Imh0dHA6Ly90ZXh0dXJlcy5taW5lY3JhZnQubmV0L3RleHR1cmUvMzVmNzViYWUxMzQ5NmI5N2Y1NWRjNDJmYzM3MjQyYTg4MTU4OTUyYjZjY2U5M2MwNTdhYjAyOGFjYmE4MGIyMCJ9fX0="}]}},Rot:4b,id:"minecraft:skull",SkullType:3b}}
:enddata
:endrule

rule:
plugin=vanillaBlocks
number=91
data:
JSON:{blockState:{blockName:"quark:candle",properties:{variant:"candle_silver"}}}
:enddata
:endrule

rule:
plugin=vanillaSkull
number=92
data:
JSON:{blockState:{blockName:"minecraft:skull",properties:{nodrop:"false",facing:"up"}},skullRotation:4,teData:{Owner:{Id:"a76f5a5a-9855-4c8a-b9fa-44123e065585",Properties:{textures:[{Value:"eyJ0ZXh0dXJlcyI6eyJTS0lOIjp7InVybCI6Imh0dHA6Ly90ZXh0dXJlcy5taW5lY3JhZnQubmV0L3RleHR1cmUvMzVmNzViYWUxMzQ5NmI5N2Y1NWRjNDJmYzM3MjQyYTg4MTU4OTUyYjZjY2U5M2MwNTdhYjAyOGFjYmE4MGIyMCJ9fX0="}]}},Rot:0b,id:"minecraft:skull",SkullType:3b}}
:enddata
:endrule

rule:
plugin=vanillaSkull
number=93
data:
JSON:{blockState:{blockName:"minecraft:skull",properties:{nodrop:"false",facing:"up"}},skullRotation:8,teData:{Owner:{Id:"a76f5a5a-9855-4c8a-b9fa-44123e065585",Properties:{textures:[{Value:"eyJ0ZXh0dXJlcyI6eyJTS0lOIjp7InVybCI6Imh0dHA6Ly90ZXh0dXJlcy5taW5lY3JhZnQubmV0L3RleHR1cmUvMzVmNzViYWUxMzQ5NmI5N2Y1NWRjNDJmYzM3MjQyYTg4MTU4OTUyYjZjY2U5M2MwNTdhYjAyOGFjYmE4MGIyMCJ9fX0="}]}},Rot:4b,id:"minecraft:skull",SkullType:3b}}
:enddata
:endrule

rule:
plugin=vanillaSkull
number=94
data:
JSON:{blockState:{blockName:"minecraft:skull",properties:{nodrop:"false",facing:"up"}},skullRotation:8,teData:{Owner:{Id:"a76f5a5a-9855-4c8a-b9fa-44123e065585",Properties:{textures:[{Value:"eyJ0ZXh0dXJlcyI6eyJTS0lOIjp7InVybCI6Imh0dHA6Ly90ZXh0dXJlcy5taW5lY3JhZnQubmV0L3RleHR1cmUvMzVmNzViYWUxMzQ5NmI5N2Y1NWRjNDJmYzM3MjQyYTg4MTU4OTUyYjZjY2U5M2MwNTdhYjAyOGFjYmE4MGIyMCJ9fX0="}]}},Rot:4b,id:"minecraft:skull",SkullType:3b}}
:enddata
:endrule

rule:
plugin=vanillaBlocks
number=95
data:
JSON:{blockState:{blockName:"quark:candle",properties:{variant:"candle_light_blue"}}}
:enddata
:endrule

rule:
plugin=vanillaSkull
number=96
data:
JSON:{blockState:{blockName:"minecraft:skull",properties:{nodrop:"false",facing:"up"}},skullRotation:8,teData:{Owner:{Id:"96bfcca0-98bb-4c37-ab1d-1132c8b2cadc",Properties:{textures:[{Value:"eyJ0ZXh0dXJlcyI6eyJTS0lOIjp7InVybCI6Imh0dHA6Ly90ZXh0dXJlcy5taW5lY3JhZnQubmV0L3RleHR1cmUvMDdjYmQ3OWNhOTZhYWI2NjJjMTg2ODg4ZjRlNmQyNWEyNzViYjFiNGRkZDQzNWI2MzUyOGMzMGMxNWEyMjUifX19"}]}},Rot:4b,id:"minecraft:skull",SkullType:3b}}
:enddata
:endrule

rule:
plugin=vanillaSkull
number=97
data:
JSON:{blockState:{blockName:"minecraft:skull",properties:{nodrop:"false",facing:"up"}},skullRotation:8,teData:{Owner:{Id:"a76f5a5a-9855-4c8a-b9fa-44123e065585",Properties:{textures:[{Value:"eyJ0ZXh0dXJlcyI6eyJTS0lOIjp7InVybCI6Imh0dHA6Ly90ZXh0dXJlcy5taW5lY3JhZnQubmV0L3RleHR1cmUvMzVmNzViYWUxMzQ5NmI5N2Y1NWRjNDJmYzM3MjQyYTg4MTU4OTUyYjZjY2U5M2MwNTdhYjAyOGFjYmE4MGIyMCJ9fX0="}]}},Rot:4b,id:"minecraft:skull",SkullType:3b}}
:enddata
:endrule

rule:
plugin=vanillaSkull
number=98
data:
JSON:{blockState:{blockName:"minecraft:skull",properties:{nodrop:"false",facing:"up"}},skullRotation:6,teData:{Owner:{Id:"96bfcca0-98bb-4c37-ab1d-1132c8b2cadc",Properties:{textures:[{Value:"eyJ0ZXh0dXJlcyI6eyJTS0lOIjp7InVybCI6Imh0dHA6Ly90ZXh0dXJlcy5taW5lY3JhZnQubmV0L3RleHR1cmUvMDdjYmQ3OWNhOTZhYWI2NjJjMTg2ODg4ZjRlNmQyNWEyNzViYjFiNGRkZDQzNWI2MzUyOGMzMGMxNWEyMjUifX19"}]}},Rot:2b,id:"minecraft:skull",SkullType:3b}}
:enddata
:endrule

rule:
plugin=vanillaBlocks
number=99
data:
JSON:{blockState:{blockName:"minecraft:sandstone_stairs",properties:{half:"top",shape:"straight",facing:"north"}}}
:enddata
:endrule

rule:
plugin=vanillaBlocks
number=100
data:
JSON:{blockState:{blockName:"minecraft:sandstone_stairs",properties:{half:"top",shape:"straight",facing:"south"}}}
:enddata
:endrule

rule:
plugin=doors
number=101
data:
JSON:{blockState:{blockName:"minecraft:spruce_door",properties:{hinge:"left",half:"upper",powered:"false",facing:"east",open:"false"}}}
:enddata
:endrule

rule:
plugin=inventory
number=102
data:
JSON:{blockState:{blockName:"ancientwarfarestructure:loot_basket",properties:{visible:"true",double:"true",facing:"north"}},lootLevel:0,teData:{lootSettings:{lootRolls:1,splashPotion:0b,hasMessage:0b,hasLoot:1b,lootTableName:"ancientwarfare:chests/castle_pantry_mixed",spawnEntity:0b,entity:"minecraft:"},Items:[],id:"ancientwarfarestructure:loot_basket",Lock:""},legacyFeatures:0b}
:enddata
:endrule

rule:
plugin=vanillaBlocks
number=103
data:
JSON:{blockState:{blockName:"harvestcraft:pamflaxcrop",properties:{age:"3"}}}
:enddata
:endrule

rule:
plugin=vanillaBlocks
number=104
data:
JSON:{blockState:{blockName:"harvestcraft:pamflaxcrop",properties:{age:"2"}}}
:enddata
:endrule

rule:
plugin=vanillaBlocks
number=105
data:
JSON:{blockState:{blockName:"rustic:golden_lantern",properties:{facing:"up"}}}
:enddata
:endrule

rule:
plugin=vanillaBlocks
number=106
data:
JSON:{blockState:{blockName:"harvestcraft:pamflaxcrop",properties:{age:"1"}}}
:enddata
:endrule

rule:
plugin=vanillaSkull
number=107
data:
JSON:{blockState:{blockName:"minecraft:skull",properties:{nodrop:"false",facing:"up"}},skullRotation:14,teData:{Owner:{Id:"52b6c588-d184-11ec-9d64-0242ac120002",Properties:{textures:[{Value:"eyJ0ZXh0dXJlcyI6eyJTS0lOIjp7InVybCI6Imh0dHA6Ly90ZXh0dXJlcy5taW5lY3JhZnQubmV0L3RleHR1cmUvMjk5M2NiMTEzZjkyYmQzNmJlOTMzYzY4ZjBmOTAxZTIwZWE0MDlkMGZkYjIzYzIzM2Y4MDA3ODM0NWRkYjA3MCJ9fX0="}]}},Rot:10b,id:"minecraft:skull",SkullType:3b}}
:enddata
:endrule

rule:
plugin=vanillaSkull
number=108
data:
JSON:{blockState:{blockName:"minecraft:skull",properties:{nodrop:"false",facing:"up"}},skullRotation:2,teData:{Owner:{Id:"96bfcca0-98bb-4c37-ab1d-1132c8b2cadc",Properties:{textures:[{Value:"eyJ0ZXh0dXJlcyI6eyJTS0lOIjp7InVybCI6Imh0dHA6Ly90ZXh0dXJlcy5taW5lY3JhZnQubmV0L3RleHR1cmUvMDdjYmQ3OWNhOTZhYWI2NjJjMTg2ODg4ZjRlNmQyNWEyNzViYjFiNGRkZDQzNWI2MzUyOGMzMGMxNWEyMjUifX19"}]}},Rot:14b,id:"minecraft:skull",SkullType:3b}}
:enddata
:endrule

rule:
plugin=vanillaSkull
number=109
data:
JSON:{blockState:{blockName:"minecraft:skull",properties:{nodrop:"false",facing:"up"}},skullRotation:4,teData:{Owner:{Id:"a76f5a5a-9855-4c8a-b9fa-44123e065585",Properties:{textures:[{Value:"eyJ0ZXh0dXJlcyI6eyJTS0lOIjp7InVybCI6Imh0dHA6Ly90ZXh0dXJlcy5taW5lY3JhZnQubmV0L3RleHR1cmUvMzVmNzViYWUxMzQ5NmI5N2Y1NWRjNDJmYzM3MjQyYTg4MTU4OTUyYjZjY2U5M2MwNTdhYjAyOGFjYmE4MGIyMCJ9fX0="}]}},Rot:0b,id:"minecraft:skull",SkullType:3b}}
:enddata
:endrule

rule:
plugin=vanillaSkull
number=110
data:
JSON:{blockState:{blockName:"minecraft:skull",properties:{nodrop:"false",facing:"up"}},skullRotation:14,teData:{Owner:{Id:"4a842519-1cf4-48c5-ac2d-603e4dc4a243",Properties:{textures:[{Value:"eyJ0ZXh0dXJlcyI6eyJTS0lOIjp7InVybCI6Imh0dHA6Ly90ZXh0dXJlcy5taW5lY3JhZnQubmV0L3RleHR1cmUvNzhhNjhkZGI3ODIwMDUyNWI1YWFmNGRiMTc1MjgxNDFlNTg3NDU0Mzk1ZDg1ZTMzOWIwN2YzMTBhNDBiYTk1ZiJ9fX0="}]}},Rot:10b,id:"minecraft:skull",SkullType:3b}}
:enddata
:endrule

rule:
plugin=vanillaSkull
number=111
data:
JSON:{blockState:{blockName:"minecraft:skull",properties:{nodrop:"false",facing:"up"}},skullRotation:9,teData:{Owner:{Id:"96bfcca0-98bb-4c37-ab1d-1132c8b2cadc",Properties:{textures:[{Value:"eyJ0ZXh0dXJlcyI6eyJTS0lOIjp7InVybCI6Imh0dHA6Ly90ZXh0dXJlcy5taW5lY3JhZnQubmV0L3RleHR1cmUvMDdjYmQ3OWNhOTZhYWI2NjJjMTg2ODg4ZjRlNmQyNWEyNzViYjFiNGRkZDQzNWI2MzUyOGMzMGMxNWEyMjUifX19"}]}},Rot:5b,id:"minecraft:skull",SkullType:3b}}
:enddata
:endrule

rule:
plugin=vanillaSkull
number=112
data:
JSON:{blockState:{blockName:"minecraft:skull",properties:{nodrop:"false",facing:"up"}},skullRotation:7,teData:{Owner:{Id:"96bfcca0-98bb-4c37-ab1d-1132c8b2cadc",Properties:{textures:[{Value:"eyJ0ZXh0dXJlcyI6eyJTS0lOIjp7InVybCI6Imh0dHA6Ly90ZXh0dXJlcy5taW5lY3JhZnQubmV0L3RleHR1cmUvMDdjYmQ3OWNhOTZhYWI2NjJjMTg2ODg4ZjRlNmQyNWEyNzViYjFiNGRkZDQzNWI2MzUyOGMzMGMxNWEyMjUifX19"}]}},Rot:3b,id:"minecraft:skull",SkullType:3b}}
:enddata
:endrule

rule:
plugin=vanillaBlocks
number=113
data:
JSON:{blockState:{blockName:"harvestcraft:pamflaxcrop",properties:{age:"0"}}}
:enddata
:endrule

rule:
plugin=blockTile
number=114
data:
JSON:{blockState:{blockName:"ancientwarfarestructure:gate_proxy"},teData:{lsb:-6062094447113034482L,id:"ancientwarfarestructure:gate_proxy_tile",msb:-642925891553310447L,render:0b}}
:enddata
:endrule

rule:
plugin=blockTile
number=115
data:
JSON:{blockState:{blockName:"ancientwarfarestructure:gate_proxy"},teData:{lsb:-6062094447113034482L,id:"ancientwarfarestructure:gate_proxy_tile",msb:-642925891553310447L,render:0b}}
:enddata
:endrule

rule:
plugin=blockTile
number=116
data:
JSON:{blockState:{blockName:"ancientwarfarestructure:gate_proxy"},teData:{lsb:-6062094447113034482L,id:"ancientwarfarestructure:gate_proxy_tile",msb:-642925891553310447L,render:0b}}
:enddata
:endrule

rule:
plugin=vanillaBlocks
number=117
data:
JSON:{blockState:{blockName:"minecraft:wooden_slab",properties:{half:"top",variant:"oak"}}}
:enddata
:endrule

rule:
plugin=vanillaSkull
number=118
data:
JSON:{blockState:{blockName:"minecraft:skull",properties:{nodrop:"false",facing:"up"}},skullRotation:0,teData:{Owner:{Id:"4a842519-1cf4-48c5-ac2d-603e4dc4a243",Properties:{textures:[{Value:"eyJ0ZXh0dXJlcyI6eyJTS0lOIjp7InVybCI6Imh0dHA6Ly90ZXh0dXJlcy5taW5lY3JhZnQubmV0L3RleHR1cmUvNzhhNjhkZGI3ODIwMDUyNWI1YWFmNGRiMTc1MjgxNDFlNTg3NDU0Mzk1ZDg1ZTMzOWIwN2YzMTBhNDBiYTk1ZiJ9fX0="}]}},Rot:12b,id:"minecraft:skull",SkullType:3b}}
:enddata
:endrule

rule:
plugin=vanillaSkull
number=119
data:
JSON:{blockState:{blockName:"minecraft:skull",properties:{nodrop:"false",facing:"up"}},skullRotation:2,teData:{Owner:{Id:"52b6c588-d184-11ec-9d64-0242ac120002",Properties:{textures:[{Value:"eyJ0ZXh0dXJlcyI6eyJTS0lOIjp7InVybCI6Imh0dHA6Ly90ZXh0dXJlcy5taW5lY3JhZnQubmV0L3RleHR1cmUvMjk5M2NiMTEzZjkyYmQzNmJlOTMzYzY4ZjBmOTAxZTIwZWE0MDlkMGZkYjIzYzIzM2Y4MDA3ODM0NWRkYjA3MCJ9fX0="}]}},Rot:14b,id:"minecraft:skull",SkullType:3b}}
:enddata
:endrule

rule:
plugin=vanillaSkull
number=120
data:
JSON:{blockState:{blockName:"minecraft:skull",properties:{nodrop:"false",facing:"up"}},skullRotation:8,teData:{Owner:{Id:"a76f5a5a-9855-4c8a-b9fa-44123e065585",Properties:{textures:[{Value:"eyJ0ZXh0dXJlcyI6eyJTS0lOIjp7InVybCI6Imh0dHA6Ly90ZXh0dXJlcy5taW5lY3JhZnQubmV0L3RleHR1cmUvMzVmNzViYWUxMzQ5NmI5N2Y1NWRjNDJmYzM3MjQyYTg4MTU4OTUyYjZjY2U5M2MwNTdhYjAyOGFjYmE4MGIyMCJ9fX0="}]}},Rot:4b,id:"minecraft:skull",SkullType:3b}}
:enddata
:endrule

rule:
plugin=vanillaSkull
number=121
data:
JSON:{blockState:{blockName:"minecraft:skull",properties:{nodrop:"false",facing:"up"}},skullRotation:7,teData:{Owner:{Id:"a76f5a5a-9855-4c8a-b9fa-44123e065585",Properties:{textures:[{Value:"eyJ0ZXh0dXJlcyI6eyJTS0lOIjp7InVybCI6Imh0dHA6Ly90ZXh0dXJlcy5taW5lY3JhZnQubmV0L3RleHR1cmUvMzVmNzViYWUxMzQ5NmI5N2Y1NWRjNDJmYzM3MjQyYTg4MTU4OTUyYjZjY2U5M2MwNTdhYjAyOGFjYmE4MGIyMCJ9fX0="}]}},Rot:3b,id:"minecraft:skull",SkullType:3b}}
:enddata
:endrule

rule:
plugin=vanillaSkull
number=122
data:
JSON:{blockState:{blockName:"minecraft:skull",properties:{nodrop:"false",facing:"up"}},skullRotation:3,teData:{Owner:{Id:"a76f5a5a-9855-4c8a-b9fa-44123e065585",Properties:{textures:[{Value:"eyJ0ZXh0dXJlcyI6eyJTS0lOIjp7InVybCI6Imh0dHA6Ly90ZXh0dXJlcy5taW5lY3JhZnQubmV0L3RleHR1cmUvMzVmNzViYWUxMzQ5NmI5N2Y1NWRjNDJmYzM3MjQyYTg4MTU4OTUyYjZjY2U5M2MwNTdhYjAyOGFjYmE4MGIyMCJ9fX0="}]}},Rot:15b,id:"minecraft:skull",SkullType:3b}}
:enddata
:endrule

rule:
plugin=vanillaSkull
number=123
data:
JSON:{blockState:{blockName:"minecraft:skull",properties:{nodrop:"false",facing:"up"}},skullRotation:4,teData:{Owner:{Id:"4a842519-1cf4-48c5-ac2d-603e4dc4a243",Properties:{textures:[{Value:"eyJ0ZXh0dXJlcyI6eyJTS0lOIjp7InVybCI6Imh0dHA6Ly90ZXh0dXJlcy5taW5lY3JhZnQubmV0L3RleHR1cmUvNzhhNjhkZGI3ODIwMDUyNWI1YWFmNGRiMTc1MjgxNDFlNTg3NDU0Mzk1ZDg1ZTMzOWIwN2YzMTBhNDBiYTk1ZiJ9fX0="}]}},Rot:0b,id:"minecraft:skull",SkullType:3b}}
:enddata
:endrule

rule:
plugin=inventory
number=124
data:
JSON:{blockState:{blockName:"ancientwarfarestructure:loot_basket",properties:{visible:"true",double:"true",facing:"east"}},lootLevel:0,teData:{lootSettings:{lootRolls:1,splashPotion:0b,hasMessage:0b,hasLoot:1b,lootTableName:"ancientwarfare:chests/compat/harvestcraft/harvestcraft_village_farm_flax",spawnEntity:0b,entity:"minecraft:"},Items:[],id:"ancientwarfarestructure:loot_basket",Lock:""},legacyFeatures:0b}
:enddata
:endrule

rule:
plugin=vanillaSkull
number=125
data:
JSON:{blockState:{blockName:"minecraft:skull",properties:{nodrop:"false",facing:"up"}},skullRotation:3,teData:{Owner:{Id:"52b6c588-d184-11ec-9d64-0242ac120002",Properties:{textures:[{Value:"eyJ0ZXh0dXJlcyI6eyJTS0lOIjp7InVybCI6Imh0dHA6Ly90ZXh0dXJlcy5taW5lY3JhZnQubmV0L3RleHR1cmUvMjk5M2NiMTEzZjkyYmQzNmJlOTMzYzY4ZjBmOTAxZTIwZWE0MDlkMGZkYjIzYzIzM2Y4MDA3ODM0NWRkYjA3MCJ9fX0="}]}},Rot:15b,id:"minecraft:skull",SkullType:3b}}
:enddata
:endrule

rule:
plugin=vanillaSkull
number=126
data:
JSON:{blockState:{blockName:"minecraft:skull",properties:{nodrop:"false",facing:"up"}},skullRotation:9,teData:{Owner:{Id:"a76f5a5a-9855-4c8a-b9fa-44123e065585",Properties:{textures:[{Value:"eyJ0ZXh0dXJlcyI6eyJTS0lOIjp7InVybCI6Imh0dHA6Ly90ZXh0dXJlcy5taW5lY3JhZnQubmV0L3RleHR1cmUvMzVmNzViYWUxMzQ5NmI5N2Y1NWRjNDJmYzM3MjQyYTg4MTU4OTUyYjZjY2U5M2MwNTdhYjAyOGFjYmE4MGIyMCJ9fX0="}]}},Rot:5b,id:"minecraft:skull",SkullType:3b}}
:enddata
:endrule

rule:
plugin=vanillaBlocks
number=127
data:
JSON:{blockState:{blockName:"minecraft:torch",properties:{facing:"east"}}}
:enddata
:endrule

rule:
plugin=vanillaBlocks
number=128
data:
JSON:{blockState:{blockName:"minecraft:torch",properties:{facing:"south"}}}
:enddata
:endrule

rule:
plugin=vanillaBlocks
number=129
data:
JSON:{blockState:{blockName:"minecraft:red_sandstone_stairs",properties:{half:"bottom",shape:"straight",facing:"west"}}}
:enddata
:endrule

rule:
plugin=vanillaBlocks
number=130
data:
JSON:{blockState:{blockName:"minecraft:torch",properties:{facing:"west"}}}
:enddata
:endrule

rule:
plugin=vanillaBlocks
number=131
data:
JSON:{blockState:{blockName:"minecraft:red_sandstone_stairs",properties:{half:"top",shape:"straight",facing:"east"}}}
:enddata
:endrule

rule:
plugin=vanillaBlocks
number=132
data:
JSON:{blockState:{blockName:"minecraft:red_sandstone_stairs",properties:{half:"top",shape:"straight",facing:"west"}}}
:enddata
:endrule

rule:
plugin=vanillaBlocks
number=133
data:
JSON:{blockState:{blockName:"minecraft:red_sandstone_stairs",properties:{half:"top",shape:"straight",facing:"north"}}}
:enddata
:endrule

rule:
plugin=vanillaBlocks
number=134
data:
JSON:{blockState:{blockName:"minecraft:red_sandstone_stairs",properties:{half:"top",shape:"straight",facing:"south"}}}
:enddata
:endrule

rule:
plugin=blockTile
number=135
data:
JSON:{blockState:{blockName:"ancientwarfarestructure:gate_proxy"},teData:{lsb:-6062094447113034482L,id:"ancientwarfarestructure:gate_proxy_tile",msb:-642925891553310447L,render:0b}}
:enddata
:endrule

rule:
plugin=blockTile
number=136
data:
JSON:{blockState:{blockName:"ancientwarfarestructure:gate_proxy"},teData:{lsb:-6062094447113034482L,id:"ancientwarfarestructure:gate_proxy_tile",msb:-642925891553310447L,render:0b}}
:enddata
:endrule

rule:
plugin=blockTile
number=137
data:
JSON:{blockState:{blockName:"ancientwarfarestructure:gate_proxy"},teData:{lsb:-6062094447113034482L,id:"ancientwarfarestructure:gate_proxy_tile",msb:-642925891553310447L,render:0b}}
:enddata
:endrule

rule:
plugin=blockTile
number=138
data:
JSON:{blockState:{blockName:"ancientwarfarestructure:advanced_loot_chest",properties:{facing:"south"}},teData:{lootSettings:{lootRolls:1,splashPotion:0b,hasMessage:0b,hasLoot:1b,lootTableName:"ancientwarfare:chests/compat/harvestcraft/harvestcraft_village_farm_flax",spawnEntity:0b,entity:"minecraft:"},Items:[],id:"ancientwarfarestructure:advanced_loot_chest_tile",Lock:""}}
:enddata
:endrule

rule:
plugin=vanillaBlocks
number=139
data:
JSON:{blockState:{blockName:"minecraft:sandstone_stairs",properties:{half:"top",shape:"straight",facing:"east"}}}
:enddata
:endrule

rule:
plugin=vanillaSkull
number=140
data:
JSON:{blockState:{blockName:"minecraft:skull",properties:{nodrop:"false",facing:"up"}},skullRotation:7,teData:{Owner:{Id:"682bf1f3-4e79-4793-9a05-fba882293adf",Properties:{textures:[{Value:"eyJ0ZXh0dXJlcyI6eyJTS0lOIjp7InVybCI6Imh0dHA6Ly90ZXh0dXJlcy5taW5lY3JhZnQubmV0L3RleHR1cmUvNDBjNmMzYzk1MzM3MzY1Nzk5YzZjNTAyZDZmYzM0YTViMTk3NWNmNzM2NGJhMmRlOGZkYjBhZjUxZTZhMjhjIn19fQ=="}]}},Rot:3b,id:"minecraft:skull",SkullType:3b}}
:enddata
:endrule

rule:
plugin=vanillaBlocks
number=141
data:
JSON:{blockState:{blockName:"minecraft:sandstone_stairs",properties:{half:"top",shape:"straight",facing:"west"}}}
:enddata
:endrule

rule:
plugin=blockTile
number=142
data:
JSON:{blockState:{blockName:"ancientwarfarestructure:advanced_loot_chest",properties:{facing:"south"}},teData:{ForgeData:{},lootSettings:{lootRolls:1,splashPotion:0b,hasMessage:0b,hasLoot:1b,lootTableName:"ancientwarfare:chests/compat/harvestcraft/harvestcraft_village_farm_flax",spawnEntity:0b,entity:"minecraft:"},Items:[],id:"ancientwarfarestructure:advanced_loot_chest_tile",Lock:""}}
:enddata
:endrule

rule:
plugin=blockTile
number=143
data:
JSON:{blockState:{blockName:"ancientwarfarestructure:urn"},teData:{lootSettings:{lootRolls:1,splashPotion:0b,hasMessage:0b,hasLoot:1b,lootTableName:"ancientwarfare:chests/compat/harvestcraft/harvestcraft_village_farm_flax",spawnEntity:0b,entity:"minecraft:"},id:"ancientwarfarestructure:urn_tile"}}
:enddata
:endrule

rule:
plugin=blockTile
number=144
data:
JSON:{blockState:{blockName:"ancientwarfarestructure:advanced_loot_chest",properties:{facing:"south"}},teData:{lootSettings:{lootRolls:1,splashPotion:0b,hasMessage:0b,hasLoot:1b,lootTableName:"ancientwarfare:chests/compat/harvestcraft/harvestcraft_village_farm_flax",spawnEntity:0b,entity:"minecraft:"},Items:[],id:"ancientwarfarestructure:advanced_loot_chest_tile",Lock:""}}
:enddata
:endrule

rule:
plugin=vanillaSkull
number=145
data:
JSON:{blockState:{blockName:"minecraft:skull",properties:{nodrop:"false",facing:"up"}},skullRotation:4,teData:{Owner:{Id:"52b6c588-d184-11ec-9d64-0242ac120002",Properties:{textures:[{Value:"eyJ0ZXh0dXJlcyI6eyJTS0lOIjp7InVybCI6Imh0dHA6Ly90ZXh0dXJlcy5taW5lY3JhZnQubmV0L3RleHR1cmUvMjk5M2NiMTEzZjkyYmQzNmJlOTMzYzY4ZjBmOTAxZTIwZWE0MDlkMGZkYjIzYzIzM2Y4MDA3ODM0NWRkYjA3MCJ9fX0="}]}},Rot:0b,id:"minecraft:skull",SkullType:3b}}
:enddata
:endrule

rule:
plugin=vanillaBlocks
number=146
data:
JSON:{blockState:{blockName:"minecraft:stained_hardened_clay",properties:{color:"light_blue"}}}
:enddata
:endrule

rule:
plugin=vanillaBlocks
number=147
data:
JSON:{blockState:{blockName:"minecraft:stone_slab",properties:{half:"top",variant:"sandstone"}}}
:enddata
:endrule

rule:
plugin=vanillaBlocks
number=148
data:
JSON:{blockState:{blockName:"minecraft:wooden_slab",properties:{half:"bottom",variant:"birch"}}}
:enddata
:endrule

rule:
plugin=vanillaBlocks
number=149
data:
JSON:{blockState:{blockName:"minecraft:wool",properties:{color:"lime"}}}
:enddata
:endrule

rule:
plugin=vanillaBlocks
number=150
data:
JSON:{blockState:{blockName:"minecraft:wool",properties:{color:"light_blue"}}}
:enddata
:endrule

rule:
plugin=vanillaSkull
number=151
data:
