# Ancient Warfare Structure Template File
# Auto-generated structure template file. created on: 1/22/2021 at: 17:59:46
# Lines beginning with # denote comments

header:
version=2.11
name=nogg_lms_normal
mods=tconstruct,earthenbounty,inspirations,betteranimalsplus,conarm,biomesoplenty,chisel,growthcraft_milk,iceandfire,basemetals,rusticbopwoods,rustic,growthcraft_apples,gemsplusplus,bountiful,drpmedieval
size=63,53,19
offset=38,2,9
:endheader

#### VALIDATION ####
validation:
type=water
structureAuthor=TheOddlySeagull
survival=false
worldGenEnabled=true
unique=false
preserveBlocks=true
preventNaturalHostileSpawns=true
selectionWeight=2
clusterValue=400
minDuplicateDistance=10000
dimensionWhiteList=true
dimensionList=0
biomeGroupList=
biomeWhiteList=true
biomeList=minecraft:ocean,minecraft:deep_ocean
leveling=0
fill=0
border=0
blockSwap=false
territoryName=nog
biomeReplacement=minecraft:
:endvalidation

#### LAYERS ####
layer: 0
0,0,0,0,0,0,0,0,0,0,0,0,0,0,0,0,0,0,0,0,0,0,0,0,0,0,0,0,0,0,0,0,0,0,0,0,0,0,0,0,0,0,0,0,0,0,0,0,0,0,0,0,0,0,0,0,0,0,0,0,0,0,0
0,0,0,0,0,0,0,0,0,0,0,0,0,0,0,0,0,0,0,0,0,0,0,0,0,0,0,0,0,0,0,0,0,0,0,0,0,0,0,0,0,0,0,0,0,0,0,0,0,0,0,0,0,0,0,0,0,0,0,0,0,0,0
0,0,0,0,0,0,0,0,0,0,0,0,0,0,0,0,0,0,0,0,0,0,0,0,0,0,0,0,0,0,0,0,0,0,0,0,0,0,0,0,0,0,0,0,0,0,0,0,0,0,0,0,0,0,0,0,0,0,0,0,0,0,0
0,0,0,0,0,0,0,0,0,0,0,0,0,0,0,0,0,0,0,0,0,0,0,0,0,0,0,0,0,0,0,0,0,0,0,0,0,0,0,0,0,0,0,0,0,0,0,0,0,0,0,0,0,0,0,0,0,0,0,0,0,0,0
0,0,0,0,0,0,0,0,0,0,0,0,0,0,0,0,0,0,0,0,0,0,0,0,0,0,0,0,0,0,0,0,0,0,0,0,0,0,0,0,0,0,0,0,0,0,0,0,0,0,0,0,0,0,0,0,0,0,0,0,0,0,0
0,0,0,0,0,0,0,0,0,0,0,0,0,0,0,0,0,0,0,0,0,0,0,0,0,0,0,0,0,0,0,0,0,0,0,0,0,0,0,0,0,0,0,0,0,0,0,0,0,0,0,0,0,0,0,0,0,0,0,0,0,0,0
0,0,0,0,0,0,0,0,0,0,0,0,0,0,0,0,0,0,0,0,0,0,0,0,0,0,0,0,0,0,0,0,0,0,0,0,0,0,0,0,0,0,0,0,0,0,0,0,0,0,0,0,0,0,0,0,0,0,0,0,0,0,0
0,0,0,0,0,0,0,0,0,0,0,0,0,0,0,0,0,0,0,0,0,0,0,0,0,0,0,0,0,0,0,0,0,0,0,0,0,0,0,0,0,0,0,0,0,0,0,0,0,0,0,0,0,0,0,0,0,0,0,0,0,0,0
0,0,0,0,0,0,0,0,0,0,0,0,0,0,0,0,0,0,0,0,0,0,0,0,0,0,0,0,0,0,0,0,0,0,0,0,0,0,0,0,0,0,0,0,0,0,0,0,0,0,0,0,0,0,0,0,0,0,0,0,0,0,0
0,0,0,0,0,0,0,0,1,1,1,1,1,1,1,1,1,1,1,1,1,1,1,1,1,1,1,1,1,1,1,1,1,1,1,1,1,1,0,0,0,0,0,0,0,0,0,0,0,0,0,0,0,0,0,0,0,0,0,0,0,0,0
0,0,0,0,0,0,0,0,0,0,0,0,0,0,0,0,0,0,0,0,0,0,0,0,0,0,0,0,0,0,0,0,0,0,0,0,0,0,0,0,0,0,0,0,0,0,0,0,0,0,0,0,0,0,0,0,0,0,0,0,0,0,0
0,0,0,0,0,0,0,0,0,0,0,0,0,0,0,0,0,0,0,0,0,0,0,0,0,0,0,0,0,0,0,0,0,0,0,0,0,0,0,0,0,0,0,0,0,0,0,0,0,0,0,0,0,0,0,0,0,0,0,0,0,0,0
0,0,0,0,0,0,0,0,0,0,0,0,0,0,0,0,0,0,0,0,0,0,0,0,0,0,0,0,0,0,0,0,0,0,0,0,0,0,0,0,0,0,0,0,0,0,0,0,0,0,0,0,0,0,0,0,0,0,0,0,0,0,0
0,0,0,0,0,0,0,0,0,0,0,0,0,0,0,0,0,0,0,0,0,0,0,0,0,0,0,0,0,0,0,0,0,0,0,0,0,0,0,0,0,0,0,0,0,0,0,0,0,0,0,0,0,0,0,0,0,0,0,0,0,0,0
0,0,0,0,0,0,0,0,0,0,0,0,0,0,0,0,0,0,0,0,0,0,0,0,0,0,0,0,0,0,0,0,0,0,0,0,0,0,0,0,0,0,0,0,0,0,0,0,0,0,0,0,0,0,0,0,0,0,0,0,0,0,0
0,0,0,0,0,0,0,0,0,0,0,0,0,0,0,0,0,0,0,0,0,0,0,0,0,0,0,0,0,0,0,0,0,0,0,0,0,0,0,0,0,0,0,0,0,0,0,0,0,0,0,0,0,0,0,0,0,0,0,0,0,0,0
0,0,0,0,0,0,0,0,0,0,0,0,0,0,0,0,0,0,0,0,0,0,0,0,0,0,0,0,0,0,0,0,0,0,0,0,0,0,0,0,0,0,0,0,0,0,0,0,0,0,0,0,0,0,0,0,0,0,0,0,0,0,0
0,0,0,0,0,0,0,0,0,0,0,0,0,0,0,0,0,0,0,0,0,0,0,0,0,0,0,0,0,0,0,0,0,0,0,0,0,0,0,0,0,0,0,0,0,0,0,0,0,0,0,0,0,0,0,0,0,0,0,0,0,0,0
0,0,0,0,0,0,0,0,0,0,0,0,0,0,0,0,0,0,0,0,0,0,0,0,0,0,0,0,0,0,0,0,0,0,0,0,0,0,0,0,0,0,0,0,0,0,0,0,0,0,0,0,0,0,0,0,0,0,0,0,0,0,0
:endlayer
layer: 1
0,0,0,0,0,0,0,0,0,0,0,0,0,0,0,0,0,0,0,0,0,0,0,0,0,0,0,0,0,0,0,0,0,0,0,0,0,0,0,0,0,0,0,0,0,0,0,0,0,0,0,0,0,0,0,0,0,0,0,0,0,0,0
0,0,0,0,0,0,0,0,0,0,0,0,0,0,0,0,0,0,0,0,0,0,0,0,0,0,0,0,0,0,0,0,0,0,0,0,0,0,0,0,0,0,0,0,0,0,0,0,0,0,0,0,0,0,0,0,0,0,0,0,0,0,0
0,0,0,0,0,0,0,0,0,0,0,0,0,0,0,0,0,0,0,0,0,0,0,0,0,0,0,0,0,0,0,0,0,0,0,0,0,0,0,0,0,0,0,0,0,0,0,0,0,0,0,0,0,0,0,0,0,0,0,0,0,0,0
0,0,0,0,0,0,0,0,0,0,0,0,0,0,0,0,0,0,0,0,0,0,0,0,0,0,0,0,0,0,0,0,0,0,0,0,0,0,0,0,0,0,0,0,0,0,0,0,0,0,0,0,0,0,0,0,0,0,0,0,0,0,0
0,0,0,0,0,0,0,0,0,0,0,0,0,0,0,0,0,0,0,0,0,0,0,0,0,0,0,0,0,0,0,0,0,0,0,0,0,0,0,0,0,0,0,0,0,0,0,0,0,0,0,0,0,0,0,0,0,0,0,0,0,0,0
0,0,0,0,0,0,0,0,0,0,0,0,0,0,0,0,0,0,0,0,0,0,0,0,0,0,0,0,0,0,0,0,0,0,0,0,0,0,0,0,0,0,0,0,0,0,0,0,0,0,0,0,0,0,0,0,0,0,0,0,0,0,0
0,0,0,0,0,0,0,0,0,0,0,0,0,0,0,0,0,0,0,0,0,0,0,0,0,0,0,0,0,0,0,0,0,0,0,0,0,0,0,0,0,0,0,0,0,0,0,0,0,0,0,0,0,0,0,0,0,0,0,0,0,0,0
0,0,0,0,0,0,0,0,0,0,1,1,1,1,1,1,1,1,1,1,1,1,1,1,1,1,1,1,1,1,1,1,1,1,1,1,0,0,0,0,0,0,0,0,0,0,0,0,0,0,0,0,0,0,0,0,0,0,0,0,0,0,0
0,0,0,0,0,0,0,0,0,1,1,1,1,1,1,1,1,1,1,1,1,1,1,1,1,1,1,1,1,1,1,1,1,1,1,1,1,1,0,0,0,0,0,0,0,0,0,0,0,0,0,0,0,0,0,0,0,0,0,0,0,0,0
0,0,0,0,0,0,0,0,1,1,1,1,1,1,1,1,1,1,1,1,1,1,1,1,1,1,1,1,1,1,1,1,1,1,1,1,1,1,1,1,0,0,0,0,0,0,0,0,0,0,0,0,0,0,0,0,0,0,0,0,0,0,0
0,0,0,0,0,0,0,0,0,1,1,1,1,1,1,1,1,1,1,1,1,1,1,1,1,1,1,1,1,1,1,1,1,1,1,1,1,1,0,0,0,0,0,0,0,0,0,0,0,0,0,0,0,0,0,0,0,0,0,0,0,0,0
0,0,0,0,0,0,0,0,0,0,1,1,1,1,1,1,1,1,1,1,1,1,1,1,1,1,1,1,1,1,1,1,1,1,1,1,0,0,0,0,0,0,0,0,0,0,0,0,0,0,0,0,0,0,0,0,0,0,0,0,0,0,0
0,0,0,0,0,0,0,0,0,0,0,0,0,0,0,0,0,0,0,0,0,0,0,0,0,0,0,0,0,0,0,0,0,0,0,0,0,0,0,0,0,0,0,0,0,0,0,0,0,0,0,0,0,0,0,0,0,0,0,0,0,0,0
0,0,0,0,0,0,0,0,0,0,0,0,0,0,0,0,0,0,0,0,0,0,0,0,0,0,0,0,0,0,0,0,0,0,0,0,0,0,0,0,0,0,0,0,0,0,0,0,0,0,0,0,0,0,0,0,0,0,0,0,0,0,0
0,0,0,0,0,0,0,0,0,0,0,0,0,0,0,0,0,0,0,0,0,0,0,0,0,0,0,0,0,0,0,0,0,0,0,0,0,0,0,0,0,0,0,0,0,0,0,0,0,0,0,0,0,0,0,0,0,0,0,0,0,0,0
0,0,0,0,0,0,0,0,0,0,0,0,0,0,0,0,0,0,0,0,0,0,0,0,0,0,0,0,0,0,0,0,0,0,0,0,0,0,0,0,0,0,0,0,0,0,0,0,0,0,0,0,0,0,0,0,0,0,0,0,0,0,0
0,0,0,0,0,0,0,0,0,0,0,0,0,0,0,0,0,0,0,0,0,0,0,0,0,0,0,0,0,0,0,0,0,0,0,0,0,0,0,0,0,0,0,0,0,0,0,0,0,0,0,0,0,0,0,0,0,0,0,0,0,0,0
0,0,0,0,0,0,0,0,0,0,0,0,0,0,0,0,0,0,0,0,0,0,0,0,0,0,0,0,0,0,0,0,0,0,0,0,0,0,0,0,0,0,0,0,0,0,0,0,0,0,0,0,0,0,0,0,0,0,0,0,0,0,0
0,0,0,0,0,0,0,0,0,0,0,0,0,0,0,0,0,0,0,0,0,0,0,0,0,0,0,0,0,0,0,0,0,0,0,0,0,0,0,0,0,0,0,0,0,0,0,0,0,0,0,0,0,0,0,0,0,0,0,0,0,0,0
:endlayer
layer: 2
0,0,0,0,0,0,0,0,0,0,0,0,0,0,0,0,0,0,0,0,0,0,0,0,0,0,0,0,0,0,0,0,0,0,0,0,0,0,0,0,0,0,0,0,0,0,0,0,0,0,0,0,0,0,0,0,0,0,0,0,0,0,0
0,0,0,0,0,0,0,0,0,0,0,0,0,0,0,0,0,0,0,0,0,0,0,0,0,0,0,0,0,0,0,0,0,0,0,0,0,0,0,0,0,0,0,0,0,0,0,0,0,0,0,0,0,0,0,0,0,0,0,0,0,0,0
0,0,0,0,0,0,0,0,0,0,0,0,0,0,0,0,0,0,0,0,0,0,0,0,0,0,0,0,0,0,0,0,0,0,0,0,0,0,0,0,0,0,0,0,0,0,0,0,0,0,0,0,0,0,0,0,0,0,0,0,0,0,0
0,0,0,0,0,0,0,0,0,0,0,0,0,0,0,0,0,0,0,0,0,0,0,0,0,0,0,0,0,0,0,0,0,0,0,0,0,0,0,0,0,0,0,0,0,0,0,0,0,0,0,0,0,0,0,0,0,0,0,0,0,0,0
0,0,0,0,0,0,0,0,0,0,0,0,0,0,0,0,0,0,0,0,0,0,0,0,0,0,0,0,0,0,0,0,0,0,0,0,0,0,0,0,0,0,0,0,0,0,0,0,0,0,0,0,0,0,0,0,0,0,0,0,0,0,0
0,0,0,0,0,0,0,0,0,0,0,0,0,0,0,0,0,0,0,0,0,0,0,0,0,0,0,0,0,0,0,0,0,0,0,0,0,0,0,0,0,0,0,0,0,0,0,0,0,0,0,0,0,0,0,0,0,0,0,0,0,0,0
0,0,0,0,0,0,0,0,0,0,1,1,1,1,1,1,1,1,1,1,30,30,1,30,1,30,30,1,30,1,30,30,30,30,30,60,0,0,0,0,0,0,0,0,0,0,0,0,0,0,0,0,0,0,0,0,0,0,0,0,0,0,0
0,0,0,0,0,0,0,0,0,1,5,2,13,16,20,1,23,0,27,1,27,0,23,0,22,0,41,43,45,46,48,0,52,56,0,60,1,1,0,0,0,0,0,0,0,0,0,0,0,0,0,0,0,0,0,0,0,0,0,0,0,0,0
0,0,0,0,0,0,0,0,0,1,4,0,12,15,19,1,0,26,0,1,0,33,34,0,37,0,27,1,29,1,29,29,51,55,58,1,62,65,1,1,0,0,0,0,0,0,0,0,0,0,0,0,0,0,0,0,0,0,0,0,0,0,0
0,0,0,0,0,0,0,0,1,1,1,8,11,3,18,1,0,0,0,28,0,0,0,36,22,39,27,1,28,28,1,50,51,54,57,46,0,64,66,28,1,1,0,0,0,0,0,0,0,0,0,0,0,0,0,0,0,0,0,0,0,0,0
0,0,0,0,0,0,0,0,0,1,3,7,10,0,17,1,22,25,22,1,22,32,22,22,22,38,0,42,44,1,1,0,29,29,1,59,61,63,1,1,0,0,0,0,0,0,0,0,0,0,0,0,0,0,0,0,0,0,0,0,0,0,0
0,0,0,0,0,0,0,0,0,1,2,6,9,14,0,21,0,24,0,21,0,31,0,35,0,0,40,27,44,1,47,49,0,53,1,59,1,1,0,0,0,0,0,0,0,0,0,0,0,0,0,0,0,0,0,0,0,0,0,0,0,0,0
0,0,0,0,0,0,0,0,0,0,1,1,1,1,1,1,1,1,1,1,29,29,1,29,1,29,29,1,1,1,1,1,1,1,1,1,0,0,0,0,0,0,0,0,0,0,0,0,0,0,0,0,0,0,0,0,0,0,0,0,0,0,0
0,0,0,0,0,0,0,0,0,0,0,0,0,0,0,0,0,0,0,0,0,0,0,0,0,0,0,0,0,0,0,0,0,0,0,0,0,0,0,0,0,0,0,0,0,0,0,0,0,0,0,0,0,0,0,0,0,0,0,0,0,0,0
0,0,0,0,0,0,0,0,0,0,0,0,0,0,0,0,0,0,0,0,0,0,0,0,0,0,0,0,0,0,0,0,0,0,0,0,0,0,0,0,0,0,0,0,0,0,0,0,0,0,0,0,0,0,0,0,0,0,0,0,0,0,0
0,0,0,0,0,0,0,0,0,0,0,0,0,0,0,0,0,0,0,0,0,0,0,0,0,0,0,0,0,0,0,0,0,0,0,0,0,0,0,0,0,0,0,0,0,0,0,0,0,0,0,0,0,0,0,0,0,0,0,0,0,0,0
0,0,0,0,0,0,0,0,0,0,0,0,0,0,0,0,0,0,0,0,0,0,0,0,0,0,0,0,0,0,0,0,0,0,0,0,0,0,0,0,0,0,0,0,0,0,0,0,0,0,0,0,0,0,0,0,0,0,0,0,0,0,0
0,0,0,0,0,0,0,0,0,0,0,0,0,0,0,0,0,0,0,0,0,0,0,0,0,0,0,0,0,0,0,0,0,0,0,0,0,0,0,0,0,0,0,0,0,0,0,0,0,0,0,0,0,0,0,0,0,0,0,0,0,0,0
0,0,0,0,0,0,0,0,0,0,0,0,0,0,0,0,0,0,0,0,0,0,0,0,0,0,0,0,0,0,0,0,0,0,0,0,0,0,0,0,0,0,0,0,0,0,0,0,0,0,0,0,0,0,0,0,0,0,0,0,0,0,0
:endlayer
layer: 3
0,0,0,0,0,0,0,0,0,0,0,0,0,0,0,0,0,0,0,0,0,0,0,0,0,0,0,0,0,0,0,0,0,0,0,0,0,0,0,0,0,0,0,0,0,0,0,0,0,0,0,0,0,0,0,0,0,0,0,0,0,0,0
0,0,0,0,0,0,0,0,0,0,0,0,0,0,0,0,0,0,0,0,0,0,0,0,0,0,0,0,0,0,0,0,0,0,0,0,0,0,0,0,0,0,0,0,0,0,0,0,0,0,0,0,0,0,0,0,0,0,0,0,0,0,0
0,0,0,0,0,0,0,0,0,0,0,0,0,0,0,0,0,0,0,0,0,0,0,0,0,0,0,0,0,0,0,0,0,0,0,0,0,0,0,0,0,0,0,0,0,0,0,0,0,0,0,0,0,0,0,0,0,0,0,0,0,0,0
0,0,0,0,0,0,0,0,0,0,0,0,0,0,0,0,0,0,0,0,0,0,0,0,0,0,0,0,0,109,0,0,0,0,0,0,0,0,0,0,0,0,0,0,0,0,0,0,0,0,0,0,0,0,0,0,0,0,0,0,0,0,0
0,0,0,0,0,0,0,0,0,0,0,0,0,0,0,0,0,0,0,0,0,0,0,0,0,0,0,0,0,1,0,0,0,0,0,0,0,0,0,0,0,0,0,0,0,0,0,0,0,0,0,0,0,0,0,0,0,0,0,0,0,0,0
0,0,0,0,0,0,0,0,0,68,1,1,1,1,1,1,1,1,1,1,1,1,1,1,1,1,1,1,1,1,1,1,1,1,1,1,116,0,0,0,0,0,0,0,0,0,0,0,0,0,0,0,0,0,0,0,0,0,0,0,0,0,0
0,0,0,0,0,0,0,0,68,1,1,77,80,84,87,1,0,91,27,1,95,97,1,99,1,101,103,1,106,1,67,67,67,67,67,67,1,1,116,0,0,0,0,0,0,0,0,0,0,0,0,0,0,0,0,0,0,0,0,0,0,0,0
0,0,0,0,0,0,0,0,1,72,73,0,0,83,86,1,0,0,0,1,0,0,91,0,22,0,0,88,0,108,0,0,0,0,0,115,118,123,1,1,116,0,0,0,0,0,0,0,0,0,0,0,0,0,0,0,0,0,0,0,0,0,0
0,0,0,0,0,0,0,0,1,71,73,0,0,0,3,1,0,0,0,1,0,0,0,0,0,0,40,1,105,1,68,68,113,0,85,1,0,122,126,128,1,1,116,0,0,0,0,0,0,0,0,0,0,0,0,0,0,0,0,0,0,0,0
0,0,0,0,0,0,0,0,1,28,1,76,79,82,85,1,0,0,85,28,76,0,0,0,22,0,85,1,28,28,111,0,113,0,114,108,0,121,125,28,129,130,1,1,116,0,0,0,0,0,0,0,0,0,0,0,0,0,0,0,0,0,0
0,0,0,0,0,0,0,0,1,70,73,0,0,0,0,1,22,0,22,1,22,0,22,22,22,0,0,0,0,1,110,0,68,68,1,113,0,120,124,127,1,1,116,0,0,0,0,0,0,0,0,0,0,0,0,0,0,0,0,0,0,0,0
0,0,0,0,0,0,0,0,1,69,73,75,0,0,0,88,0,0,0,93,0,0,90,0,90,0,0,90,104,1,0,112,0,1,1,113,117,119,1,1,116,0,0,0,0,0,0,0,0,0,0,0,0,0,0,0,0,0,0,0,0,0,0
0,0,0,0,0,0,0,0,67,1,1,74,78,81,81,1,89,90,92,1,94,96,1,98,1,100,102,1,44,1,1,1,1,1,1,1,1,1,116,0,0,0,0,0,0,0,0,0,0,0,0,0,0,0,0,0,0,0,0,0,0,0,0
0,0,0,0,0,0,0,0,0,67,1,1,1,1,1,1,1,1,1,1,1,1,1,1,1,1,1,1,1,1,1,1,1,1,1,1,116,0,0,0,0,0,0,0,0,0,0,0,0,0,0,0,0,0,0,0,0,0,0,0,0,0,0
0,0,0,0,0,0,0,0,0,0,0,0,0,0,0,0,0,0,0,0,0,0,0,0,0,0,0,0,0,1,0,0,0,0,0,0,0,0,0,0,0,0,0,0,0,0,0,0,0,0,0,0,0,0,0,0,0,0,0,0,0,0,0
0,0,0,0,0,0,0,0,0,0,0,0,0,0,0,0,0,0,0,0,0,0,0,0,0,0,0,0,0,107,0,0,0,0,0,0,0,0,0,0,0,0,0,0,0,0,0,0,0,0,0,0,0,0,0,0,0,0,0,0,0,0,0
0,0,0,0,0,0,0,0,0,0,0,0,0,0,0,0,0,0,0,0,0,0,0,0,0,0,0,0,0,0,0,0,0,0,0,0,0,0,0,0,0,0,0,0,0,0,0,0,0,0,0,0,0,0,0,0,0,0,0,0,0,0,0
0,0,0,0,0,0,0,0,0,0,0,0,0,0,0,0,0,0,0,0,0,0,0,0,0,0,0,0,0,0,0,0,0,0,0,0,0,0,0,0,0,0,0,0,0,0,0,0,0,0,0,0,0,0,0,0,0,0,0,0,0,0,0
0,0,0,0,0,0,0,0,0,0,0,0,0,0,0,0,0,0,0,0,0,0,0,0,0,0,0,0,0,0,0,0,0,0,0,0,0,0,0,0,0,0,0,0,0,0,0,0,0,0,0,0,0,0,0,0,0,0,0,0,0,0,0
:endlayer
layer: 4
0,0,0,0,0,0,0,0,0,0,0,0,0,0,0,0,0,0,0,0,0,0,0,0,0,0,0,0,0,0,0,0,0,0,0,0,0,0,0,0,0,0,0,0,0,0,0,0,0,0,0,0,0,0,0,0,0,0,0,0,0,0,0
0,0,0,0,0,0,0,0,0,0,0,0,0,0,0,0,0,0,0,0,0,0,0,0,0,0,0,0,0,0,0,0,0,0,0,0,0,0,0,0,0,0,0,0,0,0,0,0,0,0,0,0,0,0,0,0,0,0,0,0,0,0,0
0,0,0,0,0,0,0,0,0,0,0,0,0,0,0,0,0,0,0,0,0,0,0,0,0,0,0,0,0,0,0,0,0,0,0,0,0,0,0,0,0,0,0,0,0,0,0,0,0,0,0,0,0,0,0,0,0,0,0,0,0,0,0
0,0,0,0,0,0,0,0,0,0,0,0,0,0,0,0,0,0,0,0,0,0,0,0,0,0,0,0,0,109,0,0,0,0,0,0,0,0,0,0,0,0,0,0,0,0,0,0,0,0,0,0,0,0,0,0,0,0,0,0,0,0,0
0,0,0,0,0,0,0,0,0,0,0,0,0,0,0,0,0,0,0,0,0,0,0,0,0,0,0,0,0,1,0,0,0,0,0,0,0,0,0,0,0,0,0,0,0,0,0,0,0,0,0,0,0,0,0,0,0,0,0,0,0,0,0
0,0,0,0,0,0,0,0,68,1,1,1,1,1,1,1,1,1,1,1,1,1,1,1,1,1,1,1,1,1,1,1,1,1,1,1,1,1,116,0,0,0,0,0,0,0,0,0,0,0,0,0,0,0,0,0,0,0,0,0,0,0,0
0,0,0,0,0,0,0,0,1,44,44,132,132,132,132,44,132,132,132,44,134,134,44,134,44,134,134,44,132,1,44,44,44,44,44,1,138,143,1,1,116,0,0,0,0,0,0,0,0,0,0,0,0,0,0,0,0,0,0,0,0,0,0
0,0,0,0,0,0,0,116,1,131,131,132,132,132,132,44,132,132,132,44,132,132,132,132,132,132,132,44,132,1,44,44,44,44,44,1,0,0,148,150,1,1,116,0,0,0,0,0,0,0,0,0,0,0,0,0,0,0,0,0,0,0,0
0,0,0,0,0,0,0,1,44,131,131,132,132,132,132,44,132,132,132,44,132,132,132,132,132,132,132,44,132,1,44,44,44,44,44,1,0,142,147,0,152,154,1,1,116,0,0,0,0,0,0,0,0,0,0,0,0,0,0,0,0,0,0
0,0,0,0,0,0,0,1,44,28,44,132,132,132,132,44,132,132,132,28,132,132,132,132,132,132,132,44,28,28,44,44,44,44,44,1,0,141,146,28,0,0,155,156,1,1,116,0,0,0,0,0,0,0,0,0,0,0,0,0,0,0,0
0,0,0,0,0,0,0,1,44,131,131,132,132,132,132,44,132,132,132,44,132,132,132,132,132,132,0,0,0,1,132,132,44,44,1,1,0,140,145,0,151,153,1,1,116,0,0,0,0,0,0,0,0,0,0,0,0,0,0,0,0,0,0
0,0,0,0,0,0,0,116,1,131,131,132,132,132,132,44,132,132,132,44,132,132,132,132,132,132,132,132,0,1,1,1,1,1,136,1,0,0,144,149,1,1,116,0,0,0,0,0,0,0,0,0,0,0,0,0,0,0,0,0,0,0,0
0,0,0,0,0,0,0,0,1,44,44,132,132,132,132,44,132,132,132,44,133,133,44,133,44,133,133,44,104,1,1,1,1,1,135,1,137,139,1,1,116,0,0,0,0,0,0,0,0,0,0,0,0,0,0,0,0,0,0,0,0,0,0
0,0,0,0,0,0,0,0,67,1,1,1,1,1,1,1,1,1,1,1,1,1,1,1,1,1,1,1,1,1,1,1,1,1,1,1,1,1,116,0,0,0,0,0,0,0,0,0,0,0,0,0,0,0,0,0,0,0,0,0,0,0,0
0,0,0,0,0,0,0,0,0,0,0,0,0,0,0,0,0,0,0,0,0,0,0,0,0,0,0,0,0,1,0,0,0,0,0,0,0,0,0,0,0,0,0,0,0,0,0,0,0,0,0,0,0,0,0,0,0,0,0,0,0,0,0
0,0,0,0,0,0,0,0,0,0,0,0,0,0,0,0,0,0,0,0,0,0,0,0,0,0,0,0,0,107,0,0,0,0,0,0,0,0,0,0,0,0,0,0,0,0,0,0,0,0,0,0,0,0,0,0,0,0,0,0,0,0,0
0,0,0,0,0,0,0,0,0,0,0,0,0,0,0,0,0,0,0,0,0,0,0,0,0,0,0,0,0,0,0,0,0,0,0,0,0,0,0,0,0,0,0,0,0,0,0,0,0,0,0,0,0,0,0,0,0,0,0,0,0,0,0
0,0,0,0,0,0,0,0,0,0,0,0,0,0,0,0,0,0,0,0,0,0,0,0,0,0,0,0,0,0,0,0,0,0,0,0,0,0,0,0,0,0,0,0,0,0,0,0,0,0,0,0,0,0,0,0,0,0,0,0,0,0,0
0,0,0,0,0,0,0,0,0,0,0,0,0,0,0,0,0,0,0,0,0,0,0,0,0,0,0,0,0,0,0,0,0,0,0,0,0,0,0,0,0,0,0,0,0,0,0,0,0,0,0,0,0,0,0,0,0,0,0,0,0,0,0
:endlayer
layer: 5
0,0,0,0,0,0,0,0,0,0,0,0,0,0,0,0,0,0,0,0,0,0,0,0,0,0,0,0,0,0,0,0,0,0,0,0,0,0,0,0,0,0,0,0,0,0,0,0,0,0,0,0,0,0,0,0,0,0,0,0,0,0,0
0,0,0,0,0,0,0,0,0,0,0,0,0,0,0,0,0,0,0,0,0,0,0,0,0,0,0,0,0,0,0,0,0,0,0,0,0,0,0,0,0,0,0,0,0,0,0,0,0,0,0,0,0,0,0,0,0,0,0,0,0,0,0
0,0,0,0,0,0,0,0,0,0,0,0,0,0,0,0,0,0,0,0,0,0,0,0,0,0,0,0,0,0,0,0,0,0,0,0,0,0,0,0,0,0,0,0,0,0,0,0,0,0,0,0,0,0,0,0,0,0,0,0,0,0,0
0,0,0,0,0,0,0,0,0,0,0,0,0,0,0,0,0,0,0,0,0,0,0,0,0,0,0,0,0,109,0,0,0,0,0,0,0,0,0,0,0,0,0,0,0,0,0,0,0,0,0,0,0,0,0,0,0,0,0,0,0,0,0
0,0,0,0,0,0,0,0,68,1,1,1,1,1,1,1,1,1,1,1,1,1,1,1,1,1,1,1,1,1,1,1,1,1,1,1,1,1,116,0,0,0,0,0,0,0,0,0,0,0,0,0,0,0,0,0,0,0,0,0,0,0,0
0,0,0,0,0,0,0,68,51,163,167,172,175,177,182,1,187,191,195,1,200,200,200,200,200,200,200,200,200,1,224,181,224,181,224,1,242,244,1,1,116,0,0,0,0,0,0,0,0,0,0,0,0,0,0,0,0,0,0,0,0,0,0
0,0,0,0,0,0,0,1,160,162,0,171,171,171,181,1,186,186,186,1,199,199,199,199,199,199,199,199,199,1,223,181,223,181,223,1,0,0,246,248,1,1,116,0,0,0,0,0,0,0,0,0,0,0,0,0,0,0,0,0,0,0,0
0,0,0,0,0,0,0,1,160,162,0,171,171,171,173,1,161,186,186,43,0,0,202,0,207,0,0,214,0,43,222,227,230,0,236,1,241,0,0,0,250,252,1,1,116,0,0,0,0,0,0,0,0,0,0,0,0,0,0,0,0,0,0
0,0,0,0,0,0,0,1,159,0,166,171,171,171,173,1,161,161,161,1,160,162,0,0,206,0,211,0,216,1,221,221,221,232,235,1,240,0,0,90,0,0,254,256,1,1,116,0,0,0,0,0,0,0,0,0,0,0,0,0,0,0,0
0,0,0,0,0,0,0,1,1,28,1,170,170,1,28,1,1,1,1,28,160,162,201,204,42,131,210,213,28,28,220,226,229,73,234,1,76,0,85,28,76,0,0,0,257,1,1,1,116,0,0,0,0,0,0,0,0,0,0,0,0,0,0
0,0,0,0,0,0,0,1,1,0,165,0,0,0,180,42,1,1,194,1,160,162,0,203,205,0,209,209,209,1,1,1,1,231,1,1,239,0,0,91,0,0,253,255,1,1,116,0,0,0,0,0,0,0,0,0,0,0,0,0,0,0,0
0,0,0,0,0,0,0,1,158,0,164,169,174,0,1,1,185,190,0,43,198,0,0,0,0,0,208,212,215,1,219,0,228,228,215,1,238,0,0,0,249,251,1,1,116,0,0,0,0,0,0,0,0,0,0,0,0,0,0,0,0,0,0
0,0,0,0,0,0,0,1,157,0,0,0,0,176,179,1,184,189,193,1,197,197,197,197,197,197,197,197,215,1,218,0,228,228,215,1,0,0,245,247,1,1,116,0,0,0,0,0,0,0,0,0,0,0,0,0,0,0,0,0,0,0,0
0,0,0,0,0,0,0,67,1,161,161,168,173,173,178,1,183,188,192,28,196,196,196,196,196,196,196,196,0,1,217,225,228,228,233,1,237,243,1,1,116,0,0,0,0,0,0,0,0,0,0,0,0,0,0,0,0,0,0,0,0,0,0
0,0,0,0,0,0,0,0,67,1,1,1,1,1,1,1,1,1,1,1,1,1,1,1,1,1,1,1,1,1,1,1,1,1,1,1,1,1,116,0,0,0,0,0,0,0,0,0,0,0,0,0,0,0,0,0,0,0,0,0,0,0,0
0,0,0,0,0,0,0,0,0,0,0,0,0,0,0,0,0,0,0,0,0,0,0,0,0,0,0,0,0,107,0,0,0,0,0,0,0,0,0,0,0,0,0,0,0,0,0,0,0,0,0,0,0,0,0,0,0,0,0,0,0,0,0
0,0,0,0,0,0,0,0,0,0,0,0,0,0,0,0,0,0,0,0,0,0,0,0,0,0,0,0,0,0,0,0,0,0,0,0,0,0,0,0,0,0,0,0,0,0,0,0,0,0,0,0,0,0,0,0,0,0,0,0,0,0,0
0,0,0,0,0,0,0,0,0,0,0,0,0,0,0,0,0,0,0,0,0,0,0,0,0,0,0,0,0,0,0,0,0,0,0,0,0,0,0,0,0,0,0,0,0,0,0,0,0,0,0,0,0,0,0,0,0,0,0,0,0,0,0
0,0,0,0,0,0,0,0,0,0,0,0,0,0,0,0,0,0,0,0,0,0,0,0,0,0,0,0,0,0,0,0,0,0,0,0,0,0,0,0,0,0,0,0,0,0,0,0,0,0,0,0,0,0,0,0,0,0,0,0,0,0,0
:endlayer
layer: 6
0,0,0,0,0,0,0,0,0,0,0,0,0,0,0,0,0,0,0,0,0,0,0,0,0,0,0,0,0,0,0,0,0,0,0,0,0,0,0,0,0,0,0,0,0,0,0,0,0,0,0,0,0,0,0,0,0,0,0,0,0,0,0
0,0,0,0,0,0,0,0,0,0,0,0,0,0,0,0,0,0,0,0,0,0,0,0,0,0,0,0,0,0,0,0,0,0,0,0,0,0,0,0,0,0,0,0,0,0,0,0,0,0,0,0,0,0,0,0,0,0,0,0,0,0,0
0,0,0,0,0,0,0,0,0,0,0,0,0,0,0,0,0,0,0,0,0,0,0,0,0,0,0,0,0,0,0,0,0,0,0,0,0,0,0,0,0,0,0,0,0,0,0,0,0,0,0,0,0,0,0,0,0,0,0,0,0,0,0
0,0,0,0,0,0,0,0,0,0,0,0,0,0,0,0,0,0,0,0,0,0,0,0,0,0,0,0,0,109,0,0,0,0,0,0,0,0,0,0,0,0,0,0,0,0,0,0,0,0,0,0,0,0,0,0,0,0,0,0,0,0,0
0,0,0,0,0,0,0,68,1,1,259,1,259,1,259,1,259,1,259,1,259,1,259,1,259,1,259,1,259,1,259,1,259,1,259,1,282,1,1,1,116,0,0,0,0,0,0,0,0,0,0,0,0,0,0,0,0,0,0,0,0,0,0
0,0,0,0,0,0,0,51,0,0,260,0,264,0,0,1,270,270,270,1,200,200,200,200,200,200,200,200,200,1,278,181,278,181,278,1,134,134,44,44,1,1,116,0,0,0,0,0,0,0,0,0,0,0,0,0,0,0,0,0,0,0,0
0,0,0,0,0,0,0,51,0,0,0,262,0,0,181,1,0,0,0,1,199,199,199,199,199,199,199,199,199,1,0,181,0,181,0,1,132,132,134,134,44,44,1,1,116,0,0,0,0,0,0,0,0,0,0,0,0,0,0,0,0,0,0
0,0,0,0,0,0,116,51,0,0,0,0,0,0,266,1,0,272,0,88,0,0,0,0,0,0,0,0,0,88,0,0,0,0,0,1,132,132,132,132,134,134,44,44,1,1,116,0,0,0,0,0,0,0,0,0,0,0,0,0,0,0,0
0,0,0,0,0,0,1,51,0,0,0,0,0,0,266,1,269,0,276,1,160,162,0,0,0,0,0,0,0,1,0,0,0,0,0,1,132,132,132,132,132,132,134,134,44,44,1,1,116,0,0,0,0,0,0,0,0,0,0,0,0,0,0
0,0,0,0,0,0,1,1,1,28,1,261,263,1,28,1,1,1,1,28,160,162,0,0,0,42,131,0,28,28,277,279,0,0,281,1,132,132,132,28,132,132,132,132,283,44,44,44,1,1,116,0,0,0,0,0,0,0,0,0,0,0,0
0,0,0,0,0,0,1,51,186,0,0,0,0,0,265,267,42,1,275,1,160,162,0,0,0,0,0,0,0,1,1,1,1,265,1,1,132,132,132,132,132,132,133,133,44,44,1,1,116,0,0,0,0,0,0,0,0,0,0,0,0,0,0
0,0,0,0,0,0,116,51,186,0,0,0,0,0,1,1,67,67,0,88,0,0,0,0,0,0,0,0,0,1,0,0,0,0,0,1,132,132,132,132,133,133,44,44,1,1,116,0,0,0,0,0,0,0,0,0,0,0,0,0,0,0,0
0,0,0,0,0,0,0,51,186,0,0,0,0,0,186,1,0,0,274,1,197,197,197,197,197,197,197,197,0,1,0,0,0,280,0,1,132,132,133,133,44,44,1,1,116,0,0,0,0,0,0,0,0,0,0,0,0,0,0,0,0,0,0
0,0,0,0,0,0,0,51,258,186,186,186,186,186,186,1,268,271,273,28,196,196,196,196,196,196,196,196,0,1,0,0,0,0,0,1,133,133,44,44,1,1,116,0,0,0,0,0,0,0,0,0,0,0,0,0,0,0,0,0,0,0,0
0,0,0,0,0,0,0,67,1,1,259,1,259,1,259,1,259,1,259,1,259,1,259,1,259,1,259,1,259,1,259,1,259,1,259,1,282,1,1,1,116,0,0,0,0,0,0,0,0,0,0,0,0,0,0,0,0,0,0,0,0,0,0
0,0,0,0,0,0,0,0,0,0,0,0,0,0,0,0,0,0,0,0,0,0,0,0,0,0,0,0,0,107,0,0,0,0,0,0,0,0,0,0,0,0,0,0,0,0,0,0,0,0,0,0,0,0,0,0,0,0,0,0,0,0,0
0,0,0,0,0,0,0,0,0,0,0,0,0,0,0,0,0,0,0,0,0,0,0,0,0,0,0,0,0,0,0,0,0,0,0,0,0,0,0,0,0,0,0,0,0,0,0,0,0,0,0,0,0,0,0,0,0,0,0,0,0,0,0
0,0,0,0,0,0,0,0,0,0,0,0,0,0,0,0,0,0,0,0,0,0,0,0,0,0,0,0,0,0,0,0,0,0,0,0,0,0,0,0,0,0,0,0,0,0,0,0,0,0,0,0,0,0,0,0,0,0,0,0,0,0,0
0,0,0,0,0,0,0,0,0,0,0,0,0,0,0,0,0,0,0,0,0,0,0,0,0,0,0,0,0,0,0,0,0,0,0,0,0,0,0,0,0,0,0,0,0,0,0,0,0,0,0,0,0,0,0,0,0,0,0,0,0,0,0
:endlayer
layer: 7
0,0,0,0,0,0,0,0,0,0,0,0,0,0,0,0,0,0,0,0,0,0,0,0,0,0,0,0,0,0,0,0,0,0,0,0,0,0,0,0,0,0,0,0,0,0,0,0,0,0,0,0,0,0,0,0,0,0,0,0,0,0,0
0,0,0,0,0,0,0,0,0,0,0,0,0,0,0,0,0,0,0,0,0,0,0,0,0,0,0,0,0,0,0,0,0,0,0,0,0,0,0,0,0,0,0,0,0,0,0,0,0,0,0,0,0,0,0,0,0,0,0,0,0,0,0
0,0,0,0,0,0,0,0,0,0,0,0,0,0,0,0,0,0,0,0,0,0,0,0,0,0,0,0,0,0,0,0,0,0,0,0,0,0,0,0,0,0,0,0,0,0,0,0,0,0,0,0,0,0,0,0,0,0,0,0,0,0,0
0,0,0,0,0,0,0,0,0,0,68,0,0,0,0,0,0,0,0,0,0,0,0,0,0,0,0,0,0,109,0,0,0,0,0,181,284,284,284,284,284,181,0,0,0,0,0,0,0,0,0,0,0,0,0,0,0,0,0,0,0,0,0
0,0,0,0,0,0,115,284,284,284,284,284,284,284,284,284,284,284,284,284,284,284,284,284,284,284,284,284,284,284,284,284,284,284,284,284,51,0,296,0,60,284,116,0,0,0,0,0,0,0,0,0,0,0,0,0,0,0,0,0,0,0,0
0,0,0,0,0,0,282,0,0,91,0,91,0,91,0,282,0,91,0,282,200,200,200,200,200,200,200,200,200,282,91,181,91,181,91,282,288,294,294,294,0,60,284,284,116,0,0,0,0,0,0,0,0,0,0,0,0,0,0,0,0,0,0
0,0,0,0,0,115,282,0,0,0,0,0,0,0,181,282,0,0,0,282,199,199,199,199,199,199,199,199,199,282,0,181,0,181,0,282,287,293,293,293,294,294,294,60,284,284,116,0,0,0,0,0,0,0,0,0,0,0,0,0,0,0,0
0,0,0,0,0,116,282,0,0,0,0,0,0,0,266,282,0,0,0,282,0,0,0,0,0,0,0,0,0,282,0,0,0,0,0,282,1,292,0,298,293,293,293,294,0,60,284,284,116,0,0,0,0,0,0,0,0,0,0,0,0,0,0
0,0,0,0,0,116,282,0,0,90,0,90,0,0,266,282,0,90,0,282,0,0,0,0,0,0,0,0,0,282,0,0,0,0,0,282,51,0,0,0,0,300,0,293,302,303,0,60,284,284,116,0,0,0,0,0,0,0,0,0,0,0,0
0,0,0,0,0,116,282,284,284,28,284,284,284,284,28,284,284,284,284,28,76,0,0,0,0,0,42,131,28,28,0,0,90,0,0,282,1,181,0,28,0,0,0,301,0,304,302,303,305,28,1,1,116,0,0,0,0,0,0,0,0,0,0
0,0,0,0,0,116,282,0,0,91,0,0,0,0,285,0,0,42,113,282,0,0,0,0,0,0,0,0,0,282,284,284,284,284,284,282,51,0,0,0,0,299,0,290,302,303,0,60,284,284,116,0,0,0,0,0,0,0,0,0,0,0,0
0,0,0,0,0,116,282,0,0,0,0,0,0,85,1,1,1,1,113,282,0,0,0,0,0,0,0,0,0,282,0,0,0,0,0,282,51,291,0,297,290,290,290,289,0,60,284,284,116,0,0,0,0,0,0,0,0,0,0,0,0,0,0
0,0,0,0,0,115,282,0,0,0,0,0,0,0,0,282,0,0,0,282,197,197,197,197,197,197,197,197,0,282,76,0,0,0,85,282,1,290,290,290,289,289,289,60,284,284,116,0,0,0,0,0,0,0,0,0,0,0,0,0,0,0,0
0,0,0,0,0,0,282,90,0,90,0,90,0,90,0,282,286,90,0,28,196,196,196,196,196,196,196,196,90,282,0,0,90,0,0,282,51,289,289,289,0,60,284,284,116,0,0,0,0,0,0,0,0,0,0,0,0,0,0,0,0,0,0
0,0,0,0,0,0,115,284,284,284,284,284,284,284,284,284,284,284,284,284,284,284,284,284,284,284,284,284,284,284,284,284,284,284,284,284,51,0,295,0,60,284,116,0,0,0,0,0,0,0,0,0,0,0,0,0,0,0,0,0,0,0,0
0,0,0,0,0,0,0,0,0,0,67,0,0,0,0,0,0,0,0,0,0,0,0,0,0,0,0,0,0,107,0,0,0,0,0,181,284,284,284,284,284,181,0,0,0,0,0,0,0,0,0,0,0,0,0,0,0,0,0,0,0,0,0
0,0,0,0,0,0,0,0,0,0,0,0,0,0,0,0,0,0,0,0,0,0,0,0,0,0,0,0,0,0,0,0,0,0,0,0,0,0,0,0,0,0,0,0,0,0,0,0,0,0,0,0,0,0,0,0,0,0,0,0,0,0,0
0,0,0,0,0,0,0,0,0,0,0,0,0,0,0,0,0,0,0,0,0,0,0,0,0,0,0,0,0,0,0,0,0,0,0,0,0,0,0,0,0,0,0,0,0,0,0,0,0,0,0,0,0,0,0,0,0,0,0,0,0,0,0
0,0,0,0,0,0,0,0,0,0,0,0,0,0,0,0,0,0,0,0,0,0,0,0,0,0,0,0,0,0,0,0,0,0,0,0,0,0,0,0,0,0,0,0,0,0,0,0,0,0,0,0,0,0,0,0,0,0,0,0,0,0,0
:endlayer
layer: 8
0,0,0,0,0,0,0,0,0,0,0,0,0,0,0,0,0,0,0,0,0,0,0,0,0,0,0,0,0,0,0,0,0,0,0,0,0,0,0,0,0,0,0,0,0,0,0,0,0,0,0,0,0,0,0,0,0,0,0,0,0,0,0
0,0,0,0,0,0,0,0,0,0,0,0,0,0,0,0,0,0,0,0,0,0,0,0,0,0,0,0,0,0,0,0,0,0,0,0,0,0,0,0,0,0,0,0,0,0,0,0,0,0,0,0,0,0,0,0,0,0,0,0,0,0,0
0,0,0,0,0,0,0,0,0,0,0,0,0,0,0,0,0,0,0,0,0,0,0,0,0,0,0,0,0,0,0,0,0,0,0,0,0,0,0,0,0,0,0,0,0,0,0,0,0,0,0,0,0,0,0,0,0,0,0,0,0,0,0
0,0,0,0,0,0,0,68,68,1,1,1,68,68,116,116,116,116,116,68,0,0,68,116,116,116,116,68,0,0,0,68,116,116,116,28,1,313,1,313,1,28,0,0,0,0,0,0,0,0,0,0,0,0,0,0,0,0,0,0,0,0,0
0,0,0,0,0,0,1,1,1,1,1,1,1,1,1,1,1,1,1,1,1,1,1,1,1,1,1,1,51,29,60,1,1,1,1,1,0,0,91,0,0,1,284,284,116,0,0,0,0,0,0,0,0,0,0,0,0,0,0,0,0,0,0
0,0,0,0,0,0,1,44,44,44,44,44,44,44,44,44,44,44,44,44,44,44,44,44,44,44,44,44,44,44,44,44,44,44,44,1,311,0,0,0,0,91,315,60,284,284,116,0,0,0,0,0,0,0,0,0,0,0,0,0,0,0,0
0,0,0,0,0,1,1,44,44,44,44,44,44,44,44,44,44,44,44,44,44,44,44,44,44,44,44,44,44,44,44,44,44,44,44,1,310,0,0,0,0,0,0,0,317,60,284,284,116,0,0,0,0,0,0,0,0,0,0,0,0,0,0
0,0,0,0,115,1,44,44,44,44,44,44,44,44,44,44,44,44,44,44,44,44,44,44,44,44,44,44,44,44,44,44,44,44,44,1,1,0,0,0,0,0,0,0,0,0,319,60,284,284,116,0,0,0,0,0,0,0,0,0,0,0,0
0,0,0,0,116,1,44,44,44,44,44,44,44,44,44,44,44,44,44,44,44,0,0,0,0,0,0,0,44,28,44,44,44,44,44,51,0,0,0,90,0,0,0,0,0,0,0,0,321,60,284,284,116,0,0,0,0,0,0,0,0,0,0
0,0,0,0,116,1,44,44,44,28,44,44,44,44,28,1,1,1,1,28,44,0,0,0,0,0,0,42,28,28,44,44,44,44,44,1,1,312,85,28,76,0,0,0,0,0,0,0,85,28,1,1,284,284,116,0,0,0,0,0,0,0,0
0,0,0,0,116,1,44,44,44,44,44,44,44,44,113,0,0,0,42,44,44,0,0,0,0,0,0,0,44,28,44,44,44,44,44,1,309,0,0,91,0,0,0,0,0,0,0,0,320,60,284,284,116,0,0,0,0,0,0,0,0,0,0
0,0,0,0,115,1,44,44,44,44,44,44,44,44,1,1,1,1,1,44,44,44,44,44,44,44,44,44,44,44,44,44,44,44,44,1,308,0,0,0,0,0,0,0,0,0,318,60,284,284,116,0,0,0,0,0,0,0,0,0,0,0,0
0,0,0,0,0,1,1,44,44,44,44,44,44,44,44,44,131,132,283,44,44,44,44,44,44,44,44,44,44,44,44,44,44,44,44,1,1,0,0,0,0,0,0,0,316,60,284,284,116,0,0,0,0,0,0,0,0,0,0,0,0,0,0
0,0,0,0,0,0,1,44,44,44,44,44,44,44,44,44,131,132,283,44,44,44,44,44,44,44,44,44,44,44,44,44,44,44,44,1,307,0,0,0,0,90,314,60,284,284,116,0,0,0,0,0,0,0,0,0,0,0,0,0,0,0,0
0,0,0,0,0,0,1,1,1,1,1,1,1,1,1,1,1,1,1,1,1,1,1,1,1,1,1,1,51,30,60,1,1,1,1,1,306,0,90,0,0,1,284,284,116,0,0,0,0,0,0,0,0,0,0,0,0,0,0,0,0,0,0
0,0,0,0,0,0,0,67,67,1,1,1,67,67,116,116,116,116,116,67,0,0,67,116,116,116,116,67,0,0,0,67,116,116,116,28,1,259,1,259,1,28,0,0,0,0,0,0,0,0,0,0,0,0,0,0,0,0,0,0,0,0,0
0,0,0,0,0,0,0,0,0,0,0,0,0,0,0,0,0,0,0,0,0,0,0,0,0,0,0,0,0,0,0,0,0,0,0,0,0,0,0,0,0,0,0,0,0,0,0,0,0,0,0,0,0,0,0,0,0,0,0,0,0,0,0
0,0,0,0,0,0,0,0,0,0,0,0,0,0,0,0,0,0,0,0,0,0,0,0,0,0,0,0,0,0,0,0,0,0,0,0,0,0,0,0,0,0,0,0,0,0,0,0,0,0,0,0,0,0,0,0,0,0,0,0,0,0,0
0,0,0,0,0,0,0,0,0,0,0,0,0,0,0,0,0,0,0,0,0,0,0,0,0,0,0,0,0,0,0,0,0,0,0,0,0,0,0,0,0,0,0,0,0,0,0,0,0,0,0,0,0,0,0,0,0,0,0,0,0,0,0
:endlayer
layer: 9
0,0,0,0,0,0,0,0,0,0,0,0,0,0,0,0,0,0,0,0,0,0,0,0,0,0,0,0,0,0,0,0,0,0,0,0,0,0,0,0,0,0,0,0,0,0,0,0,0,0,0,0,0,0,0,0,0,0,0,0,0,0,0
0,0,0,0,0,0,0,0,0,0,0,0,0,0,0,0,0,0,0,0,0,0,0,0,0,0,0,0,0,0,0,0,0,0,0,0,0,0,0,0,0,0,0,0,0,0,0,0,0,0,0,0,0,0,0,0,0,0,0,0,0,0,0
0,0,0,0,0,0,0,0,0,0,0,0,0,0,0,0,0,0,0,0,0,0,0,0,0,0,0,0,0,0,0,0,0,0,0,0,0,0,0,0,0,0,0,0,0,0,0,0,0,0,0,0,0,0,0,0,0,0,0,0,0,0,0
0,0,0,0,0,0,181,1,284,1,284,1,284,1,1,1,51,0,0,0,0,0,60,22,22,0,0,0,0,0,0,60,1,22,22,68,284,284,284,284,284,68,116,68,0,0,0,0,0,0,0,0,0,0,0,0,0,0,0,0,0,0,0
0,0,0,0,0,0,1,329,0,228,228,228,0,348,1,1,1,1,1,181,1,181,1,181,1,181,1,1,76,379,85,1,1,181,1,1,131,134,134,134,134,1,1,1,1,1,116,0,0,0,0,0,0,0,0,0,0,0,0,0,0,0,0
0,0,0,0,0,0,282,0,0,228,228,228,343,0,282,0,354,0,30,363,0,0,30,370,91,372,374,30,0,0,0,30,389,0,392,44,131,132,132,132,283,134,134,134,44,44,1,1,116,0,0,0,0,0,0,0,0,0,0,0,0,0,0
0,0,0,0,0,1,1,328,328,1,337,339,342,347,28,181,0,357,0,0,365,0,0,0,0,0,0,375,0,378,382,0,388,0,392,44,133,133,133,133,132,132,132,283,134,134,44,44,1,1,116,0,0,0,0,0,0,0,0,0,0,0,0
0,0,0,0,181,28,324,0,0,1,0,338,338,0,349,353,0,356,360,0,359,359,359,359,359,359,359,359,359,109,381,0,387,0,1,1,1,116,116,131,132,132,132,132,132,283,134,134,44,44,1,1,116,0,0,0,0,0,0,0,0,0,0
0,0,0,0,181,259,323,327,0,1,0,0,0,346,349,352,0,0,0,0,359,209,209,209,209,209,209,209,60,28,181,0,0,0,393,0,0,0,116,131,132,132,132,132,132,132,132,283,134,283,44,44,1,1,116,0,0,0,0,0,0,0,0
0,0,0,0,181,259,219,219,332,28,1,1,1,1,28,1,181,1,359,28,359,367,367,367,367,367,367,367,28,28,28,384,0,85,1,1,1,116,116,28,132,132,132,132,132,132,132,132,132,28,284,284,44,44,284,284,116,0,0,0,0,0,0
0,0,0,0,181,259,219,219,0,1,336,219,341,345,282,76,0,0,0,0,359,367,367,367,367,367,367,367,60,28,181,383,0,391,42,1,131,134,134,131,132,132,132,132,132,132,132,283,133,283,44,44,1,1,116,0,0,0,0,0,0,0,0
0,0,0,0,181,28,322,326,0,1,335,335,0,0,1,1,1,1,51,362,359,359,359,359,359,359,359,359,359,107,380,0,0,0,1,1,131,133,132,132,132,132,132,132,132,283,133,133,44,44,1,1,116,0,0,0,0,0,0,0,0,0,0
0,0,0,0,0,1,1,0,0,43,335,335,340,0,43,351,44,355,358,0,364,366,368,0,0,371,0,0,0,377,0,0,386,0,392,44,44,131,132,132,132,132,132,283,133,283,44,44,1,1,116,0,0,0,0,0,0,0,0,0,0,0,0
0,0,0,0,0,0,282,0,331,1,334,334,0,0,43,350,44,355,0,361,0,0,29,369,90,0,373,29,0,0,0,29,385,390,392,44,134,134,132,132,283,133,133,133,44,44,1,1,116,0,0,0,0,0,0,0,0,0,0,0,0,0,0
0,0,0,0,0,0,1,325,330,1,333,333,159,344,1,1,1,1,1,181,1,181,1,181,1,181,1,1,76,376,85,1,1,181,1,1,131,133,133,133,133,1,1,1,1,1,116,0,0,0,0,0,0,0,0,0,0,0,0,0,0,0,0
0,0,0,0,0,0,181,1,284,1,284,1,284,1,1,1,51,0,0,0,0,0,60,22,22,0,0,0,0,0,0,60,1,22,22,67,284,284,284,284,284,67,116,67,0,0,0,0,0,0,0,0,0,0,0,0,0,0,0,0,0,0,0
0,0,0,0,0,0,0,0,0,0,0,0,0,0,0,0,0,0,0,0,0,0,0,0,0,0,0,0,0,0,0,0,0,0,0,0,0,0,0,0,0,0,0,0,0,0,0,0,0,0,0,0,0,0,0,0,0,0,0,0,0,0,0
0,0,0,0,0,0,0,0,0,0,0,0,0,0,0,0,0,0,0,0,0,0,0,0,0,0,0,0,0,0,0,0,0,0,0,0,0,0,0,0,0,0,0,0,0,0,0,0,0,0,0,0,0,0,0,0,0,0,0,0,0,0,0
0,0,0,0,0,0,0,0,0,0,0,0,0,0,0,0,0,0,0,0,0,0,0,0,0,0,0,0,0,0,0,0,0,0,0,0,0,0,0,0,0,0,0,0,0,0,0,0,0,0,0,0,0,0,0,0,0,0,0,0,0,0,0
:endlayer
layer: 10
0,0,0,0,0,0,0,0,0,0,0,0,0,0,0,0,0,0,0,0,0,0,0,0,0,0,0,0,0,0,0,0,0,0,0,0,0,0,0,0,0,0,0,0,0,0,0,0,0,0,0,0,0,0,0,0,0,0,0,0,0,0,0
0,0,0,0,0,0,0,0,0,0,0,0,0,0,0,0,0,0,0,0,0,0,0,0,0,0,0,0,0,0,0,0,0,0,0,0,0,0,0,0,0,0,0,0,0,0,0,0,0,0,0,0,0,0,0,0,0,0,0,0,0,0,0
0,0,0,0,0,0,0,0,0,0,0,0,0,0,22,22,0,0,0,0,0,0,0,0,22,22,0,0,0,0,0,0,0,0,22,22,0,0,0,0,0,0,0,0,0,0,0,0,0,0,0,0,0,0,0,0,0,0,0,0,0,0,0
0,0,0,0,0,0,181,1,259,1,259,1,259,1,22,22,90,0,0,0,0,0,0,0,22,22,0,0,0,0,0,0,0,0,22,22,1,181,181,181,181,1,22,22,0,0,0,0,0,0,0,0,0,0,0,0,0,0,0,0,0,0,0
0,0,0,0,0,0,1,0,0,0,0,0,0,0,1,409,1,51,0,359,359,359,0,359,359,359,359,0,0,0,0,0,359,359,60,51,359,0,432,0,60,1,1,1,181,181,51,0,0,0,0,0,0,0,0,0,0,0,0,0,0,0,0
0,0,0,0,0,0,259,0,0,0,0,0,405,0,259,0,0,0,0,0,0,0,0,0,0,0,0,0,0,0,0,0,0,0,0,426,429,0,0,433,0,438,0,0,0,0,181,181,51,0,0,0,0,0,0,0,0,0,0,0,0,0,0
0,0,0,0,0,1,1,400,88,1,0,402,0,408,28,181,0,0,0,0,0,0,0,0,0,0,0,0,0,0,0,0,0,0,0,0,0,0,0,0,435,0,442,0,0,446,0,451,181,181,51,0,0,0,0,0,0,0,0,0,0,0,0
0,0,0,0,0,28,0,0,0,1,0,0,0,0,400,0,0,0,0,0,0,0,0,418,0,421,424,0,0,109,0,0,0,0,60,1,1,1,1,181,0,0,0,0,444,0,0,1,0,0,181,181,51,0,0,0,0,0,0,0,0,0,0
0,0,0,0,0,259,396,399,0,1,0,0,0,0,88,0,0,0,0,0,0,414,0,0,0,420,0,0,181,28,181,0,0,0,0,0,0,115,1,1,0,0,441,234,234,441,0,30,0,453,0,457,60,1,51,359,359,116,116,0,0,0,0
0,0,0,0,0,259,395,395,0,28,1,1,1,1,28,51,359,359,411,28,0,413,0,417,419,0,423,0,28,28,28,0,0,0,60,1,1,1,1,28,76,437,441,234,234,441,448,450,411,28,455,60,284,284,284,284,284,284,284,116,0,0,0
0,0,0,0,0,259,395,395,0,1,401,0,404,0,259,0,0,0,0,0,412,0,415,0,0,0,0,0,181,28,181,0,0,0,0,42,1,1,1,1,0,0,441,234,234,441,447,29,0,452,454,456,60,1,51,359,359,116,116,0,0,0,0
0,0,0,0,0,28,394,398,0,1,0,0,0,0,1,409,1,51,0,0,0,0,0,416,0,0,422,425,0,107,0,0,0,0,60,1,428,430,1,181,0,0,440,443,0,0,0,1,0,0,181,181,51,0,0,0,0,0,0,0,0,0,0
0,0,0,0,0,1,1,0,0,88,0,0,0,407,88,283,355,0,0,0,0,0,0,0,0,0,0,0,0,0,0,0,0,0,0,0,427,0,0,0,434,0,0,0,0,445,0,449,181,181,51,0,0,0,0,0,0,0,0,0,0,0,0
0,0,0,0,0,0,259,0,0,1,0,0,0,406,400,283,355,410,0,0,0,0,0,0,0,0,0,0,0,0,0,0,0,0,0,0,0,0,431,0,0,436,439,0,0,0,181,181,51,0,0,0,0,0,0,0,0,0,0,0,0,0,0
0,0,0,0,0,0,1,397,397,1,0,0,403,0,1,409,1,51,359,359,359,359,0,359,359,359,359,0,0,0,0,0,359,359,60,51,359,0,0,0,60,1,1,1,181,181,51,0,0,0,0,0,0,0,0,0,0,0,0,0,0,0,0
0,0,0,0,0,0,181,1,259,1,259,1,259,1,22,22,91,0,0,0,0,0,0,0,22,22,0,0,0,0,0,0,0,0,22,22,1,181,181,181,181,1,22,22,0,0,0,0,0,0,0,0,0,0,0,0,0,0,0,0,0,0,0
0,0,0,0,0,0,0,0,0,0,0,0,0,0,22,22,0,0,0,0,0,0,0,0,22,22,0,0,0,0,0,0,0,0,22,22,0,0,0,0,0,0,0,0,0,0,0,0,0,0,0,0,0,0,0,0,0,0,0,0,0,0,0
0,0,0,0,0,0,0,0,0,0,0,0,0,0,0,0,0,0,0,0,0,0,0,0,0,0,0,0,0,0,0,0,0,0,0,0,0,0,0,0,0,0,0,0,0,0,0,0,0,0,0,0,0,0,0,0,0,0,0,0,0,0,0
0,0,0,0,0,0,0,0,0,0,0,0,0,0,0,0,0,0,0,0,0,0,0,0,0,0,0,0,0,0,0,0,0,0,0,0,0,0,0,0,0,0,0,0,0,0,0,0,0,0,0,0,0,0,0,0,0,0,0,0,0,0,0
:endlayer
layer: 11
0,0,0,0,0,0,0,0,0,0,0,0,0,0,0,0,0,0,0,0,0,0,0,0,0,0,0,0,0,0,0,0,0,0,0,0,0,0,0,0,0,0,0,0,0,0,0,0,0,0,0,0,0,0,0,0,0,0,0,0,0,0,0
0,0,0,0,0,0,0,0,0,0,0,0,0,0,0,0,0,0,0,0,0,0,0,0,0,0,0,0,0,0,0,0,0,0,0,0,0,0,0,0,0,0,0,0,0,0,0,0,0,0,0,0,0,0,0,0,0,0,0,0,0,0,0
0,0,0,0,0,0,0,0,0,0,0,0,0,0,0,22,22,0,0,0,0,0,0,0,0,22,22,0,0,0,0,0,0,0,0,22,22,0,0,0,0,0,0,0,0,0,0,0,0,0,0,0,0,0,0,0,0,0,0,0,0,0,0
0,0,0,0,0,0,115,1,259,1,259,1,259,1,181,0,0,0,0,0,0,0,0,0,0,0,0,0,0,0,0,0,0,0,0,0,204,0,0,0,0,204,22,22,22,0,0,0,0,0,0,0,0,0,0,0,0,0,0,0,0,0,0
0,0,0,0,0,0,1,91,0,67,0,91,0,91,1,1,51,0,0,0,469,0,0,0,470,0,0,0,0,0,0,0,0,472,0,474,0,0,0,0,0,0,0,476,0,0,478,0,0,0,0,0,0,0,0,0,0,0,0,0,0,0,0
0,0,0,0,0,0,259,0,0,68,0,0,0,0,259,0,0,0,0,0,0,0,0,0,0,0,0,0,0,0,0,0,0,0,0,0,0,0,0,0,0,0,0,0,0,0,204,0,0,0,0,0,0,0,0,0,0,0,0,0,0,0,0
0,0,0,0,0,1,1,1,1,1,0,0,0,0,28,181,0,0,0,0,0,0,0,0,0,0,0,0,0,0,0,0,0,0,0,0,0,0,0,0,0,0,0,0,0,0,0,0,0,0,480,0,0,0,0,0,0,0,0,0,0,0,0
0,0,0,0,0,28,76,0,0,1,462,0,0,0,465,0,0,0,0,0,0,0,0,0,0,0,0,0,0,109,0,0,0,0,0,60,1,1,1,181,0,0,0,0,0,0,0,0,0,0,204,0,0,0,0,0,0,0,0,0,0,0,0
0,0,0,0,0,259,0,0,459,1,90,463,464,90,465,0,0,0,0,90,0,0,0,0,0,0,0,0,181,28,181,0,0,0,0,0,115,44,44,1,0,0,0,0,0,0,0,0,0,0,0,0,0,0,359,359,116,116,0,359,116,0,0
0,0,0,0,0,259,0,0,85,28,1,1,1,1,28,181,0,0,411,28,76,0,0,0,0,0,0,0,28,28,28,0,0,0,0,60,1,44,44,28,0,0,0,475,0,0,0,0,411,28,0,0,0,0,60,284,284,284,481,284,284,113,116
0,0,0,0,0,259,0,0,458,1,0,91,0,0,259,0,0,0,0,91,0,0,0,0,0,0,0,0,181,28,181,0,0,0,0,0,42,44,44,1,0,0,0,0,0,0,0,0,0,0,0,0,0,0,359,359,116,116,0,359,116,0,0
0,0,0,0,0,28,76,0,0,1,461,0,0,0,1,1,51,0,0,0,0,0,0,0,0,0,0,0,0,107,0,0,0,0,0,60,67,67,1,181,0,0,0,0,0,0,0,0,0,0,204,0,0,0,0,0,0,0,0,0,0,0,0
0,0,0,0,0,1,1,0,85,1,0,0,0,0,1,355,466,0,0,0,0,0,0,0,0,0,0,0,0,0,0,0,0,0,0,0,0,0,0,0,0,0,0,0,0,0,0,0,0,0,479,0,0,0,0,0,0,0,0,0,0,0,0
0,0,0,0,0,0,259,0,0,1,460,0,0,0,1,355,0,0,0,0,0,0,0,0,0,0,0,0,0,0,0,0,0,0,0,0,0,0,0,0,0,0,0,0,0,0,204,0,0,0,0,0,0,0,0,0,0,0,0,0,0,0,0
0,0,0,0,0,0,1,90,0,1,0,90,0,90,1,1,51,0,467,0,468,0,0,0,0,471,0,0,0,0,0,0,0,0,473,0,0,0,0,0,0,0,0,0,0,0,477,0,0,0,0,0,0,0,0,0,0,0,0,0,0,0,0
0,0,0,0,0,0,115,1,259,1,259,1,259,1,181,0,0,0,0,0,0,0,0,0,0,0,0,0,0,0,0,0,0,0,0,0,204,0,0,0,0,204,22,22,22,0,0,0,0,0,0,0,0,0,0,0,0,0,0,0,0,0,0
0,0,0,0,0,0,0,0,0,0,0,0,0,0,0,22,22,0,0,0,0,0,0,0,0,22,22,0,0,0,0,0,0,0,0,22,22,0,0,0,0,0,0,0,0,0,0,0,0,0,0,0,0,0,0,0,0,0,0,0,0,0,0
0,0,0,0,0,0,0,0,0,0,0,0,0,0,0,0,0,0,0,0,0,0,0,0,0,0,0,0,0,0,0,0,0,0,0,0,0,0,0,0,0,0,0,0,0,0,0,0,0,0,0,0,0,0,0,0,0,0,0,0,0,0,0
0,0,0,0,0,0,0,0,0,0,0,0,0,0,0,0,0,0,0,0,0,0,0,0,0,0,0,0,0,0,0,0,0,0,0,0,0,0,0,0,0,0,0,0,0,0,0,0,0,0,0,0,0,0,0,0,0,0,0,0,0,0,0
:endlayer
layer: 12
0,0,0,0,0,0,0,0,0,0,0,0,0,0,0,0,0,0,0,0,0,0,0,0,0,0,0,0,0,0,0,0,0,0,0,0,0,0,0,0,0,0,0,0,0,0,0,0,0,0,0,0,0,0,0,0,0,0,0,0,0,0,0
0,0,0,0,0,0,0,0,0,0,0,0,0,0,0,0,0,0,0,0,0,0,0,0,0,0,0,0,0,0,0,0,0,0,0,0,0,0,0,0,0,0,0,0,0,0,0,0,0,0,0,0,0,0,0,0,0,0,0,0,0,0,0
0,0,0,0,0,0,0,68,116,68,116,68,116,68,0,0,22,22,0,0,0,0,0,0,0,0,22,22,0,0,0,0,0,0,0,0,22,22,0,0,0,0,0,0,0,0,0,0,0,0,0,0,0,0,0,0,0,0,0,0,0,0,0
0,0,0,0,0,115,1,1,1,1,1,1,1,1,113,0,0,0,0,0,0,0,0,0,0,0,0,0,0,0,0,0,0,0,0,0,0,0,0,0,0,0,0,0,22,22,22,0,0,0,0,0,0,0,0,0,0,0,0,0,0,0,0
0,0,0,0,0,115,1,44,44,44,44,44,44,44,1,51,0,0,0,0,0,0,0,0,0,0,0,0,0,0,0,0,0,0,0,0,0,0,0,0,0,0,0,0,0,0,0,0,0,0,0,0,0,0,0,0,0,0,0,0,0,0,0
0,0,0,0,0,116,1,44,44,44,44,44,44,44,282,116,0,0,0,0,0,0,0,0,0,0,0,0,0,0,0,0,0,0,0,0,0,0,0,0,0,0,0,0,0,0,0,0,0,0,0,0,0,0,0,0,0,0,0,0,0,0,0
0,0,0,0,115,1,1,44,44,44,44,44,44,44,282,51,0,0,0,0,0,0,0,0,0,0,0,0,0,0,0,0,0,0,0,0,0,0,0,0,0,0,0,0,0,0,0,0,0,0,0,0,0,0,0,0,0,0,0,0,0,0,0
0,0,0,0,116,1,44,44,44,44,44,44,44,44,282,116,0,0,0,0,0,0,0,0,0,0,0,0,0,109,0,0,0,0,0,0,181,181,181,181,0,0,0,0,0,0,0,0,0,0,0,0,0,0,0,0,0,0,0,0,0,0,0
0,0,0,0,116,1,44,44,44,44,44,44,44,44,282,116,0,0,0,0,0,0,0,0,0,0,0,0,181,28,181,0,0,0,0,0,181,0,0,181,0,0,0,0,0,0,0,0,0,90,0,0,0,0,0,0,487,0,359,359,0,0,0
0,0,0,0,115,1,44,44,44,28,44,44,44,44,282,51,0,0,411,28,0,0,0,0,0,0,0,85,28,28,28,76,0,0,0,483,181,485,411,28,0,0,0,0,0,0,0,0,411,28,76,0,0,0,0,359,359,60,284,284,51,0,0
0,0,0,0,116,1,44,44,44,44,44,44,44,44,282,116,0,0,0,0,0,0,0,0,0,0,0,0,181,28,181,0,0,0,0,0,0,484,0,181,0,0,0,0,0,0,0,0,0,91,0,0,0,0,0,0,486,0,359,359,0,0,0
0,0,0,0,116,1,44,44,44,44,44,44,44,44,1,51,0,0,0,0,0,0,0,0,0,0,0,0,0,107,0,0,0,0,0,0,181,181,181,181,0,0,0,0,0,0,0,0,0,0,0,0,0,0,0,0,0,0,0,0,0,0,0
0,0,0,0,115,1,1,44,44,44,44,44,44,44,355,482,0,0,0,0,0,0,0,0,0,0,0,0,0,0,0,0,0,0,0,0,0,0,0,0,0,0,0,0,0,0,0,0,0,0,0,0,0,0,0,0,0,0,0,0,0,0,0
0,0,0,0,0,116,1,44,44,44,44,44,44,44,355,0,0,0,0,0,0,0,0,0,0,0,0,0,0,0,0,0,0,0,0,0,0,0,0,0,0,0,0,0,0,0,0,0,0,0,0,0,0,0,0,0,0,0,0,0,0,0,0
0,0,0,0,0,115,1,44,44,44,44,44,44,44,1,51,0,0,0,0,0,0,0,0,0,0,0,0,0,0,0,0,0,0,0,0,0,0,0,0,0,0,0,0,0,0,0,0,0,0,0,0,0,0,0,0,0,0,0,0,0,0,0
0,0,0,0,0,115,1,1,1,1,1,1,1,1,113,0,0,0,0,0,0,0,0,0,0,0,0,0,0,0,0,0,0,0,0,0,0,0,0,0,0,0,0,0,22,22,22,0,0,0,0,0,0,0,0,0,0,0,0,0,0,0,0
0,0,0,0,0,0,0,67,116,67,116,67,116,67,0,0,22,22,0,0,0,0,0,0,0,0,22,22,0,0,0,0,0,0,0,0,22,22,0,0,0,0,0,0,0,0,0,0,0,0,0,0,0,0,0,0,0,0,0,0,0,0,0
0,0,0,0,0,0,0,0,0,0,0,0,0,0,0,0,0,0,0,0,0,0,0,0,0,0,0,0,0,0,0,0,0,0,0,0,0,0,0,0,0,0,0,0,0,0,0,0,0,0,0,0,0,0,0,0,0,0,0,0,0,0,0
0,0,0,0,0,0,0,0,0,0,0,0,0,0,0,0,0,0,0,0,0,0,0,0,0,0,0,0,0,0,0,0,0,0,0,0,0,0,0,0,0,0,0,0,0,0,0,0,0,0,0,0,0,0,0,0,0,0,0,0,0,0,0
:endlayer
layer: 13
0,0,0,0,0,0,0,0,0,0,0,0,0,0,0,0,0,0,0,0,0,0,0,0,0,0,0,0,0,0,0,0,0,0,0,0,0,0,0,0,0,0,0,0,0,0,0,0,0,0,0,0,0,0,0,0,0,0,0,0,0,0,0
0,0,0,0,0,0,0,0,0,0,0,0,0,0,0,0,0,22,22,0,0,0,0,0,0,0,0,22,22,0,0,0,0,0,0,0,0,22,22,0,0,0,0,0,0,0,0,0,0,0,0,0,0,0,0,0,0,0,0,0,0,0,0
0,0,0,0,0,0,0,60,181,29,29,29,181,51,0,0,0,22,22,0,0,0,0,0,0,0,0,22,22,0,0,0,0,0,0,0,0,22,22,0,0,0,0,0,0,0,0,0,0,0,0,0,0,0,0,0,0,0,0,0,0,0,0
0,0,0,0,0,60,22,22,506,1,1,1,517,181,51,0,0,0,0,0,0,0,0,0,0,0,0,0,0,0,0,0,0,0,0,0,0,0,0,0,0,0,0,0,0,0,22,22,22,0,0,0,0,0,0,0,0,0,0,0,0,0,0
0,0,0,0,0,181,181,0,505,1,1,1,0,0,359,0,0,0,0,0,0,0,0,0,0,0,0,0,0,0,0,0,0,0,0,0,0,0,0,0,0,0,0,0,0,0,0,0,0,0,0,0,0,0,0,0,0,0,0,0,0,0,0
0,0,0,0,0,181,494,500,0,30,30,30,0,520,0,29,0,0,0,0,0,0,0,0,0,0,0,0,0,0,0,0,0,0,0,0,0,0,0,0,0,0,0,0,0,0,0,0,0,0,0,0,0,0,0,0,0,0,0,0,0,0,0
0,0,0,0,29,1,51,499,504,0,511,0,0,0,524,181,0,0,0,0,0,0,0,0,0,0,0,0,0,0,0,0,0,0,0,0,0,0,0,0,0,0,0,0,0,0,0,0,0,0,0,0,0,0,0,0,0,0,0,0,0,0,0
0,0,0,0,181,490,0,0,0,0,510,0,516,0,523,181,0,0,0,0,0,0,0,0,0,0,0,0,0,109,0,0,0,0,0,0,0,0,0,0,0,0,0,0,0,0,0,0,0,0,0,0,0,0,0,0,0,0,0,0,0,0,0
0,0,0,0,181,0,493,498,60,1,29,29,1,51,522,181,0,0,0,0,0,0,0,0,0,0,0,0,181,28,181,0,0,0,0,0,0,0,0,0,0,0,0,0,0,0,0,0,0,0,0,0,0,0,0,0,0,0,0,0,0,0,0
0,0,0,0,181,489,0,497,503,28,509,513,1,1,76,181,0,0,411,28,0,0,0,0,0,0,0,0,28,28,28,0,0,0,0,0,0,0,411,28,0,0,0,0,0,0,0,0,411,28,0,0,0,0,0,525,0,0,0,0,0,0,0
0,0,0,0,181,488,492,0,60,1,30,30,1,51,521,30,0,0,0,0,0,0,0,0,0,0,0,0,181,28,181,0,0,0,0,0,0,0,0,0,0,0,0,0,0,0,0,0,0,0,0,0,0,0,0,0,0,0,0,0,0,0,0
0,0,0,0,181,0,0,496,0,507,508,0,0,519,359,0,0,0,0,0,0,0,0,0,0,0,0,0,0,107,0,0,0,0,0,0,0,0,0,0,0,0,0,0,0,0,0,0,0,0,0,0,0,0,0,0,0,0,0,0,0,0,0
0,0,0,0,30,1,51,0,0,0,0,512,0,0,0,0,0,0,0,0,0,0,0,0,0,0,0,0,0,0,0,0,0,0,0,0,0,0,0,0,0,0,0,0,0,0,0,0,0,0,0,0,0,0,0,0,0,0,0,0,0,0,0
0,0,0,0,0,181,491,495,502,29,29,29,515,518,0,0,0,0,0,0,0,0,0,0,0,0,0,0,0,0,0,0,0,0,0,0,0,0,0,0,0,0,0,0,0,0,0,0,0,0,0,0,0,0,0,0,0,0,0,0,0,0,0
0,0,0,0,0,181,181,0,0,1,1,1,0,0,359,0,0,0,0,0,0,0,0,0,0,0,0,0,0,0,0,0,0,0,0,0,0,0,0,0,0,0,0,0,0,0,0,0,0,0,0,0,0,0,0,0,0,0,0,0,0,0,0
0,0,0,0,0,60,22,22,501,1,1,1,514,181,51,0,0,0,0,0,0,0,0,0,0,0,0,0,0,0,0,0,0,0,0,0,0,0,0,0,0,0,0,0,0,0,22,22,22,0,0,0,0,0,0,0,0,0,0,0,0,0,0
0,0,0,0,0,0,0,60,181,30,30,30,181,51,0,0,0,22,22,0,0,0,0,0,0,0,0,22,22,0,0,0,0,0,0,0,0,22,22,0,0,0,0,0,0,0,0,0,0,0,0,0,0,0,0,0,0,0,0,0,0,0,0
0,0,0,0,0,0,0,0,0,0,0,0,0,0,0,0,0,22,22,0,0,0,0,0,0,0,0,22,22,0,0,0,0,0,0,0,0,22,22,0,0,0,0,0,0,0,0,0,0,0,0,0,0,0,0,0,0,0,0,0,0,0,0
0,0,0,0,0,0,0,0,0,0,0,0,0,0,0,0,0,0,0,0,0,0,0,0,0,0,0,0,0,0,0,0,0,0,0,0,0,0,0,0,0,0,0,0,0,0,0,0,0,0,0,0,0,0,0,0,0,0,0,0,0,0,0
:endlayer
layer: 14
0,0,0,0,0,0,0,0,0,0,0,0,0,0,0,0,0,0,0,0,0,0,0,0,0,0,0,0,0,0,0,0,0,0,0,0,0,0,0,0,0,0,0,0,0,0,0,0,0,0,0,0,0,0,0,0,0,0,0,0,0,0,0
0,0,0,0,0,0,0,0,0,0,0,0,0,0,0,0,0,0,22,22,0,0,0,0,0,0,0,0,22,22,0,0,0,0,0,0,0,0,22,22,0,0,0,0,0,0,0,0,0,0,0,0,0,0,0,0,0,0,0,0,0,0,0
0,0,0,0,0,0,0,0,0,0,0,0,0,0,0,0,0,0,0,0,0,0,0,0,0,0,0,0,0,0,0,0,0,0,0,0,0,0,0,0,0,0,0,0,0,0,0,0,0,0,0,0,0,0,0,0,0,0,0,0,0,0,0
0,0,0,0,0,0,22,22,0,0,0,0,0,204,0,0,0,0,0,0,0,0,0,0,0,0,0,0,0,0,0,0,0,0,0,0,0,0,0,0,0,0,0,0,0,0,0,0,22,22,22,0,0,0,0,0,0,0,0,0,0,0,0
0,0,0,0,0,0,204,0,0,0,0,0,0,0,0,0,0,0,0,0,0,0,0,0,0,0,0,0,0,0,0,0,0,0,0,0,0,0,0,0,0,0,0,0,0,0,0,0,0,0,0,0,0,0,0,0,0,0,0,0,0,0,0
0,0,0,0,0,0,0,0,0,0,0,0,0,0,0,0,0,0,0,0,0,0,0,0,0,0,0,0,0,0,0,0,0,0,0,0,0,0,0,0,0,0,0,0,0,0,0,0,0,0,0,0,0,0,0,0,0,0,0,0,0,0,0
0,0,0,0,0,0,0,0,0,0,0,0,0,0,0,0,0,0,0,0,0,0,0,0,0,0,0,0,0,0,0,0,0,0,0,0,0,0,0,0,0,0,0,0,0,0,0,0,0,0,0,0,0,0,0,0,0,0,0,0,0,0,0
0,0,0,0,204,0,0,0,0,0,0,0,0,0,0,0,0,0,0,0,0,0,0,0,0,0,0,0,0,109,0,0,0,0,0,0,0,0,0,0,0,0,0,0,0,0,0,0,0,0,0,0,0,0,0,0,0,0,0,0,0,0,0
0,0,0,0,0,0,0,0,0,526,0,0,530,181,0,0,0,0,0,0,0,0,0,0,0,0,0,0,181,28,181,0,0,0,0,0,0,0,0,90,0,0,0,0,0,0,0,0,0,0,0,0,0,0,0,0,0,0,0,0,0,0,0
0,0,0,0,204,0,0,0,0,28,527,527,529,51,0,0,0,0,411,28,0,0,0,0,0,0,0,0,28,28,28,0,0,0,0,0,0,0,411,28,76,0,0,0,0,0,0,0,411,28,0,0,0,0,0,0,0,0,0,0,0,0,0
0,0,0,0,0,0,0,0,0,107,0,0,528,181,0,0,0,0,0,0,0,0,0,0,0,0,0,0,181,28,181,0,0,0,0,0,0,0,0,91,0,0,0,0,0,0,0,0,0,0,0,0,0,0,0,0,0,0,0,0,0,0,0
0,0,0,0,204,0,0,0,0,0,0,0,0,0,532,0,0,0,0,0,0,0,0,0,0,0,0,0,0,107,0,0,0,0,0,0,0,0,0,0,0,0,0,0,0,0,0,0,0,0,0,0,0,0,0,0,0,0,0,0,0,0,0
0,0,0,0,0,0,0,0,0,0,0,0,0,0,0,0,0,0,0,0,0,0,0,0,0,0,0,0,0,0,0,0,0,0,0,0,0,0,0,0,0,0,0,0,0,0,0,0,0,0,0,0,0,0,0,0,0,0,0,0,0,0,0
0,0,0,0,0,0,0,0,0,0,0,0,0,0,0,0,0,0,0,0,0,0,0,0,0,0,0,0,0,0,0,0,0,0,0,0,0,0,0,0,0,0,0,0,0,0,0,0,0,0,0,0,0,0,0,0,0,0,0,0,0,0,0
0,0,0,0,0,0,204,0,0,0,0,0,0,0,531,0,0,0,0,0,0,0,0,0,0,0,0,0,0,0,0,0,0,0,0,0,0,0,0,0,0,0,0,0,0,0,0,0,0,0,0,0,0,0,0,0,0,0,0,0,0,0,0
0,0,0,0,0,0,22,22,0,0,0,0,0,204,0,0,0,0,0,0,0,0,0,0,0,0,0,0,0,0,0,0,0,0,0,0,0,0,0,0,0,0,0,0,0,0,0,0,22,22,22,0,0,0,0,0,0,0,0,0,0,0,0
0,0,0,0,0,0,0,0,0,0,0,0,0,0,0,0,0,0,0,0,0,0,0,0,0,0,0,0,0,0,0,0,0,0,0,0,0,0,0,0,0,0,0,0,0,0,0,0,0,0,0,0,0,0,0,0,0,0,0,0,0,0,0
0,0,0,0,0,0,0,0,0,0,0,0,0,0,0,0,0,0,22,22,0,0,0,0,0,0,0,0,22,22,0,0,0,0,0,0,0,0,22,22,0,0,0,0,0,0,0,0,0,0,0,0,0,0,0,0,0,0,0,0,0,0,0
0,0,0,0,0,0,0,0,0,0,0,0,0,0,0,0,0,0,0,0,0,0,0,0,0,0,0,0,0,0,0,0,0,0,0,0,0,0,0,0,0,0,0,0,0,0,0,0,0,0,0,0,0,0,0,0,0,0,0,0,0,0,0
:endlayer
layer: 15
0,0,0,0,0,0,0,0,0,0,0,0,0,0,0,0,0,0,0,0,0,0,0,0,0,0,0,0,0,0,0,0,0,0,0,0,0,0,0,0,0,0,0,0,0,0,0,0,0,0,0,0,0,0,0,0,0,0,0,0,0,0,0
0,0,0,0,0,0,0,0,0,0,0,0,0,0,0,0,0,0,0,22,22,0,0,0,0,0,0,0,0,22,22,0,0,0,0,0,0,0,0,22,22,0,0,0,0,0,0,0,0,0,0,0,0,0,0,0,0,0,0,0,0,0,0
0,0,0,0,0,0,0,0,0,0,0,0,0,0,0,0,0,0,0,0,0,0,0,0,0,0,0,0,0,0,0,0,0,0,0,0,0,0,0,0,0,0,0,0,0,0,0,0,0,0,0,0,0,0,0,0,0,0,0,0,0,0,0
0,0,0,0,0,0,0,22,22,0,0,0,0,0,0,0,0,0,0,0,0,0,0,0,0,0,0,0,0,0,0,0,0,0,0,0,0,0,0,0,0,0,0,0,0,0,0,0,0,22,534,0,0,0,0,0,0,0,0,0,0,0,0
0,0,0,0,0,0,0,0,0,0,0,0,0,0,0,0,0,0,0,0,0,0,0,0,0,0,0,0,0,0,0,0,0,0,0,0,0,0,0,0,0,0,0,0,0,0,0,0,0,0,0,534,0,0,0,0,0,0,0,0,0,0,0
0,0,0,0,0,0,0,0,0,0,0,0,0,0,0,0,0,0,0,0,0,0,0,0,0,0,0,0,0,0,0,0,0,0,0,0,0,0,0,0,0,0,0,0,0,0,0,0,0,0,0,535,0,0,0,0,0,0,0,0,0,0,0
0,0,0,0,0,0,0,0,0,0,0,0,0,0,0,0,0,0,0,0,0,0,0,0,0,0,0,0,0,0,0,0,0,0,0,0,0,0,0,0,0,0,0,0,0,0,0,0,0,0,0,535,0,0,0,0,0,0,0,0,0,0,0
0,0,0,0,0,0,0,0,0,0,0,0,0,0,0,0,0,0,0,0,0,0,0,0,0,0,0,0,0,109,0,0,0,0,0,0,0,0,0,0,0,0,0,0,0,0,0,0,0,0,0,535,0,0,0,0,0,0,0,0,0,0,0
0,0,0,0,0,0,0,0,0,90,0,0,0,0,0,0,0,0,0,0,0,0,0,0,0,0,0,0,0,28,0,0,0,0,0,0,0,0,0,0,0,0,0,0,0,0,0,0,0,0,0,535,0,0,0,0,0,0,0,0,0,0,0
0,0,0,0,0,0,0,0,85,28,76,533,0,0,0,0,0,0,411,28,0,0,0,0,0,0,0,0,28,28,28,0,0,0,0,0,0,0,411,28,0,0,0,0,0,0,0,0,411,28,0,534,0,0,0,0,0,0,0,0,0,0,0
0,0,0,0,0,0,0,0,0,107,0,0,0,0,0,0,0,0,0,0,0,0,0,0,0,0,0,0,0,28,0,0,0,0,0,0,0,0,0,0,0,0,0,0,0,0,0,0,0,0,0,535,0,0,0,0,0,0,0,0,0,0,0
0,0,0,0,0,0,0,0,0,0,0,0,0,0,0,0,0,0,0,0,0,0,0,0,0,0,0,0,0,107,0,0,0,0,0,0,0,0,0,0,0,0,0,0,0,0,0,0,0,0,0,535,0,0,0,0,0,0,0,0,0,0,0
0,0,0,0,0,0,0,0,0,0,0,0,0,0,0,0,0,0,0,0,0,0,0,0,0,0,0,0,0,0,0,0,0,0,0,0,0,0,0,0,0,0,0,0,0,0,0,0,0,0,0,535,0,0,0,0,0,0,0,0,0,0,0
0,0,0,0,0,0,0,0,0,0,0,0,0,0,0,0,0,0,0,0,0,0,0,0,0,0,0,0,0,0,0,0,0,0,0,0,0,0,0,0,0,0,0,0,0,0,0,0,0,0,0,535,0,0,0,0,0,0,0,0,0,0,0
0,0,0,0,0,0,0,0,0,0,0,0,0,0,0,0,0,0,0,0,0,0,0,0,0,0,0,0,0,0,0,0,0,0,0,0,0,0,0,0,0,0,0,0,0,0,0,0,0,0,0,534,0,0,0,0,0,0,0,0,0,0,0
0,0,0,0,0,0,0,22,22,0,0,0,0,0,0,0,0,0,0,0,0,0,0,0,0,0,0,0,0,0,0,0,0,0,0,0,0,0,0,0,0,0,0,0,0,0,0,0,0,22,534,0,0,0,0,0,0,0,0,0,0,0,0
0,0,0,0,0,0,0,0,0,0,0,0,0,0,0,0,0,0,0,0,0,0,0,0,0,0,0,0,0,0,0,0,0,0,0,0,0,0,0,0,0,0,0,0,0,0,0,0,0,0,0,0,0,0,0,0,0,0,0,0,0,0,0
0,0,0,0,0,0,0,0,0,0,0,0,0,0,0,0,0,0,0,22,22,0,0,0,0,0,0,0,0,22,22,0,0,0,0,0,0,0,0,22,22,0,0,0,0,0,0,0,0,0,0,0,0,0,0,0,0,0,0,0,0,0,0
0,0,0,0,0,0,0,0,0,0,0,0,0,0,0,0,0,0,0,0,0,0,0,0,0,0,0,0,0,0,0,0,0,0,0,0,0,0,0,0,0,0,0,0,0,0,0,0,0,0,0,0,0,0,0,0,0,0,0,0,0,0,0
:endlayer
layer: 16
0,0,0,0,0,0,0,0,0,0,0,0,0,0,0,0,0,0,0,0,0,0,0,0,0,0,0,0,0,0,0,0,0,0,0,0,0,0,0,0,0,0,0,0,0,0,0,0,0,0,0,0,0,0,0,0,0,0,0,0,0,0,0
0,0,0,0,0,0,0,0,0,0,0,0,0,0,0,0,0,0,0,22,534,0,0,0,0,0,0,0,0,22,534,0,0,0,0,0,0,0,0,22,534,0,0,0,0,0,0,0,0,0,0,0,0,0,0,0,0,0,0,0,0,0,0
0,0,0,0,0,0,0,0,0,0,0,0,0,0,0,0,0,0,0,0,534,0,0,0,0,0,0,0,0,0,534,0,0,0,0,0,0,0,0,0,534,0,0,0,0,0,0,0,0,0,0,0,0,0,0,0,0,0,0,0,0,0,0
0,0,0,0,0,0,0,22,22,0,0,0,0,0,0,0,0,0,0,0,0,535,0,0,0,0,0,0,0,0,0,535,0,0,0,0,0,0,0,0,0,535,0,0,0,0,0,0,0,0,22,535,0,0,0,0,0,0,0,0,0,0,0
0,0,0,0,0,0,0,0,0,0,0,0,0,0,0,0,0,0,0,0,0,535,0,0,0,0,0,0,0,0,0,535,0,0,0,0,0,0,0,0,0,535,0,0,0,0,0,0,0,0,0,535,0,0,0,0,0,0,0,0,0,0,0
0,0,0,0,0,0,0,0,0,0,0,0,0,0,0,0,0,0,0,0,0,535,0,0,0,0,0,0,0,0,0,535,0,0,0,0,0,0,0,0,0,535,0,0,0,0,0,0,0,0,0,534,0,0,0,0,0,0,0,0,0,0,0
0,0,0,0,0,0,0,0,0,0,0,0,0,0,0,0,0,0,0,0,0,534,0,0,0,0,0,0,0,0,0,534,0,0,0,0,0,0,0,0,0,534,0,0,0,0,0,0,0,0,0,22,534,0,0,0,0,0,0,0,0,0,0
0,0,0,0,0,0,0,0,0,0,0,0,0,0,0,0,0,0,0,0,0,534,0,0,0,0,0,0,0,109,0,534,0,0,0,0,0,0,0,0,0,534,0,0,0,0,0,0,0,0,0,0,535,0,0,0,0,0,0,0,0,0,0
0,0,0,0,0,0,0,0,0,0,0,0,0,0,0,0,0,0,0,0,0,535,0,0,0,0,0,0,0,28,0,535,0,0,0,0,0,0,0,0,0,535,0,0,0,0,0,0,0,0,0,0,535,0,0,0,0,0,0,0,0,0,0
0,0,0,0,0,0,116,284,284,28,0,0,0,0,0,0,0,0,411,28,0,534,0,0,0,0,0,0,28,28,28,534,0,0,0,0,0,0,411,28,0,534,0,0,0,0,0,0,411,28,76,0,534,0,0,0,0,0,0,0,0,0,0
0,0,0,0,0,0,0,0,0,107,0,0,0,0,0,0,0,0,0,0,0,535,0,0,0,0,0,0,0,28,0,535,0,0,0,0,0,0,0,0,0,535,0,0,0,0,0,0,0,0,0,0,535,0,0,0,0,0,0,0,0,0,0
0,0,0,0,0,0,0,0,0,0,0,0,0,0,0,0,0,0,0,0,0,534,0,0,0,0,0,0,0,107,0,534,0,0,0,0,0,0,0,0,0,534,0,0,0,0,0,0,0,0,0,0,535,0,0,0,0,0,0,0,0,0,0
0,0,0,0,0,0,0,0,0,0,0,0,0,0,0,0,0,0,0,0,0,534,0,0,0,0,0,0,0,0,0,534,0,0,0,0,0,0,0,0,0,534,0,0,0,0,0,0,0,0,0,22,534,0,0,0,0,0,0,0,0,0,0
0,0,0,0,0,0,0,0,0,0,0,0,0,0,0,0,0,0,0,0,0,535,0,0,0,0,0,0,0,0,0,535,0,0,0,0,0,0,0,0,0,535,0,0,0,0,0,0,0,0,0,534,0,0,0,0,0,0,0,0,0,0,0
0,0,0,0,0,0,0,0,0,0,0,0,0,0,0,0,0,0,0,0,0,535,0,0,0,0,0,0,0,0,0,535,0,0,0,0,0,0,0,0,0,535,0,0,0,0,0,0,0,0,0,535,0,0,0,0,0,0,0,0,0,0,0
0,0,0,0,0,0,0,22,22,0,0,0,0,0,0,0,0,0,0,0,0,535,0,0,0,0,0,0,0,0,0,535,0,0,0,0,0,0,0,0,0,535,0,0,0,0,0,0,0,0,22,535,0,0,0,0,0,0,0,0,0,0,0
0,0,0,0,0,0,0,0,0,0,0,0,0,0,0,0,0,0,0,0,534,0,0,0,0,0,0,0,0,0,534,0,0,0,0,0,0,0,0,0,534,0,0,0,0,0,0,0,0,0,0,0,0,0,0,0,0,0,0,0,0,0,0
0,0,0,0,0,0,0,0,0,0,0,0,0,0,0,0,0,0,0,22,534,0,0,0,0,0,0,0,0,22,534,0,0,0,0,0,0,0,0,22,534,0,0,0,0,0,0,0,0,0,0,0,0,0,0,0,0,0,0,0,0,0,0
0,0,0,0,0,0,0,0,0,0,0,0,0,0,0,0,0,0,0,0,0,0,0,0,0,0,0,0,0,0,0,0,0,0,0,0,0,0,0,0,0,0,0,0,0,0,0,0,0,0,0,0,0,0,0,0,0,0,0,0,0,0,0
:endlayer
layer: 17
0,0,0,0,0,0,0,0,0,0,0,0,0,0,0,0,0,0,0,0,0,0,0,0,0,0,0,0,0,0,0,0,0,0,0,0,0,0,0,0,0,0,0,0,0,0,0,0,0,0,0,0,0,0,0,0,0,0,0,0,0,0,0
0,0,0,0,0,0,0,0,0,0,0,0,0,0,0,0,0,0,0,0,0,535,0,0,0,0,0,0,0,0,0,535,0,0,0,0,0,0,0,0,0,535,0,0,0,0,0,0,0,0,0,0,0,0,0,0,0,0,0,0,0,0,0
0,0,0,0,0,0,0,0,0,0,0,0,0,0,0,0,0,0,0,0,22,535,0,0,0,0,0,0,0,0,22,535,0,0,0,0,0,0,0,0,22,535,0,0,0,0,0,0,0,0,0,0,0,0,0,0,0,0,0,0,0,0,0
0,0,0,0,0,0,0,0,22,22,0,0,0,0,0,0,0,0,0,0,0,534,0,0,0,0,0,0,0,0,0,534,0,0,0,0,0,0,0,0,0,534,0,0,0,0,0,0,0,0,0,535,0,0,0,0,0,0,0,0,0,0,0
0,0,0,0,0,0,0,0,0,0,0,0,0,0,0,0,0,0,0,0,0,534,0,0,0,0,0,0,0,0,0,534,0,0,0,0,0,0,0,0,0,534,0,0,0,0,0,0,0,0,0,0,535,0,0,0,0,0,0,0,0,0,0
0,0,0,0,0,0,0,0,0,0,0,0,0,0,0,0,0,0,0,0,0,535,0,0,0,0,0,0,0,0,0,535,0,0,0,0,0,0,0,0,0,535,0,0,0,0,0,0,0,0,0,0,535,0,0,0,0,0,0,0,0,0,0
0,0,0,0,0,0,0,0,0,0,0,0,0,0,0,0,0,0,0,0,0,22,535,0,0,0,0,0,0,0,0,22,535,0,0,0,0,0,0,0,0,22,535,0,0,0,0,0,0,0,0,0,535,0,0,0,0,0,0,0,0,0,0
0,0,0,0,0,0,0,0,0,0,0,0,0,0,0,0,0,0,0,0,0,0,535,0,0,0,0,0,0,109,0,0,535,0,0,0,0,0,0,0,0,0,535,0,0,0,0,0,0,0,0,0,534,0,0,0,0,0,0,0,0,0,0
0,0,0,0,0,0,0,0,0,0,0,0,0,0,0,0,0,0,0,0,0,0,535,0,0,0,0,0,0,28,0,0,535,0,0,0,0,0,0,0,0,0,535,0,0,0,0,0,0,0,0,0,0,534,0,0,0,0,0,0,0,0,0
0,0,0,0,116,284,284,535,535,28,0,0,0,0,0,0,0,0,411,28,76,0,534,0,0,0,0,0,28,28,28,76,534,0,0,0,0,0,411,28,76,0,534,0,0,0,0,0,411,28,0,0,0,535,0,0,0,0,0,0,0,0,0
0,0,0,0,0,0,0,0,0,107,0,0,0,0,0,0,0,0,0,0,0,0,535,0,0,0,0,0,0,28,0,0,535,0,0,0,0,0,0,0,0,0,535,0,0,0,0,0,0,0,0,0,0,534,0,0,0,0,0,0,0,0,0
0,0,0,0,0,0,0,0,0,0,0,0,0,0,0,0,0,0,0,0,0,0,535,0,0,0,0,0,0,107,0,0,535,0,0,0,0,0,0,0,0,0,535,0,0,0,0,0,0,0,0,0,534,0,0,0,0,0,0,0,0,0,0
0,0,0,0,0,0,0,0,0,0,0,0,0,0,0,0,0,0,0,0,0,22,535,0,0,0,0,0,0,0,0,22,535,0,0,0,0,0,0,0,0,22,535,0,0,0,0,0,0,0,0,0,535,0,0,0,0,0,0,0,0,0,0
0,0,0,0,0,0,0,0,0,0,0,0,0,0,0,0,0,0,0,0,0,535,0,0,0,0,0,0,0,0,0,535,0,0,0,0,0,0,0,0,0,535,0,0,0,0,0,0,0,0,0,0,535,0,0,0,0,0,0,0,0,0,0
0,0,0,0,0,0,0,0,0,0,0,0,0,0,0,0,0,0,0,0,0,534,0,0,0,0,0,0,0,0,0,534,0,0,0,0,0,0,0,0,0,534,0,0,0,0,0,0,0,0,0,0,535,0,0,0,0,0,0,0,0,0,0
0,0,0,0,0,0,0,0,22,22,0,0,0,0,0,0,0,0,0,0,0,534,0,0,0,0,0,0,0,0,0,534,0,0,0,0,0,0,0,0,0,534,0,0,0,0,0,0,0,0,0,535,0,0,0,0,0,0,0,0,0,0,0
0,0,0,0,0,0,0,0,0,0,0,0,0,0,0,0,0,0,0,0,22,535,0,0,0,0,0,0,0,0,22,535,0,0,0,0,0,0,0,0,22,535,0,0,0,0,0,0,0,0,0,0,0,0,0,0,0,0,0,0,0,0,0
0,0,0,0,0,0,0,0,0,0,0,0,0,0,0,0,0,0,0,0,0,535,0,0,0,0,0,0,0,0,0,535,0,0,0,0,0,0,0,0,0,535,0,0,0,0,0,0,0,0,0,0,0,0,0,0,0,0,0,0,0,0,0
0,0,0,0,0,0,0,0,0,0,0,0,0,0,0,0,0,0,0,0,0,0,0,0,0,0,0,0,0,0,0,0,0,0,0,0,0,0,0,0,0,0,0,0,0,0,0,0,0,0,0,0,0,0,0,0,0,0,0,0,0,0,0
:endlayer
layer: 18
0,0,0,0,0,0,0,0,0,0,0,0,0,0,0,0,0,0,0,0,0,0,0,0,0,0,0,0,0,0,0,0,0,0,0,0,0,0,0,0,0,0,0,0,0,0,0,0,0,0,0,0,0,0,0,0,0,0,0,0,0,0,0
0,0,0,0,0,0,0,0,0,0,0,0,0,0,0,0,0,0,0,0,0,534,0,0,0,0,0,0,0,0,0,534,0,0,0,0,0,0,0,0,0,534,0,0,0,0,0,0,0,0,0,0,0,0,0,0,0,0,0,0,0,0,0
0,0,0,0,0,0,0,0,0,0,0,0,0,0,0,0,0,0,0,0,0,535,0,0,0,0,0,0,0,0,0,535,0,0,0,0,0,0,0,0,0,535,0,0,0,0,0,0,0,0,0,0,0,0,0,0,0,0,0,0,0,0,0
0,0,0,0,0,0,0,0,22,22,0,0,0,0,0,0,0,0,0,0,0,535,0,0,0,0,0,0,0,0,0,535,0,0,0,0,0,0,0,0,0,535,0,0,0,0,0,0,0,0,0,535,0,0,0,0,0,0,0,0,0,0,0
0,0,0,0,0,0,0,0,0,0,0,0,0,0,0,0,0,0,0,0,0,0,535,0,0,0,0,0,0,0,0,0,535,0,0,0,0,0,0,0,0,0,535,0,0,0,0,0,0,0,0,0,535,0,0,0,0,0,0,0,0,0,0
0,0,0,0,0,0,0,0,0,0,0,0,0,0,0,0,0,0,0,0,0,0,534,0,0,0,0,0,0,0,0,0,534,0,0,0,0,0,0,0,0,0,534,0,0,0,0,0,0,0,0,0,534,0,0,0,0,0,0,0,0,0,0
0,0,0,0,0,0,0,0,0,0,0,0,0,0,0,0,0,0,0,0,0,0,534,0,0,0,0,0,0,0,0,0,534,0,0,0,0,0,0,0,0,0,534,0,0,0,0,0,0,0,0,0,22,534,0,0,0,0,0,0,0,0,0
0,0,0,0,0,0,0,0,0,0,0,0,0,0,0,0,0,0,0,0,0,0,535,0,0,0,0,0,0,109,0,0,535,0,0,0,0,0,0,0,0,0,535,0,0,0,0,0,0,0,0,0,0,535,0,0,0,0,0,0,0,0,0
0,0,0,0,0,0,0,535,535,0,0,0,0,0,0,0,0,0,0,0,0,0,22,535,0,0,0,0,0,28,0,0,22,535,0,0,0,0,0,0,0,0,22,535,0,0,0,0,0,0,0,0,0,535,0,0,0,0,0,0,0,0,0
0,0,116,284,284,535,535,0,22,28,0,0,0,0,0,0,0,0,411,28,0,0,0,534,0,0,0,0,28,28,28,0,0,534,0,0,0,0,411,28,0,0,0,534,0,0,0,0,411,28,0,0,0,534,0,0,0,0,0,0,0,0,0
0,0,0,0,0,0,0,0,0,107,0,0,0,0,0,0,0,0,0,0,0,0,22,535,0,0,0,0,0,28,0,0,22,535,0,0,0,0,0,0,0,0,22,535,0,0,0,0,0,0,0,0,0,535,0,0,0,0,0,0,0,0,0
0,0,0,0,0,0,0,0,0,0,0,0,0,0,0,0,0,0,0,0,0,0,535,0,0,0,0,0,0,107,0,0,535,0,0,0,0,0,0,0,0,0,535,0,0,0,0,0,0,0,0,0,0,535,0,0,0,0,0,0,0,0,0
0,0,0,0,0,0,0,0,0,0,0,0,0,0,0,0,0,0,0,0,0,0,534,0,0,0,0,0,0,0,0,0,534,0,0,0,0,0,0,0,0,0,534,0,0,0,0,0,0,0,0,0,22,534,0,0,0,0,0,0,0,0,0
0,0,0,0,0,0,0,0,0,0,0,0,0,0,0,0,0,0,0,0,0,0,534,0,0,0,0,0,0,0,0,0,534,0,0,0,0,0,0,0,0,0,534,0,0,0,0,0,0,0,0,0,534,0,0,0,0,0,0,0,0,0,0
0,0,0,0,0,0,0,0,0,0,0,0,0,0,0,0,0,0,0,0,0,0,535,0,0,0,0,0,0,0,0,0,535,0,0,0,0,0,0,0,0,0,535,0,0,0,0,0,0,0,0,0,535,0,0,0,0,0,0,0,0,0,0
0,0,0,0,0,0,0,0,22,22,0,0,0,0,0,0,0,0,0,0,0,535,0,0,0,0,0,0,0,0,0,535,0,0,0,0,0,0,0,0,0,535,0,0,0,0,0,0,0,0,0,535,0,0,0,0,0,0,0,0,0,0,0
0,0,0,0,0,0,0,0,0,0,0,0,0,0,0,0,0,0,0,0,0,535,0,0,0,0,0,0,0,0,0,535,0,0,0,0,0,0,0,0,0,535,0,0,0,0,0,0,0,0,0,0,0,0,0,0,0,0,0,0,0,0,0
0,0,0,0,0,0,0,0,0,0,0,0,0,0,0,0,0,0,0,0,0,534,0,0,0,0,0,0,0,0,0,534,0,0,0,0,0,0,0,0,0,534,0,0,0,0,0,0,0,0,0,0,0,0,0,0,0,0,0,0,0,0,0
0,0,0,0,0,0,0,0,0,0,0,0,0,0,0,0,0,0,0,0,0,0,0,0,0,0,0,0,0,0,0,0,0,0,0,0,0,0,0,0,0,0,0,0,0,0,0,0,0,0,0,0,0,0,0,0,0,0,0,0,0,0,0
:endlayer
layer: 19
0,0,0,0,0,0,0,0,0,0,0,0,0,0,0,0,0,0,0,0,0,0,0,0,0,0,0,0,0,0,0,0,0,0,0,0,0,0,0,0,0,0,0,0,0,0,0,0,0,0,0,0,0,0,0,0,0,0,0,0,0,0,0
0,0,0,0,0,0,0,0,0,0,0,0,0,0,0,0,0,0,0,0,0,535,0,0,0,0,0,0,0,0,0,535,0,0,0,0,0,0,0,0,0,535,0,0,0,0,0,0,0,0,0,0,0,0,0,0,0,0,0,0,0,0,0
0,0,0,0,0,0,0,0,0,0,0,0,0,0,0,0,0,0,0,0,0,0,535,0,0,0,0,0,0,0,0,0,535,0,0,0,0,0,0,0,0,0,535,0,0,0,0,0,0,0,0,0,0,0,0,0,0,0,0,0,0,0,0
0,0,0,0,0,0,0,0,0,22,22,0,0,0,0,0,0,0,0,0,0,0,535,0,0,0,0,0,0,0,0,0,535,0,0,0,0,0,0,0,0,0,535,0,0,0,0,0,0,0,0,535,0,0,0,0,0,0,0,0,0,0,0
0,0,0,0,0,0,0,0,0,0,0,0,0,0,0,0,0,0,0,0,0,0,535,0,0,0,0,0,0,0,0,0,535,0,0,0,0,0,0,0,0,0,535,0,0,0,0,0,0,0,0,0,535,0,0,0,0,0,0,0,0,0,0
0,0,0,0,0,0,0,0,0,0,0,0,0,0,0,0,0,0,0,0,0,0,535,0,0,0,0,0,0,0,0,0,535,0,0,0,0,0,0,0,0,0,535,0,0,0,0,0,0,0,0,0,535,0,0,0,0,0,0,0,0,0,0
0,0,0,0,0,0,0,0,0,0,0,0,0,0,0,0,0,0,0,0,0,0,0,535,0,0,0,0,0,0,0,0,0,535,0,0,0,0,0,0,0,0,0,535,0,0,0,0,0,0,0,0,535,0,0,0,0,0,0,0,0,0,0
0,0,0,0,0,0,0,0,0,0,0,0,0,0,0,0,0,0,0,0,0,0,0,534,0,0,0,0,0,109,0,0,0,534,0,0,0,0,0,0,0,0,0,534,0,0,0,0,0,0,0,0,534,0,0,0,0,0,0,0,0,0,0
0,0,0,0,0,535,535,535,535,0,0,0,0,0,0,0,0,0,0,0,0,0,0,534,0,0,0,0,0,28,0,0,0,534,0,0,0,0,0,0,0,0,0,534,0,0,0,0,0,0,0,0,0,534,0,0,0,0,0,0,0,0,0
116,284,284,535,535,22,0,0,0,28,0,0,0,0,0,0,0,0,411,28,0,0,0,535,0,0,0,0,28,28,28,0,0,535,0,0,0,0,411,28,0,0,0,535,0,0,0,0,411,28,0,0,0,535,0,0,0,0,0,0,0,0,0
0,0,0,0,0,0,0,0,0,107,0,0,0,0,0,0,0,0,0,0,0,0,0,534,0,0,0,0,0,28,0,0,0,534,0,0,0,0,0,0,0,0,0,534,0,0,0,0,0,0,0,0,0,534,0,0,0,0,0,0,0,0,0
0,0,0,0,0,0,0,0,0,0,0,0,0,0,0,0,0,0,0,0,0,0,0,534,0,0,0,0,0,107,0,0,0,534,0,0,0,0,0,0,0,0,0,534,0,0,0,0,0,0,0,0,534,0,0,0,0,0,0,0,0,0,0
0,0,0,0,0,0,0,0,0,0,0,0,0,0,0,0,0,0,0,0,0,0,0,535,0,0,0,0,0,0,0,0,0,535,0,0,0,0,0,0,0,0,0,535,0,0,0,0,0,0,0,0,535,0,0,0,0,0,0,0,0,0,0
0,0,0,0,0,0,0,0,0,0,0,0,0,0,0,0,0,0,0,0,0,0,535,0,0,0,0,0,0,0,0,0,535,0,0,0,0,0,0,0,0,0,535,0,0,0,0,0,0,0,0,0,535,0,0,0,0,0,0,0,0,0,0
0,0,0,0,0,0,0,0,0,0,0,0,0,0,0,0,0,0,0,0,0,0,535,0,0,0,0,0,0,0,0,0,535,0,0,0,0,0,0,0,0,0,535,0,0,0,0,0,0,0,0,0,535,0,0,0,0,0,0,0,0,0,0
0,0,0,0,0,0,0,0,0,22,22,0,0,0,0,0,0,0,0,0,0,0,535,0,0,0,0,0,0,0,0,0,535,0,0,0,0,0,0,0,0,0,535,0,0,0,0,0,0,0,0,535,0,0,0,0,0,0,0,0,0,0,0
0,0,0,0,0,0,0,0,0,0,0,0,0,0,0,0,0,0,0,0,0,0,535,0,0,0,0,0,0,0,0,0,535,0,0,0,0,0,0,0,0,0,535,0,0,0,0,0,0,0,0,0,0,0,0,0,0,0,0,0,0,0,0
0,0,0,0,0,0,0,0,0,0,0,0,0,0,0,0,0,0,0,0,0,535,0,0,0,0,0,0,0,0,0,535,0,0,0,0,0,0,0,0,0,535,0,0,0,0,0,0,0,0,0,0,0,0,0,0,0,0,0,0,0,0,0
0,0,0,0,0,0,0,0,0,0,0,0,0,0,0,0,0,0,0,0,0,0,0,0,0,0,0,0,0,0,0,0,0,0,0,0,0,0,0,0,0,0,0,0,0,0,0,0,0,0,0,0,0,0,0,0,0,0,0,0,0,0,0
:endlayer
layer: 20
0,0,0,0,0,0,0,0,0,0,0,0,0,0,0,0,0,0,0,0,0,0,0,0,0,0,0,0,0,0,0,0,0,0,0,0,0,0,0,0,0,0,0,0,0,0,0,0,0,0,0,0,0,0,0,0,0,0,0,0,0,0,0
0,0,0,0,0,0,0,0,0,0,0,0,0,0,0,0,0,0,0,0,0,534,0,0,0,0,0,0,0,0,0,534,0,0,0,0,0,0,0,0,0,534,0,0,0,0,0,0,0,0,0,0,0,0,0,0,0,0,0,0,0,0,0
0,0,0,0,0,0,0,0,0,0,0,0,0,0,0,0,0,0,0,0,0,22,534,0,0,0,0,0,0,0,0,22,534,0,0,0,0,0,0,0,0,22,534,0,0,0,0,0,0,0,0,0,0,0,0,0,0,0,0,0,0,0,0
0,0,0,0,0,0,0,0,0,22,534,0,0,0,0,0,0,0,0,0,0,0,534,0,0,0,0,0,0,0,0,0,534,0,0,0,0,0,0,0,0,0,534,0,0,0,0,0,0,0,22,535,0,0,0,0,0,0,0,0,0,0,0
0,0,0,0,0,0,0,0,0,0,0,534,0,0,0,0,0,0,0,0,0,0,22,534,0,0,0,0,0,0,0,0,22,534,0,0,0,0,0,0,0,0,22,534,0,0,0,0,0,0,0,535,0,0,0,0,0,0,0,0,0,0,0
0,0,0,0,0,0,0,0,0,0,0,535,0,0,0,0,0,0,0,0,0,0,0,534,0,0,0,0,0,0,0,0,0,534,0,0,0,0,0,0,0,0,0,534,0,0,0,0,0,0,0,534,0,0,0,0,0,0,0,0,0,0,0
0,0,0,0,0,0,0,0,0,0,0,535,0,0,0,0,0,0,0,0,0,0,0,534,0,0,0,0,0,0,0,0,0,534,0,0,0,0,0,0,0,0,0,534,0,0,0,0,0,0,0,22,534,0,0,0,0,0,0,0,0,0,0
0,0,0,0,0,0,535,535,0,0,0,535,0,0,0,0,0,0,0,0,0,0,0,535,0,0,0,0,0,109,0,0,0,535,0,0,0,0,0,0,0,0,0,535,0,0,0,0,0,0,0,0,535,0,0,0,0,0,0,0,0,0,0
0,0,0,535,535,535,0,0,535,0,0,535,0,0,0,0,0,0,0,0,0,0,0,535,0,0,0,0,181,28,181,0,0,535,0,0,0,0,0,0,0,0,0,535,0,0,0,0,0,0,0,0,535,0,0,0,0,0,0,0,0,0,0
204,535,535,22,0,0,0,0,0,28,0,534,0,0,0,0,0,0,411,28,0,0,0,534,0,0,0,0,28,28,28,0,0,534,0,0,0,0,411,28,0,0,0,534,0,0,0,0,411,28,0,0,534,0,0,0,0,0,0,0,0,0,0
0,0,0,0,0,0,0,0,0,107,0,535,0,0,0,0,0,0,0,0,0,0,0,535,0,0,0,0,181,28,181,0,0,535,0,0,0,0,0,0,0,0,0,535,0,0,0,0,0,0,0,0,535,0,0,0,0,0,0,0,0,0,0
0,0,0,0,0,0,0,0,0,0,0,535,0,0,0,0,0,0,0,0,0,0,0,535,0,0,0,0,0,107,0,0,0,535,0,0,0,0,0,0,0,0,0,535,0,0,0,0,0,0,0,0,535,0,0,0,0,0,0,0,0,0,0
0,0,0,0,0,0,0,0,0,0,0,535,0,0,0,0,0,0,0,0,0,0,0,534,0,0,0,0,0,0,0,0,0,534,0,0,0,0,0,0,0,0,0,534,0,0,0,0,0,0,0,22,534,0,0,0,0,0,0,0,0,0,0
0,0,0,0,0,0,0,0,0,0,0,535,0,0,0,0,0,0,0,0,0,0,0,534,0,0,0,0,0,0,0,0,0,534,0,0,0,0,0,0,0,0,0,534,0,0,0,0,0,0,0,534,0,0,0,0,0,0,0,0,0,0,0
0,0,0,0,0,0,0,0,0,0,0,534,0,0,0,0,0,0,0,0,0,0,22,534,0,0,0,0,0,0,0,0,22,534,0,0,0,0,0,0,0,0,22,534,0,0,0,0,0,0,0,535,0,0,0,0,0,0,0,0,0,0,0
0,0,0,0,0,0,0,0,0,22,534,0,0,0,0,0,0,0,0,0,0,0,534,0,0,0,0,0,0,0,0,0,534,0,0,0,0,0,0,0,0,0,534,0,0,0,0,0,0,0,22,535,0,0,0,0,0,0,0,0,0,0,0
0,0,0,0,0,0,0,0,0,0,0,0,0,0,0,0,0,0,0,0,0,22,534,0,0,0,0,0,0,0,0,22,534,0,0,0,0,0,0,0,0,22,534,0,0,0,0,0,0,0,0,0,0,0,0,0,0,0,0,0,0,0,0
0,0,0,0,0,0,0,0,0,0,0,0,0,0,0,0,0,0,0,0,0,534,0,0,0,0,0,0,0,0,0,534,0,0,0,0,0,0,0,0,0,534,0,0,0,0,0,0,0,0,0,0,0,0,0,0,0,0,0,0,0,0,0
0,0,0,0,0,0,0,0,0,0,0,0,0,0,0,0,0,0,0,0,0,0,0,0,0,0,0,0,0,0,0,0,0,0,0,0,0,0,0,0,0,0,0,0,0,0,0,0,0,0,0,0,0,0,0,0,0,0,0,0,0,0,0
:endlayer
layer: 21
0,0,0,0,0,0,0,0,0,0,0,0,0,0,0,0,0,0,0,0,0,0,0,0,0,0,0,0,0,0,0,0,0,0,0,0,0,0,0,0,0,0,0,0,0,0,0,0,0,0,0,0,0,0,0,0,0,0,0,0,0,0,0
0,0,0,0,0,0,0,0,0,0,0,0,0,0,0,0,0,0,0,0,0,535,0,0,0,0,0,0,0,0,0,535,0,0,0,0,0,0,0,0,0,535,0,0,0,0,0,0,0,0,0,0,0,0,0,0,0,0,0,0,0,0,0
0,0,0,0,0,0,0,0,0,0,0,0,0,0,0,0,0,0,0,0,0,0,535,0,0,0,0,0,0,0,0,0,535,0,0,0,0,0,0,0,0,0,535,0,0,0,0,0,0,0,0,0,0,0,0,0,0,0,0,0,0,0,0
0,0,0,0,0,0,0,0,0,0,22,535,0,0,0,0,0,0,0,0,0,0,535,0,0,0,0,0,0,0,0,0,535,0,0,0,0,0,0,0,0,0,535,0,0,0,0,0,0,0,534,0,0,0,0,0,0,0,0,0,0,0,0
0,0,0,0,0,0,0,0,0,0,0,535,0,0,0,0,0,0,0,0,0,0,535,0,0,0,0,0,0,0,0,0,535,0,0,0,0,0,0,0,0,0,535,0,0,0,0,0,0,0,0,534,0,0,0,0,0,0,0,0,0,0,0
0,0,0,0,0,0,0,0,0,0,0,534,0,0,0,0,0,0,0,0,0,0,535,0,0,0,0,0,0,0,0,0,535,0,0,0,0,0,0,0,0,0,535,0,0,0,0,0,0,0,0,535,0,0,0,0,0,0,0,0,0,0,0
0,0,0,0,0,0,0,0,0,0,0,22,534,0,0,0,0,0,0,0,0,0,0,535,0,0,0,0,0,0,0,0,0,535,0,0,0,0,0,0,0,0,0,535,0,0,0,0,0,0,0,535,0,0,0,0,0,0,0,0,0,0,0
0,0,0,0,535,535,535,535,0,0,0,0,535,0,0,0,0,0,0,0,0,0,0,534,0,0,0,0,116,109,116,0,0,534,0,0,0,0,0,0,0,0,0,534,0,0,0,0,0,0,0,535,0,0,0,0,0,0,0,0,0,0,0
0,535,535,535,0,0,0,22,535,0,0,0,535,0,0,0,0,0,0,0,0,0,0,534,0,0,0,116,68,282,68,116,0,534,0,0,0,0,0,0,0,0,0,534,0,0,0,0,0,0,0,535,0,0,0,0,0,0,0,0,0,0,0
0,22,0,0,0,0,0,0,0,28,76,0,534,0,0,0,0,0,411,28,0,0,0,535,0,0,0,116,284,28,284,116,0,535,0,0,0,0,411,28,0,0,0,535,0,0,0,0,411,28,0,534,0,0,0,0,0,0,0,0,0,0,0
0,0,0,0,0,0,0,0,0,107,0,0,535,0,0,0,0,0,0,0,0,0,0,534,0,0,0,116,67,282,67,116,0,534,0,0,0,0,0,0,0,0,0,534,0,0,0,0,0,0,0,535,0,0,0,0,0,0,0,0,0,0,0
0,0,0,0,0,0,0,0,0,0,0,0,535,0,0,0,0,0,0,0,0,0,0,534,0,0,0,0,116,107,116,0,0,534,0,0,0,0,0,0,0,0,0,534,0,0,0,0,0,0,0,535,0,0,0,0,0,0,0,0,0,0,0
0,0,0,0,0,0,0,0,0,0,0,22,534,0,0,0,0,0,0,0,0,0,0,535,0,0,0,0,0,0,0,0,0,535,0,0,0,0,0,0,0,0,0,535,0,0,0,0,0,0,0,535,0,0,0,0,0,0,0,0,0,0,0
0,0,0,0,0,0,0,0,0,0,0,534,0,0,0,0,0,0,0,0,0,0,535,0,0,0,0,0,0,0,0,0,535,0,0,0,0,0,0,0,0,0,535,0,0,0,0,0,0,0,0,535,0,0,0,0,0,0,0,0,0,0,0
0,0,0,0,0,0,0,0,0,0,0,535,0,0,0,0,0,0,0,0,0,0,535,0,0,0,0,0,0,0,0,0,535,0,0,0,0,0,0,0,0,0,535,0,0,0,0,0,0,0,0,534,0,0,0,0,0,0,0,0,0,0,0
0,0,0,0,0,0,0,0,0,0,22,535,0,0,0,0,0,0,0,0,0,0,535,0,0,0,0,0,0,0,0,0,535,0,0,0,0,0,0,0,0,0,535,0,0,0,0,0,0,0,534,0,0,0,0,0,0,0,0,0,0,0,0
0,0,0,0,0,0,0,0,0,0,0,0,0,0,0,0,0,0,0,0,0,0,535,0,0,0,0,0,0,0,0,0,535,0,0,0,0,0,0,0,0,0,535,0,0,0,0,0,0,0,0,0,0,0,0,0,0,0,0,0,0,0,0
0,0,0,0,0,0,0,0,0,0,0,0,0,0,0,0,0,0,0,0,0,535,0,0,0,0,0,0,0,0,0,535,0,0,0,0,0,0,0,0,0,535,0,0,0,0,0,0,0,0,0,0,0,0,0,0,0,0,0,0,0,0,0
0,0,0,0,0,0,0,0,0,0,0,0,0,0,0,0,0,0,0,0,0,0,0,0,0,0,0,0,0,0,0,0,0,0,0,0,0,0,0,0,0,0,0,0,0,0,0,0,0,0,0,0,0,0,0,0,0,0,0,0,0,0,0
:endlayer
layer: 22
0,0,0,0,0,0,0,0,0,0,0,0,0,0,0,0,0,0,0,0,0,0,0,0,0,0,0,0,0,0,0,0,0,0,0,0,0,0,0,0,0,0,0,0,0,0,0,0,0,0,0,0,0,0,0,0,0,0,0,0,0,0,0
0,0,0,0,0,0,0,0,0,0,0,0,0,0,0,0,0,0,0,0,0,534,0,0,0,0,0,0,0,0,0,534,0,0,0,0,0,0,0,0,0,534,0,0,0,0,0,0,0,0,0,0,0,0,0,0,0,0,0,0,0,0,0
0,0,0,0,0,0,0,0,0,0,0,0,0,0,0,0,0,0,0,0,0,535,0,0,0,0,0,0,0,0,0,535,0,0,0,0,0,0,0,0,0,535,0,0,0,0,0,0,0,0,68,0,0,0,0,0,0,0,0,0,0,0,0
0,0,0,0,0,0,0,0,0,0,0,535,0,0,0,0,0,0,0,0,0,535,0,0,0,0,0,0,0,0,0,535,0,0,0,0,0,0,0,0,0,535,0,0,0,0,0,22,22,22,282,0,0,0,0,0,0,0,0,0,0,0,0
0,0,0,0,0,0,0,0,0,0,0,0,535,0,0,0,0,0,0,0,0,0,535,0,0,0,0,0,0,0,0,0,535,0,0,0,0,0,0,0,0,0,535,0,0,0,0,0,0,0,282,0,0,0,0,0,0,0,0,0,0,0,0
0,0,0,0,0,0,0,0,0,0,0,0,535,0,0,0,0,0,0,0,0,0,534,0,0,0,0,0,0,0,0,0,534,0,0,0,0,0,0,0,0,0,534,0,0,0,0,0,0,0,282,0,0,0,0,0,0,0,0,0,0,0,0
0,0,0,0,0,0,0,0,0,0,0,0,535,0,0,0,0,0,0,0,0,0,534,0,0,0,0,0,221,221,221,0,534,0,0,0,0,0,0,0,0,0,534,0,0,0,0,0,0,0,282,0,0,0,0,0,0,0,0,0,0,0,0
0,0,534,535,534,535,534,535,0,0,0,0,534,0,0,0,0,0,0,0,0,0,535,0,0,0,0,221,73,0,529,221,535,0,0,0,0,0,0,0,0,0,535,0,0,0,0,0,0,0,282,0,0,0,0,0,0,0,0,0,0,0,0
0,535,0,0,0,0,0,0,535,0,0,0,0,534,0,0,0,0,0,0,0,0,22,535,0,0,0,73,0,0,0,529,22,535,0,0,0,0,0,0,0,0,22,535,0,0,0,0,0,0,282,0,0,0,0,0,0,0,0,0,0,0,0
0,0,0,0,0,0,0,0,0,28,0,0,0,535,0,0,0,0,411,28,0,0,0,534,0,0,0,73,411,28,0,529,0,534,0,0,0,0,411,28,0,0,0,534,0,0,0,0,411,28,282,113,0,0,0,0,0,0,0,0,0,0,0
0,0,0,0,0,0,0,0,0,107,0,0,0,534,0,0,0,0,0,0,0,0,22,535,0,0,0,73,0,0,0,529,22,535,0,0,0,0,0,0,0,0,22,535,0,0,0,0,0,0,282,0,0,0,0,0,0,0,0,0,0,0,0
0,0,0,0,0,0,0,0,0,0,0,0,534,0,0,0,0,0,0,0,0,0,535,0,0,0,0,536,73,0,529,536,535,0,0,0,0,0,0,0,0,0,535,0,0,0,0,0,0,0,282,0,0,0,0,0,0,0,0,0,0,0,0
0,0,0,0,0,0,0,0,0,0,0,0,535,0,0,0,0,0,0,0,0,0,534,0,0,0,0,0,536,536,536,0,534,0,0,0,0,0,0,0,0,0,534,0,0,0,0,0,0,0,282,0,0,0,0,0,0,0,0,0,0,0,0
0,0,0,0,0,0,0,0,0,0,0,0,535,0,0,0,0,0,0,0,0,0,534,0,0,0,0,0,0,0,0,0,534,0,0,0,0,0,0,0,0,0,534,0,0,0,0,0,0,0,282,0,0,0,0,0,0,0,0,0,0,0,0
0,0,0,0,0,0,0,0,0,0,0,0,535,0,0,0,0,0,0,0,0,0,535,0,0,0,0,0,0,0,0,0,535,0,0,0,0,0,0,0,0,0,535,0,0,0,0,0,0,0,282,0,0,0,0,0,0,0,0,0,0,0,0
0,0,0,0,0,0,0,0,0,0,0,535,0,0,0,0,0,0,0,0,0,535,0,0,0,0,0,0,0,0,0,535,0,0,0,0,0,0,0,0,0,535,0,0,0,0,0,22,22,22,282,0,0,0,0,0,0,0,0,0,0,0,0
0,0,0,0,0,0,0,0,0,0,0,0,0,0,0,0,0,0,0,0,0,535,0,0,0,0,0,0,0,0,0,535,0,0,0,0,0,0,0,0,0,535,0,0,0,0,0,0,0,0,67,0,0,0,0,0,0,0,0,0,0,0,0
0,0,0,0,0,0,0,0,0,0,0,0,0,0,0,0,0,0,0,0,0,534,0,0,0,0,0,0,0,0,0,534,0,0,0,0,0,0,0,0,0,534,0,0,0,0,0,0,0,0,0,0,0,0,0,0,0,0,0,0,0,0,0
0,0,0,0,0,0,0,0,0,0,0,0,0,0,0,0,0,0,0,0,0,0,0,0,0,0,0,0,0,0,0,0,0,0,0,0,0,0,0,0,0,0,0,0,0,0,0,0,0,0,0,0,0,0,0,0,0,0,0,0,0,0,0
:endlayer
layer: 23
0,0,0,0,0,0,0,0,0,0,0,0,0,0,0,0,0,0,0,0,0,0,0,0,0,0,0,0,0,0,0,0,0,0,0,0,0,0,0,0,0,0,0,0,0,0,0,0,0,0,0,0,0,0,0,0,0,0,0,0,0,0,0
0,0,0,0,0,0,0,0,0,0,0,0,0,0,0,0,0,0,0,0,0,535,0,0,0,0,0,0,0,0,0,535,0,0,0,0,0,0,0,0,0,535,0,0,0,0,0,0,0,0,0,0,0,0,0,0,0,0,0,0,0,0,0
0,0,0,0,0,0,0,0,0,0,0,0,0,0,0,0,0,0,0,0,22,535,0,0,0,0,0,0,0,0,22,535,0,0,0,0,0,0,0,0,22,535,0,0,0,22,22,22,0,0,0,0,0,0,0,0,0,0,0,0,0,0,0
0,0,0,0,0,0,0,0,0,0,0,535,0,0,0,0,0,0,0,0,0,534,0,0,0,0,0,0,0,0,0,534,0,0,0,0,0,0,0,0,0,534,0,0,0,22,22,22,0,0,204,0,0,0,0,0,0,0,0,0,0,0,0
0,0,0,0,0,0,0,0,0,0,0,0,535,0,0,0,0,0,0,0,0,534,0,0,0,0,0,0,0,0,0,534,0,0,0,0,0,0,0,0,0,534,0,0,0,0,0,0,0,0,0,0,0,0,0,0,0,0,0,0,0,0,0
0,0,0,0,0,0,0,0,0,0,0,0,534,0,0,0,0,0,0,0,0,535,0,0,0,0,0,0,0,0,0,535,0,0,0,0,0,0,0,0,0,535,0,0,0,0,0,0,0,0,0,0,0,0,0,0,0,0,0,0,0,0,0
0,0,0,0,0,0,0,0,0,0,0,0,22,534,0,0,0,0,0,0,0,22,535,0,0,0,0,0,0,0,0,22,535,0,0,0,0,0,0,0,0,22,535,0,0,0,0,0,0,0,0,0,0,0,0,0,0,0,0,0,0,0,0
0,0,535,535,534,535,535,0,0,0,0,0,0,535,0,0,0,0,0,0,0,0,535,0,0,0,0,0,0,0,0,0,535,0,0,0,0,0,0,0,0,0,535,0,0,0,0,0,0,0,0,0,0,0,0,0,0,0,0,0,0,0,0
535,535,22,0,0,0,0,535,535,0,0,0,0,535,0,0,0,0,0,0,0,0,535,0,0,0,0,0,0,0,0,0,535,0,0,0,0,0,0,0,0,0,535,0,0,0,0,0,0,0,0,0,0,0,0,0,0,0,0,0,0,0,0
0,0,0,0,0,0,0,0,22,28,0,0,0,534,0,0,0,0,411,28,0,0,534,0,0,0,0,0,411,28,0,0,534,0,0,0,0,0,411,28,0,0,534,0,0,0,0,0,411,28,51,359,0,0,0,0,0,0,0,0,0,0,0
0,0,0,0,0,0,0,0,0,107,0,0,0,535,0,0,0,0,0,0,0,0,535,0,0,0,0,0,0,0,0,0,535,0,0,0,0,0,0,0,0,0,535,0,0,0,0,0,0,0,0,0,0,0,0,0,0,0,0,0,0,0,0
0,0,0,0,0,0,0,0,0,0,0,0,0,535,0,0,0,0,0,0,0,0,535,0,0,0,0,0,0,0,0,0,535,0,0,0,0,0,0,0,0,0,535,0,0,0,0,0,0,0,0,0,0,0,0,0,0,0,0,0,0,0,0
0,0,0,0,0,0,0,0,0,0,0,0,22,534,0,0,0,0,0,0,0,22,535,0,0,0,0,0,0,0,0,22,535,0,0,0,0,0,0,0,0,22,535,0,0,0,0,0,0,0,0,0,0,0,0,0,0,0,0,0,0,0,0
0,0,0,0,0,0,0,0,0,0,0,0,534,0,0,0,0,0,0,0,0,535,0,0,0,0,0,0,0,0,0,535,0,0,0,0,0,0,0,0,0,535,0,0,0,0,0,0,0,0,0,0,0,0,0,0,0,0,0,0,0,0,0
0,0,0,0,0,0,0,0,0,0,0,0,535,0,0,0,0,0,0,0,0,534,0,0,0,0,0,0,0,0,0,534,0,0,0,0,0,0,0,0,0,534,0,0,0,0,0,0,0,0,0,0,0,0,0,0,0,0,0,0,0,0,0
0,0,0,0,0,0,0,0,0,0,0,535,0,0,0,0,0,0,0,0,0,534,0,0,0,0,0,0,0,0,0,534,0,0,0,0,0,0,0,0,0,534,0,0,0,22,22,22,0,0,204,0,0,0,0,0,0,0,0,0,0,0,0
0,0,0,0,0,0,0,0,0,0,0,0,0,0,0,0,0,0,0,0,22,535,0,0,0,0,0,0,0,0,22,535,0,0,0,0,0,0,0,0,22,535,0,0,0,22,22,22,0,0,0,0,0,0,0,0,0,0,0,0,0,0,0
0,0,0,0,0,0,0,0,0,0,0,0,0,0,0,0,0,0,0,0,0,535,0,0,0,0,0,0,0,0,0,535,0,0,0,0,0,0,0,0,0,535,0,0,0,0,0,0,0,0,0,0,0,0,0,0,0,0,0,0,0,0,0
0,0,0,0,0,0,0,0,0,0,0,0,0,0,0,0,0,0,0,0,0,0,0,0,0,0,0,0,0,0,0,0,0,0,0,0,0,0,0,0,0,0,0,0,0,0,0,0,0,0,0,0,0,0,0,0,0,0,0,0,0,0,0
:endlayer
layer: 24
0,0,0,0,0,0,0,0,0,0,0,0,0,0,0,0,0,0,0,0,0,0,0,0,0,0,0,0,0,0,0,0,0,0,0,0,0,0,0,0,0,0,0,0,0,0,0,0,0,0,0,0,0,0,0,0,0,0,0,0,0,0,0
0,0,0,0,0,0,0,0,0,0,0,0,0,0,0,0,0,0,0,0,534,0,0,22,22,22,22,22,0,0,534,0,0,22,22,22,22,22,0,0,534,0,0,22,22,22,0,0,0,0,0,0,0,0,0,0,0,0,0,0,0,0,0
0,0,0,0,0,0,0,0,0,0,0,0,0,0,0,0,0,0,0,0,534,0,0,0,0,0,0,0,0,0,534,0,0,0,0,0,0,0,0,0,534,0,0,22,22,22,0,0,0,0,0,0,0,0,0,0,0,0,0,0,0,0,0
0,0,0,0,0,0,0,0,0,0,0,535,0,0,0,0,0,0,0,0,0,535,0,0,0,0,0,0,0,0,0,535,0,0,0,0,0,0,0,0,0,535,0,0,0,0,0,0,0,0,0,0,0,0,0,0,0,0,0,0,0,0,0
0,0,0,0,0,0,0,0,0,0,0,0,535,0,0,0,0,0,0,0,0,535,0,0,0,0,0,0,0,0,0,535,0,0,0,0,0,0,0,0,0,535,0,0,0,0,0,0,0,0,0,0,0,0,0,0,0,0,0,0,0,0,0
0,0,0,0,0,0,0,0,0,0,0,0,535,0,0,0,0,0,0,0,0,535,0,0,0,0,0,0,0,0,0,535,0,0,0,0,0,0,0,0,0,535,0,0,0,0,0,0,0,0,0,0,0,0,0,0,0,0,0,0,0,0,0
0,0,0,0,0,0,0,0,0,0,0,0,535,0,0,0,0,0,0,0,0,534,0,0,0,0,0,0,0,0,0,534,0,0,0,0,0,0,0,0,0,534,0,0,0,0,0,0,0,0,0,0,0,0,0,0,0,0,0,0,0,0,0
0,535,534,534,535,534,0,0,0,0,0,0,534,0,0,0,0,0,0,0,0,534,0,0,0,0,0,0,0,0,0,534,0,0,0,0,0,0,0,0,0,534,0,0,0,0,0,0,0,0,0,0,0,0,0,0,0,0,0,0,0,0,0
535,0,0,0,0,0,534,535,0,0,0,0,0,534,0,0,0,0,0,0,0,535,0,0,0,0,0,0,0,90,0,535,0,0,0,0,0,0,0,0,0,535,0,0,0,0,0,0,116,68,116,0,0,0,0,0,0,0,0,0,0,0,0
0,0,0,0,0,0,0,22,535,28,0,0,0,535,0,0,0,0,411,28,0,534,0,0,0,0,0,0,411,28,76,534,0,0,0,0,0,0,411,28,0,534,0,0,0,0,0,0,411,28,113,0,0,0,0,0,0,0,0,0,0,0,0
0,0,0,0,0,0,0,0,0,107,0,0,0,534,0,0,0,0,0,0,0,535,0,0,0,0,0,0,0,91,0,535,0,0,0,0,0,0,0,0,0,535,0,0,0,0,0,0,116,67,116,0,0,0,0,0,0,0,0,0,0,0,0
0,0,0,0,0,0,0,0,0,0,0,0,534,0,0,0,0,0,0,0,0,534,0,0,0,0,0,0,0,0,0,534,0,0,0,0,0,0,0,0,0,534,0,0,0,0,0,0,0,0,0,0,0,0,0,0,0,0,0,0,0,0,0
0,0,0,0,0,0,0,0,0,0,0,0,535,0,0,0,0,0,0,0,0,534,0,0,0,0,0,0,0,0,0,534,0,0,0,0,0,0,0,0,0,534,0,0,0,0,0,0,0,0,0,0,0,0,0,0,0,0,0,0,0,0,0
0,0,0,0,0,0,0,0,0,0,0,0,535,0,0,0,0,0,0,0,0,535,0,0,0,0,0,0,0,0,0,535,0,0,0,0,0,0,0,0,0,535,0,0,0,0,0,0,0,0,0,0,0,0,0,0,0,0,0,0,0,0,0
0,0,0,0,0,0,0,0,0,0,0,0,535,0,0,0,0,0,0,0,0,535,0,0,0,0,0,0,0,0,0,535,0,0,0,0,0,0,0,0,0,535,0,0,0,0,0,0,0,0,0,0,0,0,0,0,0,0,0,0,0,0,0
0,0,0,0,0,0,0,0,0,0,0,535,0,0,0,0,0,0,0,0,0,535,0,0,0,0,0,0,0,0,0,535,0,0,0,0,0,0,0,0,0,535,0,0,0,0,0,0,0,0,0,0,0,0,0,0,0,0,0,0,0,0,0
0,0,0,0,0,0,0,0,0,0,0,0,0,0,0,0,0,0,0,0,534,0,0,0,0,0,0,0,0,0,534,0,0,0,0,0,0,0,0,0,534,0,0,22,22,22,0,0,0,0,0,0,0,0,0,0,0,0,0,0,0,0,0
0,0,0,0,0,0,0,0,0,0,0,0,0,0,0,0,0,0,0,0,534,0,0,22,22,22,22,22,0,0,534,0,0,22,22,22,22,22,0,0,534,0,0,22,22,22,0,0,0,0,0,0,0,0,0,0,0,0,0,0,0,0,0
0,0,0,0,0,0,0,0,0,0,0,0,0,0,0,0,0,0,0,0,0,0,0,0,0,0,0,0,0,0,0,0,0,0,0,0,0,0,0,0,0,0,0,0,0,0,0,0,0,0,0,0,0,0,0,0,0,0,0,0,0,0,0
:endlayer
layer: 25
0,0,0,0,0,0,0,0,0,0,0,0,0,0,0,0,0,0,0,0,68,0,0,0,0,0,0,0,0,0,68,0,0,0,0,0,0,0,0,0,68,0,0,0,0,0,0,0,0,0,0,0,0,0,0,0,0,0,0,0,0,0,0
0,0,0,0,0,0,0,0,0,0,0,0,0,0,0,0,22,22,22,22,282,22,22,22,0,0,0,22,22,22,282,22,22,22,0,0,0,22,22,22,282,22,22,22,0,0,0,0,0,0,0,0,0,0,0,0,0,0,0,0,0,0,0
0,0,0,0,0,0,0,0,0,0,0,0,0,0,0,0,22,0,0,0,282,0,0,0,0,0,0,0,0,0,282,0,0,0,0,0,0,0,0,0,282,0,0,0,0,0,0,0,0,0,0,0,0,0,0,0,0,0,0,0,0,0,0
0,0,0,0,0,0,0,0,0,0,22,535,0,0,0,0,0,0,0,0,282,0,0,0,0,0,0,0,0,0,282,0,0,0,0,0,0,0,0,0,282,0,0,0,0,0,0,0,0,0,0,0,0,0,0,0,0,0,0,0,0,0,0
0,0,0,0,0,0,0,0,0,0,0,535,0,0,0,0,0,0,0,0,282,0,0,0,0,0,0,0,0,0,282,0,0,0,0,0,0,0,0,0,282,0,0,0,0,0,0,0,0,0,0,0,0,0,0,0,0,0,0,0,0,0,0
0,0,0,0,0,0,0,0,0,0,0,534,0,0,0,0,0,0,0,0,282,0,0,0,0,0,0,0,0,0,282,0,0,0,0,0,0,0,0,0,282,0,0,0,0,0,0,0,0,0,0,0,0,0,0,0,0,0,0,0,0,0,0
0,0,0,0,0,0,0,0,0,0,0,22,534,0,0,0,0,0,0,0,282,0,0,0,0,0,0,0,0,0,282,0,0,0,0,0,0,0,0,0,282,0,0,0,0,0,0,0,0,0,0,0,0,0,0,0,0,0,0,0,0,0,0
0,535,535,535,534,0,0,0,0,0,0,0,535,0,0,0,0,0,0,0,282,0,0,0,0,0,0,0,0,0,282,0,0,0,0,0,0,0,0,0,282,0,0,0,0,0,0,0,221,221,221,0,0,0,0,0,0,0,0,0,0,0,0
535,0,0,0,0,535,535,0,0,0,0,0,535,0,0,0,0,0,0,0,282,0,0,0,0,0,0,0,0,0,282,0,0,0,0,0,0,0,0,0,282,0,0,0,0,0,0,529,537,537,537,73,0,0,0,0,0,0,0,0,0,0,0
0,0,0,0,0,0,22,535,284,28,0,0,534,0,0,0,0,0,411,28,282,113,0,0,0,0,0,0,411,28,282,113,0,0,0,0,0,0,411,28,282,113,0,0,0,0,0,529,411,28,537,73,0,0,0,0,0,0,0,0,0,0,0
0,0,0,0,0,0,0,0,0,107,0,0,535,0,0,0,0,0,0,0,282,0,0,0,0,0,0,0,0,0,282,0,0,0,0,0,0,0,0,0,282,0,0,0,0,0,0,529,537,537,537,73,0,0,0,0,0,0,0,0,0,0,0
0,0,0,0,0,0,0,0,0,0,0,0,535,0,0,0,0,0,0,0,282,0,0,0,0,0,0,0,0,0,282,0,0,0,0,0,0,0,0,0,282,0,0,0,0,0,0,0,536,536,536,0,0,0,0,0,0,0,0,0,0,0,0
0,0,0,0,0,0,0,0,0,0,0,22,534,0,0,0,0,0,0,0,282,0,0,0,0,0,0,0,0,0,282,0,0,0,0,0,0,0,0,0,282,0,0,0,0,0,0,0,0,0,0,0,0,0,0,0,0,0,0,0,0,0,0
0,0,0,0,0,0,0,0,0,0,0,534,0,0,0,0,0,0,0,0,282,0,0,0,0,0,0,0,0,0,282,0,0,0,0,0,0,0,0,0,282,0,0,0,0,0,0,0,0,0,0,0,0,0,0,0,0,0,0,0,0,0,0
0,0,0,0,0,0,0,0,0,0,0,535,0,0,0,0,0,0,0,0,282,0,0,0,0,0,0,0,0,0,282,0,0,0,0,0,0,0,0,0,282,0,0,0,0,0,0,0,0,0,0,0,0,0,0,0,0,0,0,0,0,0,0
0,0,0,0,0,0,0,0,0,0,22,535,0,0,0,0,0,0,0,0,282,0,0,0,0,0,0,0,0,0,282,0,0,0,0,0,0,0,0,0,282,0,0,0,0,0,0,0,0,0,0,0,0,0,0,0,0,0,0,0,0,0,0
0,0,0,0,0,0,0,0,0,0,0,0,0,0,0,0,22,0,0,0,282,0,0,0,0,0,0,0,0,0,282,0,0,0,0,0,0,0,0,0,282,0,0,0,0,0,0,0,0,0,0,0,0,0,0,0,0,0,0,0,0,0,0
0,0,0,0,0,0,0,0,0,0,0,0,0,0,0,0,22,22,22,22,282,22,22,22,0,0,0,22,22,22,282,22,22,22,0,0,0,22,22,22,282,22,22,22,0,0,0,0,0,0,0,0,0,0,0,0,0,0,0,0,0,0,0
0,0,0,0,0,0,0,0,0,0,0,0,0,0,0,0,0,0,0,0,67,0,0,0,0,0,0,0,0,0,67,0,0,0,0,0,0,0,0,0,67,0,0,0,0,0,0,0,0,0,0,0,0,0,0,0,0,0,0,0,0,0,0
:endlayer
layer: 26
0,0,0,0,0,0,0,0,0,0,0,0,0,0,0,0,0,0,0,0,0,0,0,0,0,0,0,0,0,0,0,0,0,0,0,0,0,0,0,0,0,0,0,0,0,0,0,0,0,0,0,0,0,0,0,0,0,0,0,0,0,0,0
0,0,0,0,0,0,0,0,0,0,0,0,0,0,0,0,0,0,0,0,204,0,0,0,0,0,0,0,0,0,534,0,0,0,0,0,0,0,0,0,204,0,0,0,0,0,0,0,0,0,0,0,0,0,0,0,0,0,0,0,0,0,0
0,0,0,0,0,0,0,0,0,0,0,0,0,22,22,22,22,0,0,0,0,0,0,0,0,0,0,0,0,0,534,0,0,0,0,0,0,0,0,0,0,0,0,0,0,0,0,0,0,0,0,0,0,0,0,0,0,0,0,0,0,0,0
0,0,0,0,0,0,0,0,0,0,534,0,0,22,0,0,0,0,0,0,534,0,0,0,0,0,0,0,0,0,0,535,0,0,0,0,0,0,0,0,534,0,0,0,0,0,0,0,0,0,0,0,0,0,0,0,0,0,0,0,0,0,0
0,0,0,0,0,0,0,0,0,0,0,534,0,0,0,0,0,0,0,0,0,534,0,0,0,0,0,0,0,0,0,535,0,0,0,0,0,0,0,0,0,534,0,0,0,0,0,0,0,0,0,0,0,0,0,0,0,0,0,0,0,0,0
0,0,0,0,0,0,0,0,0,0,0,535,0,0,0,0,0,0,0,0,0,535,0,0,0,0,0,0,0,0,0,535,0,0,0,0,0,0,0,0,0,535,0,0,0,0,0,0,0,0,0,0,0,0,0,0,0,0,0,0,0,0,0
0,0,0,0,0,0,0,0,0,0,0,535,0,0,0,0,0,0,0,0,0,535,0,0,0,0,0,0,0,0,0,534,0,0,0,0,0,0,0,0,0,535,0,0,0,0,0,0,0,0,0,0,0,0,0,0,0,0,0,0,0,0,0
0,0,534,535,0,0,0,0,0,0,0,535,0,0,0,0,0,0,0,0,0,535,0,0,0,0,0,0,0,0,0,534,0,0,0,0,0,0,0,0,0,535,0,0,0,0,0,0,0,0,0,0,0,0,0,0,0,0,0,0,0,0,0
535,535,0,22,534,535,0,0,0,0,0,535,0,0,0,0,0,0,0,0,0,535,0,0,0,0,0,0,0,0,0,535,0,0,0,0,0,0,0,0,0,535,0,0,0,0,0,0,0,539,541,0,0,0,0,0,0,0,0,0,0,0,0
0,0,0,0,0,22,534,284,51,28,0,534,0,0,0,0,0,0,411,28,0,534,0,0,0,0,0,0,411,28,0,534,0,0,0,0,0,0,411,28,0,534,0,0,0,0,0,0,411,28,540,0,0,0,0,0,0,0,0,0,0,0,0
0,0,0,0,0,0,0,0,0,107,0,535,0,0,0,0,0,0,0,0,0,535,0,0,0,0,0,0,0,0,0,535,0,0,0,0,0,0,0,0,0,535,0,0,0,0,0,0,0,538,0,0,0,0,0,0,0,0,0,0,0,0,0
0,0,0,0,0,0,0,0,0,0,0,535,0,0,0,0,0,0,0,0,0,535,0,0,0,0,0,0,0,0,0,534,0,0,0,0,0,0,0,0,0,535,0,0,0,0,0,0,0,0,0,0,0,0,0,0,0,0,0,0,0,0,0
0,0,0,0,0,0,0,0,0,0,0,535,0,0,0,0,0,0,0,0,0,535,0,0,0,0,0,0,0,0,0,534,0,0,0,0,0,0,0,0,0,535,0,0,0,0,0,0,0,0,0,0,0,0,0,0,0,0,0,0,0,0,0
0,0,0,0,0,0,0,0,0,0,0,535,0,0,0,0,0,0,0,0,0,535,0,0,0,0,0,0,0,0,0,535,0,0,0,0,0,0,0,0,0,535,0,0,0,0,0,0,0,0,0,0,0,0,0,0,0,0,0,0,0,0,0
0,0,0,0,0,0,0,0,0,0,0,534,0,0,0,0,0,0,0,0,0,534,0,0,0,0,0,0,0,0,0,535,0,0,0,0,0,0,0,0,0,534,0,0,0,0,0,0,0,0,0,0,0,0,0,0,0,0,0,0,0,0,0
0,0,0,0,0,0,0,0,0,0,534,0,0,22,0,0,0,0,0,0,534,0,0,0,0,0,0,0,0,0,0,535,0,0,0,0,0,0,0,0,534,0,0,0,0,0,0,0,0,0,0,0,0,0,0,0,0,0,0,0,0,0,0
0,0,0,0,0,0,0,0,0,0,0,0,0,22,22,22,22,0,0,0,0,0,0,0,0,0,0,0,0,0,534,0,0,0,0,0,0,0,0,0,0,0,0,0,0,0,0,0,0,0,0,0,0,0,0,0,0,0,0,0,0,0,0
0,0,0,0,0,0,0,0,0,0,0,0,0,0,0,0,0,0,0,0,204,0,0,0,0,0,0,0,0,0,534,0,0,0,0,0,0,0,0,0,204,0,0,0,0,0,0,0,0,0,0,0,0,0,0,0,0,0,0,0,0,0,0
0,0,0,0,0,0,0,0,0,0,0,0,0,0,0,0,0,0,0,0,0,0,0,0,0,0,0,0,0,0,0,0,0,0,0,0,0,0,0,0,0,0,0,0,0,0,0,0,0,0,0,0,0,0,0,0,0,0,0,0,0,0,0
:endlayer
layer: 27
0,0,0,0,0,0,0,0,0,0,0,0,0,0,0,0,0,0,0,0,0,0,0,0,0,0,0,0,0,0,0,0,0,0,0,0,0,0,0,0,0,0,0,0,0,0,0,0,0,0,0,0,0,0,0,0,0,0,0,0,0,0,0
0,0,0,0,0,0,0,0,0,0,0,0,0,0,0,0,0,0,0,0,0,0,0,0,0,0,0,0,0,0,0,535,0,0,0,0,0,0,0,0,0,0,0,0,0,0,0,0,0,0,0,0,0,0,0,0,0,0,0,0,0,0,0
0,0,0,0,0,0,0,0,0,0,68,0,0,0,0,0,0,0,0,0,0,0,0,0,0,0,0,0,0,0,22,535,0,0,0,0,0,0,0,0,0,0,0,0,0,0,0,0,0,0,0,0,0,0,0,0,0,0,0,0,0,0,0
0,0,0,0,0,0,0,22,22,22,282,22,22,22,0,0,0,0,0,0,22,535,0,0,0,0,0,0,0,0,0,534,0,0,0,0,0,0,0,0,22,535,0,0,0,0,0,0,0,0,0,0,0,0,0,0,0,0,0,0,0,0,0
0,0,0,0,0,0,0,0,0,0,282,0,0,0,0,0,0,0,0,0,0,535,0,0,0,0,0,0,0,0,0,534,0,0,0,0,0,0,0,0,0,535,0,0,0,0,0,0,0,0,0,0,0,0,0,0,0,0,0,0,0,0,0
0,0,0,0,0,0,0,0,0,0,282,0,0,0,0,0,0,0,0,0,0,534,0,0,0,0,0,0,0,0,0,535,0,0,0,0,0,0,0,0,0,534,0,0,0,0,0,0,0,0,0,0,0,0,0,0,0,0,0,0,0,0,0
0,0,0,0,0,0,0,0,0,0,282,0,0,0,0,0,0,0,0,0,0,22,534,0,0,0,0,0,0,0,0,22,535,0,0,0,0,0,0,0,0,22,534,0,0,0,0,0,0,0,0,0,0,0,0,0,0,0,0,0,0,0,0
0,0,535,0,0,0,0,0,0,0,282,0,0,0,0,0,0,0,0,0,0,0,535,0,0,0,0,0,0,0,0,0,535,0,0,0,0,0,0,0,0,0,535,0,0,0,0,0,0,0,0,0,0,0,0,0,0,0,0,0,0,0,0
0,535,0,535,535,0,0,0,0,0,282,0,0,0,0,0,0,0,0,0,0,0,535,0,0,0,0,0,0,0,0,0,535,0,0,0,0,0,0,0,0,0,535,0,0,0,0,0,0,90,0,0,0,0,0,0,0,0,0,0,0,0,0
0,0,0,0,22,535,284,51,0,28,282,113,0,0,0,0,0,0,411,28,76,0,534,0,0,0,0,0,411,28,76,0,534,0,0,0,0,0,411,28,76,0,534,0,0,0,0,0,411,28,76,0,0,0,0,0,0,0,0,0,0,0,0
0,0,0,0,0,0,0,0,0,107,282,0,0,0,0,0,0,0,0,0,0,0,535,0,0,0,0,0,0,0,0,0,535,0,0,0,0,0,0,0,0,0,535,0,0,0,0,0,0,91,0,0,0,0,0,0,0,0,0,0,0,0,0
0,0,0,0,0,0,0,0,0,0,282,0,0,0,0,0,0,0,0,0,0,0,535,0,0,0,0,0,0,0,0,0,535,0,0,0,0,0,0,0,0,0,535,0,0,0,0,0,0,0,0,0,0,0,0,0,0,0,0,0,0,0,0
0,0,0,0,0,0,0,0,0,0,282,0,0,0,0,0,0,0,0,0,0,22,534,0,0,0,0,0,0,0,0,22,535,0,0,0,0,0,0,0,0,22,534,0,0,0,0,0,0,0,0,0,0,0,0,0,0,0,0,0,0,0,0
0,0,0,0,0,0,0,0,0,0,282,0,0,0,0,0,0,0,0,0,0,534,0,0,0,0,0,0,0,0,0,535,0,0,0,0,0,0,0,0,0,534,0,0,0,0,0,0,0,0,0,0,0,0,0,0,0,0,0,0,0,0,0
0,0,0,0,0,0,0,0,0,0,282,0,0,0,0,0,0,0,0,0,0,535,0,0,0,0,0,0,0,0,0,534,0,0,0,0,0,0,0,0,0,535,0,0,0,0,0,0,0,0,0,0,0,0,0,0,0,0,0,0,0,0,0
0,0,0,0,0,0,0,22,22,22,282,22,22,22,0,0,0,0,0,0,22,535,0,0,0,0,0,0,0,0,0,534,0,0,0,0,0,0,0,0,22,535,0,0,0,0,0,0,0,0,0,0,0,0,0,0,0,0,0,0,0,0,0
0,0,0,0,0,0,0,0,0,0,67,0,0,0,0,0,0,0,0,0,0,0,0,0,0,0,0,0,0,0,22,535,0,0,0,0,0,0,0,0,0,0,0,0,0,0,0,0,0,0,0,0,0,0,0,0,0,0,0,0,0,0,0
0,0,0,0,0,0,0,0,0,0,0,0,0,0,0,0,0,0,0,0,0,0,0,0,0,0,0,0,0,0,0,535,0,0,0,0,0,0,0,0,0,0,0,0,0,0,0,0,0,0,0,0,0,0,0,0,0,0,0,0,0,0,0
0,0,0,0,0,0,0,0,0,0,0,0,0,0,0,0,0,0,0,0,0,0,0,0,0,0,0,0,0,0,0,0,0,0,0,0,0,0,0,0,0,0,0,0,0,0,0,0,0,0,0,0,0,0,0,0,0,0,0,0,0,0,0
:endlayer
layer: 28
0,0,0,0,0,0,0,0,0,0,0,0,0,0,0,0,0,0,0,0,0,0,0,0,0,0,0,0,0,0,0,0,0,0,0,0,0,0,0,0,0,0,0,0,0,0,0,0,0,0,0,0,0,0,0,0,0,0,0,0,0,0,0
0,0,0,0,0,0,0,0,0,0,0,0,0,0,0,0,0,0,0,0,0,0,0,0,0,0,0,0,0,0,0,534,0,0,0,0,0,0,0,0,0,0,0,0,0,0,0,0,0,0,0,0,0,0,0,0,0,0,0,0,0,0,0
0,0,0,0,0,0,0,0,0,0,0,0,0,0,0,0,0,0,0,0,0,0,0,0,0,0,0,0,0,0,0,535,0,0,0,0,0,0,0,0,0,0,0,0,0,0,0,0,0,0,0,0,0,0,0,0,0,0,0,0,0,0,0
0,0,0,0,0,0,0,22,22,0,204,0,0,0,0,0,0,0,0,0,0,535,0,0,0,0,0,0,0,0,0,535,0,0,0,0,0,0,0,0,0,535,0,0,0,0,0,0,0,0,0,0,0,0,0,0,0,0,0,0,0,0,0
0,0,0,0,0,0,22,22,0,0,0,0,0,0,0,0,0,0,0,0,0,0,535,0,0,0,0,0,0,0,0,0,535,0,0,0,0,0,0,0,0,0,535,0,0,0,0,0,0,0,0,0,0,0,0,0,0,0,0,0,0,0,0
0,0,0,0,0,22,22,0,0,0,0,0,0,0,0,0,0,0,0,0,0,0,535,0,0,0,0,0,0,0,0,0,534,0,0,0,0,0,0,0,0,0,535,0,0,0,0,0,0,0,0,0,0,0,0,0,0,0,0,0,0,0,0
0,0,0,0,0,0,0,0,0,0,0,0,0,0,0,0,0,0,0,0,0,0,535,0,0,0,0,0,0,0,0,0,534,0,0,0,0,0,0,0,0,0,535,0,0,0,0,0,0,0,0,0,0,0,0,0,0,0,0,0,0,0,0
0,0,0,0,0,0,0,0,0,0,0,0,0,0,0,0,0,0,0,0,0,0,534,0,0,0,0,0,0,0,0,0,535,0,0,0,0,0,0,0,0,0,534,0,0,0,0,0,0,0,0,0,0,0,0,0,0,0,0,0,0,0,0
0,535,535,535,0,0,0,0,0,0,0,0,0,0,0,0,0,0,0,0,0,0,0,534,0,0,0,0,0,0,0,0,22,535,0,0,0,0,0,0,0,0,0,534,0,0,0,0,0,0,0,0,0,0,0,0,0,0,0,0,0,0,0
0,0,0,22,535,284,51,0,0,28,51,359,0,0,0,0,0,0,411,28,0,0,0,535,0,0,0,0,411,28,0,0,0,534,0,0,0,0,411,28,0,0,0,535,0,0,0,0,0,181,0,0,0,0,0,0,0,0,0,0,0,0,0
0,0,0,0,0,0,0,0,0,107,0,0,0,0,0,0,0,0,0,0,0,0,0,534,0,0,0,0,0,0,0,0,22,535,0,0,0,0,0,0,0,0,0,534,0,0,0,0,0,0,0,0,0,0,0,0,0,0,0,0,0,0,0
0,0,0,0,0,0,0,0,0,0,0,0,0,0,0,0,0,0,0,0,0,0,534,0,0,0,0,0,0,0,0,0,535,0,0,0,0,0,0,0,0,0,534,0,0,0,0,0,0,0,0,0,0,0,0,0,0,0,0,0,0,0,0
0,0,0,0,0,0,0,0,0,0,0,0,0,0,0,0,0,0,0,0,0,0,535,0,0,0,0,0,0,0,0,0,534,0,0,0,0,0,0,0,0,0,535,0,0,0,0,0,0,0,0,0,0,0,0,0,0,0,0,0,0,0,0
0,0,0,0,0,22,22,0,0,0,0,0,0,0,0,0,0,0,0,0,0,0,535,0,0,0,0,0,0,0,0,0,534,0,0,0,0,0,0,0,0,0,535,0,0,0,0,0,0,0,0,0,0,0,0,0,0,0,0,0,0,0,0
0,0,0,0,0,0,22,22,0,0,0,0,0,0,0,0,0,0,0,0,0,0,535,0,0,0,0,0,0,0,0,0,535,0,0,0,0,0,0,0,0,0,535,0,0,0,0,0,0,0,0,0,0,0,0,0,0,0,0,0,0,0,0
0,0,0,0,0,0,0,22,22,0,204,0,0,0,0,0,0,0,0,0,0,535,0,0,0,0,0,0,0,0,0,535,0,0,0,0,0,0,0,0,0,535,0,0,0,0,0,0,0,0,0,0,0,0,0,0,0,0,0,0,0,0,0
0,0,0,0,0,0,0,0,0,0,0,0,0,0,0,0,0,0,0,0,0,0,0,0,0,0,0,0,0,0,0,535,0,0,0,0,0,0,0,0,0,0,0,0,0,0,0,0,0,0,0,0,0,0,0,0,0,0,0,0,0,0,0
0,0,0,0,0,0,0,0,0,0,0,0,0,0,0,0,0,0,0,0,0,0,0,0,0,0,0,0,0,0,0,534,0,0,0,0,0,0,0,0,0,0,0,0,0,0,0,0,0,0,0,0,0,0,0,0,0,0,0,0,0,0,0
0,0,0,0,0,0,0,0,0,0,0,0,0,0,0,0,0,0,0,0,0,0,0,0,0,0,0,0,0,0,0,0,0,0,0,0,0,0,0,0,0,0,0,0,0,0,0,0,0,0,0,0,0,0,0,0,0,0,0,0,0,0,0
:endlayer
layer: 29
0,0,0,0,0,0,0,0,0,0,0,0,0,0,0,0,0,0,0,0,0,0,0,0,0,0,0,0,0,0,0,0,0,0,0,0,0,0,0,0,0,0,0,0,0,0,0,0,0,0,0,0,0,0,0,0,0,0,0,0,0,0,0
0,0,0,0,0,0,0,0,0,0,0,0,0,0,0,0,0,0,0,0,0,0,0,0,0,0,0,0,0,0,0,535,0,0,0,0,0,0,0,0,0,0,0,0,0,0,0,0,0,0,0,0,0,0,0,0,0,0,0,0,0,0,0
0,0,0,0,0,0,0,0,0,0,0,0,0,0,0,0,0,0,0,0,0,0,0,0,0,0,0,0,0,0,0,0,535,0,0,0,0,0,0,0,0,0,0,0,0,0,0,0,0,0,0,0,0,0,0,0,0,0,0,0,0,0,0
0,0,0,0,0,0,0,0,0,0,0,0,0,0,0,0,0,0,0,0,0,535,0,0,0,0,0,0,0,0,0,0,535,0,0,0,0,0,0,0,0,535,0,0,0,0,0,0,0,0,0,0,0,0,0,0,0,0,0,0,0,0,0
0,0,0,0,0,0,0,0,0,0,0,0,0,0,0,0,0,0,0,0,0,0,535,0,0,0,0,0,0,0,0,0,535,0,0,0,0,0,0,0,0,0,535,0,0,0,0,0,0,0,0,0,0,0,0,0,0,0,0,0,0,0,0
0,0,0,0,0,22,22,0,0,0,0,0,0,0,0,0,0,0,0,0,0,0,534,0,0,0,0,0,0,0,0,0,535,0,0,0,0,0,0,0,0,0,534,0,0,0,0,0,0,0,0,0,0,0,0,0,0,0,0,0,0,0,0
0,0,0,0,22,22,0,0,0,0,0,0,0,0,0,0,0,0,0,0,0,0,22,534,0,0,0,0,0,0,0,0,0,535,0,0,0,0,0,0,0,0,22,534,0,0,0,0,0,0,0,0,0,0,0,0,0,0,0,0,0,0,0
0,0,0,0,0,0,0,0,0,0,0,0,0,0,0,0,0,0,0,0,0,0,0,535,0,0,0,0,0,0,0,0,0,534,0,0,0,0,0,0,0,0,0,535,0,0,0,0,0,0,0,0,0,0,0,0,0,0,0,0,0,0,0
0,0,535,0,0,0,0,0,116,68,116,0,0,0,0,0,0,0,0,0,0,0,0,535,0,0,0,0,0,0,0,0,0,534,0,0,0,0,0,0,0,0,0,535,0,0,0,0,0,0,0,0,0,0,0,0,0,0,0,0,0,0,0
0,0,22,535,284,51,0,0,115,28,113,0,0,0,0,0,0,0,411,28,0,0,0,534,0,0,0,0,411,28,0,0,0,535,0,0,0,0,411,28,0,0,0,534,0,535,535,535,535,181,0,0,0,0,0,0,0,0,0,0,0,0,0
0,0,0,0,0,0,0,0,116,107,116,0,0,0,0,0,0,0,0,0,0,0,0,535,0,0,0,0,0,0,0,0,0,534,0,0,0,0,0,0,0,0,0,535,0,0,0,0,0,0,0,0,0,0,0,0,0,0,0,0,0,0,0
0,0,0,0,0,0,0,0,0,0,0,0,0,0,0,0,0,0,0,0,0,0,0,535,0,0,0,0,0,0,0,0,0,534,0,0,0,0,0,0,0,0,0,535,0,0,0,0,0,0,0,0,0,0,0,0,0,0,0,0,0,0,0
0,0,0,0,22,22,0,0,0,0,0,0,0,0,0,0,0,0,0,0,0,0,22,534,0,0,0,0,0,0,0,0,0,535,0,0,0,0,0,0,0,0,22,534,0,0,0,0,0,0,0,0,0,0,0,0,0,0,0,0,0,0,0
0,0,0,0,0,22,22,0,0,0,0,0,0,0,0,0,0,0,0,0,0,0,534,0,0,0,0,0,0,0,0,0,535,0,0,0,0,0,0,0,0,0,534,0,0,0,0,0,0,0,0,0,0,0,0,0,0,0,0,0,0,0,0
0,0,0,0,0,0,0,0,0,0,0,0,0,0,0,0,0,0,0,0,0,0,535,0,0,0,0,0,0,0,0,0,535,0,0,0,0,0,0,0,0,0,535,0,0,0,0,0,0,0,0,0,0,0,0,0,0,0,0,0,0,0,0
0,0,0,0,0,0,0,0,0,0,0,0,0,0,0,0,0,0,0,0,0,535,0,0,0,0,0,0,0,0,0,0,535,0,0,0,0,0,0,0,0,535,0,0,0,0,0,0,0,0,0,0,0,0,0,0,0,0,0,0,0,0,0
0,0,0,0,0,0,0,0,0,0,0,0,0,0,0,0,0,0,0,0,0,0,0,0,0,0,0,0,0,0,0,0,535,0,0,0,0,0,0,0,0,0,0,0,0,0,0,0,0,0,0,0,0,0,0,0,0,0,0,0,0,0,0
0,0,0,0,0,0,0,0,0,0,0,0,0,0,0,0,0,0,0,0,0,0,0,0,0,0,0,0,0,0,0,535,0,0,0,0,0,0,0,0,0,0,0,0,0,0,0,0,0,0,0,0,0,0,0,0,0,0,0,0,0,0,0
0,0,0,0,0,0,0,0,0,0,0,0,0,0,0,0,0,0,0,0,0,0,0,0,0,0,0,0,0,0,0,0,0,0,0,0,0,0,0,0,0,0,0,0,0,0,0,0,0,0,0,0,0,0,0,0,0,0,0,0,0,0,0
:endlayer
layer: 30
0,0,0,0,0,0,0,0,0,0,0,0,0,0,0,0,0,0,0,0,0,0,0,0,0,0,0,0,0,0,0,0,0,0,0,0,0,0,0,0,0,0,0,0,0,0,0,0,0,0,0,0,0,0,0,0,0,0,0,0,0,0,0
0,0,0,0,0,0,0,0,0,0,0,0,0,0,0,0,0,0,0,0,0,0,0,0,0,0,0,0,0,0,0,534,0,0,0,0,0,0,0,0,0,0,0,0,0,0,0,0,0,0,0,0,0,0,0,0,0,0,0,0,0,0,0
0,0,0,0,0,0,0,0,0,0,0,0,0,0,0,0,0,0,0,0,0,0,0,0,0,0,0,0,0,0,0,22,534,0,0,0,0,0,0,0,0,0,0,0,0,0,0,0,0,0,0,0,0,0,0,0,0,0,0,0,0,0,0
0,0,0,0,0,0,0,0,0,0,0,0,0,0,0,0,0,0,0,0,0,535,0,0,0,0,0,0,0,0,0,0,534,0,0,0,0,0,0,0,0,535,0,0,0,0,0,0,0,0,0,0,0,0,0,0,0,0,0,0,0,0,0
0,0,0,0,0,0,0,0,0,0,0,0,0,0,0,0,0,0,0,0,0,0,535,0,0,0,0,0,0,0,0,0,22,534,0,0,0,0,0,0,0,0,535,0,0,0,0,0,0,0,0,0,0,0,0,0,0,0,0,0,0,0,0
0,0,0,0,0,0,0,0,0,0,0,0,0,0,0,0,0,0,0,0,0,0,535,0,0,0,0,0,0,0,0,0,0,534,0,0,0,0,0,0,0,0,535,0,0,0,0,0,0,0,0,0,0,0,0,0,0,0,0,0,0,0,0
0,0,0,0,22,0,0,0,0,0,0,0,0,0,0,0,0,0,0,0,0,0,535,0,0,0,0,0,0,0,0,0,0,534,0,0,0,0,0,0,0,0,535,0,0,0,0,0,0,0,0,0,0,0,0,0,0,0,0,0,0,0,0
0,0,0,22,22,0,0,0,221,221,221,0,0,0,0,0,0,0,0,0,0,0,534,0,0,0,0,0,0,0,0,0,0,535,0,0,0,0,0,0,0,0,534,0,0,0,0,0,0,0,0,0,0,0,0,0,0,0,0,0,0,0,0
0,0,0,22,0,0,0,529,537,537,537,73,0,0,0,0,0,0,0,0,0,0,0,534,0,0,0,0,0,0,0,0,0,535,0,0,0,0,0,0,0,0,0,534,0,0,0,0,0,0,0,0,0,0,0,0,0,0,0,0,0,0,0
0,0,535,284,51,0,0,529,537,28,537,73,0,0,0,0,0,0,411,28,0,0,0,535,0,0,0,0,411,28,0,0,0,534,0,0,0,0,411,28,0,0,0,535,0,0,0,535,535,181,0,0,0,0,0,0,0,0,0,0,0,0,0
0,0,0,22,0,0,0,529,537,107,537,73,0,0,0,0,0,0,0,0,0,0,0,534,0,0,0,0,0,0,0,0,0,535,0,0,0,0,0,0,0,0,0,534,0,0,0,0,0,0,0,0,0,0,0,0,0,0,0,0,0,0,0
0,0,0,22,22,0,0,0,536,536,536,0,0,0,0,0,0,0,0,0,0,0,534,0,0,0,0,0,0,0,0,0,0,535,0,0,0,0,0,0,0,0,534,0,0,0,0,0,0,0,0,0,0,0,0,0,0,0,0,0,0,0,0
0,0,0,0,22,0,0,0,0,0,0,0,0,0,0,0,0,0,0,0,0,0,535,0,0,0,0,0,0,0,0,0,0,534,0,0,0,0,0,0,0,0,535,0,0,0,0,0,0,0,0,0,0,0,0,0,0,0,0,0,0,0,0
0,0,0,0,0,0,0,0,0,0,0,0,0,0,0,0,0,0,0,0,0,0,535,0,0,0,0,0,0,0,0,0,0,534,0,0,0,0,0,0,0,0,535,0,0,0,0,0,0,0,0,0,0,0,0,0,0,0,0,0,0,0,0
0,0,0,0,0,0,0,0,0,0,0,0,0,0,0,0,0,0,0,0,0,0,535,0,0,0,0,0,0,0,0,0,22,534,0,0,0,0,0,0,0,0,535,0,0,0,0,0,0,0,0,0,0,0,0,0,0,0,0,0,0,0,0
0,0,0,0,0,0,0,0,0,0,0,0,0,0,0,0,0,0,0,0,0,535,0,0,0,0,0,0,0,0,0,0,534,0,0,0,0,0,0,0,0,535,0,0,0,0,0,0,0,0,0,0,0,0,0,0,0,0,0,0,0,0,0
0,0,0,0,0,0,0,0,0,0,0,0,0,0,0,0,0,0,0,0,0,0,0,0,0,0,0,0,0,0,0,22,534,0,0,0,0,0,0,0,0,0,0,0,0,0,0,0,0,0,0,0,0,0,0,0,0,0,0,0,0,0,0
0,0,0,0,0,0,0,0,0,0,0,0,0,0,0,0,0,0,0,0,0,0,0,0,0,0,0,0,0,0,0,534,0,0,0,0,0,0,0,0,0,0,0,0,0,0,0,0,0,0,0,0,0,0,0,0,0,0,0,0,0,0,0
0,0,0,0,0,0,0,0,0,0,0,0,0,0,0,0,0,0,0,0,0,0,0,0,0,0,0,0,0,0,0,0,0,0,0,0,0,0,0,0,0,0,0,0,0,0,0,0,0,0,0,0,0,0,0,0,0,0,0,0,0,0,0
:endlayer
layer: 31
0,0,0,0,0,0,0,0,0,0,0,0,0,0,0,0,0,0,0,0,0,0,0,0,0,0,0,0,0,0,0,0,0,0,0,0,0,0,0,0,0,0,0,0,0,0,0,0,0,0,0,0,0,0,0,0,0,0,0,0,0,0,0
0,0,0,0,0,0,0,0,0,0,0,0,0,0,0,0,0,0,0,0,0,0,0,0,0,0,0,0,0,0,0,535,0,0,0,0,0,0,0,0,0,0,0,0,0,0,0,0,0,0,0,0,0,0,0,0,0,0,0,0,0,0,0
0,0,0,0,0,0,0,0,0,0,0,0,0,0,0,0,0,0,0,0,0,0,0,0,0,0,0,0,0,0,0,0,535,0,0,0,0,0,0,0,0,0,0,0,0,0,0,0,0,0,0,0,0,0,0,0,0,0,0,0,0,0,0
0,0,0,0,0,0,0,0,0,0,0,0,0,0,0,0,0,0,0,0,22,535,0,0,0,0,0,0,0,0,0,0,535,0,0,0,0,0,0,0,22,535,0,0,0,0,0,0,0,0,0,0,0,0,0,0,0,0,0,0,0,0,0
0,0,0,0,0,0,0,0,0,0,0,0,0,0,0,0,0,0,0,0,0,535,0,0,0,0,0,0,0,0,0,0,535,0,0,0,0,0,0,0,0,535,0,0,0,0,0,0,0,0,0,0,0,0,0,0,0,0,0,0,0,0,0
0,0,0,0,0,0,0,0,0,0,0,0,0,0,0,0,0,0,0,0,0,534,0,0,0,0,0,0,0,0,0,0,535,0,0,0,0,0,0,0,0,534,0,0,0,0,0,0,0,0,0,0,0,0,0,0,0,0,0,0,0,0,0
0,0,0,0,0,0,0,0,0,0,0,0,0,0,0,0,0,0,0,0,0,22,534,0,0,0,0,0,0,0,0,0,0,535,0,0,0,0,0,0,0,22,534,0,0,0,0,0,0,0,0,0,0,0,0,0,0,0,0,0,0,0,0
0,0,0,0,0,0,0,0,0,0,0,0,0,0,0,0,0,0,0,0,0,0,535,0,0,0,0,0,0,0,0,0,0,534,0,0,0,0,0,0,0,0,535,0,0,0,0,0,0,0,0,0,0,0,0,0,0,0,0,0,0,0,0
0,0,22,22,0,0,0,0,0,543,0,0,0,0,0,0,0,0,0,0,0,0,535,0,0,0,0,0,0,0,0,0,0,534,0,0,0,0,0,0,0,0,535,0,0,0,0,0,0,0,0,0,0,0,0,0,0,0,0,0,0,0,0
0,115,284,51,0,0,0,0,542,28,544,0,0,0,0,0,0,0,411,28,0,0,534,0,0,0,0,0,411,28,0,0,0,535,0,0,0,0,411,28,0,0,534,0,0,0,0,0,0,204,0,0,0,0,0,0,0,0,0,0,0,0,0
0,0,22,22,0,0,0,0,0,107,0,0,0,0,0,0,0,0,0,0,0,0,535,0,0,0,0,0,0,0,0,0,0,534,0,0,0,0,0,0,0,0,535,0,0,0,0,0,0,0,0,0,0,0,0,0,0,0,0,0,0,0,0
0,0,0,0,0,0,0,0,0,0,0,0,0,0,0,0,0,0,0,0,0,0,535,0,0,0,0,0,0,0,0,0,0,534,0,0,0,0,0,0,0,0,535,0,0,0,0,0,0,0,0,0,0,0,0,0,0,0,0,0,0,0,0
0,0,0,0,0,0,0,0,0,0,0,0,0,0,0,0,0,0,0,0,0,22,534,0,0,0,0,0,0,0,0,0,0,535,0,0,0,0,0,0,0,22,534,0,0,0,0,0,0,0,0,0,0,0,0,0,0,0,0,0,0,0,0
0,0,0,0,0,0,0,0,0,0,0,0,0,0,0,0,0,0,0,0,0,534,0,0,0,0,0,0,0,0,0,0,535,0,0,0,0,0,0,0,0,534,0,0,0,0,0,0,0,0,0,0,0,0,0,0,0,0,0,0,0,0,0
0,0,0,0,0,0,0,0,0,0,0,0,0,0,0,0,0,0,0,0,0,535,0,0,0,0,0,0,0,0,0,0,535,0,0,0,0,0,0,0,0,535,0,0,0,0,0,0,0,0,0,0,0,0,0,0,0,0,0,0,0,0,0
0,0,0,0,0,0,0,0,0,0,0,0,0,0,0,0,0,0,0,0,22,535,0,0,0,0,0,0,0,0,0,0,535,0,0,0,0,0,0,0,22,535,0,0,0,0,0,0,0,0,0,0,0,0,0,0,0,0,0,0,0,0,0
0,0,0,0,0,0,0,0,0,0,0,0,0,0,0,0,0,0,0,0,0,0,0,0,0,0,0,0,0,0,0,0,535,0,0,0,0,0,0,0,0,0,0,0,0,0,0,0,0,0,0,0,0,0,0,0,0,0,0,0,0,0,0
0,0,0,0,0,0,0,0,0,0,0,0,0,0,0,0,0,0,0,0,0,0,0,0,0,0,0,0,0,0,0,535,0,0,0,0,0,0,0,0,0,0,0,0,0,0,0,0,0,0,0,0,0,0,0,0,0,0,0,0,0,0,0
0,0,0,0,0,0,0,0,0,0,0,0,0,0,0,0,0,0,0,0,0,0,0,0,0,0,0,0,0,0,0,0,0,0,0,0,0,0,0,0,0,0,0,0,0,0,0,0,0,0,0,0,0,0,0,0,0,0,0,0,0,0,0
:endlayer
layer: 32
0,0,0,0,0,0,0,0,0,0,0,0,0,0,0,0,0,0,0,0,0,0,0,0,0,0,0,0,0,0,0,0,0,0,0,0,0,0,0,0,0,0,0,0,0,0,0,0,0,0,0,0,0,0,0,0,0,0,0,0,0,0,0
0,0,0,0,0,0,0,0,0,0,0,0,0,0,0,0,0,0,0,0,0,0,0,0,0,0,0,0,0,0,0,534,0,0,0,0,0,0,0,0,0,0,0,0,0,0,0,0,0,0,0,0,0,0,0,0,0,0,0,0,0,0,0
0,0,0,0,0,0,0,0,0,0,0,0,0,0,0,0,0,0,0,0,0,0,0,0,0,0,0,0,0,0,0,535,0,0,0,0,0,0,0,0,0,0,0,0,0,0,0,0,0,0,0,0,0,0,0,0,0,0,0,0,0,0,0
0,0,0,0,0,0,0,0,0,0,0,0,0,0,0,0,0,0,0,0,534,0,0,0,0,0,0,0,0,0,0,535,0,0,0,0,0,0,0,0,534,0,0,0,0,0,0,0,0,0,0,0,0,0,0,0,0,0,0,0,0,0,0
0,0,0,0,0,0,0,0,0,0,0,0,0,0,0,0,0,0,0,0,0,534,0,0,0,0,0,0,0,0,0,0,535,0,0,0,0,0,0,0,0,534,0,0,0,0,0,0,0,0,0,0,0,0,0,0,0,0,0,0,0,0,0
0,0,0,0,0,0,0,0,0,0,0,0,0,0,0,0,0,0,0,0,0,535,0,0,0,0,0,0,0,0,0,0,534,0,0,0,0,0,0,0,0,535,0,0,0,0,0,0,0,0,0,0,0,0,0,0,0,0,0,0,0,0,0
0,0,0,0,0,0,0,0,0,0,0,0,0,0,0,0,0,0,0,0,0,535,0,0,0,0,0,0,0,0,0,0,534,0,0,0,0,0,0,0,0,535,0,0,0,0,0,0,0,0,0,0,0,0,0,0,0,0,0,0,0,0,0
0,0,0,0,0,0,0,0,0,0,0,0,0,0,0,0,0,0,0,0,0,535,0,0,0,0,0,0,0,0,0,0,535,0,0,0,0,0,0,0,0,535,0,0,0,0,0,0,0,0,0,0,0,0,0,0,0,0,0,0,0,0,0
0,0,0,0,0,0,0,0,0,90,0,0,0,0,0,0,0,0,0,0,0,535,0,0,0,0,0,0,0,0,0,0,22,535,0,0,0,0,0,0,0,535,0,0,0,0,0,0,0,0,0,0,0,0,0,0,0,0,0,0,0,0,0
0,0,204,0,0,0,0,0,85,28,76,0,0,0,0,0,0,0,411,28,0,534,0,0,0,0,0,0,411,28,0,0,0,534,0,0,0,0,411,28,0,534,0,0,0,0,0,0,0,0,0,0,0,0,0,0,0,0,0,0,0,0,0
0,0,0,0,0,0,0,0,0,107,0,0,0,0,0,0,0,0,0,0,0,535,0,0,0,0,0,0,0,0,0,0,22,535,0,0,0,0,0,0,0,535,0,0,0,0,0,0,0,0,0,0,0,0,0,0,0,0,0,0,0,0,0
0,0,0,0,0,0,0,0,0,0,0,0,0,0,0,0,0,0,0,0,0,535,0,0,0,0,0,0,0,0,0,0,535,0,0,0,0,0,0,0,0,535,0,0,0,0,0,0,0,0,0,0,0,0,0,0,0,0,0,0,0,0,0
0,0,0,0,0,0,0,0,0,0,0,0,0,0,0,0,0,0,0,0,0,535,0,0,0,0,0,0,0,0,0,0,534,0,0,0,0,0,0,0,0,535,0,0,0,0,0,0,0,0,0,0,0,0,0,0,0,0,0,0,0,0,0
0,0,0,0,0,0,0,0,0,0,0,0,0,0,0,0,0,0,0,0,0,535,0,0,0,0,0,0,0,0,0,0,534,0,0,0,0,0,0,0,0,535,0,0,0,0,0,0,0,0,0,0,0,0,0,0,0,0,0,0,0,0,0
0,0,0,0,0,0,0,0,0,0,0,0,0,0,0,0,0,0,0,0,0,534,0,0,0,0,0,0,0,0,0,0,535,0,0,0,0,0,0,0,0,534,0,0,0,0,0,0,0,0,0,0,0,0,0,0,0,0,0,0,0,0,0
0,0,0,0,0,0,0,0,0,0,0,0,0,0,0,0,0,0,0,0,534,0,0,0,0,0,0,0,0,0,0,535,0,0,0,0,0,0,0,0,534,0,0,0,0,0,0,0,0,0,0,0,0,0,0,0,0,0,0,0,0,0,0
0,0,0,0,0,0,0,0,0,0,0,0,0,0,0,0,0,0,0,0,0,0,0,0,0,0,0,0,0,0,0,535,0,0,0,0,0,0,0,0,0,0,0,0,0,0,0,0,0,0,0,0,0,0,0,0,0,0,0,0,0,0,0
0,0,0,0,0,0,0,0,0,0,0,0,0,0,0,0,0,0,0,0,0,0,0,0,0,0,0,0,0,0,0,534,0,0,0,0,0,0,0,0,0,0,0,0,0,0,0,0,0,0,0,0,0,0,0,0,0,0,0,0,0,0,0
0,0,0,0,0,0,0,0,0,0,0,0,0,0,0,0,0,0,0,0,0,0,0,0,0,0,0,0,0,0,0,0,0,0,0,0,0,0,0,0,0,0,0,0,0,0,0,0,0,0,0,0,0,0,0,0,0,0,0,0,0,0,0
:endlayer
layer: 33
0,0,0,0,0,0,0,0,0,0,0,0,0,0,0,0,0,0,0,0,0,0,0,0,0,0,0,0,0,0,0,0,0,0,0,0,0,0,0,0,0,0,0,0,0,0,0,0,0,0,0,0,0,0,0,0,0,0,0,0,0,0,0
0,0,0,0,0,0,0,0,0,0,0,0,0,0,0,0,0,0,0,0,0,0,0,0,0,0,0,0,0,0,0,535,0,0,0,0,0,0,0,0,0,0,0,0,0,0,0,0,0,0,0,0,0,0,0,0,0,0,0,0,0,0,0
0,0,0,0,0,0,0,0,0,0,0,0,0,0,0,0,0,0,0,0,68,0,0,22,22,22,0,0,0,0,22,535,0,0,0,22,22,22,0,0,68,0,0,0,0,0,0,0,0,0,0,0,0,0,0,0,0,0,0,0,0,0,0
0,0,0,0,0,0,0,0,0,0,0,0,0,0,0,0,0,0,0,0,282,22,22,22,22,0,0,0,0,0,0,534,0,0,0,0,22,22,22,22,282,0,0,0,0,0,0,0,0,0,0,0,0,0,0,0,0,0,0,0,0,0,0
0,0,0,0,0,0,0,0,0,0,0,0,0,0,0,0,0,0,0,0,282,0,0,0,0,0,0,0,0,0,0,534,0,0,0,0,0,0,0,0,282,0,0,0,0,0,0,0,0,0,0,0,0,0,0,0,0,0,0,0,0,0,0
0,0,0,0,0,0,0,0,0,0,0,0,0,0,0,0,0,0,0,0,282,0,0,0,0,0,0,0,0,0,0,535,0,0,0,0,0,0,0,0,282,0,0,0,0,0,0,0,0,0,0,0,0,0,0,0,0,0,0,0,0,0,0
0,0,0,0,0,0,0,0,0,0,0,0,0,0,0,0,0,0,0,0,282,0,0,0,0,0,0,0,0,0,0,22,535,0,0,0,0,0,0,0,282,0,0,0,0,0,0,0,0,0,0,0,0,0,0,0,0,0,0,0,0,0,0
0,0,0,0,0,0,0,0,0,0,0,0,0,0,0,0,0,0,0,0,282,0,0,0,0,0,0,0,0,0,0,0,535,0,0,0,0,0,0,0,282,0,0,0,0,0,0,0,0,0,0,0,0,0,0,0,0,0,0,0,0,0,0
0,0,0,0,0,0,0,0,0,0,0,0,0,0,0,0,0,0,0,0,282,0,0,0,0,0,0,0,0,0,0,0,535,0,0,0,0,0,0,0,282,0,0,0,0,0,0,0,0,0,0,0,0,0,0,0,0,0,0,0,0,0,0
0,0,0,0,0,0,0,0,0,181,0,0,0,0,0,0,0,0,411,28,282,113,0,0,0,0,0,0,411,28,0,0,534,0,0,0,0,0,411,28,282,113,0,0,0,0,0,0,0,0,0,0,0,0,0,0,0,0,0,0,0,0,0
0,0,0,0,0,0,0,0,0,0,0,0,0,0,0,0,0,0,0,0,282,0,0,0,0,0,0,0,0,0,0,0,535,0,0,0,0,0,0,0,282,0,0,0,0,0,0,0,0,0,0,0,0,0,0,0,0,0,0,0,0,0,0
0,0,0,0,0,0,0,0,0,0,0,0,0,0,0,0,0,0,0,0,282,0,0,0,0,0,0,0,0,0,0,0,535,0,0,0,0,0,0,0,282,0,0,0,0,0,0,0,0,0,0,0,0,0,0,0,0,0,0,0,0,0,0
0,0,0,0,0,0,0,0,0,0,0,0,0,0,0,0,0,0,0,0,282,0,0,0,0,0,0,0,0,0,0,22,535,0,0,0,0,0,0,0,282,0,0,0,0,0,0,0,0,0,0,0,0,0,0,0,0,0,0,0,0,0,0
0,0,0,0,0,0,0,0,0,0,0,0,0,0,0,0,0,0,0,0,282,0,0,0,0,0,0,0,0,0,0,535,0,0,0,0,0,0,0,0,282,0,0,0,0,0,0,0,0,0,0,0,0,0,0,0,0,0,0,0,0,0,0
0,0,0,0,0,0,0,0,0,0,0,0,0,0,0,0,0,0,0,0,282,0,0,0,0,0,0,0,0,0,0,534,0,0,0,0,0,0,0,0,282,0,0,0,0,0,0,0,0,0,0,0,0,0,0,0,0,0,0,0,0,0,0
0,0,0,0,0,0,0,0,0,0,0,0,0,0,0,0,0,0,0,0,282,22,22,22,22,0,0,0,0,0,0,534,0,0,0,22,22,22,22,22,282,0,0,0,0,0,0,0,0,0,0,0,0,0,0,0,0,0,0,0,0,0,0
0,0,0,0,0,0,0,0,0,0,0,0,0,0,0,0,0,0,0,0,67,0,0,22,22,22,0,0,0,0,22,535,0,0,22,22,22,0,0,0,67,0,0,0,0,0,0,0,0,0,0,0,0,0,0,0,0,0,0,0,0,0,0
0,0,0,0,0,0,0,0,0,0,0,0,0,0,0,0,0,0,0,0,0,0,0,0,0,0,0,0,0,0,0,535,0,0,0,0,0,0,0,0,0,0,0,0,0,0,0,0,0,0,0,0,0,0,0,0,0,0,0,0,0,0,0
0,0,0,0,0,0,0,0,0,0,0,0,0,0,0,0,0,0,0,0,0,0,0,0,0,0,0,0,0,0,0,0,0,0,0,0,0,0,0,0,0,0,0,0,0,0,0,0,0,0,0,0,0,0,0,0,0,0,0,0,0,0,0
:endlayer
layer: 34
0,0,0,0,0,0,0,0,0,0,0,0,0,0,0,0,0,0,0,0,0,0,0,0,0,0,0,0,0,0,0,0,0,0,0,0,0,0,0,0,0,0,0,0,0,0,0,0,0,0,0,0,0,0,0,0,0,0,0,0,0,0,0
0,0,0,0,0,0,0,0,0,0,0,0,0,0,0,0,0,0,0,0,0,0,0,0,0,22,22,22,0,0,534,0,0,22,22,22,0,0,0,0,0,0,0,0,0,0,0,0,0,0,0,0,0,0,0,0,0,0,0,0,0,0,0
0,0,0,0,0,0,0,0,0,0,0,0,0,0,0,0,0,0,0,0,0,0,0,0,22,22,22,22,0,0,534,0,0,22,22,22,22,0,0,0,0,0,0,0,0,0,0,0,0,0,0,0,0,0,0,0,0,0,0,0,0,0,0
0,0,0,0,0,0,0,0,0,0,0,0,0,0,0,0,0,0,0,0,204,0,0,0,0,0,0,0,0,0,0,535,0,0,0,0,0,0,0,0,204,0,0,0,0,0,0,0,0,0,0,0,0,0,0,0,0,0,0,0,0,0,0
0,0,0,0,0,0,0,0,0,0,0,0,0,0,0,0,0,0,0,0,0,0,0,0,0,0,0,0,0,0,0,535,0,0,0,0,0,0,0,0,0,0,0,0,0,0,0,0,0,0,0,0,0,0,0,0,0,0,0,0,0,0,0
0,0,0,0,0,0,0,0,0,0,0,0,0,0,0,0,0,0,0,0,0,0,0,0,0,0,0,0,0,0,0,535,0,0,0,0,0,0,0,0,0,0,0,0,0,0,0,0,0,0,0,0,0,0,0,0,0,0,0,0,0,0,0
0,0,0,0,0,0,0,0,0,0,0,0,0,0,0,0,0,0,0,0,0,0,0,0,0,0,0,0,0,0,0,534,0,0,0,0,0,0,0,0,0,0,0,0,0,0,0,0,0,0,0,0,0,0,0,0,0,0,0,0,0,0,0
0,0,0,0,0,0,0,0,0,0,0,0,0,0,0,0,0,0,0,0,0,0,0,0,0,0,0,0,0,0,0,534,0,0,0,0,0,0,0,0,0,0,0,0,0,0,0,0,0,0,0,0,0,0,0,0,0,0,0,0,0,0,0
0,0,0,0,0,0,0,0,0,0,0,0,0,0,0,0,0,0,0,0,0,0,0,0,0,0,0,0,0,0,0,535,0,0,0,0,0,0,0,0,0,0,0,0,0,0,0,0,0,0,0,0,0,0,0,0,0,0,0,0,0,0,0
0,0,0,0,0,535,535,535,535,181,0,0,0,0,0,0,0,0,411,28,51,359,0,0,0,0,0,0,411,28,0,534,0,0,0,0,0,0,411,28,51,359,0,0,0,0,0,0,0,0,0,0,0,0,0,0,0,0,0,0,0,0,0
0,0,0,0,0,0,0,0,0,0,0,0,0,0,0,0,0,0,0,0,0,0,0,0,0,0,0,0,0,0,0,535,0,0,0,0,0,0,0,0,0,0,0,0,0,0,0,0,0,0,0,0,0,0,0,0,0,0,0,0,0,0,0
0,0,0,0,0,0,0,0,0,0,0,0,0,0,0,0,0,0,0,0,0,0,0,0,0,0,0,0,0,0,0,534,0,0,0,0,0,0,0,0,0,0,0,0,0,0,0,0,0,0,0,0,0,0,0,0,0,0,0,0,0,0,0
0,0,0,0,0,0,0,0,0,0,0,0,0,0,0,0,0,0,0,0,0,0,0,0,0,0,0,0,0,0,0,534,0,0,0,0,0,0,0,0,0,0,0,0,0,0,0,0,0,0,0,0,0,0,0,0,0,0,0,0,0,0,0
0,0,0,0,0,0,0,0,0,0,0,0,0,0,0,0,0,0,0,0,0,0,0,0,0,0,0,0,0,0,0,535,0,0,0,0,0,0,0,0,0,0,0,0,0,0,0,0,0,0,0,0,0,0,0,0,0,0,0,0,0,0,0
0,0,0,0,0,0,0,0,0,0,0,0,0,0,0,0,0,0,0,0,0,0,0,0,0,0,0,0,0,0,0,535,0,0,0,0,0,0,0,0,0,0,0,0,0,0,0,0,0,0,0,0,0,0,0,0,0,0,0,0,0,0,0
0,0,0,0,0,0,0,0,0,0,0,0,0,0,0,0,0,0,0,0,204,0,0,0,0,0,0,0,0,0,0,535,0,0,0,0,0,0,0,0,204,0,0,0,0,0,0,0,0,0,0,0,0,0,0,0,0,0,0,0,0,0,0
0,0,0,0,0,0,0,0,0,0,0,0,0,0,0,0,0,0,0,0,0,0,0,0,22,22,22,22,0,0,534,0,0,22,22,22,0,0,0,0,0,0,0,0,0,0,0,0,0,0,0,0,0,0,0,0,0,0,0,0,0,0,0
0,0,0,0,0,0,0,0,0,0,0,0,0,0,0,0,0,0,0,0,0,0,0,0,0,22,22,22,0,0,534,0,0,22,22,22,0,0,0,0,0,0,0,0,0,0,0,0,0,0,0,0,0,0,0,0,0,0,0,0,0,0,0
0,0,0,0,0,0,0,0,0,0,0,0,0,0,0,0,0,0,0,0,0,0,0,0,0,0,0,0,0,0,0,0,0,0,0,0,0,0,0,0,0,0,0,0,0,0,0,0,0,0,0,0,0,0,0,0,0,0,0,0,0,0,0
:endlayer
layer: 35
0,0,0,0,0,0,0,0,0,0,0,0,0,0,0,0,0,0,0,0,0,0,0,0,0,0,0,0,0,0,68,0,0,0,0,0,0,0,0,0,0,0,0,0,0,0,0,0,0,0,0,0,0,0,0,0,0,0,0,0,0,0,0
0,0,0,0,0,0,0,0,0,0,0,0,0,0,0,0,0,0,0,0,0,0,0,0,0,0,0,22,22,22,282,22,22,22,0,0,0,0,0,0,0,0,0,0,0,0,0,0,0,0,0,0,0,0,0,0,0,0,0,0,0,0,0
0,0,0,0,0,0,0,0,0,0,0,0,0,0,0,0,0,0,0,0,0,0,0,0,0,0,0,0,0,0,282,0,0,0,0,0,0,0,0,0,0,0,0,0,0,0,0,0,0,0,0,0,0,0,0,0,0,0,0,0,0,0,0
0,0,0,0,0,0,0,0,0,0,0,0,0,0,0,0,0,0,0,0,0,0,0,0,0,0,0,0,0,0,282,0,0,0,0,0,0,0,0,0,0,0,0,0,0,0,0,0,0,0,0,0,0,0,0,0,0,0,0,0,0,0,0
0,0,0,0,0,0,0,0,0,0,0,0,0,0,0,0,0,0,0,0,0,0,0,0,0,0,0,0,0,0,282,0,0,0,0,0,0,0,0,0,0,0,0,0,0,0,0,0,0,0,0,0,0,0,0,0,0,0,0,0,0,0,0
0,0,0,0,0,0,0,0,0,0,0,0,0,0,0,0,0,0,0,0,0,0,0,0,0,0,0,0,0,0,282,0,0,0,0,0,0,0,0,0,0,0,0,0,0,0,0,0,0,0,0,0,0,0,0,0,0,0,0,0,0,0,0
0,0,0,0,0,0,0,0,0,0,0,0,0,0,0,0,0,0,0,0,0,0,0,0,0,0,0,0,0,0,282,0,0,0,0,0,0,0,0,0,0,0,0,0,0,0,0,0,0,0,0,0,0,0,0,0,0,0,0,0,0,0,0
0,0,0,0,0,0,0,0,0,0,0,0,0,0,0,0,0,0,0,0,0,0,0,0,0,0,0,0,0,0,282,0,0,0,0,0,0,0,0,0,0,0,0,0,0,0,0,0,0,0,0,0,0,0,0,0,0,0,0,0,0,0,0
0,0,0,0,0,0,0,0,0,0,0,0,0,0,0,0,0,0,116,68,116,0,0,0,0,0,0,0,0,0,282,0,0,0,0,0,0,0,116,68,116,0,0,0,0,0,0,0,0,0,0,0,0,0,0,0,0,0,0,0,0,0,0
0,0,0,0,0,0,0,535,535,181,0,0,0,0,0,0,0,0,411,28,113,0,0,0,0,0,0,0,411,28,282,113,0,0,0,0,0,0,411,28,113,0,0,0,0,0,0,0,0,0,0,0,0,0,0,0,0,0,0,0,0,0,0
0,0,0,0,0,0,0,0,0,0,0,0,0,0,0,0,0,0,116,67,116,0,0,0,0,0,0,0,0,0,282,0,0,0,0,0,0,0,116,67,116,0,0,0,0,0,0,0,0,0,0,0,0,0,0,0,0,0,0,0,0,0,0
0,0,0,0,0,0,0,0,0,0,0,0,0,0,0,0,0,0,0,0,0,0,0,0,0,0,0,0,0,0,282,0,0,0,0,0,0,0,0,0,0,0,0,0,0,0,0,0,0,0,0,0,0,0,0,0,0,0,0,0,0,0,0
0,0,0,0,0,0,0,0,0,0,0,0,0,0,0,0,0,0,0,0,0,0,0,0,0,0,0,0,0,0,282,0,0,0,0,0,0,0,0,0,0,0,0,0,0,0,0,0,0,0,0,0,0,0,0,0,0,0,0,0,0,0,0
0,0,0,0,0,0,0,0,0,0,0,0,0,0,0,0,0,0,0,0,0,0,0,0,0,0,0,0,0,0,282,0,0,0,0,0,0,0,0,0,0,0,0,0,0,0,0,0,0,0,0,0,0,0,0,0,0,0,0,0,0,0,0
0,0,0,0,0,0,0,0,0,0,0,0,0,0,0,0,0,0,0,0,0,0,0,0,0,0,0,0,0,0,282,0,0,0,0,0,0,0,0,0,0,0,0,0,0,0,0,0,0,0,0,0,0,0,0,0,0,0,0,0,0,0,0
0,0,0,0,0,0,0,0,0,0,0,0,0,0,0,0,0,0,0,0,0,0,0,0,0,0,0,0,0,0,282,0,0,0,0,0,0,0,0,0,0,0,0,0,0,0,0,0,0,0,0,0,0,0,0,0,0,0,0,0,0,0,0
0,0,0,0,0,0,0,0,0,0,0,0,0,0,0,0,0,0,0,0,0,0,0,0,0,0,0,0,0,0,282,0,0,0,0,0,0,0,0,0,0,0,0,0,0,0,0,0,0,0,0,0,0,0,0,0,0,0,0,0,0,0,0
0,0,0,0,0,0,0,0,0,0,0,0,0,0,0,0,0,0,0,0,0,0,0,0,0,0,0,22,22,22,282,22,22,22,0,0,0,0,0,0,0,0,0,0,0,0,0,0,0,0,0,0,0,0,0,0,0,0,0,0,0,0,0
0,0,0,0,0,0,0,0,0,0,0,0,0,0,0,0,0,0,0,0,0,0,0,0,0,0,0,0,0,0,67,0,0,0,0,0,0,0,0,0,0,0,0,0,0,0,0,0,0,0,0,0,0,0,0,0,0,0,0,0,0,0,0
:endlayer
layer: 36
0,0,0,0,0,0,0,0,0,0,0,0,0,0,0,0,0,0,0,0,0,0,0,0,0,0,0,0,0,0,0,0,0,0,0,0,0,0,0,0,0,0,0,0,0,0,0,0,0,0,0,0,0,0,0,0,0,0,0,0,0,0,0
0,0,0,0,0,0,0,0,0,0,0,0,0,0,0,0,0,0,0,0,0,0,0,0,0,0,0,0,0,0,204,0,0,0,0,0,0,0,0,0,0,0,0,0,0,0,0,0,0,0,0,0,0,0,0,0,0,0,0,0,0,0,0
0,0,0,0,0,0,0,0,0,0,0,0,0,0,0,0,0,0,0,0,0,0,0,0,0,0,0,0,0,0,0,0,0,0,0,0,0,0,0,0,0,0,0,0,0,0,0,0,0,0,0,0,0,0,0,0,0,0,0,0,0,0,0
0,0,0,0,0,0,0,0,0,0,0,0,0,0,0,0,0,0,0,0,0,0,0,0,0,0,0,0,0,0,534,0,0,0,0,0,0,0,0,0,0,0,0,0,0,0,0,0,0,0,0,0,0,0,0,0,0,0,0,0,0,0,0
0,0,0,0,0,0,0,0,0,0,0,0,0,0,0,0,0,0,0,0,0,0,0,0,0,0,0,0,0,0,0,534,0,0,0,0,0,0,0,0,0,0,0,0,0,0,0,0,0,0,0,0,0,0,0,0,0,0,0,0,0,0,0
0,0,0,0,0,0,0,0,0,0,0,0,0,0,0,0,0,0,0,0,0,0,0,0,0,0,0,0,0,0,0,535,0,0,0,0,0,0,0,0,0,0,0,0,0,0,0,0,0,0,0,0,0,0,0,0,0,0,0,0,0,0,0
0,0,0,0,0,0,0,0,0,0,0,0,0,0,0,0,0,0,0,0,0,0,0,0,0,0,0,0,0,0,0,535,0,0,0,0,0,0,0,0,0,0,0,0,0,0,0,0,0,0,0,0,0,0,0,0,0,0,0,0,0,0,0
0,0,0,0,0,0,0,0,0,0,0,0,0,0,0,0,0,0,221,221,221,0,0,0,0,0,0,0,0,0,0,535,0,0,0,0,0,0,221,221,221,0,0,0,0,0,0,0,0,0,0,0,0,0,0,0,0,0,0,0,0,0,0
0,0,0,0,0,0,0,0,0,0,0,0,0,0,0,0,0,529,537,537,537,73,0,0,0,0,0,0,0,0,0,535,0,0,0,0,0,529,537,537,537,73,0,0,0,0,0,0,0,0,0,0,0,0,0,0,0,0,0,0,0,0,0
0,0,0,0,0,0,0,0,0,204,0,0,0,0,0,0,0,529,411,28,537,73,0,0,0,0,0,0,411,28,0,534,0,0,0,0,0,529,411,28,537,73,0,0,0,0,0,0,0,0,0,0,0,0,0,0,0,0,0,0,0,0,0
0,0,0,0,0,0,0,0,0,0,0,0,0,0,0,0,0,529,537,537,537,73,0,0,0,0,0,0,0,0,0,535,0,0,0,0,0,529,537,537,537,73,0,0,0,0,0,0,0,0,0,0,0,0,0,0,0,0,0,0,0,0,0
0,0,0,0,0,0,0,0,0,0,0,0,0,0,0,0,0,0,536,536,536,0,0,0,0,0,0,0,0,0,0,535,0,0,0,0,0,0,536,536,536,0,0,0,0,0,0,0,0,0,0,0,0,0,0,0,0,0,0,0,0,0,0
0,0,0,0,0,0,0,0,0,0,0,0,0,0,0,0,0,0,0,0,0,0,0,0,0,0,0,0,0,0,0,535,0,0,0,0,0,0,0,0,0,0,0,0,0,0,0,0,0,0,0,0,0,0,0,0,0,0,0,0,0,0,0
0,0,0,0,0,0,0,0,0,0,0,0,0,0,0,0,0,0,0,0,0,0,0,0,0,0,0,0,0,0,0,535,0,0,0,0,0,0,0,0,0,0,0,0,0,0,0,0,0,0,0,0,0,0,0,0,0,0,0,0,0,0,0
0,0,0,0,0,0,0,0,0,0,0,0,0,0,0,0,0,0,0,0,0,0,0,0,0,0,0,0,0,0,0,534,0,0,0,0,0,0,0,0,0,0,0,0,0,0,0,0,0,0,0,0,0,0,0,0,0,0,0,0,0,0,0
0,0,0,0,0,0,0,0,0,0,0,0,0,0,0,0,0,0,0,0,0,0,0,0,0,0,0,0,0,0,534,0,0,0,0,0,0,0,0,0,0,0,0,0,0,0,0,0,0,0,0,0,0,0,0,0,0,0,0,0,0,0,0
0,0,0,0,0,0,0,0,0,0,0,0,0,0,0,0,0,0,0,0,0,0,0,0,0,0,0,0,0,0,0,0,0,0,0,0,0,0,0,0,0,0,0,0,0,0,0,0,0,0,0,0,0,0,0,0,0,0,0,0,0,0,0
0,0,0,0,0,0,0,0,0,0,0,0,0,0,0,0,0,0,0,0,0,0,0,0,0,0,0,0,0,0,204,0,0,0,0,0,0,0,0,0,0,0,0,0,0,0,0,0,0,0,0,0,0,0,0,0,0,0,0,0,0,0,0
0,0,0,0,0,0,0,0,0,0,0,0,0,0,0,0,0,0,0,0,0,0,0,0,0,0,0,0,0,0,0,0,0,0,0,0,0,0,0,0,0,0,0,0,0,0,0,0,0,0,0,0,0,0,0,0,0,0,0,0,0,0,0
:endlayer
layer: 37
0,0,0,0,0,0,0,0,0,0,0,0,0,0,0,0,0,0,0,0,0,0,0,0,0,0,0,0,0,0,0,0,0,0,0,0,0,0,0,0,0,0,0,0,0,0,0,0,0,0,0,0,0,0,0,0,0,0,0,0,0,0,0
0,0,0,0,0,0,0,0,0,0,0,0,0,0,0,0,0,0,0,0,0,0,0,0,0,0,0,0,0,0,0,0,0,0,0,0,0,0,0,0,0,0,0,0,0,0,0,0,0,0,0,0,0,0,0,0,0,0,0,0,0,0,0
0,0,0,0,0,0,0,0,0,0,0,0,0,0,0,0,0,0,0,0,0,0,0,0,0,0,0,0,0,0,0,0,0,0,0,0,0,0,0,0,0,0,0,0,0,0,0,0,0,0,0,0,0,0,0,0,0,0,0,0,0,0,0
0,0,0,0,0,0,0,0,0,0,0,0,0,0,0,0,0,0,0,0,0,0,0,0,0,0,0,0,0,0,22,535,0,0,0,0,0,0,0,0,0,0,0,0,0,0,0,0,0,0,0,0,0,0,0,0,0,0,0,0,0,0,0
0,0,0,0,0,0,0,0,0,0,0,0,0,0,0,0,0,0,0,0,0,0,0,0,0,0,0,0,0,0,0,535,0,0,0,0,0,0,0,0,0,0,0,0,0,0,0,0,0,0,0,0,0,0,0,0,0,0,0,0,0,0,0
0,0,0,0,0,0,0,0,0,0,0,0,0,0,0,0,0,0,0,0,0,0,0,0,0,0,0,0,0,0,0,534,0,0,0,0,0,0,0,0,0,0,0,0,0,0,0,0,0,0,0,0,0,0,0,0,0,0,0,0,0,0,0
0,0,0,0,0,0,0,0,0,0,0,0,0,0,0,0,0,0,0,0,0,0,0,0,0,0,0,0,0,0,0,22,534,0,0,0,0,0,0,0,0,0,0,0,0,0,0,0,0,0,0,0,0,0,0,0,0,0,0,0,0,0,0
0,0,0,0,0,0,0,0,0,0,0,0,0,0,0,0,0,0,0,0,0,0,0,0,0,0,0,0,0,0,0,0,535,0,0,0,0,0,0,0,0,0,0,0,0,0,0,0,0,0,0,0,0,0,0,0,0,0,0,0,0,0,0
