# Ancient Warfare Structure Template File
# Auto-generated structure template file. created on: 2/24/2024 at: 0:53:42
# Lines beginning with # denote comments

header:
version=2.11
name=EmpireLeviathanSeaSovereignShipOfTheLine
mods=
size=25,66,79
offset=12,7,63
:endheader

#### VALIDATION ####
validation:
type=water
structureAuthor=TheOddlySeagull
survival=false
worldGenEnabled=true
unique=false
preserveBlocks=false
preventNaturalHostileSpawns=true
selectionWeight=5
clusterValue=500
minDuplicateDistance=20000
dimensionWhiteList=true
dimensionList=0
biomeGroupList=
biomeWhiteList=true
biomeList=minecraft:ocean,minecraft:deep_ocean
leveling=0
fill=0
border=0
blockSwap=false
territoryName=empire
biomeReplacement=minecraft:
:endvalidation

#### LAYERS ####
layer: 0
1,1,1,1,1,1,1,1,1,1,1,1,1,1,1,1,1,1,1,1,1,1,1,1,1
1,1,1,1,1,1,1,1,1,1,1,1,1,1,1,1,1,1,1,1,1,1,1,1,1
1,1,1,1,1,1,1,1,1,1,1,1,1,1,1,1,1,1,1,1,1,1,1,1,1
1,1,1,1,1,1,1,1,1,1,1,1,1,1,1,1,1,1,1,1,1,1,1,1,1
1,1,1,1,1,1,1,1,1,1,1,1,1,1,1,1,1,1,1,1,1,1,1,1,1
1,1,1,1,1,1,1,1,1,1,1,1,1,1,1,1,1,1,1,1,1,1,1,1,1
1,1,1,1,1,1,1,1,1,1,1,1,1,1,1,1,1,1,1,1,1,1,1,1,1
1,1,1,1,1,1,1,1,1,1,1,1,1,1,1,1,1,1,1,1,1,1,1,1,1
1,1,1,1,1,1,1,1,1,1,1,1,1,1,1,1,1,1,1,1,1,1,1,1,1
1,1,1,1,1,1,1,1,1,1,1,1,1,1,1,1,1,1,1,1,1,1,1,1,1
1,1,1,1,1,1,1,1,1,1,1,1,1,1,1,1,1,1,1,1,1,1,1,1,1
1,1,1,1,1,1,1,1,1,1,1,1,1,1,1,1,1,1,1,1,1,1,1,1,1
1,1,1,1,1,1,1,1,1,1,1,1,1,1,1,1,1,1,1,1,1,1,1,1,1
1,1,1,1,1,1,1,1,1,1,1,1,1,1,1,1,1,1,1,1,1,1,1,1,1
1,1,1,1,1,1,1,1,1,1,1,1,1,1,1,1,1,1,1,1,1,1,1,1,1
1,1,1,1,1,1,1,1,1,1,1,1,1,1,1,1,1,1,1,1,1,1,1,1,1
1,1,1,1,1,1,1,1,1,1,1,1,1,1,1,1,1,1,1,1,1,1,1,1,1
1,1,1,1,1,1,1,1,1,1,1,1,1,1,1,1,1,1,1,1,1,1,1,1,1
1,1,1,1,1,1,1,1,1,1,1,1,1,1,1,1,1,1,1,1,1,1,1,1,1
1,1,1,1,1,1,1,1,1,1,1,1,1,1,1,1,1,1,1,1,1,1,1,1,1
1,1,1,1,1,1,1,1,1,1,1,1,1,1,1,1,1,1,1,1,1,1,1,1,1
1,1,1,1,1,1,1,1,1,1,1,1,1,1,1,1,1,1,1,1,1,1,1,1,1
1,1,1,1,1,1,1,1,1,1,1,1,1,1,1,1,1,1,1,1,1,1,1,1,1
1,1,1,1,1,1,1,1,1,1,1,1,1,1,1,1,1,1,1,1,1,1,1,1,1
1,1,1,1,1,1,1,1,1,1,1,1,1,1,1,1,1,1,1,1,1,1,1,1,1
1,1,1,1,1,1,1,1,1,1,1,1,1,1,1,1,1,1,1,1,1,1,1,1,1
1,1,1,1,1,1,1,1,1,1,1,1,1,1,1,1,1,1,1,1,1,1,1,1,1
1,1,1,1,1,1,1,1,1,1,1,1,1,1,1,1,1,1,1,1,1,1,1,1,1
1,1,1,1,1,1,1,1,1,1,1,1,1,1,1,1,1,1,1,1,1,1,1,1,1
1,1,1,1,1,1,1,1,1,1,1,1,1,1,1,1,1,1,1,1,1,1,1,1,1
1,1,1,1,1,1,1,1,1,1,1,1,1,1,1,1,1,1,1,1,1,1,1,1,1
1,1,1,1,1,1,1,1,1,1,1,1,1,1,1,1,1,1,1,1,1,1,1,1,1
1,1,1,1,1,1,1,1,1,1,1,1,1,1,1,1,1,1,1,1,1,1,1,1,1
1,1,1,1,1,1,1,1,1,1,1,1,1,1,1,1,1,1,1,1,1,1,1,1,1
1,1,1,1,1,1,1,1,1,1,1,1,1,1,1,1,1,1,1,1,1,1,1,1,1
1,1,1,1,1,1,1,1,1,1,1,1,1,1,1,1,1,1,1,1,1,1,1,1,1
1,1,1,1,1,1,1,1,1,1,1,1,1,1,1,1,1,1,1,1,1,1,1,1,1
1,1,1,1,1,1,1,1,1,1,1,1,1,1,1,1,1,1,1,1,1,1,1,1,1
1,1,1,1,1,1,1,1,1,1,1,1,1,1,1,1,1,1,1,1,1,1,1,1,1
1,1,1,1,1,1,1,1,1,1,1,1,1,1,1,1,1,1,1,1,1,1,1,1,1
1,1,1,1,1,1,1,1,1,1,1,1,1,1,1,1,1,1,1,1,1,1,1,1,1
1,1,1,1,1,1,1,1,1,1,1,1,1,1,1,1,1,1,1,1,1,1,1,1,1
1,1,1,1,1,1,1,1,1,1,1,1,1,1,1,1,1,1,1,1,1,1,1,1,1
1,1,1,1,1,1,1,1,1,1,1,1,1,1,1,1,1,1,1,1,1,1,1,1,1
1,1,1,1,1,1,1,1,1,1,1,1,1,1,1,1,1,1,1,1,1,1,1,1,1
1,1,1,1,1,1,1,1,1,1,1,1,1,1,1,1,1,1,1,1,1,1,1,1,1
1,1,1,1,1,1,1,1,1,1,1,1,1,1,1,1,1,1,1,1,1,1,1,1,1
1,1,1,1,1,1,1,1,1,1,1,1,1,1,1,1,1,1,1,1,1,1,1,1,1
1,1,1,1,1,1,1,1,1,1,1,1,1,1,1,1,1,1,1,1,1,1,1,1,1
1,1,1,1,1,1,1,1,1,1,1,1,1,1,1,1,1,1,1,1,1,1,1,1,1
1,1,1,1,1,1,1,1,1,1,1,1,1,1,1,1,1,1,1,1,1,1,1,1,1
1,1,1,1,1,1,1,1,1,1,1,1,1,1,1,1,1,1,1,1,1,1,1,1,1
1,1,1,1,1,1,1,1,1,1,1,1,1,1,1,1,1,1,1,1,1,1,1,1,1
1,1,1,1,1,1,1,1,1,1,1,1,1,1,1,1,1,1,1,1,1,1,1,1,1
1,1,1,1,1,1,1,1,1,1,1,1,1,1,1,1,1,1,1,1,1,1,1,1,1
1,1,1,1,1,1,1,1,1,1,1,1,1,1,1,1,1,1,1,1,1,1,1,1,1
1,1,1,1,1,1,1,1,1,1,1,1,1,1,1,1,1,1,1,1,1,1,1,1,1
1,1,1,1,1,1,1,1,1,1,1,1,1,1,1,1,1,1,1,1,1,1,1,1,1
1,1,1,1,1,1,1,1,1,1,1,1,1,1,1,1,1,1,1,1,1,1,1,1,1
1,1,1,1,1,1,1,1,1,1,1,1,1,1,1,1,1,1,1,1,1,1,1,1,1
1,1,1,1,1,1,1,1,1,1,1,1,1,1,1,1,1,1,1,1,1,1,1,1,1
1,1,1,1,1,1,1,1,1,1,1,1,1,1,1,1,1,1,1,1,1,1,1,1,1
1,1,1,1,1,1,1,1,1,1,1,1,1,1,1,1,1,1,1,1,1,1,1,1,1
1,1,1,1,1,1,1,1,1,1,1,1,1,1,1,1,1,1,1,1,1,1,1,1,1
1,1,1,1,1,1,1,1,1,1,1,1,1,1,1,1,1,1,1,1,1,1,1,1,1
1,1,1,1,1,1,1,1,1,1,1,1,1,1,1,1,1,1,1,1,1,1,1,1,1
1,1,1,1,1,1,1,1,1,1,1,1,1,1,1,1,1,1,1,1,1,1,1,1,1
1,1,1,1,1,1,1,1,1,1,1,1,1,1,1,1,1,1,1,1,1,1,1,1,1
1,1,1,1,1,1,1,1,1,1,1,1,1,1,1,1,1,1,1,1,1,1,1,1,1
1,1,1,1,1,1,1,1,1,1,1,1,1,1,1,1,1,1,1,1,1,1,1,1,1
1,1,1,1,1,1,1,1,1,1,1,1,1,1,1,1,1,1,1,1,1,1,1,1,1
1,1,1,1,1,1,1,1,1,1,1,1,1,1,1,1,1,1,1,1,1,1,1,1,1
1,1,1,1,1,1,1,1,1,1,1,1,1,1,1,1,1,1,1,1,1,1,1,1,1
1,1,1,1,1,1,1,1,1,1,1,1,1,1,1,1,1,1,1,1,1,1,1,1,1
1,1,1,1,1,1,1,1,1,1,1,1,1,1,1,1,1,1,1,1,1,1,1,1,1
1,1,1,1,1,1,1,1,1,1,1,1,1,1,1,1,1,1,1,1,1,1,1,1,1
1,1,1,1,1,1,1,1,1,1,1,1,1,1,1,1,1,1,1,1,1,1,1,1,1
1,1,1,1,1,1,1,1,1,1,1,1,1,1,1,1,1,1,1,1,1,1,1,1,1
1,1,1,1,1,1,1,1,1,1,1,1,1,1,1,1,1,1,1,1,1,1,1,1,1
:endlayer
layer: 1
1,1,1,1,1,1,1,1,1,1,1,1,1,1,1,1,1,1,1,1,1,1,1,1,1
1,1,1,1,1,1,1,1,1,1,1,1,1,1,1,1,1,1,1,1,1,1,1,1,1
1,1,1,1,1,1,1,1,1,1,1,1,1,1,1,1,1,1,1,1,1,1,1,1,1
1,1,1,1,1,1,1,1,1,1,1,1,1,1,1,1,1,1,1,1,1,1,1,1,1
1,1,1,1,1,1,1,1,1,1,1,1,1,1,1,1,1,1,1,1,1,1,1,1,1
1,1,1,1,1,1,1,1,1,1,1,1,1,1,1,1,1,1,1,1,1,1,1,1,1
1,1,1,1,1,1,1,1,1,1,1,1,1,1,1,1,1,1,1,1,1,1,1,1,1
1,1,1,1,1,1,1,1,1,1,1,1,1,1,1,1,1,1,1,1,1,1,1,1,1
1,1,1,1,1,1,1,1,1,1,1,1,1,1,1,1,1,1,1,1,1,1,1,1,1
1,1,1,1,1,1,1,1,1,1,1,1,1,1,1,1,1,1,1,1,1,1,1,1,1
1,1,1,1,1,1,1,1,1,1,1,1,1,1,1,1,1,1,1,1,1,1,1,1,1
1,1,1,1,1,1,1,1,1,1,1,1,1,1,1,1,1,1,1,1,1,1,1,1,1
1,1,1,1,1,1,1,1,1,1,1,1,1,1,1,1,1,1,1,1,1,1,1,1,1
1,1,1,1,1,1,1,1,1,1,1,1,1,1,1,1,1,1,1,1,1,1,1,1,1
1,1,1,1,1,1,1,1,1,1,1,1,1,1,1,1,1,1,1,1,1,1,1,1,1
1,1,1,1,1,1,1,1,1,1,1,1,1,1,1,1,1,1,1,1,1,1,1,1,1
1,1,1,1,1,1,1,1,1,1,1,1,1,1,1,1,1,1,1,1,1,1,1,1,1
1,1,1,1,1,1,1,1,1,1,1,1,1,1,1,1,1,1,1,1,1,1,1,1,1
1,1,1,1,1,1,1,1,1,1,1,1,1,1,1,1,1,1,1,1,1,1,1,1,1
1,1,1,1,1,1,1,1,1,1,1,1,1,1,1,1,1,1,1,1,1,1,1,1,1
1,1,1,1,1,1,1,1,1,1,1,1,1,1,1,1,1,1,1,1,1,1,1,1,1
1,1,1,1,1,1,1,1,1,1,1,1,1,1,1,1,1,1,1,1,1,1,1,1,1
1,1,1,1,1,1,1,1,1,1,1,1,1,1,1,1,1,1,1,1,1,1,1,1,1
1,1,1,1,1,1,1,1,1,1,1,1,1,1,1,1,1,1,1,1,1,1,1,1,1
1,1,1,1,1,1,1,1,1,1,1,1,1,1,1,1,1,1,1,1,1,1,1,1,1
1,1,1,1,1,1,1,1,1,1,1,1,1,1,1,1,1,1,1,1,1,1,1,1,1
1,1,1,1,1,1,1,1,1,1,1,1,1,1,1,1,1,1,1,1,1,1,1,1,1
1,1,1,1,1,1,1,1,1,1,1,1,1,1,1,1,1,1,1,1,1,1,1,1,1
1,1,1,1,1,1,1,1,1,1,1,1,1,1,1,1,1,1,1,1,1,1,1,1,1
1,1,1,1,1,1,1,1,1,1,1,1,1,1,1,1,1,1,1,1,1,1,1,1,1
1,1,1,1,1,1,1,1,1,1,1,1,1,1,1,1,1,1,1,1,1,1,1,1,1
1,1,1,1,1,1,1,1,1,1,1,1,1,1,1,1,1,1,1,1,1,1,1,1,1
1,1,1,1,1,1,1,1,1,1,1,1,1,1,1,1,1,1,1,1,1,1,1,1,1
1,1,1,1,1,1,1,1,1,1,1,1,1,1,1,1,1,1,1,1,1,1,1,1,1
1,1,1,1,1,1,1,1,1,1,1,1,1,1,1,1,1,1,1,1,1,1,1,1,1
1,1,1,1,1,1,1,1,1,1,1,1,1,1,1,1,1,1,1,1,1,1,1,1,1
1,1,1,1,1,1,1,1,1,1,1,1,1,1,1,1,1,1,1,1,1,1,1,1,1
1,1,1,1,1,1,1,1,1,1,1,1,1,1,1,1,1,1,1,1,1,1,1,1,1
1,1,1,1,1,1,1,1,1,1,1,1,1,1,1,1,1,1,1,1,1,1,1,1,1
1,1,1,1,1,1,1,1,1,1,1,1,1,1,1,1,1,1,1,1,1,1,1,1,1
1,1,1,1,1,1,1,1,1,1,1,1,1,1,1,1,1,1,1,1,1,1,1,1,1
1,1,1,1,1,1,1,1,1,1,1,1,1,1,1,1,1,1,1,1,1,1,1,1,1
1,1,1,1,1,1,1,1,1,1,1,1,1,1,1,1,1,1,1,1,1,1,1,1,1
1,1,1,1,1,1,1,1,1,1,1,1,1,1,1,1,1,1,1,1,1,1,1,1,1
1,1,1,1,1,1,1,1,1,1,1,1,1,1,1,1,1,1,1,1,1,1,1,1,1
1,1,1,1,1,1,1,1,1,1,1,1,1,1,1,1,1,1,1,1,1,1,1,1,1
1,1,1,1,1,1,1,1,1,1,1,1,1,1,1,1,1,1,1,1,1,1,1,1,1
1,1,1,1,1,1,1,1,1,1,1,1,1,1,1,1,1,1,1,1,1,1,1,1,1
1,1,1,1,1,1,1,1,1,1,1,1,1,1,1,1,1,1,1,1,1,1,1,1,1
1,1,1,1,1,1,1,1,1,1,1,1,1,1,1,1,1,1,1,1,1,1,1,1,1
1,1,1,1,1,1,1,1,1,1,1,1,1,1,1,1,1,1,1,1,1,1,1,1,1
1,1,1,1,1,1,1,1,1,1,1,1,1,1,1,1,1,1,1,1,1,1,1,1,1
1,1,1,1,1,1,1,1,1,1,1,1,1,1,1,1,1,1,1,1,1,1,1,1,1
1,1,1,1,1,1,1,1,1,1,1,1,1,1,1,1,1,1,1,1,1,1,1,1,1
1,1,1,1,1,1,1,1,1,1,1,1,1,1,1,1,1,1,1,1,1,1,1,1,1
1,1,1,1,1,1,1,1,1,1,1,1,1,1,1,1,1,1,1,1,1,1,1,1,1
1,1,1,1,1,1,1,1,1,1,1,1,1,1,1,1,1,1,1,1,1,1,1,1,1
1,1,1,1,1,1,1,1,1,1,1,1,1,1,1,1,1,1,1,1,1,1,1,1,1
1,1,1,1,1,1,1,1,1,1,1,1,1,1,1,1,1,1,1,1,1,1,1,1,1
1,1,1,1,1,1,1,1,1,1,1,1,1,1,1,1,1,1,1,1,1,1,1,1,1
1,1,1,1,1,1,1,1,1,1,1,1,1,1,1,1,1,1,1,1,1,1,1,1,1
1,1,1,1,1,1,1,1,1,1,1,1,1,1,1,1,1,1,1,1,1,1,1,1,1
1,1,1,1,1,1,1,1,1,1,1,1,1,1,1,1,1,1,1,1,1,1,1,1,1
1,1,1,1,1,1,1,1,1,1,1,1,1,1,1,1,1,1,1,1,1,1,1,1,1
1,1,1,1,1,1,1,1,1,1,1,1,1,1,1,1,1,1,1,1,1,1,1,1,1
1,1,1,1,1,1,1,1,1,1,1,1,1,1,1,1,1,1,1,1,1,1,1,1,1
1,1,1,1,1,1,1,1,1,1,1,1,1,1,1,1,1,1,1,1,1,1,1,1,1
1,1,1,1,1,1,1,1,1,1,1,1,1,1,1,1,1,1,1,1,1,1,1,1,1
1,1,1,1,1,1,1,1,1,1,1,1,1,1,1,1,1,1,1,1,1,1,1,1,1
1,1,1,1,1,1,1,1,1,1,1,1,1,1,1,1,1,1,1,1,1,1,1,1,1
1,1,1,1,1,1,1,1,1,1,1,1,1,1,1,1,1,1,1,1,1,1,1,1,1
1,1,1,1,1,1,1,1,1,1,1,1,1,1,1,1,1,1,1,1,1,1,1,1,1
1,1,1,1,1,1,1,1,1,1,1,1,1,1,1,1,1,1,1,1,1,1,1,1,1
1,1,1,1,1,1,1,1,1,1,1,1,1,1,1,1,1,1,1,1,1,1,1,1,1
1,1,1,1,1,1,1,1,1,1,1,1,1,1,1,1,1,1,1,1,1,1,1,1,1
1,1,1,1,1,1,1,1,1,1,1,1,1,1,1,1,1,1,1,1,1,1,1,1,1
1,1,1,1,1,1,1,1,1,1,1,1,1,1,1,1,1,1,1,1,1,1,1,1,1
1,1,1,1,1,1,1,1,1,1,1,1,1,1,1,1,1,1,1,1,1,1,1,1,1
1,1,1,1,1,1,1,1,1,1,1,1,1,1,1,1,1,1,1,1,1,1,1,1,1
:endlayer
layer: 2
1,1,1,1,1,1,1,1,1,1,1,1,1,1,1,1,1,1,1,1,1,1,1,1,1
1,1,1,1,1,1,1,1,1,1,1,1,1,1,1,1,1,1,1,1,1,1,1,1,1
1,1,1,1,1,1,1,1,1,1,1,1,1,1,1,1,1,1,1,1,1,1,1,1,1
1,1,1,1,1,1,1,1,1,1,1,1,1,1,1,1,1,1,1,1,1,1,1,1,1
1,1,1,1,1,1,1,1,1,1,1,1,1,1,1,1,1,1,1,1,1,1,1,1,1
1,1,1,1,1,1,1,1,1,1,1,1,1,1,1,1,1,1,1,1,1,1,1,1,1
1,1,1,1,1,1,1,1,1,1,1,1,1,1,1,1,1,1,1,1,1,1,1,1,1
1,1,1,1,1,1,1,1,1,1,1,1,1,1,1,1,1,1,1,1,1,1,1,1,1
1,1,1,1,1,1,1,1,1,1,1,1,1,1,1,1,1,1,1,1,1,1,1,1,1
1,1,1,1,1,1,1,1,1,1,1,1,1,1,1,1,1,1,1,1,1,1,1,1,1
1,1,1,1,1,1,1,1,1,1,1,1,1,1,1,1,1,1,1,1,1,1,1,1,1
1,1,1,1,1,1,1,1,1,1,1,1,1,1,1,1,1,1,1,1,1,1,1,1,1
1,1,1,1,1,1,1,1,1,1,1,1,1,1,1,1,1,1,1,1,1,1,1,1,1
1,1,1,1,1,1,1,1,1,1,1,1,1,1,1,1,1,1,1,1,1,1,1,1,1
1,1,1,1,1,1,1,1,1,1,1,1,1,1,1,1,1,1,1,1,1,1,1,1,1
1,1,1,1,1,1,1,1,1,1,1,1,1,1,1,1,1,1,1,1,1,1,1,1,1
1,1,1,1,1,1,1,1,1,1,1,1,1,1,1,1,1,1,1,1,1,1,1,1,1
1,1,1,1,1,1,1,1,1,1,1,1,1,1,1,1,1,1,1,1,1,1,1,1,1
1,1,1,1,1,1,1,1,1,1,1,1,1,1,1,1,1,1,1,1,1,1,1,1,1
1,1,1,1,1,1,1,1,1,1,1,1,1,1,1,1,1,1,1,1,1,1,1,1,1
1,1,1,1,1,1,1,1,1,1,1,1,1,1,1,1,1,1,1,1,1,1,1,1,1
1,1,1,1,1,1,1,1,1,1,1,1,1,1,1,1,1,1,1,1,1,1,1,1,1
1,1,1,1,1,1,1,1,1,1,1,1,1,1,1,1,1,1,1,1,1,1,1,1,1
1,1,1,1,1,1,1,1,1,1,1,1,1,1,1,1,1,1,1,1,1,1,1,1,1
1,1,1,1,1,1,1,1,1,1,1,1,1,1,1,1,1,1,1,1,1,1,1,1,1
1,1,1,1,1,1,1,1,1,1,1,1,1,1,1,1,1,1,1,1,1,1,1,1,1
1,1,1,1,1,1,1,1,1,1,1,1,1,1,1,1,1,1,1,1,1,1,1,1,1
1,1,1,1,1,1,1,1,1,1,1,1,1,1,1,1,1,1,1,1,1,1,1,1,1
1,1,1,1,1,1,1,1,1,1,1,1,1,1,1,1,1,1,1,1,1,1,1,1,1
1,1,1,1,1,1,1,1,1,1,1,1,1,1,1,1,1,1,1,1,1,1,1,1,1
1,1,1,1,1,1,1,1,1,1,1,1,1,1,1,1,1,1,1,1,1,1,1,1,1
1,1,1,1,1,1,1,1,1,1,1,1,1,1,1,1,1,1,1,1,1,1,1,1,1
1,1,1,1,1,1,1,1,1,1,1,1,1,1,1,1,1,1,1,1,1,1,1,1,1
1,1,1,1,1,1,1,1,1,1,1,1,1,1,1,1,1,1,1,1,1,1,1,1,1
1,1,1,1,1,1,1,1,1,1,1,1,1,1,1,1,1,1,1,1,1,1,1,1,1
1,1,1,1,1,1,1,1,1,1,1,1,1,1,1,1,1,1,1,1,1,1,1,1,1
1,1,1,1,1,1,1,1,1,1,1,1,1,1,1,1,1,1,1,1,1,1,1,1,1
1,1,1,1,1,1,1,1,1,1,1,1,1,1,1,1,1,1,1,1,1,1,1,1,1
1,1,1,1,1,1,1,1,1,1,1,1,1,1,1,1,1,1,1,1,1,1,1,1,1
1,1,1,1,1,1,1,1,1,1,1,1,1,1,1,1,1,1,1,1,1,1,1,1,1
1,1,1,1,1,1,1,1,1,1,1,1,1,1,1,1,1,1,1,1,1,1,1,1,1
1,1,1,1,1,1,1,1,1,1,1,1,1,1,1,1,1,1,1,1,1,1,1,1,1
1,1,1,1,1,1,1,1,1,1,1,1,1,1,1,1,1,1,1,1,1,1,1,1,1
1,1,1,1,1,1,1,1,1,1,1,1,1,1,1,1,1,1,1,1,1,1,1,1,1
1,1,1,1,1,1,1,1,1,1,1,1,1,1,1,1,1,1,1,1,1,1,1,1,1
1,1,1,1,1,1,1,1,1,1,1,1,1,1,1,1,1,1,1,1,1,1,1,1,1
1,1,1,1,1,1,1,1,1,1,1,1,1,1,1,1,1,1,1,1,1,1,1,1,1
1,1,1,1,1,1,1,1,1,1,1,1,1,1,1,1,1,1,1,1,1,1,1,1,1
1,1,1,1,1,1,1,1,1,1,1,1,1,1,1,1,1,1,1,1,1,1,1,1,1
1,1,1,1,1,1,1,1,1,1,1,1,1,1,1,1,1,1,1,1,1,1,1,1,1
1,1,1,1,1,1,1,1,1,1,1,1,1,1,1,1,1,1,1,1,1,1,1,1,1
1,1,1,1,1,1,1,1,1,1,1,1,1,1,1,1,1,1,1,1,1,1,1,1,1
1,1,1,1,1,1,1,1,1,1,1,1,1,1,1,1,1,1,1,1,1,1,1,1,1
1,1,1,1,1,1,1,1,1,1,1,1,1,1,1,1,1,1,1,1,1,1,1,1,1
1,1,1,1,1,1,1,1,1,1,1,1,1,1,1,1,1,1,1,1,1,1,1,1,1
1,1,1,1,1,1,1,1,1,1,1,1,1,1,1,1,1,1,1,1,1,1,1,1,1
1,1,1,1,1,1,1,1,1,1,1,1,1,1,1,1,1,1,1,1,1,1,1,1,1
1,1,1,1,1,1,1,1,1,1,1,1,1,1,1,1,1,1,1,1,1,1,1,1,1
1,1,1,1,1,1,1,1,1,1,1,1,1,1,1,1,1,1,1,1,1,1,1,1,1
1,1,1,1,1,1,1,1,1,1,1,1,1,1,1,1,1,1,1,1,1,1,1,1,1
1,1,1,1,1,1,1,1,1,1,1,1,1,1,1,1,1,1,1,1,1,1,1,1,1
1,1,1,1,1,1,1,1,1,1,1,1,1,1,1,1,1,1,1,1,1,1,1,1,1
1,1,1,1,1,1,1,1,1,1,1,1,1,1,1,1,1,1,1,1,1,1,1,1,1
1,1,1,1,1,1,1,1,1,1,1,1,1,1,1,1,1,1,1,1,1,1,1,1,1
1,1,1,1,1,1,1,1,1,1,1,1,1,1,1,1,1,1,1,1,1,1,1,1,1
1,1,1,1,1,1,1,1,1,1,1,1,1,1,1,1,1,1,1,1,1,1,1,1,1
1,1,1,1,1,1,1,1,1,1,1,1,1,1,1,1,1,1,1,1,1,1,1,1,1
1,1,1,1,1,1,1,1,1,1,1,1,1,1,1,1,1,1,1,1,1,1,1,1,1
1,1,1,1,1,1,1,1,1,1,1,1,1,1,1,1,1,1,1,1,1,1,1,1,1
1,1,1,1,1,1,1,1,1,1,1,1,1,1,1,1,1,1,1,1,1,1,1,1,1
1,1,1,1,1,1,1,1,1,1,1,1,1,1,1,1,1,1,1,1,1,1,1,1,1
1,1,1,1,1,1,1,1,1,1,1,1,1,1,1,1,1,1,1,1,1,1,1,1,1
1,1,1,1,1,1,1,1,1,1,1,1,1,1,1,1,1,1,1,1,1,1,1,1,1
1,1,1,1,1,1,1,1,1,1,1,1,1,1,1,1,1,1,1,1,1,1,1,1,1
1,1,1,1,1,1,1,1,1,1,1,1,1,1,1,1,1,1,1,1,1,1,1,1,1
1,1,1,1,1,1,1,1,1,1,1,1,1,1,1,1,1,1,1,1,1,1,1,1,1
1,1,1,1,1,1,1,1,1,1,1,1,1,1,1,1,1,1,1,1,1,1,1,1,1
1,1,1,1,1,1,1,1,1,1,1,1,1,1,1,1,1,1,1,1,1,1,1,1,1
1,1,1,1,1,1,1,1,1,1,1,1,1,1,1,1,1,1,1,1,1,1,1,1,1
:endlayer
layer: 3
1,1,1,1,1,1,1,1,1,1,1,1,1,1,1,1,1,1,1,1,1,1,1,1,1
1,1,1,1,1,1,1,1,1,1,1,1,1,1,1,1,1,1,1,1,1,1,1,1,1
1,1,1,1,1,1,1,1,1,1,1,1,1,1,1,1,1,1,1,1,1,1,1,1,1
1,1,1,1,1,1,1,1,1,1,1,1,1,1,1,1,1,1,1,1,1,1,1,1,1
1,1,1,1,1,1,1,1,1,1,1,1,1,1,1,1,1,1,1,1,1,1,1,1,1
1,1,1,1,1,1,1,1,1,1,1,1,1,1,1,1,1,1,1,1,1,1,1,1,1
1,1,1,1,1,1,1,1,1,1,1,1,1,1,1,1,1,1,1,1,1,1,1,1,1
1,1,1,1,1,1,1,1,1,1,1,1,1,1,1,1,1,1,1,1,1,1,1,1,1
1,1,1,1,1,1,1,1,1,1,1,1,1,1,1,1,1,1,1,1,1,1,1,1,1
1,1,1,1,1,1,1,1,1,1,1,1,1,1,1,1,1,1,1,1,1,1,1,1,1
1,1,1,1,1,1,1,1,1,1,1,1,1,1,1,1,1,1,1,1,1,1,1,1,1
1,1,1,1,1,1,1,1,1,1,1,1,1,1,1,1,1,1,1,1,1,1,1,1,1
1,1,1,1,1,1,1,1,1,1,1,1,1,1,1,1,1,1,1,1,1,1,1,1,1
1,1,1,1,1,1,1,1,1,1,1,1,1,1,1,1,1,1,1,1,1,1,1,1,1
1,1,1,1,1,1,1,1,1,1,1,1,1,1,1,1,1,1,1,1,1,1,1,1,1
1,1,1,1,1,1,1,1,1,1,1,1,1,1,1,1,1,1,1,1,1,1,1,1,1
1,1,1,1,1,1,1,1,1,1,1,1,1,1,1,1,1,1,1,1,1,1,1,1,1
1,1,1,1,1,1,1,1,1,1,1,1,1,1,1,1,1,1,1,1,1,1,1,1,1
1,1,1,1,1,1,1,1,1,1,1,2,2,2,1,1,1,1,1,1,1,1,1,1,1
1,1,1,1,1,1,1,1,1,1,2,2,2,2,2,1,1,1,1,1,1,1,1,1,1
1,1,1,1,1,1,1,1,1,1,2,2,2,2,2,1,1,1,1,1,1,1,1,1,1
1,1,1,1,1,1,1,1,1,1,2,2,2,2,2,1,1,1,1,1,1,1,1,1,1
1,1,1,1,1,1,1,1,1,1,2,2,2,2,2,1,1,1,1,1,1,1,1,1,1
1,1,1,1,1,1,1,1,1,1,2,2,2,2,2,1,1,1,1,1,1,1,1,1,1
1,1,1,1,1,1,1,1,1,1,2,2,2,2,2,1,1,1,1,1,1,1,1,1,1
1,1,1,1,1,1,1,1,1,1,2,2,2,2,2,1,1,1,1,1,1,1,1,1,1
1,1,1,1,1,1,1,1,1,1,2,2,2,2,2,1,1,1,1,1,1,1,1,1,1
1,1,1,1,1,1,1,1,1,1,2,2,2,2,2,1,1,1,1,1,1,1,1,1,1
1,1,1,1,1,1,1,1,1,1,2,2,2,2,2,1,1,1,1,1,1,1,1,1,1
1,1,1,1,1,1,1,1,1,1,2,2,2,2,2,1,1,1,1,1,1,1,1,1,1
1,1,1,1,1,1,1,1,1,1,2,2,2,2,2,1,1,1,1,1,1,1,1,1,1
1,1,1,1,1,1,1,1,1,1,2,2,2,2,2,1,1,1,1,1,1,1,1,1,1
1,1,1,1,1,1,1,1,1,1,2,2,2,2,2,1,1,1,1,1,1,1,1,1,1
1,1,1,1,1,1,1,1,1,1,2,2,2,2,2,1,1,1,1,1,1,1,1,1,1
1,1,1,1,1,1,1,1,1,1,2,2,2,2,2,1,1,1,1,1,1,1,1,1,1
1,1,1,1,1,1,1,1,1,1,2,2,2,2,2,1,1,1,1,1,1,1,1,1,1
1,1,1,1,1,1,1,1,1,1,2,2,2,2,2,1,1,1,1,1,1,1,1,1,1
1,1,1,1,1,1,1,1,1,1,2,2,2,2,2,1,1,1,1,1,1,1,1,1,1
1,1,1,1,1,1,1,1,1,1,2,2,2,2,2,1,1,1,1,1,1,1,1,1,1
1,1,1,1,1,1,1,1,1,1,2,2,2,2,2,1,1,1,1,1,1,1,1,1,1
1,1,1,1,1,1,1,1,1,1,2,2,2,2,2,1,1,1,1,1,1,1,1,1,1
1,1,1,1,1,1,1,1,1,1,2,2,2,2,2,1,1,1,1,1,1,1,1,1,1
1,1,1,1,1,1,1,1,1,1,2,2,2,2,2,1,1,1,1,1,1,1,1,1,1
1,1,1,1,1,1,1,1,1,1,2,2,2,2,2,1,1,1,1,1,1,1,1,1,1
1,1,1,1,1,1,1,1,1,1,2,2,2,2,2,1,1,1,1,1,1,1,1,1,1
1,1,1,1,1,1,1,1,1,1,2,2,2,2,2,1,1,1,1,1,1,1,1,1,1
1,1,1,1,1,1,1,1,1,1,2,2,2,2,2,1,1,1,1,1,1,1,1,1,1
1,1,1,1,1,1,1,1,1,1,2,2,2,2,2,1,1,1,1,1,1,1,1,1,1
1,1,1,1,1,1,1,1,1,1,2,2,2,2,2,1,1,1,1,1,1,1,1,1,1
1,1,1,1,1,1,1,1,1,1,2,2,2,2,2,1,1,1,1,1,1,1,1,1,1
1,1,1,1,1,1,1,1,1,1,2,2,2,2,2,1,1,1,1,1,1,1,1,1,1
1,1,1,1,1,1,1,1,1,1,2,2,2,2,2,1,1,1,1,1,1,1,1,1,1
1,1,1,1,1,1,1,1,1,1,1,2,2,2,1,1,1,1,1,1,1,1,1,1,1
1,1,1,1,1,1,1,1,1,1,1,2,2,2,1,1,1,1,1,1,1,1,1,1,1
1,1,1,1,1,1,1,1,1,1,1,1,2,1,1,1,1,1,1,1,1,1,1,1,1
1,1,1,1,1,1,1,1,1,1,1,1,2,1,1,1,1,1,1,1,1,1,1,1,1
1,1,1,1,1,1,1,1,1,1,1,1,1,1,1,1,1,1,1,1,1,1,1,1,1
1,1,1,1,1,1,1,1,1,1,1,1,1,1,1,1,1,1,1,1,1,1,1,1,1
1,1,1,1,1,1,1,1,1,1,1,1,1,1,1,1,1,1,1,1,1,1,1,1,1
1,1,1,1,1,1,1,1,1,1,1,1,1,1,1,1,1,1,1,1,1,1,1,1,1
1,1,1,1,1,1,1,1,1,1,1,1,1,1,1,1,1,1,1,1,1,1,1,1,1
1,1,1,1,1,1,1,1,1,1,1,1,1,1,1,1,1,1,1,1,1,1,1,1,1
1,1,1,1,1,1,1,1,1,1,1,1,1,1,1,1,1,1,1,1,1,1,1,1,1
1,1,1,1,1,1,1,1,1,1,1,1,1,1,1,1,1,1,1,1,1,1,1,1,1
1,1,1,1,1,1,1,1,1,1,1,1,1,1,1,1,1,1,1,1,1,1,1,1,1
1,1,1,1,1,1,1,1,1,1,1,1,1,1,1,1,1,1,1,1,1,1,1,1,1
1,1,1,1,1,1,1,1,1,1,1,1,1,1,1,1,1,1,1,1,1,1,1,1,1
1,1,1,1,1,1,1,1,1,1,1,1,1,1,1,1,1,1,1,1,1,1,1,1,1
1,1,1,1,1,1,1,1,1,1,1,1,1,1,1,1,1,1,1,1,1,1,1,1,1
1,1,1,1,1,1,1,1,1,1,1,1,1,1,1,1,1,1,1,1,1,1,1,1,1
1,1,1,1,1,1,1,1,1,1,1,1,1,1,1,1,1,1,1,1,1,1,1,1,1
1,1,1,1,1,1,1,1,1,1,1,1,1,1,1,1,1,1,1,1,1,1,1,1,1
1,1,1,1,1,1,1,1,1,1,1,1,1,1,1,1,1,1,1,1,1,1,1,1,1
1,1,1,1,1,1,1,1,1,1,1,1,1,1,1,1,1,1,1,1,1,1,1,1,1
1,1,1,1,1,1,1,1,1,1,1,1,1,1,1,1,1,1,1,1,1,1,1,1,1
1,1,1,1,1,1,1,1,1,1,1,1,1,1,1,1,1,1,1,1,1,1,1,1,1
1,1,1,1,1,1,1,1,1,1,1,1,1,1,1,1,1,1,1,1,1,1,1,1,1
1,1,1,1,1,1,1,1,1,1,1,1,1,1,1,1,1,1,1,1,1,1,1,1,1
1,1,1,1,1,1,1,1,1,1,1,1,1,1,1,1,1,1,1,1,1,1,1,1,1
:endlayer
layer: 4
1,1,1,1,1,1,1,1,1,1,1,1,1,1,1,1,1,1,1,1,1,1,1,1,1
1,1,1,1,1,1,1,1,1,1,1,1,1,1,1,1,1,1,1,1,1,1,1,1,1
1,1,1,1,1,1,1,1,1,1,1,1,1,1,1,1,1,1,1,1,1,1,1,1,1
1,1,1,1,1,1,1,1,1,1,1,1,1,1,1,1,1,1,1,1,1,1,1,1,1
1,1,1,1,1,1,1,1,1,1,1,1,1,1,1,1,1,1,1,1,1,1,1,1,1
1,1,1,1,1,1,1,1,1,1,1,1,1,1,1,1,1,1,1,1,1,1,1,1,1
1,1,1,1,1,1,1,1,1,1,1,1,1,1,1,1,1,1,1,1,1,1,1,1,1
1,1,1,1,1,1,1,1,1,1,1,1,1,1,1,1,1,1,1,1,1,1,1,1,1
1,1,1,1,1,1,1,1,1,1,1,1,1,1,1,1,1,1,1,1,1,1,1,1,1
1,1,1,1,1,1,1,1,1,1,1,1,1,1,1,1,1,1,1,1,1,1,1,1,1
1,1,1,1,1,1,1,1,1,1,1,1,1,1,1,1,1,1,1,1,1,1,1,1,1
1,1,1,1,1,1,1,1,1,1,1,1,1,1,1,1,1,1,1,1,1,1,1,1,1
1,1,1,1,1,1,1,1,1,1,1,1,1,1,1,1,1,1,1,1,1,1,1,1,1
1,1,1,1,1,1,1,1,1,1,1,1,1,1,1,1,1,1,1,1,1,1,1,1,1
1,1,1,1,1,1,1,1,1,1,1,1,1,1,1,1,1,1,1,1,1,1,1,1,1
1,1,1,1,1,1,1,1,1,1,1,1,1,1,1,1,1,1,1,1,1,1,1,1,1
1,1,1,1,1,1,1,1,1,1,1,1,1,1,1,1,1,1,1,1,1,1,1,1,1
1,1,1,1,1,1,1,1,1,1,2,2,2,2,2,1,1,1,1,1,1,1,1,1,1
1,1,1,1,1,1,1,1,1,2,2,40,2,2,2,2,1,1,1,1,1,1,1,1,1
1,1,1,1,1,1,1,1,1,2,55,0,2,2,2,2,1,1,1,1,1,1,1,1,1
1,1,1,1,1,1,1,1,1,2,56,33,2,2,2,2,1,1,1,1,1,1,1,1,1
1,1,1,1,1,1,1,1,1,2,2,2,31,2,2,2,1,1,1,1,1,1,1,1,1
1,1,1,1,1,1,1,1,1,2,57,41,22,20,3,2,1,1,1,1,1,1,1,1,1
1,1,1,1,1,1,1,1,1,2,58,42,0,21,4,2,1,1,1,1,1,1,1,1,1
1,1,1,1,1,1,1,1,1,2,59,0,0,22,5,2,1,1,1,1,1,1,1,1,1
1,1,1,1,1,1,1,1,1,2,60,43,0,23,6,2,1,1,1,1,1,1,1,1,1
1,1,1,1,1,1,1,1,1,2,61,44,32,22,7,2,1,1,1,1,1,1,1,1,1
1,1,1,1,1,1,1,1,1,2,59,22,0,0,5,2,1,1,1,1,1,1,1,1,1
1,1,1,1,1,1,1,1,1,2,62,22,0,24,8,2,1,1,1,1,1,1,1,1,1
1,1,1,1,1,1,1,1,1,2,63,0,0,0,9,2,1,1,1,1,1,1,1,1,1
1,1,1,1,1,1,1,1,1,2,59,45,33,22,5,2,1,1,1,1,1,1,1,1,1
1,1,1,1,1,1,1,1,1,2,2,2,31,2,2,2,1,1,1,1,1,1,1,1,1
1,1,1,1,1,1,1,1,1,2,64,46,34,0,0,2,1,1,1,1,1,1,1,1,1
1,1,1,1,1,1,1,1,1,2,65,0,10,25,0,2,1,1,1,1,1,1,1,1,1
1,1,1,1,1,1,1,1,1,2,66,0,10,10,10,2,1,1,1,1,1,1,1,1,1
1,1,1,1,1,1,1,1,1,2,67,0,34,0,0,2,1,1,1,1,1,1,1,1,1
1,1,1,1,1,1,1,1,1,2,68,47,10,26,0,2,1,1,1,1,1,1,1,1,1
1,1,1,1,1,1,1,1,1,2,68,0,10,10,10,2,1,1,1,1,1,1,1,1,1
1,1,1,1,1,1,1,1,1,2,67,0,34,0,11,2,1,1,1,1,1,1,1,1,1
1,1,1,1,1,1,1,1,1,2,0,0,10,10,10,2,1,1,1,1,1,1,1,1,1
1,1,1,1,1,1,1,1,1,2,69,0,33,27,12,2,1,1,1,1,1,1,1,1,1
1,1,1,1,1,1,1,1,1,2,2,48,31,2,2,2,1,1,1,1,1,1,1,1,1
1,1,1,1,1,1,1,1,1,2,22,0,0,28,13,2,1,1,1,1,1,1,1,1,1
1,1,1,1,1,1,1,1,1,2,70,22,0,29,14,2,1,1,1,1,1,1,1,1,1
1,1,1,1,1,1,1,1,1,2,71,49,0,0,15,2,1,1,1,1,1,1,1,1,1
1,1,1,1,1,1,1,1,1,2,72,50,35,0,16,2,1,1,1,1,1,1,1,1,1
1,1,1,1,1,1,1,1,1,2,73,51,0,0,17,2,1,1,1,1,1,1,1,1,1
1,1,1,1,1,1,1,1,1,2,74,52,36,0,18,2,1,1,1,1,1,1,1,1,1
1,1,1,1,1,1,1,1,1,2,2,2,31,30,2,2,1,1,1,1,1,1,1,1,1
1,1,1,1,1,1,1,1,1,2,75,0,37,0,19,2,1,1,1,1,1,1,1,1,1
1,1,1,1,1,1,1,1,1,2,2,0,33,0,2,2,1,1,1,1,1,1,1,1,1
1,1,1,1,1,1,1,1,1,1,2,53,31,0,2,1,1,1,1,1,1,1,1,1,1
1,1,1,1,1,1,1,1,1,1,2,54,0,0,2,1,1,1,1,1,1,1,1,1,1
1,1,1,1,1,1,1,1,1,1,2,2,38,2,2,1,1,1,1,1,1,1,1,1,1
1,1,1,1,1,1,1,1,1,1,1,2,39,2,1,1,1,1,1,1,1,1,1,1,1
1,1,1,1,1,1,1,1,1,1,1,2,2,2,1,1,1,1,1,1,1,1,1,1,1
1,1,1,1,1,1,1,1,1,1,1,1,2,1,1,1,1,1,1,1,1,1,1,1,1
1,1,1,1,1,1,1,1,1,1,1,1,2,1,1,1,1,1,1,1,1,1,1,1,1
1,1,1,1,1,1,1,1,1,1,1,1,2,1,1,1,1,1,1,1,1,1,1,1,1
1,1,1,1,1,1,1,1,1,1,1,1,1,1,1,1,1,1,1,1,1,1,1,1,1
1,1,1,1,1,1,1,1,1,1,1,1,1,1,1,1,1,1,1,1,1,1,1,1,1
1,1,1,1,1,1,1,1,1,1,1,1,1,1,1,1,1,1,1,1,1,1,1,1,1
1,1,1,1,1,1,1,1,1,1,1,1,1,1,1,1,1,1,1,1,1,1,1,1,1
1,1,1,1,1,1,1,1,1,1,1,1,1,1,1,1,1,1,1,1,1,1,1,1,1
1,1,1,1,1,1,1,1,1,1,1,1,1,1,1,1,1,1,1,1,1,1,1,1,1
1,1,1,1,1,1,1,1,1,1,1,1,1,1,1,1,1,1,1,1,1,1,1,1,1
1,1,1,1,1,1,1,1,1,1,1,1,1,1,1,1,1,1,1,1,1,1,1,1,1
1,1,1,1,1,1,1,1,1,1,1,1,1,1,1,1,1,1,1,1,1,1,1,1,1
1,1,1,1,1,1,1,1,1,1,1,1,1,1,1,1,1,1,1,1,1,1,1,1,1
1,1,1,1,1,1,1,1,1,1,1,1,1,1,1,1,1,1,1,1,1,1,1,1,1
1,1,1,1,1,1,1,1,1,1,1,1,1,1,1,1,1,1,1,1,1,1,1,1,1
1,1,1,1,1,1,1,1,1,1,1,1,1,1,1,1,1,1,1,1,1,1,1,1,1
1,1,1,1,1,1,1,1,1,1,1,1,1,1,1,1,1,1,1,1,1,1,1,1,1
1,1,1,1,1,1,1,1,1,1,1,1,1,1,1,1,1,1,1,1,1,1,1,1,1
1,1,1,1,1,1,1,1,1,1,1,1,1,1,1,1,1,1,1,1,1,1,1,1,1
1,1,1,1,1,1,1,1,1,1,1,1,1,1,1,1,1,1,1,1,1,1,1,1,1
1,1,1,1,1,1,1,1,1,1,1,1,1,1,1,1,1,1,1,1,1,1,1,1,1
1,1,1,1,1,1,1,1,1,1,1,1,1,1,1,1,1,1,1,1,1,1,1,1,1
1,1,1,1,1,1,1,1,1,1,1,1,1,1,1,1,1,1,1,1,1,1,1,1,1
:endlayer
layer: 5
1,1,1,1,1,1,1,1,1,1,1,1,1,1,1,1,1,1,1,1,1,1,1,1,1
1,1,1,1,1,1,1,1,1,1,1,1,1,1,1,1,1,1,1,1,1,1,1,1,1
1,1,1,1,1,1,1,1,1,1,1,1,1,1,1,1,1,1,1,1,1,1,1,1,1
1,1,1,1,1,1,1,1,1,1,1,1,1,1,1,1,1,1,1,1,1,1,1,1,1
1,1,1,1,1,1,1,1,1,1,1,1,1,1,1,1,1,1,1,1,1,1,1,1,1
1,1,1,1,1,1,1,1,1,1,1,1,1,1,1,1,1,1,1,1,1,1,1,1,1
1,1,1,1,1,1,1,1,1,1,1,1,1,1,1,1,1,1,1,1,1,1,1,1,1
1,1,1,1,1,1,1,1,1,1,1,1,1,1,1,1,1,1,1,1,1,1,1,1,1
1,1,1,1,1,1,1,1,1,1,1,1,1,1,1,1,1,1,1,1,1,1,1,1,1
1,1,1,1,1,1,1,1,1,1,1,1,1,1,1,1,1,1,1,1,1,1,1,1,1
1,1,1,1,1,1,1,1,1,1,1,1,1,1,1,1,1,1,1,1,1,1,1,1,1
1,1,1,1,1,1,1,1,1,1,1,1,1,1,1,1,1,1,1,1,1,1,1,1,1
1,1,1,1,1,1,1,1,1,1,1,1,1,1,1,1,1,1,1,1,1,1,1,1,1
1,1,1,1,1,1,1,1,1,1,1,1,1,1,1,1,1,1,1,1,1,1,1,1,1
1,1,1,1,1,1,1,1,1,1,1,1,1,1,1,1,1,1,1,1,1,1,1,1,1
1,1,1,1,1,1,1,1,1,1,1,1,2,1,1,1,1,1,1,1,1,1,1,1,1
1,1,1,1,1,1,1,1,1,2,2,2,2,2,2,2,1,1,1,1,1,1,1,1,1
1,1,1,1,1,1,1,1,2,2,118,114,2,10,97,2,2,1,1,1,1,1,1,1,1
1,1,1,1,1,1,1,1,2,122,32,0,2,105,98,76,2,1,1,1,1,1,1,1,1
1,1,1,1,1,1,1,1,2,123,0,0,2,106,99,0,2,1,1,1,1,1,1,1,1
1,1,1,1,1,1,1,1,2,124,0,33,2,107,59,77,2,1,1,1,1,1,1,1,1
1,1,1,1,1,1,1,1,2,2,2,2,31,2,2,2,2,1,1,1,1,1,1,1,1
1,1,1,1,1,1,1,1,2,125,0,0,112,0,0,78,2,1,1,1,1,1,1,1,1
1,1,1,1,1,1,1,1,2,126,0,0,0,0,0,79,2,1,1,1,1,1,1,1,1
1,1,1,1,1,1,1,1,2,127,0,0,0,0,0,80,2,1,1,1,1,1,1,1,1
1,1,1,1,1,1,1,1,2,128,0,0,0,0,0,81,2,1,1,1,1,1,1,1,1
1,1,1,1,1,1,1,1,2,129,0,0,0,0,0,82,2,1,1,1,1,1,1,1,1
1,1,1,1,1,1,1,1,2,130,0,0,0,0,0,83,2,1,1,1,1,1,1,1,1
1,1,1,1,1,1,1,1,2,131,0,0,0,0,0,84,2,1,1,1,1,1,1,1,1
1,1,1,1,1,1,1,1,2,132,0,0,0,0,0,85,2,1,1,1,1,1,1,1,1
1,1,1,1,1,1,1,1,2,133,22,108,33,108,0,86,2,1,1,1,1,1,1,1,1
1,1,1,1,1,1,1,1,2,2,2,2,31,2,2,2,2,1,1,1,1,1,1,1,1
1,1,1,1,1,1,1,1,2,64,66,0,0,0,0,65,2,1,1,1,1,1,1,1,1
1,1,1,1,1,1,1,1,2,134,0,0,0,0,0,87,2,1,1,1,1,1,1,1,1
1,1,1,1,1,1,1,1,2,135,0,0,10,32,10,10,2,1,1,1,1,1,1,1,1
1,1,1,1,1,1,1,1,2,136,0,0,0,0,0,88,2,1,1,1,1,1,1,1,1
1,1,1,1,1,1,1,1,2,137,0,0,0,0,0,66,2,1,1,1,1,1,1,1,1
1,1,1,1,1,1,1,1,2,138,0,0,10,32,10,10,2,1,1,1,1,1,1,1,1
1,1,1,1,1,1,1,1,2,136,0,0,0,0,0,89,2,1,1,1,1,1,1,1,1
1,1,1,1,1,1,1,1,2,139,0,0,10,32,10,10,2,1,1,1,1,1,1,1,1
1,1,1,1,1,1,1,1,2,140,0,0,33,0,0,90,2,1,1,1,1,1,1,1,1
1,1,1,1,1,1,1,1,2,2,2,115,31,2,2,2,2,1,1,1,1,1,1,1,1
1,1,1,1,1,1,1,1,2,141,0,0,112,0,0,91,2,1,1,1,1,1,1,1,1
1,1,1,1,1,1,1,1,2,142,0,0,0,0,0,92,2,1,1,1,1,1,1,1,1
1,1,1,1,1,1,1,1,2,143,0,0,0,0,100,93,2,1,1,1,1,1,1,1,1
1,1,1,1,1,1,1,1,2,144,0,0,0,0,0,94,2,1,1,1,1,1,1,1,1
1,1,1,1,1,1,1,1,2,145,0,0,0,0,0,95,2,1,1,1,1,1,1,1,1
1,1,1,1,1,1,1,1,2,146,0,0,108,0,101,96,2,1,1,1,1,1,1,1,1
1,1,1,1,1,1,1,1,2,2,2,2,31,109,2,2,2,1,1,1,1,1,1,1,1
1,1,1,1,1,1,1,1,2,2,119,0,112,0,102,2,2,1,1,1,1,1,1,1,1
1,1,1,1,1,1,1,1,1,2,2,0,33,0,2,2,1,1,1,1,1,1,1,1,1
1,1,1,1,1,1,1,1,1,2,120,0,31,0,103,2,1,1,1,1,1,1,1,1,1
1,1,1,1,1,1,1,1,1,2,121,0,112,0,104,2,1,1,1,1,1,1,1,1,1
1,1,1,1,1,1,1,1,1,2,2,116,0,110,2,2,1,1,1,1,1,1,1,1,1
1,1,1,1,1,1,1,1,1,1,2,117,0,111,2,1,1,1,1,1,1,1,1,1,1
1,1,1,1,1,1,1,1,1,1,2,2,113,2,2,1,1,1,1,1,1,1,1,1,1
1,1,1,1,1,1,1,1,1,1,1,2,2,2,1,1,1,1,1,1,1,1,1,1,1
1,1,1,1,1,1,1,1,1,1,1,2,2,2,1,1,1,1,1,1,1,1,1,1,1
1,1,1,1,1,1,1,1,1,1,1,1,2,1,1,1,1,1,1,1,1,1,1,1,1
1,1,1,1,1,1,1,1,1,1,1,1,2,1,1,1,1,1,1,1,1,1,1,1,1
1,1,1,1,1,1,1,1,1,1,1,1,2,1,1,1,1,1,1,1,1,1,1,1,1
1,1,1,1,1,1,1,1,1,1,1,1,1,1,1,1,1,1,1,1,1,1,1,1,1
1,1,1,1,1,1,1,1,1,1,1,1,1,1,1,1,1,1,1,1,1,1,1,1,1
1,1,1,1,1,1,1,1,1,1,1,1,1,1,1,1,1,1,1,1,1,1,1,1,1
1,1,1,1,1,1,1,1,1,1,1,1,1,1,1,1,1,1,1,1,1,1,1,1,1
1,1,1,1,1,1,1,1,1,1,1,1,1,1,1,1,1,1,1,1,1,1,1,1,1
1,1,1,1,1,1,1,1,1,1,1,1,1,1,1,1,1,1,1,1,1,1,1,1,1
1,1,1,1,1,1,1,1,1,1,1,1,1,1,1,1,1,1,1,1,1,1,1,1,1
1,1,1,1,1,1,1,1,1,1,1,1,1,1,1,1,1,1,1,1,1,1,1,1,1
1,1,1,1,1,1,1,1,1,1,1,1,1,1,1,1,1,1,1,1,1,1,1,1,1
1,1,1,1,1,1,1,1,1,1,1,1,1,1,1,1,1,1,1,1,1,1,1,1,1
1,1,1,1,1,1,1,1,1,1,1,1,1,1,1,1,1,1,1,1,1,1,1,1,1
1,1,1,1,1,1,1,1,1,1,1,1,1,1,1,1,1,1,1,1,1,1,1,1,1
1,1,1,1,1,1,1,1,1,1,1,1,1,1,1,1,1,1,1,1,1,1,1,1,1
1,1,1,1,1,1,1,1,1,1,1,1,1,1,1,1,1,1,1,1,1,1,1,1,1
1,1,1,1,1,1,1,1,1,1,1,1,1,1,1,1,1,1,1,1,1,1,1,1,1
1,1,1,1,1,1,1,1,1,1,1,1,1,1,1,1,1,1,1,1,1,1,1,1,1
1,1,1,1,1,1,1,1,1,1,1,1,1,1,1,1,1,1,1,1,1,1,1,1,1
1,1,1,1,1,1,1,1,1,1,1,1,1,1,1,1,1,1,1,1,1,1,1,1,1
:endlayer
layer: 6
1,1,1,1,1,1,1,1,1,1,1,1,1,1,1,1,1,1,1,1,1,1,1,1,1
1,1,1,1,1,1,1,1,1,1,1,1,1,1,1,1,1,1,1,1,1,1,1,1,1
1,1,1,1,1,1,1,1,1,1,1,1,1,1,1,1,1,1,1,1,1,1,1,1,1
1,1,1,1,1,1,1,1,1,1,1,1,1,1,1,1,1,1,1,1,1,1,1,1,1
1,1,1,1,1,1,1,1,1,1,1,1,1,1,1,1,1,1,1,1,1,1,1,1,1
1,1,1,1,1,1,1,1,1,1,1,1,1,1,1,1,1,1,1,1,1,1,1,1,1
1,1,1,1,1,1,1,1,1,1,1,1,1,1,1,1,1,1,1,1,1,1,1,1,1
1,1,1,1,1,1,1,1,1,1,1,1,1,1,1,1,1,1,1,1,1,1,1,1,1
1,1,1,1,1,1,1,1,1,1,1,1,1,1,1,1,1,1,1,1,1,1,1,1,1
1,1,1,1,1,1,1,1,1,1,1,1,1,1,1,1,1,1,1,1,1,1,1,1,1
1,1,1,1,1,1,1,1,1,1,1,1,1,1,1,1,1,1,1,1,1,1,1,1,1
1,1,1,1,1,1,1,1,1,1,1,1,1,1,1,1,1,1,1,1,1,1,1,1,1
1,1,1,1,1,1,1,1,1,1,1,1,1,1,1,1,1,1,1,1,1,1,1,1,1
1,1,1,1,1,1,1,1,1,1,1,1,1,1,1,1,1,1,1,1,1,1,1,1,1
1,1,1,1,1,1,1,1,1,1,1,2,2,2,1,1,1,1,1,1,1,1,1,1,1
1,1,1,1,1,1,1,1,2,2,2,2,2,2,2,2,2,1,1,1,1,1,1,1,1
1,1,1,1,1,1,1,2,2,158,158,158,2,156,154,76,76,2,1,1,1,1,1,1,1
1,1,1,1,1,1,1,2,158,158,158,158,2,10,155,0,147,2,1,1,1,1,1,1,1
1,1,1,1,1,1,1,2,158,158,158,158,2,157,0,0,148,2,1,1,1,1,1,1,1
1,1,1,1,1,1,1,2,158,158,158,158,2,107,0,0,149,2,1,1,1,1,1,1,1
1,1,1,1,1,1,1,2,158,158,158,33,2,59,0,0,150,2,1,1,1,1,1,1,1
1,1,1,1,1,1,1,2,2,2,2,2,31,2,2,2,2,2,1,1,1,1,1,1,1
1,1,1,1,1,1,1,2,151,152,152,152,152,152,152,152,151,2,1,1,1,1,1,1,1
1,1,1,1,1,1,1,2,151,152,152,152,152,152,152,152,151,2,1,1,1,1,1,1,1
1,1,1,1,1,1,1,2,151,152,152,152,152,152,152,152,151,2,1,1,1,1,1,1,1
1,1,1,1,1,1,1,2,151,152,152,152,152,152,152,152,151,2,1,1,1,1,1,1,1
1,1,1,1,1,1,1,2,151,152,152,152,152,152,152,152,151,2,1,1,1,1,1,1,1
1,1,1,1,1,1,1,2,151,152,152,152,152,152,152,152,151,2,1,1,1,1,1,1,1
1,1,1,1,1,1,1,2,151,152,152,152,152,152,152,152,151,2,1,1,1,1,1,1,1
1,1,1,1,1,1,1,2,151,152,152,152,152,152,152,152,151,2,1,1,1,1,1,1,1
1,1,1,1,1,1,1,2,151,152,152,152,33,152,152,152,151,2,1,1,1,1,1,1,1
1,1,1,1,1,1,1,2,151,151,151,151,31,151,151,151,151,2,1,1,1,1,1,1,1
1,1,1,1,1,1,1,2,151,152,152,152,152,152,152,152,151,2,1,1,1,1,1,1,1
1,1,1,1,1,1,1,2,151,152,152,152,152,152,152,152,151,2,1,1,1,1,1,1,1
1,1,1,1,1,1,1,2,151,152,152,152,153,152,152,153,151,2,1,1,1,1,1,1,1
1,1,1,1,1,1,1,2,151,152,152,152,152,152,152,152,151,2,1,1,1,1,1,1,1
1,1,1,1,1,1,1,2,151,152,152,152,152,152,152,152,151,2,1,1,1,1,1,1,1
1,1,1,1,1,1,1,2,151,152,152,152,153,152,152,153,151,2,1,1,1,1,1,1,1
1,1,1,1,1,1,1,2,151,152,152,152,152,152,152,152,151,2,1,1,1,1,1,1,1
1,1,1,1,1,1,1,2,151,152,152,152,153,152,152,153,151,2,1,1,1,1,1,1,1
1,1,1,1,1,1,1,2,151,152,152,152,33,152,152,152,151,2,1,1,1,1,1,1,1
1,1,1,1,1,1,1,2,151,151,151,151,31,151,151,151,151,2,1,1,1,1,1,1,1
1,1,1,1,1,1,1,2,151,152,152,152,152,152,152,152,151,2,1,1,1,1,1,1,1
1,1,1,1,1,1,1,2,151,152,152,152,152,152,152,152,151,2,1,1,1,1,1,1,1
1,1,1,1,1,1,1,2,151,152,152,152,152,152,152,152,151,2,1,1,1,1,1,1,1
1,1,1,1,1,1,1,2,151,152,152,152,152,152,152,152,151,2,1,1,1,1,1,1,1
1,1,1,1,1,1,1,2,151,152,152,152,152,152,152,152,151,2,1,1,1,1,1,1,1
1,1,1,1,1,1,1,2,151,152,152,152,152,152,152,152,151,2,1,1,1,1,1,1,1
1,1,1,1,1,1,1,2,2,2,2,2,31,2,2,2,2,2,1,1,1,1,1,1,1
1,1,1,1,1,1,1,1,2,151,152,152,152,152,152,151,2,1,1,1,1,1,1,1,1
1,1,1,1,1,1,1,1,2,151,151,152,33,152,151,151,2,1,1,1,1,1,1,1,1
1,1,1,1,1,1,1,1,2,151,152,152,31,152,152,151,2,1,1,1,1,1,1,1,1
1,1,1,1,1,1,1,1,2,151,152,152,152,152,152,151,2,1,1,1,1,1,1,1,1
1,1,1,1,1,1,1,1,2,151,151,152,152,152,151,151,2,1,1,1,1,1,1,1,1
1,1,1,1,1,1,1,1,1,2,151,152,152,152,151,2,1,1,1,1,1,1,1,1,1
1,1,1,1,1,1,1,1,1,2,151,151,152,151,151,2,1,1,1,1,1,1,1,1,1
1,1,1,1,1,1,1,1,1,1,2,2,151,2,2,1,1,1,1,1,1,1,1,1,1
1,1,1,1,1,1,1,1,1,1,2,2,2,2,2,1,1,1,1,1,1,1,1,1,1
1,1,1,1,1,1,1,1,1,1,1,2,2,2,1,1,1,1,1,1,1,1,1,1,1
1,1,1,1,1,1,1,1,1,1,1,2,2,2,1,1,1,1,1,1,1,1,1,1,1
1,1,1,1,1,1,1,1,1,1,1,2,2,2,1,1,1,1,1,1,1,1,1,1,1
1,1,1,1,1,1,1,1,1,1,1,1,2,1,1,1,1,1,1,1,1,1,1,1,1
1,1,1,1,1,1,1,1,1,1,1,1,2,1,1,1,1,1,1,1,1,1,1,1,1
1,1,1,1,1,1,1,1,1,1,1,1,1,1,1,1,1,1,1,1,1,1,1,1,1
1,1,1,1,1,1,1,1,1,1,1,1,1,1,1,1,1,1,1,1,1,1,1,1,1
1,1,1,1,1,1,1,1,1,1,1,1,1,1,1,1,1,1,1,1,1,1,1,1,1
1,1,1,1,1,1,1,1,1,1,1,1,1,1,1,1,1,1,1,1,1,1,1,1,1
1,1,1,1,1,1,1,1,1,1,1,1,1,1,1,1,1,1,1,1,1,1,1,1,1
1,1,1,1,1,1,1,1,1,1,1,1,1,1,1,1,1,1,1,1,1,1,1,1,1
1,1,1,1,1,1,1,1,1,1,1,1,1,1,1,1,1,1,1,1,1,1,1,1,1
1,1,1,1,1,1,1,1,1,1,1,1,1,1,1,1,1,1,1,1,1,1,1,1,1
1,1,1,1,1,1,1,1,1,1,1,1,1,1,1,1,1,1,1,1,1,1,1,1,1
1,1,1,1,1,1,1,1,1,1,1,1,1,1,1,1,1,1,1,1,1,1,1,1,1
1,1,1,1,1,1,1,1,1,1,1,1,1,1,1,1,1,1,1,1,1,1,1,1,1
1,1,1,1,1,1,1,1,1,1,1,1,1,1,1,1,1,1,1,1,1,1,1,1,1
1,1,1,1,1,1,1,1,1,1,1,1,1,1,1,1,1,1,1,1,1,1,1,1,1
1,1,1,1,1,1,1,1,1,1,1,1,1,1,1,1,1,1,1,1,1,1,1,1,1
1,1,1,1,1,1,1,1,1,1,1,1,1,1,1,1,1,1,1,1,1,1,1,1,1
1,1,1,1,1,1,1,1,1,1,1,1,1,1,1,1,1,1,1,1,1,1,1,1,1
:endlayer
layer: 7
0,0,0,0,0,0,0,0,0,0,0,0,0,0,0,0,0,0,0,0,0,0,0,0,0
0,0,0,0,0,0,0,0,0,0,0,0,0,0,0,0,0,0,0,0,0,0,0,0,0
0,0,0,0,0,0,0,0,0,0,0,0,0,0,0,0,0,0,0,0,0,0,0,0,0
0,0,0,0,0,0,0,0,0,0,0,0,0,0,0,0,0,0,0,0,0,0,0,0,0
0,0,0,0,0,0,0,0,0,0,0,0,0,0,0,0,0,0,0,0,0,0,0,0,0
0,0,0,0,0,0,0,0,0,0,0,0,0,0,0,0,0,0,0,0,0,0,0,0,0
0,0,0,0,0,0,0,0,0,0,0,0,0,0,0,0,0,0,0,0,0,0,0,0,0
0,0,0,0,0,0,0,0,0,0,0,0,0,0,0,0,0,0,0,0,0,0,0,0,0
0,0,0,0,0,0,0,0,0,0,0,0,0,0,0,0,0,0,0,0,0,0,0,0,0
0,0,0,0,0,0,0,0,0,0,0,0,0,0,0,0,0,0,0,0,0,0,0,0,0
0,0,0,0,0,0,0,0,0,0,0,0,0,0,0,0,0,0,0,0,0,0,0,0,0
0,0,0,0,0,0,0,0,0,0,0,0,0,0,0,0,0,0,0,0,0,0,0,0,0
0,0,0,0,0,0,0,0,0,0,0,0,0,0,0,0,0,0,0,0,0,0,0,0,0
0,0,0,0,0,0,0,0,0,251,2,2,2,2,2,160,0,0,0,0,0,0,0,0,0
0,0,0,0,0,0,0,251,2,2,2,234,2,76,76,2,2,160,0,0,0,0,0,0,0
0,0,0,0,0,0,0,2,2,252,234,234,2,215,200,190,10,2,0,0,0,0,0,0,0
0,0,0,0,0,0,159,2,112,0,0,235,2,216,0,191,178,2,159,0,0,0,0,0,0
0,0,0,0,0,0,251,0,259,0,0,236,2,10,0,0,0,161,160,0,0,0,0,0,0
0,0,0,0,0,0,251,0,0,0,247,237,2,107,0,0,0,162,160,0,0,0,0,0,0
0,0,0,0,0,0,251,0,260,0,0,0,2,217,0,0,0,163,160,0,0,0,0,0,0
0,0,0,0,0,0,251,0,0,0,0,33,2,0,0,108,179,164,160,0,0,0,0,0,0
0,0,0,0,0,0,251,2,2,30,48,2,31,2,2,2,2,2,160,0,0,0,0,0,0
0,0,0,0,0,0,251,267,261,0,0,238,228,2,201,192,180,165,160,0,0,0,0,0,0
0,0,0,0,0,0,251,268,262,207,0,0,0,30,0,193,0,166,160,0,0,0,0,0,0
0,0,0,0,0,0,251,269,0,0,0,239,0,48,0,0,0,166,160,0,0,0,0,0,0
0,0,0,0,0,0,251,268,262,207,194,183,172,2,22,0,0,167,160,0,0,0,0,0,0
0,0,0,0,0,0,251,270,263,0,0,0,22,2,202,0,181,168,160,0,0,0,0,0,0
0,0,0,0,0,0,251,268,262,207,194,183,172,2,2,0,2,2,160,0,0,0,0,0,0
0,0,0,0,0,0,251,271,0,0,0,240,229,2,203,0,0,169,160,0,0,0,0,0,0
0,0,0,0,0,0,251,268,262,207,194,183,172,2,204,0,0,170,160,0,0,0,0,0,0
0,0,0,0,0,0,251,203,264,0,0,0,33,2,205,0,182,171,160,0,0,0,0,0,0
0,0,0,0,0,0,251,2,2,0,0,2,31,2,2,2,2,2,160,0,0,0,0,0,0
0,0,0,0,0,0,251,253,253,253,0,0,10,218,206,10,0,22,160,0,0,0,0,0,0
0,0,0,0,0,0,251,254,254,254,0,0,5,219,0,194,183,172,160,0,0,0,0,0,0
0,0,0,0,0,0,251,253,253,253,248,0,0,220,0,195,0,173,160,0,0,0,0,0,0
0,0,0,0,0,0,251,253,253,253,0,194,183,172,207,194,183,172,160,0,0,0,0,0,0
0,0,0,0,0,0,251,254,254,254,249,0,0,0,0,196,0,174,160,0,0,0,0,0,0
0,0,0,0,0,0,251,253,253,253,0,194,183,172,207,194,183,172,160,0,0,0,0,0,0
0,0,0,0,0,0,251,253,253,253,250,241,0,0,0,0,184,22,160,0,0,0,0,0,0
0,0,0,0,0,0,251,254,254,254,0,194,183,172,207,194,183,172,160,0,0,0,0,0,0
0,0,0,0,0,0,251,253,253,253,0,0,33,0,208,0,0,175,160,0,0,0,0,0,0
0,0,0,0,0,0,251,2,2,2,2,2,31,0,2,2,2,2,160,0,0,0,0,0,0
0,0,0,0,0,0,251,272,0,0,209,231,209,0,209,0,0,176,160,0,0,0,0,0,0
0,0,0,0,0,0,251,268,262,207,210,0,210,0,210,194,183,172,160,0,0,0,0,0,0
0,0,0,0,0,0,251,273,0,255,211,0,211,0,211,0,185,177,160,0,0,0,0,0,0
0,0,0,0,0,0,251,268,262,207,212,242,212,0,212,194,183,172,160,0,0,0,0,0,0
0,0,0,0,0,0,251,136,0,0,213,0,213,0,213,0,0,22,160,0,0,0,0,0,0
0,0,0,0,0,0,159,2,265,207,214,22,214,221,214,194,186,2,159,0,0,0,0,0,0
0,0,0,0,0,0,0,2,2,2,2,2,31,2,2,2,2,2,0,0,0,0,0,0,0
0,0,0,0,0,0,0,2,266,256,0,243,230,222,59,0,187,2,0,0,0,0,0,0,0
0,0,0,0,0,0,0,2,266,256,0,0,33,0,0,0,188,2,0,0,0,0,0,0,0
0,0,0,0,0,0,0,159,258,257,0,0,31,223,0,197,189,159,0,0,0,0,0,0,0
0,0,0,0,0,0,0,159,258,198,0,0,0,0,0,198,189,159,0,0,0,0,0,0,0
0,0,0,0,0,0,0,0,258,199,0,244,0,0,0,199,189,0,0,0,0,0,0,0,0
0,0,0,0,0,0,0,0,2,258,166,203,166,0,198,189,2,0,0,0,0,0,0,0,0
0,0,0,0,0,0,0,0,2,258,166,203,166,224,199,189,2,0,0,0,0,0,0,0,0
0,0,0,0,0,0,0,0,159,2,2,2,2,2,2,2,159,0,0,0,0,0,0,0,0
0,0,0,0,0,0,0,0,0,2,2,245,231,225,2,2,0,0,0,0,0,0,0,0,0
0,0,0,0,0,0,0,0,0,159,2,246,0,226,2,159,0,0,0,0,0,0,0,0,0
0,0,0,0,0,0,0,0,0,0,2,2,232,2,2,0,0,0,0,0,0,0,0,0,0
0,0,0,0,0,0,0,0,0,0,159,2,233,2,159,0,0,0,0,0,0,0,0,0,0
0,0,0,0,0,0,0,0,0,0,0,2,2,2,0,0,0,0,0,0,0,0,0,0,0
0,0,0,0,0,0,0,0,0,0,0,227,2,227,0,0,0,0,0,0,0,0,0,0,0
0,0,0,0,0,0,0,0,0,0,0,0,227,0,0,0,0,0,0,0,0,0,0,0,0
0,0,0,0,0,0,0,0,0,0,0,0,0,0,0,0,0,0,0,0,0,0,0,0,0
0,0,0,0,0,0,0,0,0,0,0,0,0,0,0,0,0,0,0,0,0,0,0,0,0
0,0,0,0,0,0,0,0,0,0,0,0,0,0,0,0,0,0,0,0,0,0,0,0,0
0,0,0,0,0,0,0,0,0,0,0,0,0,0,0,0,0,0,0,0,0,0,0,0,0
0,0,0,0,0,0,0,0,0,0,0,0,0,0,0,0,0,0,0,0,0,0,0,0,0
0,0,0,0,0,0,0,0,0,0,0,0,0,0,0,0,0,0,0,0,0,0,0,0,0
0,0,0,0,0,0,0,0,0,0,0,0,0,0,0,0,0,0,0,0,0,0,0,0,0
0,0,0,0,0,0,0,0,0,0,0,0,0,0,0,0,0,0,0,0,0,0,0,0,0
0,0,0,0,0,0,0,0,0,0,0,0,0,0,0,0,0,0,0,0,0,0,0,0,0
0,0,0,0,0,0,0,0,0,0,0,0,0,0,0,0,0,0,0,0,0,0,0,0,0
0,0,0,0,0,0,0,0,0,0,0,0,0,0,0,0,0,0,0,0,0,0,0,0,0
0,0,0,0,0,0,0,0,0,0,0,0,0,0,0,0,0,0,0,0,0,0,0,0,0
0,0,0,0,0,0,0,0,0,0,0,0,0,0,0,0,0,0,0,0,0,0,0,0,0
0,0,0,0,0,0,0,0,0,0,0,0,0,0,0,0,0,0,0,0,0,0,0,0,0
0,0,0,0,0,0,0,0,0,0,0,0,0,0,0,0,0,0,0,0,0,0,0,0,0
:endlayer
layer: 8
0,0,0,0,0,0,0,0,0,0,0,0,0,0,0,0,0,0,0,0,0,0,0,0,0
0,0,0,0,0,0,0,0,0,0,0,0,0,0,0,0,0,0,0,0,0,0,0,0,0
0,0,0,0,0,0,0,0,0,0,0,0,0,0,0,0,0,0,0,0,0,0,0,0,0
0,0,0,0,0,0,0,0,0,0,0,0,0,0,0,0,0,0,0,0,0,0,0,0,0
0,0,0,0,0,0,0,0,0,0,0,0,0,0,0,0,0,0,0,0,0,0,0,0,0
0,0,0,0,0,0,0,0,0,0,0,0,0,0,0,0,0,0,0,0,0,0,0,0,0
0,0,0,0,0,0,0,0,0,0,0,0,0,0,0,0,0,0,0,0,0,0,0,0,0
0,0,0,0,0,0,0,0,0,0,0,0,0,0,0,0,0,0,0,0,0,0,0,0,0
0,0,0,0,0,0,0,0,0,0,0,0,0,0,0,0,0,0,0,0,0,0,0,0,0
0,0,0,0,0,0,0,0,0,0,0,0,0,0,0,0,0,0,0,0,0,0,0,0,0
0,0,0,0,0,0,0,0,0,0,0,0,0,0,0,0,0,0,0,0,0,0,0,0,0
0,0,0,0,0,0,0,0,0,0,0,0,159,0,0,0,0,0,0,0,0,0,0,0,0
0,0,0,0,0,0,0,0,251,2,2,2,2,2,2,2,160,0,0,0,0,0,0,0,0
0,0,0,0,0,0,274,2,2,2,234,234,2,294,287,2,2,2,274,0,0,0,0,0,0
0,0,0,0,0,0,275,2,308,234,234,0,2,10,288,286,284,2,275,0,0,0,0,0,0
0,0,0,0,0,0,275,309,0,0,0,0,2,295,0,0,10,278,275,0,0,0,0,0,0
0,0,0,0,0,0,275,310,0,0,0,0,2,296,0,0,0,279,275,0,0,0,0,0,0
0,0,0,0,0,0,275,136,0,0,0,178,2,107,0,0,0,280,275,0,0,0,0,0,0
0,0,0,0,0,0,276,0,0,0,0,0,2,217,0,0,0,281,276,0,0,0,0,0,0
0,0,0,0,0,0,275,136,0,0,0,178,2,0,0,0,0,282,275,0,0,0,0,0,0
0,0,0,0,0,0,276,0,108,0,0,33,2,0,0,0,0,0,276,0,0,0,0,0,0
0,0,0,0,0,0,275,2,2,109,115,2,31,2,2,2,2,2,275,0,0,0,0,0,0
0,0,0,0,0,0,276,0,112,0,0,302,300,275,0,0,0,0,276,0,0,0,0,0,0
0,0,0,0,0,0,275,268,262,207,0,0,0,109,0,0,0,178,275,0,0,0,0,0,0
0,0,0,0,0,0,276,283,0,0,0,0,0,115,0,0,0,0,276,0,0,0,0,0,0
0,0,0,0,0,0,275,268,262,207,194,183,172,275,289,0,0,178,275,0,0,0,0,0,0
0,0,0,0,0,0,276,0,0,0,0,0,178,275,290,0,0,0,276,0,0,0,0,0,0
0,0,0,0,0,0,275,268,262,207,194,183,172,275,275,0,275,275,275,0,0,0,0,0,0
0,0,0,0,0,0,276,0,0,0,0,0,178,275,283,0,0,0,276,0,0,0,0,0,0
0,0,0,0,0,0,275,268,262,207,194,183,172,275,0,0,0,0,275,0,0,0,0,0,0
0,0,0,0,0,0,276,0,0,0,0,0,33,275,0,0,108,0,276,0,0,0,0,0,0
0,0,0,0,0,0,275,275,275,0,0,275,31,275,275,275,275,275,275,0,0,0,0,0,0
0,0,0,0,0,0,276,0,112,0,0,112,10,297,291,10,112,0,276,0,0,0,0,0,0
0,0,0,0,0,0,275,136,0,0,0,0,0,5,219,194,183,172,275,0,0,0,0,0,0
0,0,0,0,0,0,276,0,0,0,0,0,0,0,0,0,0,0,276,0,0,0,0,0,0
0,0,0,0,0,0,275,136,0,0,0,194,183,172,207,194,183,172,275,0,0,0,0,0,0
0,0,0,0,0,0,276,0,0,0,0,0,0,0,0,0,0,0,276,0,0,0,0,0,0
0,0,0,0,0,0,275,136,0,0,0,194,183,172,207,194,183,172,275,0,0,0,0,0,0
0,0,0,0,0,0,276,0,0,0,0,0,0,0,0,0,0,283,276,0,0,0,0,0,0
0,0,0,0,0,0,275,136,0,307,0,194,183,172,207,194,183,172,275,0,0,0,0,0,0
0,0,0,0,0,0,276,0,0,0,108,0,33,0,108,0,0,0,276,0,0,0,0,0,0
0,0,0,0,0,0,275,275,275,275,275,275,31,0,275,275,275,275,275,0,0,0,0,0,0
0,0,0,0,0,0,276,0,0,112,209,231,209,0,209,112,0,0,276,0,0,0,0,0,0
0,0,0,0,0,0,275,268,262,207,210,0,210,0,210,194,183,172,275,0,0,0,0,0,0
0,0,0,0,0,0,276,0,0,0,211,0,211,0,211,0,0,0,276,0,0,0,0,0,0
0,0,0,0,0,0,275,268,262,207,212,0,212,0,212,194,183,172,275,0,0,0,0,0,0
0,0,0,0,0,0,276,0,0,0,213,0,213,0,213,0,0,283,276,0,0,0,0,0,0
0,0,0,0,0,0,275,268,262,207,214,108,214,108,214,194,183,172,275,0,0,0,0,0,0
0,0,0,0,0,0,275,275,275,275,275,275,31,275,275,275,275,275,275,0,0,0,0,0,0
0,0,0,0,0,0,277,275,136,0,0,0,153,59,0,0,178,275,277,0,0,0,0,0,0
0,0,0,0,0,0,0,276,0,0,0,0,33,0,0,0,0,276,0,0,0,0,0,0,0
0,0,0,0,0,0,0,275,136,0,0,0,31,0,0,0,178,275,0,0,0,0,0,0,0
0,0,0,0,0,0,0,276,0,0,0,0,112,0,0,0,0,276,0,0,0,0,0,0,0
0,0,0,0,0,0,0,275,136,0,0,0,0,0,0,0,178,275,0,0,0,0,0,0,0
0,0,0,0,0,0,0,277,275,136,0,0,0,0,0,178,275,277,0,0,0,0,0,0,0
0,0,0,0,0,0,0,0,276,0,0,0,0,0,0,0,276,0,0,0,0,0,0,0,0
0,0,0,0,0,0,0,0,275,275,275,275,275,275,275,275,275,0,0,0,0,0,0,0,0
0,0,0,0,0,0,0,0,285,275,305,112,231,112,292,275,285,0,0,0,0,0,0,0,0
0,0,0,0,0,0,0,0,0,275,306,0,0,0,293,275,0,0,0,0,0,0,0,0,0
0,0,0,0,0,0,0,0,0,285,275,303,0,298,275,285,0,0,0,0,0,0,0,0,0
0,0,0,0,0,0,0,0,0,0,275,304,0,299,275,0,0,0,0,0,0,0,0,0,0
0,0,0,0,0,0,0,0,0,0,285,275,301,275,285,0,0,0,0,0,0,0,0,0,0
0,0,0,0,0,0,0,0,0,0,0,275,275,275,0,0,0,0,0,0,0,0,0,0,0
0,0,0,0,0,0,0,0,0,0,0,0,275,0,0,0,0,0,0,0,0,0,0,0,0
0,0,0,0,0,0,0,0,0,0,0,0,0,0,0,0,0,0,0,0,0,0,0,0,0
0,0,0,0,0,0,0,0,0,0,0,0,0,0,0,0,0,0,0,0,0,0,0,0,0
0,0,0,0,0,0,0,0,0,0,0,0,0,0,0,0,0,0,0,0,0,0,0,0,0
0,0,0,0,0,0,0,0,0,0,0,0,0,0,0,0,0,0,0,0,0,0,0,0,0
0,0,0,0,0,0,0,0,0,0,0,0,0,0,0,0,0,0,0,0,0,0,0,0,0
0,0,0,0,0,0,0,0,0,0,0,0,0,0,0,0,0,0,0,0,0,0,0,0,0
0,0,0,0,0,0,0,0,0,0,0,0,0,0,0,0,0,0,0,0,0,0,0,0,0
0,0,0,0,0,0,0,0,0,0,0,0,0,0,0,0,0,0,0,0,0,0,0,0,0
0,0,0,0,0,0,0,0,0,0,0,0,0,0,0,0,0,0,0,0,0,0,0,0,0
0,0,0,0,0,0,0,0,0,0,0,0,0,0,0,0,0,0,0,0,0,0,0,0,0
0,0,0,0,0,0,0,0,0,0,0,0,0,0,0,0,0,0,0,0,0,0,0,0,0
0,0,0,0,0,0,0,0,0,0,0,0,0,0,0,0,0,0,0,0,0,0,0,0,0
0,0,0,0,0,0,0,0,0,0,0,0,0,0,0,0,0,0,0,0,0,0,0,0,0
0,0,0,0,0,0,0,0,0,0,0,0,0,0,0,0,0,0,0,0,0,0,0,0,0
0,0,0,0,0,0,0,0,0,0,0,0,0,0,0,0,0,0,0,0,0,0,0,0,0
:endlayer
layer: 9
0,0,0,0,0,0,0,0,0,0,0,0,0,0,0,0,0,0,0,0,0,0,0,0,0
0,0,0,0,0,0,0,0,0,0,0,0,0,0,0,0,0,0,0,0,0,0,0,0,0
0,0,0,0,0,0,0,0,0,0,0,0,0,0,0,0,0,0,0,0,0,0,0,0,0
0,0,0,0,0,0,0,0,0,0,0,0,0,0,0,0,0,0,0,0,0,0,0,0,0
0,0,0,0,0,0,0,0,0,0,0,0,0,0,0,0,0,0,0,0,0,0,0,0,0
0,0,0,0,0,0,0,0,0,0,0,0,0,0,0,0,0,0,0,0,0,0,0,0,0
0,0,0,0,0,0,0,0,0,0,0,0,0,0,0,0,0,0,0,0,0,0,0,0,0
0,0,0,0,0,0,0,0,0,0,0,0,0,0,0,0,0,0,0,0,0,0,0,0,0
0,0,0,0,0,0,0,0,0,0,0,0,0,0,0,0,0,0,0,0,0,0,0,0,0
0,0,0,0,0,0,0,0,0,0,0,0,0,0,0,0,0,0,0,0,0,0,0,0,0
0,0,0,0,0,0,0,0,0,0,0,0,0,0,0,0,0,0,0,0,0,0,0,0,0
0,0,0,0,0,0,0,0,0,159,2,2,2,2,2,159,0,0,0,0,0,0,0,0,0
0,0,0,0,0,0,0,251,2,2,2,2,312,2,2,2,2,160,0,0,0,0,0,0,0
0,0,0,0,0,0,2,2,151,151,152,152,312,152,152,151,151,2,2,0,0,0,0,0,0
0,0,0,0,0,0,2,151,152,152,152,152,312,219,152,152,152,151,2,0,0,0,0,0,0
0,0,0,0,0,0,2,152,152,152,152,152,312,219,152,152,151,152,2,0,0,0,0,0,0
0,0,0,0,0,0,2,152,152,152,152,152,312,107,152,152,152,152,2,0,0,0,0,0,0
0,0,0,0,0,0,2,152,152,152,152,152,312,217,152,152,152,152,2,0,0,0,0,0,0
0,0,0,0,0,0,2,152,152,152,152,152,312,0,152,152,152,152,2,0,0,0,0,0,0
0,0,0,0,0,0,2,152,152,152,152,152,312,0,152,152,152,152,2,0,0,0,0,0,0
0,0,0,0,0,0,2,152,152,152,152,152,312,0,152,152,152,152,2,0,0,0,0,0,0
0,0,0,0,0,0,2,151,151,151,151,151,31,151,151,151,151,151,2,0,0,0,0,0,0
0,0,0,0,0,0,2,152,152,152,152,152,152,151,152,152,152,152,2,0,0,0,0,0,0
0,0,0,0,0,0,2,152,152,152,152,152,152,151,152,152,152,152,2,0,0,0,0,0,0
0,0,0,0,0,0,2,152,152,152,152,152,152,151,152,152,152,152,2,0,0,0,0,0,0
0,0,0,0,0,0,2,152,152,152,152,152,152,151,152,152,152,152,2,0,0,0,0,0,0
0,0,0,0,0,0,2,152,152,152,152,152,152,151,152,152,152,152,2,0,0,0,0,0,0
0,0,0,0,0,0,2,152,152,152,152,152,152,151,151,151,151,151,2,0,0,0,0,0,0
0,0,0,0,0,0,2,152,152,152,152,152,152,151,152,152,152,152,2,0,0,0,0,0,0
0,0,0,0,0,0,2,152,152,152,152,152,152,151,152,152,152,152,2,0,0,0,0,0,0
0,0,0,0,0,0,2,152,152,152,152,152,152,151,152,152,152,152,2,0,0,0,0,0,0
0,0,0,0,0,0,2,151,151,151,151,151,31,151,151,151,151,151,2,0,0,0,0,0,0
0,0,0,0,0,0,2,152,152,152,152,152,311,311,311,311,311,311,2,0,0,0,0,0,0
0,0,0,0,0,0,2,152,152,152,152,0,0,0,5,219,152,152,2,0,0,0,0,0,0
0,0,0,0,0,0,2,152,152,152,152,152,152,152,152,152,152,152,2,0,0,0,0,0,0
0,0,0,0,0,0,2,152,152,152,152,152,152,152,152,152,152,152,2,0,0,0,0,0,0
0,0,0,0,0,0,2,152,152,152,152,152,152,152,152,152,152,152,2,0,0,0,0,0,0
0,0,0,0,0,0,2,152,152,152,152,152,152,152,152,152,152,152,2,0,0,0,0,0,0
0,0,0,0,0,0,2,152,152,152,152,152,152,152,152,152,152,152,2,0,0,0,0,0,0
0,0,0,0,0,0,2,152,152,152,152,152,152,152,152,152,152,152,2,0,0,0,0,0,0
0,0,0,0,0,0,2,152,152,152,152,152,33,152,152,152,152,152,2,0,0,0,0,0,0
0,0,0,0,0,0,2,151,151,151,151,151,31,151,151,151,151,151,2,0,0,0,0,0,0
0,0,0,0,0,0,2,152,152,152,152,152,152,152,152,152,152,152,2,0,0,0,0,0,0
0,0,0,0,0,0,2,152,152,152,152,152,152,152,152,152,152,152,2,0,0,0,0,0,0
0,0,0,0,0,0,2,152,152,152,152,152,152,152,152,152,152,152,2,0,0,0,0,0,0
0,0,0,0,0,0,2,152,152,152,152,152,152,152,152,152,152,152,2,0,0,0,0,0,0
0,0,0,0,0,0,2,152,152,152,152,152,152,152,152,152,152,152,2,0,0,0,0,0,0
0,0,0,0,0,0,2,152,152,152,152,152,152,152,152,152,152,152,2,0,0,0,0,0,0
0,0,0,0,0,0,2,2,2,2,2,2,31,2,2,2,2,2,2,0,0,0,0,0,0
0,0,0,0,0,0,2,2,152,152,152,153,59,0,0,0,0,2,2,0,0,0,0,0,0
0,0,0,0,0,0,2,2,152,152,152,152,152,152,152,152,152,2,2,0,0,0,0,0,0
0,0,0,0,0,0,159,2,152,152,152,152,31,152,152,152,152,2,159,0,0,0,0,0,0
0,0,0,0,0,0,0,2,152,152,152,152,152,152,152,152,152,2,0,0,0,0,0,0,0
0,0,0,0,0,0,0,2,152,152,152,152,152,152,152,152,152,2,0,0,0,0,0,0,0
0,0,0,0,0,0,0,2,2,152,152,152,152,152,152,152,2,2,0,0,0,0,0,0,0
0,0,0,0,0,0,0,227,2,152,152,152,152,152,152,152,2,227,0,0,0,0,0,0,0
0,0,0,0,0,0,0,0,2,2,2,2,2,2,2,2,2,0,0,0,0,0,0,0,0
0,0,0,0,0,0,0,0,2,2,152,152,231,152,152,2,2,0,0,0,0,0,0,0,0
0,0,0,0,0,0,0,0,227,2,152,152,152,152,152,2,227,0,0,0,0,0,0,0,0
0,0,0,0,0,0,0,0,0,2,2,152,152,152,2,2,0,0,0,0,0,0,0,0,0
0,0,0,0,0,0,0,0,0,227,2,152,152,152,2,227,0,0,0,0,0,0,0,0,0
0,0,0,0,0,0,0,0,0,0,2,2,152,2,2,0,0,0,0,0,0,0,0,0,0
0,0,0,0,0,0,0,0,0,0,227,2,2,2,227,0,0,0,0,0,0,0,0,0,0
0,0,0,0,0,0,0,0,0,0,0,227,2,227,0,0,0,0,0,0,0,0,0,0,0
0,0,0,0,0,0,0,0,0,0,0,0,227,0,0,0,0,0,0,0,0,0,0,0,0
0,0,0,0,0,0,0,0,0,0,0,0,0,0,0,0,0,0,0,0,0,0,0,0,0
0,0,0,0,0,0,0,0,0,0,0,0,0,0,0,0,0,0,0,0,0,0,0,0,0
0,0,0,0,0,0,0,0,0,0,0,0,0,0,0,0,0,0,0,0,0,0,0,0,0
0,0,0,0,0,0,0,0,0,0,0,0,0,0,0,0,0,0,0,0,0,0,0,0,0
0,0,0,0,0,0,0,0,0,0,0,0,0,0,0,0,0,0,0,0,0,0,0,0,0
0,0,0,0,0,0,0,0,0,0,0,0,0,0,0,0,0,0,0,0,0,0,0,0,0
0,0,0,0,0,0,0,0,0,0,0,0,0,0,0,0,0,0,0,0,0,0,0,0,0
0,0,0,0,0,0,0,0,0,0,0,0,0,0,0,0,0,0,0,0,0,0,0,0,0
0,0,0,0,0,0,0,0,0,0,0,0,0,0,0,0,0,0,0,0,0,0,0,0,0
0,0,0,0,0,0,0,0,0,0,0,0,0,0,0,0,0,0,0,0,0,0,0,0,0
0,0,0,0,0,0,0,0,0,0,0,0,0,0,0,0,0,0,0,0,0,0,0,0,0
0,0,0,0,0,0,0,0,0,0,0,0,0,0,0,0,0,0,0,0,0,0,0,0,0
0,0,0,0,0,0,0,0,0,0,0,0,0,0,0,0,0,0,0,0,0,0,0,0,0
0,0,0,0,0,0,0,0,0,0,0,0,0,0,0,0,0,0,0,0,0,0,0,0,0
:endlayer
layer: 10
0,0,0,0,0,0,0,0,0,0,0,0,0,0,0,0,0,0,0,0,0,0,0,0,0
0,0,0,0,0,0,0,0,0,0,0,0,0,0,0,0,0,0,0,0,0,0,0,0,0
0,0,0,0,0,0,0,0,0,0,0,0,0,0,0,0,0,0,0,0,0,0,0,0,0
0,0,0,0,0,0,0,0,0,0,0,0,0,0,0,0,0,0,0,0,0,0,0,0,0
0,0,0,0,0,0,0,0,0,0,0,0,0,0,0,0,0,0,0,0,0,0,0,0,0
0,0,0,0,0,0,0,0,0,0,0,0,0,0,0,0,0,0,0,0,0,0,0,0,0
0,0,0,0,0,0,0,0,0,0,0,0,0,0,0,0,0,0,0,0,0,0,0,0,0
0,0,0,0,0,0,0,0,0,0,0,0,0,0,0,0,0,0,0,0,0,0,0,0,0
0,0,0,0,0,0,0,0,0,0,0,0,0,0,0,0,0,0,0,0,0,0,0,0,0
0,0,0,0,0,0,0,0,0,0,0,0,0,0,0,0,0,0,0,0,0,0,0,0,0
0,0,0,0,0,0,0,0,0,0,159,350,350,350,159,0,0,0,0,0,0,0,0,0,0
0,0,0,0,0,0,0,159,2,2,2,2,31,2,2,2,2,159,0,0,0,0,0,0,0
0,0,0,0,0,0,251,2,203,0,0,368,2,68,341,333,324,2,160,0,0,0,0,0,0
0,0,0,0,0,159,2,400,0,0,0,369,2,351,342,334,0,10,2,159,0,0,0,0,0
0,0,0,0,0,251,22,0,0,0,0,0,2,352,0,0,0,0,68,160,0,0,0,0,0
0,0,0,0,0,251,2,2,2,2,30,2,2,10,0,68,68,0,68,160,0,0,0,0,0
0,0,0,0,0,251,407,212,212,0,0,234,2,0,0,252,68,0,68,160,0,0,0,0,0
0,0,0,0,0,251,194,401,394,207,380,234,2,0,0,252,68,0,68,160,0,0,0,0,0
0,0,0,0,0,251,0,211,211,0,0,234,2,0,0,68,68,0,68,160,0,0,0,0,0
0,0,0,0,0,251,252,402,0,0,381,370,2,0,0,0,0,0,68,160,0,0,0,0,0
0,0,0,0,0,251,2,2,30,48,2,2,2,350,2,0,325,0,2,160,0,0,0,0,0
0,0,0,0,0,251,408,0,0,0,382,371,31,313,313,313,0,313,313,160,0,0,0,0,0
0,0,0,0,0,251,409,0,395,0,10,10,2,203,203,203,0,203,203,160,0,0,0,0,0
0,0,0,0,0,251,68,0,0,0,382,371,2,313,313,313,0,313,313,160,0,0,0,0,0
0,0,0,0,0,251,68,403,0,0,10,10,2,353,0,0,326,313,313,160,0,0,0,0,0
0,0,0,0,0,251,68,0,396,0,382,371,2,313,313,313,0,203,203,160,0,0,0,0,0
0,0,0,0,0,251,68,0,0,0,10,10,2,203,203,203,327,313,313,160,0,0,0,0,0
0,0,0,0,0,251,68,0,0,0,382,371,2,313,313,313,0,313,313,160,0,0,0,0,0
0,0,0,0,0,251,68,0,0,0,10,10,2,354,0,0,0,203,203,160,0,0,0,0,0
0,0,0,0,0,251,68,0,397,0,382,371,2,313,313,313,0,313,313,160,0,0,0,0,0
0,0,0,0,0,251,410,0,0,387,10,10,2,203,203,203,0,0,0,160,0,0,0,0,0
0,0,0,0,0,251,411,0,0,0,382,371,31,313,313,313,0,319,314,160,0,0,0,0,0
0,0,0,0,0,251,2,0,0,2,2,2,2,2,2,335,0,0,2,160,0,0,0,0,0
0,0,0,0,0,251,22,0,0,388,10,0,0,0,0,0,0,0,315,160,0,0,0,0,0
0,0,0,0,0,251,268,262,0,0,31,372,362,355,31,336,0,183,172,160,0,0,0,0,0
0,0,0,0,0,251,22,0,0,389,383,107,107,107,343,337,0,0,316,160,0,0,0,0,0
0,0,0,0,0,251,268,262,0,0,31,217,217,217,31,0,0,183,172,160,0,0,0,0,0
0,0,0,0,0,251,412,0,0,0,0,0,363,0,0,0,0,0,317,160,0,0,0,0,0
0,0,0,0,0,251,268,262,0,0,384,0,0,0,344,0,0,183,172,160,0,0,0,0,0
0,0,0,0,0,251,22,0,0,0,0,0,0,0,0,0,0,0,318,160,0,0,0,0,0
0,0,0,0,0,251,268,262,0,0,31,0,33,0,31,0,0,183,172,160,0,0,0,0,0
0,0,0,0,0,251,413,0,0,0,0,373,31,356,10,0,328,0,22,160,0,0,0,0,0
0,0,0,0,0,251,2,0,398,0,0,2,2,2,2,2,2,2,2,160,0,0,0,0,0
0,0,0,0,0,251,414,0,0,0,0,320,0,0,320,0,0,320,0,160,0,0,0,0,0
0,0,0,0,0,251,158,0,0,0,385,0,0,0,0,0,0,0,0,160,0,0,0,0,0
0,0,0,0,0,251,158,0,0,0,0,374,0,357,345,0,0,321,0,160,0,0,0,0,0
0,0,0,0,0,251,158,0,0,0,0,375,0,0,0,0,329,0,0,160,0,0,0,0,0
0,0,0,0,0,251,414,404,0,0,0,203,203,203,346,338,330,0,0,160,0,0,0,0,0
0,0,0,0,0,251,2,2,0,390,0,2,31,2,2,2,2,2,2,160,0,0,0,0,0
0,0,0,0,0,159,2,252,0,0,0,0,0,0,0,0,0,322,2,159,0,0,0,0,0
0,0,0,0,0,0,2,405,313,313,0,0,10,10,10,10,10,10,2,0,0,0,0,0,0
0,0,0,0,0,0,2,406,203,203,0,0,31,204,203,204,0,323,2,0,0,0,0,0,0
0,0,0,0,0,0,2,2,313,313,0,0,0,0,347,0,331,22,2,0,0,0,0,0,0
0,0,0,0,0,0,227,2,10,0,0,376,332,332,332,332,332,2,227,0,0,0,0,0,0
0,0,0,0,0,0,0,2,399,0,0,0,31,0,0,0,67,2,0,0,0,0,0,0,0
0,0,0,0,0,0,0,2,2,391,0,0,364,0,0,252,2,2,0,0,0,0,0,0,0
0,0,0,0,0,0,0,227,2,2,30,2,2,2,2,2,2,227,0,0,0,0,0,0,0
0,0,0,0,0,0,0,0,2,392,0,0,231,358,348,339,2,0,0,0,0,0,0,0,0
0,0,0,0,0,0,0,0,2,393,0,0,0,0,0,340,2,0,0,0,0,0,0,0,0
0,0,0,0,0,0,0,0,227,2,386,377,365,359,349,2,227,0,0,0,0,0,0,0,0
0,0,0,0,0,0,0,0,0,2,2,378,366,360,2,2,0,0,0,0,0,0,0,0,0
0,0,0,0,0,0,0,0,0,227,2,379,0,361,2,227,0,0,0,0,0,0,0,0,0
0,0,0,0,0,0,0,0,0,0,2,2,367,2,2,0,0,0,0,0,0,0,0,0,0
0,0,0,0,0,0,0,0,0,0,0,2,2,2,0,0,0,0,0,0,0,0,0,0,0
0,0,0,0,0,0,0,0,0,0,0,0,2,0,0,0,0,0,0,0,0,0,0,0,0
0,0,0,0,0,0,0,0,0,0,0,0,0,0,0,0,0,0,0,0,0,0,0,0,0
0,0,0,0,0,0,0,0,0,0,0,0,0,0,0,0,0,0,0,0,0,0,0,0,0
0,0,0,0,0,0,0,0,0,0,0,0,0,0,0,0,0,0,0,0,0,0,0,0,0
0,0,0,0,0,0,0,0,0,0,0,0,0,0,0,0,0,0,0,0,0,0,0,0,0
0,0,0,0,0,0,0,0,0,0,0,0,0,0,0,0,0,0,0,0,0,0,0,0,0
0,0,0,0,0,0,0,0,0,0,0,0,0,0,0,0,0,0,0,0,0,0,0,0,0
0,0,0,0,0,0,0,0,0,0,0,0,0,0,0,0,0,0,0,0,0,0,0,0,0
0,0,0,0,0,0,0,0,0,0,0,0,0,0,0,0,0,0,0,0,0,0,0,0,0
0,0,0,0,0,0,0,0,0,0,0,0,0,0,0,0,0,0,0,0,0,0,0,0,0
0,0,0,0,0,0,0,0,0,0,0,0,0,0,0,0,0,0,0,0,0,0,0,0,0
0,0,0,0,0,0,0,0,0,0,0,0,0,0,0,0,0,0,0,0,0,0,0,0,0
0,0,0,0,0,0,0,0,0,0,0,0,0,0,0,0,0,0,0,0,0,0,0,0,0
0,0,0,0,0,0,0,0,0,0,0,0,0,0,0,0,0,0,0,0,0,0,0,0,0
0,0,0,0,0,0,0,0,0,0,0,0,0,0,0,0,0,0,0,0,0,0,0,0,0
:endlayer
layer: 11
0,0,0,0,0,0,0,0,0,0,0,0,0,0,0,0,0,0,0,0,0,0,0,0,0
0,0,0,0,0,0,0,0,0,0,0,0,0,0,0,0,0,0,0,0,0,0,0,0,0
0,0,0,0,0,0,0,0,0,0,0,0,0,0,0,0,0,0,0,0,0,0,0,0,0
0,0,0,0,0,0,0,0,0,0,0,0,0,0,0,0,0,0,0,0,0,0,0,0,0
0,0,0,0,0,0,0,0,0,0,0,0,0,0,0,0,0,0,0,0,0,0,0,0,0
0,0,0,0,0,0,0,0,0,0,0,0,0,0,0,0,0,0,0,0,0,0,0,0,0
0,0,0,0,0,0,0,0,0,0,0,0,0,0,0,0,0,0,0,0,0,0,0,0,0
0,0,0,0,0,0,0,0,0,0,0,0,0,0,0,0,0,0,0,0,0,0,0,0,0
0,0,0,0,0,0,0,0,0,0,0,0,0,0,0,0,0,0,0,0,0,0,0,0,0
0,0,0,0,0,0,0,0,0,0,0,0,0,0,0,0,0,0,0,0,0,0,0,0,0
0,0,0,0,0,0,0,0,2,2,2,2,2,2,2,2,2,0,0,0,0,0,0,0,0
0,0,0,0,0,0,2,2,283,10,456,450,31,437,433,428,424,2,2,0,0,0,0,0,0
0,0,0,0,0,2,463,462,0,0,0,0,2,10,434,32,425,423,2,2,0,0,0,0,0
0,0,0,0,0,2,464,0,0,0,0,0,2,438,0,0,0,10,416,2,0,0,0,0,0
0,0,0,0,0,276,0,0,0,0,0,0,2,439,0,0,0,0,0,276,0,0,0,0,0
0,0,0,0,0,2,2,2,2,2,109,2,2,10,0,429,0,0,417,2,0,0,0,0,0
0,0,0,0,0,276,0,0,0,0,0,451,2,0,0,0,0,0,418,276,0,0,0,0,0
0,0,0,0,0,2,0,0,0,0,0,0,2,0,0,0,0,0,419,2,0,0,0,0,0
0,0,0,0,0,276,0,0,0,0,0,0,2,0,0,0,426,0,420,276,0,0,0,0,0
0,0,0,0,0,2,0,0,0,0,0,0,2,0,0,0,0,0,421,2,0,0,0,0,0
0,0,0,0,0,415,415,415,109,115,415,415,415,415,415,0,0,0,415,415,0,0,0,0,0
0,0,0,0,0,276,0,0,0,0,0,0,31,0,0,0,0,0,0,276,0,0,0,0,0
0,0,0,0,0,415,0,0,0,0,10,10,415,0,0,430,0,0,0,415,0,0,0,0,0
0,0,0,0,0,276,0,0,0,0,0,0,415,0,0,0,0,0,0,276,0,0,0,0,0
0,0,0,0,0,415,465,0,0,0,10,10,415,440,0,0,0,0,0,415,0,0,0,0,0
0,0,0,0,0,276,0,0,0,0,0,0,415,0,0,0,0,0,0,276,0,0,0,0,0
0,0,0,0,0,415,0,0,0,0,10,10,415,0,0,0,0,0,0,415,0,0,0,0,0
0,0,0,0,0,276,0,0,0,0,0,0,415,0,0,0,0,0,0,276,0,0,0,0,0
0,0,0,0,0,415,466,0,0,0,10,10,415,441,0,0,0,0,0,415,0,0,0,0,0
0,0,0,0,0,276,467,0,0,0,0,0,415,0,0,0,0,0,0,276,0,0,0,0,0
0,0,0,0,0,415,0,0,0,0,10,10,415,0,0,0,0,0,0,415,0,0,0,0,0
0,0,0,0,0,276,0,0,0,0,0,0,31,0,0,0,0,0,0,276,0,0,0,0,0
0,0,0,0,0,415,415,0,0,415,415,415,415,415,415,0,0,0,415,415,0,0,0,0,0
0,0,0,0,0,276,0,0,0,0,10,0,0,0,0,0,0,0,0,276,0,0,0,0,0
0,0,0,0,0,415,136,0,0,0,31,107,107,107,31,0,0,0,178,415,0,0,0,0,0
0,0,0,0,0,276,0,0,0,0,457,217,217,217,435,0,0,0,0,276,0,0,0,0,0
0,0,0,0,0,415,136,0,0,0,31,0,0,0,31,0,0,0,178,415,0,0,0,0,0
0,0,0,0,0,276,0,0,0,0,0,0,0,0,0,0,0,0,0,276,0,0,0,0,0
0,0,0,0,0,415,136,0,0,0,0,0,0,0,0,0,0,0,178,415,0,0,0,0,0
0,0,0,0,0,276,0,0,0,0,0,0,0,0,0,0,0,0,0,276,0,0,0,0,0
0,0,0,0,0,415,136,0,0,0,31,0,33,0,31,0,0,0,178,415,0,0,0,0,0
0,0,0,0,0,276,0,0,0,0,0,452,31,442,10,0,0,0,0,276,0,0,0,0,0
0,0,0,0,0,415,415,0,0,0,0,415,415,415,415,415,415,415,415,415,0,0,0,0,0
0,0,0,0,0,276,0,0,0,0,443,66,446,443,66,422,427,66,422,276,0,0,0,0,0
0,0,0,0,0,415,0,0,0,0,0,0,0,0,0,0,0,0,0,415,0,0,0,0,0
0,0,0,0,0,276,0,0,0,0,0,0,0,0,0,0,0,0,0,276,0,0,0,0,0
0,0,0,0,0,415,0,0,0,0,0,0,0,0,0,0,0,0,0,415,0,0,0,0,0
0,0,0,0,0,2,468,0,0,0,0,453,447,0,0,0,0,0,0,2,0,0,0,0,0
0,0,0,0,0,2,2,2,0,0,0,2,31,2,2,10,2,2,2,2,0,0,0,0,0
0,0,0,0,0,2,2,0,0,0,0,0,0,0,112,0,112,0,2,2,0,0,0,0,0
0,0,0,0,0,2,2,136,0,0,0,0,0,0,0,0,0,0,2,2,0,0,0,0,0
0,0,0,0,0,227,2,0,0,0,0,178,31,0,0,0,0,0,2,227,0,0,0,0,0
0,0,0,0,0,0,2,2,136,0,0,0,0,0,0,0,0,10,2,0,0,0,0,0,0
0,0,0,0,0,0,2,2,10,0,0,0,332,332,332,332,332,2,2,0,0,0,0,0,0
0,0,0,0,0,0,227,2,461,0,0,443,31,0,0,0,0,2,227,0,0,0,0,0,0
0,0,0,0,0,0,0,2,2,108,0,0,448,0,108,0,2,2,0,0,0,0,0,0,0
0,0,0,0,0,0,0,2,2,2,109,2,2,2,2,2,2,2,0,0,0,0,0,0,0
0,0,0,0,0,0,0,227,2,459,0,112,231,112,0,431,2,227,0,0,0,0,0,0,0
0,0,0,0,0,0,0,0,2,460,0,0,0,0,0,432,2,0,0,0,0,0,0,0,0
0,0,0,0,0,0,0,0,2,2,458,0,0,0,436,2,2,0,0,0,0,0,0,0,0
0,0,0,0,0,0,0,0,227,2,2,454,0,444,2,2,227,0,0,0,0,0,0,0,0
0,0,0,0,0,0,0,0,0,2,2,455,0,445,2,2,0,0,0,0,0,0,0,0,0
0,0,0,0,0,0,0,0,0,277,2,2,449,2,2,277,0,0,0,0,0,0,0,0,0
0,0,0,0,0,0,0,0,0,0,227,2,2,2,227,0,0,0,0,0,0,0,0,0,0
0,0,0,0,0,0,0,0,0,0,0,227,275,227,0,0,0,0,0,0,0,0,0,0,0
0,0,0,0,0,0,0,0,0,0,0,0,285,0,0,0,0,0,0,0,0,0,0,0,0
0,0,0,0,0,0,0,0,0,0,0,0,0,0,0,0,0,0,0,0,0,0,0,0,0
0,0,0,0,0,0,0,0,0,0,0,0,0,0,0,0,0,0,0,0,0,0,0,0,0
0,0,0,0,0,0,0,0,0,0,0,0,0,0,0,0,0,0,0,0,0,0,0,0,0
0,0,0,0,0,0,0,0,0,0,0,0,0,0,0,0,0,0,0,0,0,0,0,0,0
0,0,0,0,0,0,0,0,0,0,0,0,0,0,0,0,0,0,0,0,0,0,0,0,0
0,0,0,0,0,0,0,0,0,0,0,0,0,0,0,0,0,0,0,0,0,0,0,0,0
0,0,0,0,0,0,0,0,0,0,0,0,0,0,0,0,0,0,0,0,0,0,0,0,0
0,0,0,0,0,0,0,0,0,0,0,0,0,0,0,0,0,0,0,0,0,0,0,0,0
0,0,0,0,0,0,0,0,0,0,0,0,0,0,0,0,0,0,0,0,0,0,0,0,0
0,0,0,0,0,0,0,0,0,0,0,0,0,0,0,0,0,0,0,0,0,0,0,0,0
0,0,0,0,0,0,0,0,0,0,0,0,0,0,0,0,0,0,0,0,0,0,0,0,0
0,0,0,0,0,0,0,0,0,0,0,0,0,0,0,0,0,0,0,0,0,0,0,0,0
0,0,0,0,0,0,0,0,0,0,0,0,0,0,0,0,0,0,0,0,0,0,0,0,0
:endlayer
layer: 12
0,0,0,0,0,0,0,0,0,0,0,0,0,0,0,0,0,0,0,0,0,0,0,0,0
0,0,0,0,0,0,0,0,0,0,0,0,0,0,0,0,0,0,0,0,0,0,0,0,0
0,0,0,0,0,0,0,0,0,0,0,0,0,0,0,0,0,0,0,0,0,0,0,0,0
0,0,0,0,0,0,0,0,0,0,0,0,0,0,0,0,0,0,0,0,0,0,0,0,0
0,0,0,0,0,0,0,0,0,0,0,0,0,0,0,0,0,0,0,0,0,0,0,0,0
0,0,0,0,0,0,0,0,0,0,0,0,0,0,0,0,0,0,0,0,0,0,0,0,0
0,0,0,0,0,0,0,0,0,0,0,0,0,0,0,0,0,0,0,0,0,0,0,0,0
0,0,0,0,0,0,0,0,0,0,0,0,0,0,0,0,0,0,0,0,0,0,0,0,0
0,0,0,0,0,0,0,0,0,0,0,0,0,0,0,0,0,0,0,0,0,0,0,0,0
0,0,0,0,0,0,0,0,0,0,277,275,275,275,277,0,0,0,0,0,0,0,0,0,0
0,0,0,0,0,0,0,277,275,275,275,275,275,275,275,275,275,277,0,0,0,0,0,0,0
0,0,0,0,0,274,2,2,483,10,0,0,31,159,159,159,159,2,2,274,0,0,0,0,0
0,0,0,0,0,2,463,0,0,0,0,0,2,10,0,0,0,159,2,2,0,0,0,0,0
0,0,0,0,0,2,0,0,0,0,0,178,2,480,0,0,0,10,159,2,0,0,0,0,0
0,0,0,0,277,2,0,0,108,0,0,0,2,481,0,0,0,0,0,2,277,0,0,0,0
0,0,0,0,277,2,2,2,2,2,2,2,2,10,0,0,0,0,178,2,277,0,0,0,0
0,0,0,0,0,2,0,0,112,0,0,0,2,0,0,0,0,0,0,2,0,0,0,0,0
0,0,0,0,0,2,136,0,0,0,0,178,2,136,0,0,0,0,178,2,0,0,0,0,0
0,0,0,0,0,2,0,0,0,0,0,0,2,0,0,0,0,0,0,2,0,0,0,0,0
0,0,0,0,0,2,0,0,0,108,0,0,2,0,108,0,0,0,108,2,0,0,0,0,0
0,0,0,0,0,415,415,415,415,415,415,415,415,415,415,159,159,159,415,415,0,0,0,0,0
0,0,0,0,0,276,0,112,0,0,112,178,31,136,0,0,0,0,0,276,0,0,0,0,0
0,0,0,0,0,415,136,0,0,0,0,0,415,0,0,0,0,0,178,415,0,0,0,0,0
0,0,0,0,0,276,0,0,0,0,0,178,415,136,0,0,0,0,0,276,0,0,0,0,0
0,0,0,0,0,415,136,0,0,0,0,0,415,0,0,0,0,0,178,415,0,0,0,0,0
0,0,0,0,0,276,0,0,0,0,0,178,415,136,0,0,0,0,0,276,0,0,0,0,0
0,0,0,0,0,415,136,0,0,0,0,0,415,0,0,0,0,0,178,415,0,0,0,0,0
0,0,0,0,0,276,0,0,0,0,0,178,415,136,0,0,0,0,0,276,0,0,0,0,0
0,0,0,0,0,415,136,0,0,0,0,0,415,0,0,0,0,0,178,415,0,0,0,0,0
0,0,0,0,0,276,0,0,0,0,0,178,415,136,0,0,0,0,0,276,0,0,0,0,0
0,0,0,0,0,415,136,0,0,0,0,0,415,0,0,0,0,0,178,415,0,0,0,0,0
0,0,0,0,0,276,0,0,0,0,0,178,31,136,0,0,0,0,0,276,0,0,0,0,0
0,0,0,0,0,415,415,159,159,415,415,415,415,415,415,159,159,159,415,415,0,0,0,0,0
0,0,0,0,0,276,0,0,0,0,10,107,107,107,0,0,0,0,0,276,0,0,0,0,0
0,0,0,0,0,415,477,487,484,469,31,217,217,217,31,477,474,470,469,415,0,0,0,0,0
0,0,0,0,0,276,0,0,0,0,159,0,0,0,159,0,0,0,0,276,0,0,0,0,0
0,0,0,0,0,415,477,488,485,469,31,136,0,178,31,477,475,471,469,415,0,0,0,0,0
0,0,0,0,0,276,0,0,0,0,159,0,0,0,159,0,0,0,0,276,0,0,0,0,0
0,0,0,0,0,415,0,0,0,0,159,0,0,0,159,0,0,0,0,415,0,0,0,0,0
0,0,0,0,0,276,0,0,0,0,159,0,0,0,159,0,0,0,0,276,0,0,0,0,0
0,0,0,0,0,415,477,489,486,469,31,136,33,178,31,477,476,472,469,415,0,0,0,0,0
0,0,0,0,0,276,0,0,0,0,0,159,31,159,10,0,0,0,0,276,0,0,0,0,0
0,0,0,0,0,415,415,160,159,159,251,415,415,415,415,415,415,415,415,415,0,0,0,0,0
0,0,0,0,0,276,0,0,0,0,0,482,112,0,479,0,112,473,0,276,0,0,0,0,0
0,0,0,0,0,415,136,0,0,0,0,0,0,0,0,0,0,0,178,415,0,0,0,0,0
0,0,0,0,0,276,0,0,0,0,0,0,0,0,0,0,0,0,0,276,0,0,0,0,0
0,0,0,0,0,415,136,0,0,0,0,0,0,0,0,0,0,0,178,415,0,0,0,0,0
0,0,0,0,0,2,0,108,0,0,0,108,0,108,0,108,0,108,0,2,0,0,0,0,0
0,0,0,0,0,2,2,2,159,159,159,2,31,2,2,2,2,2,2,2,0,0,0,0,0
0,0,0,0,0,2,151,152,152,152,152,152,312,152,152,152,152,152,151,2,0,0,0,0,0
0,0,0,0,0,2,151,152,152,152,152,152,312,152,152,152,152,152,151,2,0,0,0,0,0
0,0,0,0,0,2,151,152,152,152,152,152,31,152,152,152,152,152,151,2,0,0,0,0,0
0,0,0,0,0,227,2,151,152,152,152,152,312,152,152,152,152,151,2,227,0,0,0,0,0
0,0,0,0,0,159,2,151,219,152,152,152,312,151,151,151,151,151,2,159,0,0,0,0,0
0,0,0,0,0,251,2,151,219,152,152,152,312,152,152,152,152,151,2,160,0,0,0,0,0
0,0,0,0,0,0,227,2,151,152,152,152,312,152,152,152,151,2,227,0,0,0,0,0,0
0,0,0,0,0,0,159,2,151,151,151,151,312,151,151,151,151,2,159,0,0,0,0,0,0
0,0,0,0,0,0,251,2,151,219,152,152,312,152,152,153,151,2,160,0,0,0,0,0,0
0,0,0,0,0,0,0,227,2,219,152,152,312,152,152,153,2,227,0,0,0,0,0,0,0
0,0,0,0,0,0,0,159,2,151,107,152,312,152,107,151,2,159,0,0,0,0,0,0,0
0,0,0,0,0,0,0,251,2,2,2,219,311,153,2,2,2,160,0,0,0,0,0,0,0
0,0,0,0,0,0,0,0,227,312,2,219,152,153,2,312,227,0,0,0,0,0,0,0,0
0,0,0,0,0,0,0,0,0,312,2,2,107,2,2,312,0,0,0,0,0,0,0,0,0
0,0,0,0,0,0,0,0,0,478,275,2,2,2,275,478,0,0,0,0,0,0,0,0,0
0,0,0,0,0,0,0,0,0,0,285,275,2,275,285,0,0,0,0,0,0,0,0,0,0
0,0,0,0,0,0,0,0,0,0,0,275,2,275,0,0,0,0,0,0,0,0,0,0,0
0,0,0,0,0,0,0,0,0,0,0,277,275,277,0,0,0,0,0,0,0,0,0,0,0
0,0,0,0,0,0,0,0,0,0,0,0,275,0,0,0,0,0,0,0,0,0,0,0,0
0,0,0,0,0,0,0,0,0,0,0,0,277,0,0,0,0,0,0,0,0,0,0,0,0
0,0,0,0,0,0,0,0,0,0,0,0,277,0,0,0,0,0,0,0,0,0,0,0,0
0,0,0,0,0,0,0,0,0,0,0,0,0,0,0,0,0,0,0,0,0,0,0,0,0
0,0,0,0,0,0,0,0,0,0,0,0,0,0,0,0,0,0,0,0,0,0,0,0,0
0,0,0,0,0,0,0,0,0,0,0,0,0,0,0,0,0,0,0,0,0,0,0,0,0
0,0,0,0,0,0,0,0,0,0,0,0,0,0,0,0,0,0,0,0,0,0,0,0,0
0,0,0,0,0,0,0,0,0,0,0,0,0,0,0,0,0,0,0,0,0,0,0,0,0
0,0,0,0,0,0,0,0,0,0,0,0,0,0,0,0,0,0,0,0,0,0,0,0,0
0,0,0,0,0,0,0,0,0,0,0,0,0,0,0,0,0,0,0,0,0,0,0,0,0
0,0,0,0,0,0,0,0,0,0,0,0,0,0,0,0,0,0,0,0,0,0,0,0,0
0,0,0,0,0,0,0,0,0,0,0,0,0,0,0,0,0,0,0,0,0,0,0,0,0
:endlayer
layer: 13
0,0,0,0,0,0,0,0,0,0,0,0,0,0,0,0,0,0,0,0,0,0,0,0,0
0,0,0,0,0,0,0,0,0,0,0,0,0,0,0,0,0,0,0,0,0,0,0,0,0
0,0,0,0,0,0,0,0,0,0,0,0,0,0,0,0,0,0,0,0,0,0,0,0,0
0,0,0,0,0,0,0,0,0,0,0,0,0,0,0,0,0,0,0,0,0,0,0,0,0
0,0,0,0,0,0,0,0,0,0,0,0,0,0,0,0,0,0,0,0,0,0,0,0,0
0,0,0,0,0,0,0,0,0,0,0,0,0,0,0,0,0,0,0,0,0,0,0,0,0
0,0,0,0,0,0,0,0,0,0,0,0,0,0,0,0,0,0,0,0,0,0,0,0,0
0,0,0,0,0,0,0,0,0,0,0,0,0,0,0,0,0,0,0,0,0,0,0,0,0
0,0,0,0,0,0,0,0,0,159,350,159,350,159,350,159,0,0,0,0,0,0,0,0,0
0,0,0,0,0,0,0,0,526,275,275,275,275,275,275,275,490,0,0,0,0,0,0,0,0
0,0,0,0,0,526,275,275,275,151,151,151,2,151,151,151,275,275,275,490,0,0,0,0,0
0,0,0,0,274,275,151,151,151,151,151,151,31,151,151,151,151,151,151,275,274,0,0,0,0
0,0,0,0,275,151,151,151,151,151,151,151,151,151,151,151,151,151,151,151,275,0,0,0,0
0,0,0,0,275,151,151,151,151,151,151,151,151,152,151,151,151,151,151,151,275,0,0,0,0
0,0,0,0,275,151,151,151,151,151,151,151,151,152,151,151,151,151,151,151,275,0,0,0,0
0,0,0,0,275,151,151,151,151,151,151,151,151,151,151,151,151,151,151,151,275,0,0,0,0
0,0,0,0,275,151,151,151,151,151,151,151,151,151,151,151,151,151,151,151,275,0,0,0,0
0,0,0,0,275,151,151,151,151,151,151,151,151,151,151,151,151,151,151,151,275,0,0,0,0
0,0,0,0,285,2,151,151,151,151,151,151,151,151,151,151,151,151,151,2,285,0,0,0,0
0,0,0,0,159,2,151,151,151,151,151,151,151,151,151,151,151,151,151,2,159,0,0,0,0
0,0,0,0,251,2,151,151,151,151,151,151,151,151,151,151,151,151,151,2,160,0,0,0,0
0,0,0,0,159,2,151,151,151,151,151,151,31,151,151,151,151,151,151,2,159,0,0,0,0
0,0,0,0,251,2,151,151,151,151,151,151,151,151,151,151,151,151,151,2,160,0,0,0,0
0,0,0,0,159,2,151,151,151,151,151,151,151,151,151,151,151,151,151,2,159,0,0,0,0
0,0,0,0,251,2,151,151,151,498,498,498,151,498,498,498,151,151,151,2,160,0,0,0,0
0,0,0,0,159,2,151,151,151,507,507,499,151,507,499,499,151,151,151,2,159,0,0,0,0
0,0,0,0,251,2,151,151,151,507,507,499,151,507,499,499,151,151,151,2,160,0,0,0,0
0,0,0,0,159,2,151,151,151,507,507,499,151,507,499,499,151,151,151,2,159,0,0,0,0
0,0,0,0,251,2,151,151,151,507,507,499,151,507,499,499,151,151,151,2,160,0,0,0,0
0,0,0,0,159,2,151,151,151,500,500,500,151,500,500,500,151,151,151,2,159,0,0,0,0
0,0,0,0,251,2,151,151,151,151,151,151,151,151,151,151,151,151,151,2,160,0,0,0,0
0,0,0,0,159,2,151,151,151,151,151,151,31,151,151,151,151,151,151,2,159,0,0,0,0
0,0,0,0,251,2,151,151,151,151,504,504,504,504,504,151,151,151,151,2,160,0,0,0,0
0,0,0,0,159,2,151,151,151,151,312,217,217,217,312,151,151,151,151,2,159,0,0,0,0
0,0,0,0,251,2,151,151,151,151,312,0,513,0,312,151,151,151,151,2,160,0,0,0,0
0,0,0,0,159,2,151,151,151,151,312,0,0,0,312,151,151,151,151,2,159,0,0,0,0
0,0,0,0,251,2,151,151,151,151,312,500,500,500,312,151,151,151,151,2,160,0,0,0,0
0,0,0,0,159,2,151,151,151,151,312,500,500,500,312,151,151,151,151,2,159,0,0,0,0
0,0,0,0,251,2,151,151,151,151,312,500,500,500,312,151,151,151,151,2,160,0,0,0,0
0,0,0,0,159,2,151,151,151,151,504,504,504,504,504,151,151,151,151,2,159,0,0,0,0
0,0,0,0,251,2,151,151,151,151,151,151,151,151,151,151,151,151,151,2,160,0,0,0,0
0,0,0,0,159,2,151,151,151,151,151,151,31,151,151,151,151,151,151,2,159,0,0,0,0
0,0,0,0,251,2,151,151,151,151,151,151,151,151,151,151,151,151,151,2,160,0,0,0,0
0,0,0,0,159,2,151,151,151,151,151,151,151,151,151,151,151,151,151,2,159,0,0,0,0
0,0,0,0,251,2,151,151,151,151,151,151,151,151,151,151,151,151,151,2,160,0,0,0,0
0,0,0,0,159,2,151,151,151,151,151,151,151,151,151,151,151,151,151,2,159,0,0,0,0
0,0,0,0,251,2,151,151,151,151,151,151,151,151,151,151,151,151,151,2,160,0,0,0,0
0,0,0,0,159,2,151,151,151,151,151,151,151,151,151,151,151,151,151,2,159,0,0,0,0
0,0,0,0,251,275,538,532,275,275,151,151,151,151,151,151,275,495,493,275,160,0,0,0,0
0,0,0,0,0,275,539,533,527,521,463,463,275,275,275,275,275,0,0,275,0,0,0,0,0
0,0,0,0,0,531,540,0,0,0,0,0,275,508,478,501,0,0,0,491,0,0,0,0,0
0,0,0,0,0,275,541,534,0,522,254,254,31,509,0,0,0,0,494,275,0,0,0,0,0
0,0,0,0,0,492,275,535,515,515,515,515,0,0,0,0,492,492,275,492,0,0,0,0,0
0,0,0,0,0,0,531,536,515,516,516,515,514,0,0,0,182,171,491,0,0,0,0,0,0
0,0,0,0,0,492,275,537,515,515,515,515,0,0,505,0,182,171,275,492,0,0,0,0,0
0,0,0,0,0,0,492,275,528,523,517,0,31,510,0,0,492,275,492,0,0,0,0,0,0
0,0,0,0,0,0,0,531,529,0,518,0,275,511,0,0,496,491,0,0,0,0,0,0,0
0,0,0,0,0,0,492,275,530,0,0,0,275,0,0,502,497,275,492,0,0,0,0,0,0
0,0,0,0,0,0,0,492,275,524,519,0,275,0,0,503,275,492,0,0,0,0,0,0,0
0,0,0,0,0,0,0,0,531,525,520,512,31,512,506,68,491,0,0,0,0,0,0,0,0
0,0,0,0,0,0,0,492,275,275,275,275,312,275,275,275,275,492,0,0,0,0,0,0,0
0,0,0,0,0,0,0,0,492,478,2,151,312,151,2,478,492,0,0,0,0,0,0,0,0
0,0,0,0,0,0,0,0,0,492,2,151,151,151,2,492,0,0,0,0,0,0,0,0,0
0,0,0,0,0,0,0,0,0,320,2,2,151,2,2,320,0,0,0,0,0,0,0,0,0
0,0,0,0,0,0,0,0,0,320,2,2,2,2,2,320,0,0,0,0,0,0,0,0,0
0,0,0,0,0,0,0,0,320,320,478,415,2,415,478,320,320,0,0,0,0,0,0,0,0
0,0,0,0,0,0,0,0,320,320,0,415,2,415,0,320,320,0,0,0,0,0,0,0,0
0,0,0,0,0,0,0,0,0,0,0,478,415,478,0,0,0,0,0,0,0,0,0,0,0
0,0,0,0,0,0,0,0,0,0,0,0,415,0,0,0,0,0,0,0,0,0,0,0,0
0,0,0,0,0,0,0,0,0,0,0,0,415,0,0,0,0,0,0,0,0,0,0,0,0
0,0,0,0,0,0,0,0,0,0,0,0,478,0,0,0,0,0,0,0,0,0,0,0,0
0,0,0,0,0,0,0,0,0,0,0,0,0,0,0,0,0,0,0,0,0,0,0,0,0
0,0,0,0,0,0,0,0,0,0,0,0,0,0,0,0,0,0,0,0,0,0,0,0,0
0,0,0,0,0,0,0,0,0,0,0,0,0,0,0,0,0,0,0,0,0,0,0,0,0
0,0,0,0,0,0,0,0,0,0,0,0,0,0,0,0,0,0,0,0,0,0,0,0,0
0,0,0,0,0,0,0,0,0,0,0,0,0,0,0,0,0,0,0,0,0,0,0,0,0
0,0,0,0,0,0,0,0,0,0,0,0,0,0,0,0,0,0,0,0,0,0,0,0,0
0,0,0,0,0,0,0,0,0,0,0,0,0,0,0,0,0,0,0,0,0,0,0,0,0
0,0,0,0,0,0,0,0,0,0,0,0,0,0,0,0,0,0,0,0,0,0,0,0,0
:endlayer
layer: 14
0,0,0,0,0,0,0,0,0,0,0,0,0,0,0,0,0,0,0,0,0,0,0,0,0
0,0,0,0,0,0,0,0,0,0,0,0,0,0,0,0,0,0,0,0,0,0,0,0,0
0,0,0,0,0,0,0,0,0,0,0,0,0,0,0,0,0,0,0,0,0,0,0,0,0
0,0,0,0,0,0,0,0,0,0,0,0,0,0,0,0,0,0,0,0,0,0,0,0,0
0,0,0,0,0,0,0,0,0,0,0,0,0,0,0,0,0,0,0,0,0,0,0,0,0
0,0,0,0,0,0,0,0,0,0,0,0,0,0,0,0,0,0,0,0,0,0,0,0,0
0,0,0,0,0,0,0,0,0,0,0,0,0,0,0,0,0,0,0,0,0,0,0,0,0
0,0,0,0,0,0,0,0,0,0,0,0,0,0,0,0,0,0,0,0,0,0,0,0,0
0,0,0,0,0,0,0,0,0,0,492,0,492,0,492,0,0,0,0,0,0,0,0,0,0
0,0,0,0,0,0,0,0,275,512,275,512,275,512,275,512,275,0,0,0,0,0,0,0,0
0,0,0,0,0,275,512,275,22,0,0,0,275,584,0,0,562,275,512,275,0,0,0,0,0
0,0,0,0,275,22,368,275,620,0,182,171,31,0,577,0,0,0,0,542,275,0,0,0,0
0,0,0,0,531,0,369,275,621,0,182,171,463,585,577,67,0,0,0,543,491,0,0,0,0
0,0,0,0,275,0,0,275,275,563,275,463,463,463,275,275,563,275,275,275,275,0,0,0,0
0,0,0,0,531,637,0,574,0,0,0,0,0,0,578,516,516,516,516,544,491,0,0,0,0
0,0,0,0,275,275,275,275,622,0,604,0,0,0,579,516,515,515,516,0,275,0,0,0,0
0,0,0,0,531,368,0,0,2,0,0,577,577,577,0,516,515,515,516,545,491,0,0,0,0
0,0,0,0,275,369,0,0,563,0,605,577,577,577,580,516,516,516,516,546,275,0,0,0,0
0,0,0,0,275,2,0,0,2,0,606,0,0,0,581,568,2,556,0,2,275,0,0,0,0
0,0,0,0,275,2,632,627,2,0,0,0,0,0,0,0,2,557,550,2,275,0,0,0,0
0,0,0,0,531,2,2,2,2,275,275,275,275,574,563,275,2,2,2,2,491,0,0,0,0
0,0,0,0,492,275,217,217,275,612,607,0,31,0,582,569,275,217,217,275,492,0,0,0,0
0,0,0,0,531,275,0,0,478,0,0,0,0,0,0,0,478,0,0,275,491,0,0,0,0
0,0,0,0,492,275,0,0,623,0,0,0,590,0,0,0,564,0,0,275,492,0,0,0,0
0,0,0,0,531,275,136,0,0,0,0,0,0,0,0,0,0,0,178,275,491,0,0,0,0
0,0,0,0,492,492,492,0,0,0,0,0,0,0,0,0,0,0,492,492,492,0,0,0,0
0,0,0,0,531,275,633,32,624,0,0,0,591,0,0,0,565,32,551,275,491,0,0,0,0
0,0,0,0,492,492,492,0,0,0,0,0,0,0,0,0,0,0,492,492,492,0,0,0,0
0,0,0,0,531,0,0,0,0,0,0,0,592,0,0,0,0,0,0,0,491,0,0,0,0
0,0,0,0,492,638,0,0,0,0,0,0,593,0,0,0,0,0,0,547,492,0,0,0,0
0,0,0,0,531,0,0,0,625,0,0,0,33,0,0,0,566,0,0,0,491,0,0,0,0
0,0,0,0,492,492,492,0,0,0,0,598,31,586,0,0,0,0,492,492,492,0,0,0,0
0,0,0,0,531,275,634,32,0,0,0,0,0,0,0,0,0,32,552,275,491,0,0,0,0
0,0,0,0,492,275,492,0,0,613,0,0,0,0,0,570,0,0,492,275,492,0,0,0,0
0,0,0,0,531,275,136,628,0,0,0,0,0,0,0,0,0,558,178,275,491,0,0,0,0
0,0,0,0,492,478,0,0,0,614,0,0,0,0,0,571,0,0,0,478,492,0,0,0,0
0,0,0,0,531,0,0,629,0,0,608,0,0,0,583,0,0,559,0,0,491,0,0,0,0
0,0,0,0,492,492,492,0,0,0,0,0,0,0,0,0,0,0,492,492,492,0,0,0,0
0,0,0,0,531,275,635,32,0,615,0,0,0,0,0,572,0,32,553,275,491,0,0,0,0
0,0,0,0,492,492,492,0,0,0,0,0,0,0,0,0,0,0,492,492,492,0,0,0,0
0,0,0,0,531,0,0,0,0,0,0,0,33,0,0,0,0,0,0,0,491,0,0,0,0
0,0,0,0,492,639,0,630,561,616,0,561,31,561,0,573,561,560,0,548,492,0,0,0,0
0,0,0,0,531,0,0,561,275,563,574,275,275,275,563,574,275,561,0,0,491,0,0,0,0
0,0,0,0,492,0,0,0,531,617,0,0,594,0,0,0,491,0,0,0,492,0,0,0,0
0,0,0,0,531,640,0,0,275,313,313,313,313,0,0,166,275,0,0,549,491,0,0,0,0
0,0,0,0,492,492,0,0,531,0,609,599,0,0,0,166,491,0,0,492,492,0,0,0,0
0,0,0,0,531,275,636,0,275,618,610,600,595,587,0,575,275,0,554,275,491,0,0,0,0
0,0,0,0,492,415,555,555,275,0,0,601,0,0,0,166,275,555,555,415,492,0,0,0,0
0,0,0,0,531,415,311,311,275,619,611,602,596,588,0,166,275,311,311,415,491,0,0,0,0
0,0,0,0,0,415,0,0,285,285,463,463,275,275,574,275,275,0,0,415,0,0,0,0,0
0,0,0,0,0,276,0,0,0,0,0,0,275,561,0,561,0,0,0,276,0,0,0,0,0
0,0,0,0,0,415,0,0,0,0,0,0,31,0,0,0,0,0,0,415,0,0,0,0,0
0,0,0,0,0,0,415,0,0,0,0,0,0,0,0,0,0,0,415,0,0,0,0,0,0
0,0,0,0,0,0,276,0,0,0,0,0,0,0,0,0,0,0,276,0,0,0,0,0,0
0,0,0,0,0,0,415,631,0,0,0,0,0,0,0,0,0,0,415,0,0,0,0,0,0
0,0,0,0,0,0,0,415,0,0,0,0,31,0,0,0,0,415,0,0,0,0,0,0,0
0,0,0,0,0,0,0,276,0,0,0,0,415,0,0,0,0,276,0,0,0,0,0,0,0
0,0,0,0,0,0,0,415,626,0,0,0,415,0,0,0,0,415,0,0,0,0,0,0,0
0,0,0,0,0,0,0,0,415,0,0,0,415,0,0,0,415,0,0,0,0,0,0,0,0
0,0,0,0,0,0,0,0,276,0,0,0,31,0,0,0,276,0,0,0,0,0,0,0,0
0,0,0,0,0,0,0,0,415,276,415,563,415,574,415,276,415,0,0,0,0,0,0,0,0
0,0,0,0,0,0,0,0,0,0,561,0,597,0,561,0,0,0,0,0,0,0,0,0,0
0,0,0,0,0,0,0,0,0,0,561,0,312,0,561,0,0,0,0,0,0,0,0,0,0
0,0,0,0,0,0,0,0,0,0,561,603,312,589,561,0,0,0,0,0,0,0,0,0,0
0,0,0,0,0,0,0,0,0,0,561,561,152,561,561,0,0,0,0,0,0,0,0,0,0
0,0,0,0,0,0,0,0,0,0,0,478,275,478,0,0,0,0,0,0,0,0,0,0,0
0,0,0,0,0,0,0,0,320,0,0,0,478,0,0,0,320,0,0,0,0,0,0,0,0
0,0,0,0,0,0,0,0,320,0,0,0,492,0,0,0,320,0,0,0,0,0,0,0,0
0,0,0,0,0,0,0,0,320,0,0,0,492,0,0,0,320,0,0,0,0,0,0,0,0
0,0,0,0,0,0,0,0,320,0,0,0,0,0,0,0,320,0,0,0,0,0,0,0,0
0,0,0,0,0,0,0,0,567,567,567,567,567,567,567,567,567,0,0,0,0,0,0,0,0
0,0,0,0,0,0,0,0,0,0,576,576,576,576,576,0,0,0,0,0,0,0,0,0,0
0,0,0,0,0,0,0,0,0,576,576,576,576,576,576,576,0,0,0,0,0,0,0,0,0
0,0,0,0,0,0,0,0,0,0,0,576,576,576,0,0,0,0,0,0,0,0,0,0,0
0,0,0,0,0,0,0,0,0,0,0,0,0,0,0,0,0,0,0,0,0,0,0,0,0
0,0,0,0,0,0,0,0,0,0,0,0,0,0,0,0,0,0,0,0,0,0,0,0,0
0,0,0,0,0,0,0,0,0,0,0,0,0,0,0,0,0,0,0,0,0,0,0,0,0
0,0,0,0,0,0,0,0,0,0,0,0,0,0,0,0,0,0,0,0,0,0,0,0,0
0,0,0,0,0,0,0,0,0,0,0,0,0,0,0,0,0,0,0,0,0,0,0,0,0
:endlayer
layer: 15
0,0,0,0,0,0,0,0,0,0,0,0,0,0,0,0,0,0,0,0,0,0,0,0,0
0,0,0,0,0,0,0,0,0,0,0,0,0,0,0,0,0,0,0,0,0,0,0,0,0
0,0,0,0,0,0,0,0,0,0,0,0,0,0,0,0,0,0,0,0,0,0,0,0,0
0,0,0,0,0,0,0,0,0,0,0,0,0,0,0,0,0,0,0,0,0,0,0,0,0
0,0,0,0,0,0,0,0,0,0,0,0,0,0,0,0,0,0,0,0,0,0,0,0,0
0,0,0,0,0,0,0,0,0,0,0,0,0,0,0,0,0,0,0,0,0,0,0,0,0
0,0,0,0,0,0,0,0,0,0,0,0,0,0,0,0,0,0,0,0,0,0,0,0,0
0,0,0,0,0,0,0,0,0,0,0,0,0,0,0,0,0,0,0,0,0,0,0,0,0
0,0,0,0,0,0,0,0,0,0,0,0,0,0,0,0,0,0,0,0,0,0,0,0,0
0,0,0,0,0,0,0,0,415,276,415,276,415,276,415,276,415,0,0,0,0,0,0,0,0
0,0,0,0,0,415,276,415,0,0,0,0,415,0,0,0,645,415,276,415,0,0,0,0,0
0,0,0,0,415,0,0,415,0,0,0,0,31,0,0,0,0,0,0,0,415,0,0,0,0
0,0,0,0,276,0,0,415,0,0,0,0,463,0,0,0,0,0,0,0,276,0,0,0,0
0,0,0,0,415,0,0,415,415,646,415,463,463,463,415,415,646,415,415,415,415,0,0,0,0
0,0,0,0,276,0,0,647,0,0,0,0,0,0,0,0,0,0,0,0,276,0,0,0,0
0,0,0,0,415,415,415,415,0,0,0,0,0,0,0,0,0,0,0,0,415,0,0,0,0
0,0,0,0,276,0,0,0,2,0,0,0,0,0,0,0,0,0,0,0,276,0,0,0,0
0,0,0,0,415,108,0,0,646,0,0,0,0,0,0,0,0,0,0,0,415,0,0,0,0
0,0,0,0,415,2,0,0,2,0,0,0,0,0,0,0,2,0,0,2,415,0,0,0,0
0,0,0,0,478,2,107,107,2,0,0,0,0,0,0,0,2,107,107,2,478,0,0,0,0
0,0,0,0,0,2,217,217,2,415,276,276,415,647,646,415,2,217,217,2,0,0,0,0,0
0,0,0,0,0,478,0,0,478,0,0,0,31,0,0,0,478,0,0,478,0,0,0,0,0
0,0,0,0,0,512,0,0,0,0,0,0,0,0,0,0,0,0,0,512,0,0,0,0,0
0,0,0,0,0,320,0,0,0,0,0,0,0,0,0,0,0,0,0,320,0,0,0,0,0
0,0,0,0,0,320,0,0,0,0,0,0,0,0,0,0,0,0,0,320,0,0,0,0,0
0,0,0,0,0,0,0,0,0,0,0,0,0,0,0,0,0,0,0,0,0,0,0,0,0
0,0,0,0,0,0,0,0,0,0,0,0,0,0,0,0,0,0,0,0,0,0,0,0,0
0,0,0,0,0,0,655,0,0,0,0,0,0,0,0,0,0,0,642,0,0,0,0,0,0
0,0,0,0,0,0,0,0,0,0,0,0,0,0,0,0,0,0,0,0,0,0,0,0,0
0,0,0,0,0,0,0,0,0,0,0,0,0,0,0,0,0,0,0,0,0,0,0,0,0
0,0,0,0,0,0,0,0,0,0,0,0,33,0,0,0,0,0,0,0,0,0,0,0,0
0,0,0,0,0,0,656,0,0,0,0,0,31,0,0,0,0,0,643,0,0,0,0,0,0
0,0,0,0,0,0,0,0,0,0,0,0,0,0,0,0,0,0,0,0,0,0,0,0,0
0,0,0,0,0,512,0,0,0,0,0,0,0,0,0,0,0,0,0,512,0,0,0,0,0
0,0,0,0,0,320,0,0,0,0,0,0,0,0,0,0,0,0,0,320,0,0,0,0,0
0,0,0,0,0,320,0,0,0,0,0,0,0,0,0,0,0,0,0,320,0,0,0,0,0
0,0,0,0,0,0,0,0,0,0,0,0,0,0,0,0,0,0,0,0,0,0,0,0,0
0,0,0,0,0,0,657,0,0,0,0,0,0,0,0,0,0,0,644,0,0,0,0,0,0
0,0,0,0,0,0,0,0,0,0,0,0,0,0,0,0,0,0,0,0,0,0,0,0,0
0,0,0,0,0,0,0,0,0,0,0,0,0,0,0,0,0,0,0,0,0,0,0,0,0
0,0,0,0,0,0,0,0,0,0,0,0,33,0,0,0,0,0,0,0,0,0,0,0,0
0,0,0,0,0,0,0,0,561,0,0,561,31,561,0,0,561,0,0,0,0,0,0,0,0
0,0,0,0,0,0,0,561,415,646,647,415,415,415,646,647,415,561,0,0,0,0,0,0,0
0,0,0,0,0,0,0,0,276,0,0,0,0,0,0,0,276,0,0,0,0,0,0,0,0
0,0,0,0,0,0,0,0,415,0,0,0,0,0,0,0,415,0,0,0,0,0,0,0,0
0,0,0,0,0,658,0,0,276,0,0,0,0,0,0,0,276,0,0,641,0,0,0,0,0
0,0,0,0,0,32,0,0,415,652,0,0,649,0,0,648,415,0,0,32,0,0,0,0,0
0,0,0,0,0,512,0,0,415,0,0,0,0,0,0,0,415,0,0,512,0,0,0,0,0
0,0,0,0,0,415,555,555,415,653,0,0,650,0,0,0,415,555,555,415,0,0,0,0,0
0,0,0,0,0,415,311,311,415,415,463,463,415,415,647,415,415,311,311,415,0,0,0,0,0
0,0,0,0,0,276,0,0,0,0,0,0,415,561,0,561,112,0,0,276,0,0,0,0,0
0,0,0,0,0,415,0,0,0,0,0,178,31,136,0,0,0,0,0,415,0,0,0,0,0
0,0,0,0,0,0,415,136,0,0,0,0,277,0,0,0,0,178,415,0,0,0,0,0,0
0,0,0,0,0,0,276,0,0,0,0,0,277,0,0,0,0,0,276,0,0,0,0,0,0
0,0,0,0,0,0,415,0,0,0,0,0,277,0,0,0,0,0,415,0,0,0,0,0,0
0,0,0,0,0,0,0,415,136,0,0,178,31,136,0,0,178,415,0,0,0,0,0,0,0
0,0,0,0,0,0,0,276,0,0,0,0,415,0,0,0,0,276,0,0,0,0,0,0,0
0,0,0,0,0,0,0,415,654,0,0,0,415,0,0,0,0,415,0,0,0,0,0,0,0
0,0,0,0,0,0,0,0,415,0,0,0,415,0,0,178,415,0,0,0,0,0,0,0,0
0,0,0,0,0,0,0,0,276,0,0,178,31,136,0,0,276,0,0,0,0,0,0,0,0
0,0,0,0,0,0,0,0,415,276,415,646,415,647,415,276,415,0,0,0,0,0,0,0,0
0,0,0,0,0,0,0,0,277,0,112,0,112,0,112,0,277,0,0,0,0,0,0,0,0
0,0,0,0,0,0,0,0,277,0,0,0,651,0,0,0,277,0,0,0,0,0,0,0,0
0,0,0,0,0,0,0,0,0,277,32,0,597,0,32,277,0,0,0,0,0,0,0,0,0
0,0,0,0,0,0,0,0,0,0,277,0,312,0,277,0,0,0,0,0,0,0,0,0,0
0,0,0,0,0,0,0,0,0,0,0,277,312,277,0,0,0,0,0,0,0,0,0,0,0
0,0,0,0,0,0,0,0,0,0,0,277,152,277,0,0,0,0,0,0,0,0,0,0,0
0,0,0,0,0,0,0,0,0,0,0,0,0,0,0,0,0,0,0,0,0,0,0,0,0
0,0,0,0,0,0,0,0,0,0,0,0,0,0,0,0,0,0,0,0,0,0,0,0,0
0,0,0,0,0,0,0,0,320,0,0,0,0,0,0,0,320,0,0,0,0,0,0,0,0
0,0,0,0,0,0,0,320,320,0,0,0,0,0,0,0,320,320,0,0,0,0,0,0,0
0,0,0,0,0,0,0,567,576,576,0,0,0,0,0,576,576,567,0,0,0,0,0,0,0
0,0,0,0,0,0,0,567,576,320,0,0,0,0,0,320,576,567,0,0,0,0,0,0,0
0,0,0,0,0,0,0,0,0,576,576,0,0,0,576,576,0,0,0,0,0,0,0,0,0
0,0,0,0,0,0,0,0,0,576,576,576,576,576,576,576,0,0,0,0,0,0,0,0,0
0,0,0,0,0,0,0,0,0,0,0,576,576,576,0,0,0,0,0,0,0,0,0,0,0
0,0,0,0,0,0,0,0,0,0,0,0,0,0,0,0,0,0,0,0,0,0,0,0,0
0,0,0,0,0,0,0,0,0,0,0,0,0,0,0,0,0,0,0,0,0,0,0,0,0
0,0,0,0,0,0,0,0,0,0,0,0,0,0,0,0,0,0,0,0,0,0,0,0,0
:endlayer
layer: 16
0,0,0,0,0,0,0,0,0,0,0,0,0,0,0,0,0,0,0,0,0,0,0,0,0
0,0,0,0,0,0,0,0,0,0,0,0,0,0,0,0,0,0,0,0,0,0,0,0,0
0,0,0,0,0,0,0,0,0,0,0,0,0,0,0,0,0,0,0,0,0,0,0,0,0
0,0,0,0,0,0,0,0,0,0,0,0,0,0,0,0,0,0,0,0,0,0,0,0,0
0,0,0,0,0,0,0,0,0,0,0,0,0,0,0,0,0,0,0,0,0,0,0,0,0
0,0,0,0,0,0,0,0,0,0,0,0,0,0,0,0,0,0,0,0,0,0,0,0,0
0,0,0,0,0,0,0,0,0,0,0,0,0,0,0,0,0,0,0,0,0,0,0,0,0
0,0,0,0,0,0,0,0,0,0,0,0,0,0,0,0,0,0,0,0,0,0,0,0,0
0,0,0,0,0,0,0,0,0,0,0,0,0,0,0,0,0,0,0,0,0,0,0,0,0
0,0,0,0,0,0,0,0,415,276,415,276,415,276,415,276,415,0,0,0,0,0,0,0,0
0,0,0,0,0,415,276,415,0,0,112,0,415,0,112,0,0,415,276,415,0,0,0,0,0
0,0,0,0,415,0,0,415,136,0,0,0,31,0,0,0,0,0,0,178,415,0,0,0,0
0,0,0,0,276,0,178,415,0,108,0,0,463,0,108,0,0,0,108,0,276,0,0,0,0
0,0,0,0,415,136,0,415,415,415,415,463,463,463,415,415,415,415,415,415,415,0,0,0,0
0,0,0,0,276,0,0,415,0,0,112,0,0,0,112,0,0,0,112,0,276,0,0,0,0
0,0,0,0,415,415,415,415,136,0,0,0,0,0,0,0,0,0,0,178,415,0,0,0,0
0,0,0,0,276,0,112,0,2,0,0,0,0,0,0,0,0,0,0,0,276,0,0,0,0
0,0,0,0,415,350,0,0,2,136,0,0,0,0,0,0,108,0,0,350,415,0,0,0,0
0,0,0,0,478,2,107,107,2,160,0,0,0,0,0,251,2,107,107,2,478,0,0,0,0
0,0,0,0,0,2,217,217,2,160,0,0,108,0,0,251,2,217,217,2,0,0,0,0,0
0,0,0,0,0,478,0,0,478,415,276,276,415,659,659,415,478,0,0,478,0,0,0,0,0
0,0,0,0,0,0,0,0,0,112,0,0,31,0,0,112,0,0,0,0,0,0,0,0,0
0,0,0,0,0,0,0,0,0,0,0,0,112,0,0,0,0,0,0,0,0,0,0,0,0
0,0,0,0,0,0,0,0,0,0,0,0,0,0,0,0,0,0,0,0,0,0,0,0,0
0,0,0,0,0,320,0,0,0,0,0,0,0,0,0,0,0,0,0,320,0,0,0,0,0
0,0,0,0,0,320,0,0,0,0,0,0,0,0,0,0,0,0,0,320,0,0,0,0,0
0,0,0,0,0,0,0,0,0,0,0,0,0,0,0,0,0,0,0,0,0,0,0,0,0
0,0,0,0,0,0,0,0,0,0,0,0,0,0,0,0,0,0,0,0,0,0,0,0,0
0,0,0,0,0,0,0,0,0,0,0,0,0,0,0,0,0,0,0,0,0,0,0,0,0
0,0,0,0,0,0,0,0,0,0,0,0,0,0,0,0,0,0,0,0,0,0,0,0,0
0,0,0,0,0,0,0,0,0,0,0,0,33,0,0,0,0,0,0,0,0,0,0,0,0
0,0,0,0,0,0,0,0,0,0,0,0,31,0,0,0,0,0,0,0,0,0,0,0,0
0,0,0,0,0,0,0,0,0,0,0,0,0,0,0,0,0,0,0,0,0,0,0,0,0
0,0,0,0,0,0,0,0,0,0,0,0,0,0,0,0,0,0,0,0,0,0,0,0,0
0,0,0,0,0,0,0,0,0,0,0,0,0,0,0,0,0,0,0,0,0,0,0,0,0
0,0,0,0,0,320,0,0,0,0,0,0,0,0,0,0,0,0,0,320,0,0,0,0,0
0,0,0,0,0,320,0,0,0,0,0,0,0,0,0,0,0,0,0,320,0,0,0,0,0
0,0,0,0,0,0,0,0,0,0,0,0,0,0,0,0,0,0,0,0,0,0,0,0,0
0,0,0,0,0,0,0,0,0,0,0,0,0,0,0,0,0,0,0,0,0,0,0,0,0
0,0,0,0,0,0,0,0,0,0,0,0,0,0,0,0,0,0,0,0,0,0,0,0,0
0,0,0,0,0,0,0,0,0,0,0,0,33,0,0,0,0,0,0,0,0,0,0,0,0
0,0,0,0,0,0,0,0,561,0,0,561,31,561,0,0,561,0,0,0,0,0,0,0,0
0,0,0,0,0,0,0,561,415,659,659,415,415,415,659,659,415,561,0,0,0,0,0,0,0
0,0,0,0,0,0,0,0,276,0,0,112,0,112,0,0,276,0,0,0,0,0,0,0,0
0,0,0,0,0,0,0,0,415,136,0,0,0,0,0,178,415,0,0,0,0,0,0,0,0
0,0,0,0,0,0,0,0,276,0,0,0,0,0,0,0,276,0,0,0,0,0,0,0,0
0,0,0,0,0,0,0,0,415,136,0,0,0,0,0,0,415,0,0,0,0,0,0,0,0
0,0,0,0,0,0,0,0,415,0,0,0,0,0,0,178,415,0,0,0,0,0,0,0,0
0,0,0,0,0,512,0,0,415,0,0,0,0,108,0,0,415,0,0,512,0,0,0,0,0
0,0,0,0,251,275,555,555,275,275,463,463,275,275,275,275,275,555,555,275,160,0,0,0,0
0,0,0,0,159,275,151,151,151,151,151,151,151,151,151,151,151,151,151,275,159,0,0,0,0
0,0,0,0,251,275,151,151,151,151,151,151,31,151,151,151,151,151,151,275,160,0,0,0,0
0,0,0,0,0,251,275,151,151,151,151,151,151,151,151,151,151,151,275,160,0,0,0,0,0
0,0,0,0,0,159,275,151,151,151,151,151,151,151,151,151,151,151,275,159,0,0,0,0,0
0,0,0,0,0,251,275,151,151,151,507,499,151,507,499,151,151,151,275,160,0,0,0,0,0
0,0,0,0,0,0,251,275,151,151,507,499,151,507,499,151,151,275,160,0,0,0,0,0,0
0,0,0,0,0,0,159,275,151,151,507,499,151,507,499,151,151,275,159,0,0,0,0,0,0
0,0,0,0,0,0,251,275,151,151,151,151,151,151,151,151,151,275,160,0,0,0,0,0,0
0,0,0,0,0,0,0,251,275,151,151,151,151,151,151,151,275,160,0,0,0,0,0,0,0
0,0,0,0,0,0,0,159,275,151,151,151,151,151,151,151,275,159,0,0,0,0,0,0,0
0,0,0,0,0,0,0,251,275,275,275,275,275,275,275,275,275,160,0,0,0,0,0,0,0
0,0,0,0,0,0,0,0,227,159,227,159,227,159,227,159,227,0,0,0,0,0,0,0,0
0,0,0,0,0,0,0,0,0,0,0,0,0,0,0,0,0,0,0,0,0,0,0,0,0
0,0,0,0,0,0,0,0,0,661,0,0,0,0,0,660,0,0,0,0,0,0,0,0,0
0,0,0,0,0,0,0,0,0,0,0,0,0,0,0,0,0,0,0,0,0,0,0,0,0
0,0,0,0,0,0,0,0,0,0,0,0,597,0,0,0,0,0,0,0,0,0,0,0,0
0,0,0,0,0,0,0,0,0,0,0,178,312,136,0,0,0,0,0,0,0,0,0,0,0
0,0,0,0,0,0,0,0,0,0,0,0,312,0,0,0,0,0,0,0,0,0,0,0,0
0,0,0,0,0,0,0,0,0,0,0,0,152,0,0,0,0,0,0,0,0,0,0,0,0
0,0,0,0,0,0,0,0,0,0,0,0,0,0,0,0,0,0,0,0,0,0,0,0,0
0,0,0,0,0,0,0,0,0,0,0,0,0,0,0,0,0,0,0,0,0,0,0,0,0
0,0,0,0,0,0,0,0,0,0,0,0,0,0,0,0,0,0,0,0,0,0,0,0,0
0,0,0,0,0,0,0,320,0,0,0,0,0,0,0,0,0,320,0,0,0,0,0,0,0
0,0,0,0,0,0,0,567,576,0,0,0,0,0,0,0,576,567,0,0,0,0,0,0,0
0,0,0,0,0,0,0,567,576,320,0,0,0,0,0,320,576,567,0,0,0,0,0,0,0
0,0,0,0,0,0,0,0,0,576,576,0,0,0,576,576,0,0,0,0,0,0,0,0,0
0,0,0,0,0,0,0,0,0,0,0,576,576,576,0,0,0,0,0,0,0,0,0,0,0
0,0,0,0,0,0,0,0,0,0,0,0,0,0,0,0,0,0,0,0,0,0,0,0,0
0,0,0,0,0,0,0,0,0,0,0,0,0,0,0,0,0,0,0,0,0,0,0,0,0
:endlayer
layer: 17
0,0,0,0,0,0,0,0,0,0,0,0,0,0,0,0,0,0,0,0,0,0,0,0,0
0,0,0,0,0,0,0,0,0,0,0,0,0,0,0,0,0,0,0,0,0,0,0,0,0
0,0,0,0,0,0,0,0,0,0,0,0,0,0,0,0,0,0,0,0,0,0,0,0,0
0,0,0,0,0,0,0,0,0,0,0,0,0,0,0,0,0,0,0,0,0,0,0,0,0
0,0,0,0,0,0,0,0,0,0,0,0,0,0,0,0,0,0,0,0,0,0,0,0,0
0,0,0,0,0,0,0,0,0,0,0,0,0,0,0,0,0,0,0,0,0,0,0,0,0
0,0,0,0,0,0,0,0,0,0,0,0,0,0,0,0,0,0,0,0,0,0,0,0,0
0,0,0,0,0,0,0,0,0,0,0,0,0,0,0,0,0,0,0,0,0,0,0,0,0
0,0,0,0,0,0,0,0,0,0,0,0,152,0,0,0,0,0,0,0,0,0,0,0,0
0,0,0,0,0,0,0,0,275,274,275,274,312,274,275,274,275,0,0,0,0,0,0,0,0
0,0,0,0,0,275,274,275,275,151,151,151,312,151,151,151,275,275,274,275,0,0,0,0,0
0,0,0,0,275,275,151,151,151,151,151,151,31,151,151,151,151,151,151,275,275,0,0,0,0
0,0,0,0,526,151,151,151,151,151,151,151,151,151,151,151,151,151,151,151,490,0,0,0,0
0,0,0,0,275,151,151,151,151,151,151,151,151,151,151,151,151,151,151,151,275,0,0,0,0
0,0,0,0,526,151,151,151,151,151,151,151,151,151,151,151,151,151,151,151,490,0,0,0,0
0,0,0,0,275,151,151,151,151,151,151,151,151,151,151,151,151,151,151,151,275,0,0,0,0
0,0,0,0,526,151,151,151,151,151,151,151,151,151,151,151,151,151,151,151,490,0,0,0,0
0,0,0,0,478,2,151,151,151,151,151,151,151,151,151,151,151,151,151,2,478,0,0,0,0
0,0,0,0,0,2,217,217,2,2,151,151,151,151,151,2,2,217,217,2,0,0,0,0,0
0,0,0,0,0,478,0,0,478,2,151,151,151,151,151,2,478,0,0,478,0,0,0,0,0
0,0,0,0,0,0,0,0,0,2,275,275,275,275,275,2,0,0,0,0,0,0,0,0,0
0,0,0,0,0,0,0,0,0,227,159,159,31,159,159,227,0,0,0,0,0,0,0,0,0
0,0,0,0,0,0,0,0,0,0,0,0,0,0,0,0,0,0,0,0,0,0,0,0,0
0,0,0,0,0,0,0,0,0,0,0,0,0,0,0,0,0,0,0,0,0,0,0,0,0
0,0,0,0,0,0,0,0,0,0,0,0,0,0,0,0,0,0,0,0,0,0,0,0,0
0,0,0,0,0,320,0,0,0,0,0,0,0,0,0,0,0,0,0,320,0,0,0,0,0
0,0,0,0,0,320,0,0,0,0,0,0,0,0,0,0,0,0,0,320,0,0,0,0,0
0,0,0,0,0,0,0,0,0,0,0,0,0,0,0,0,0,0,0,0,0,0,0,0,0
0,0,0,0,0,0,0,0,0,0,0,0,0,0,0,0,0,0,0,0,0,0,0,0,0
0,0,0,0,0,0,0,0,0,0,0,0,0,0,0,0,0,0,0,0,0,0,0,0,0
0,0,0,0,0,0,0,0,0,0,0,0,33,0,0,0,0,0,0,0,0,0,0,0,0
0,0,0,0,0,0,0,0,0,0,0,0,31,0,0,0,0,0,0,0,0,0,0,0,0
0,0,0,0,0,0,0,0,0,0,0,0,0,0,0,0,0,0,0,0,0,0,0,0,0
0,0,0,0,0,0,0,0,0,0,0,0,0,0,0,0,0,0,0,0,0,0,0,0,0
0,0,0,0,0,0,0,0,0,0,0,0,0,0,0,0,0,0,0,0,0,0,0,0,0
0,0,0,0,0,0,0,0,0,0,0,0,0,0,0,0,0,0,0,0,0,0,0,0,0
0,0,0,0,0,320,0,0,0,0,0,0,0,0,0,0,0,0,0,320,0,0,0,0,0
0,0,0,0,0,320,0,0,0,0,0,0,0,0,0,0,0,0,0,320,0,0,0,0,0
0,0,0,0,0,0,0,0,0,0,0,0,0,0,0,0,0,0,0,0,0,0,0,0,0
0,0,0,0,0,0,0,0,0,0,0,0,0,0,0,0,0,0,0,0,0,0,0,0,0
0,0,0,0,0,0,0,0,0,0,0,0,33,0,0,0,0,0,0,0,0,0,0,0,0
0,0,0,0,0,0,0,0,274,277,277,274,31,274,277,277,274,0,0,0,0,0,0,0,0
0,0,0,0,0,0,0,526,275,275,275,275,275,275,275,275,275,490,0,0,0,0,0,0,0
0,0,0,0,0,0,0,277,526,151,151,151,151,151,151,151,490,277,0,0,0,0,0,0,0
0,0,0,0,0,0,0,526,275,151,151,151,151,151,151,151,275,490,0,0,0,0,0,0,0
0,0,0,0,0,0,0,277,526,151,507,499,151,507,499,151,490,277,0,0,0,0,0,0,0
0,0,0,0,0,0,0,526,275,151,507,499,151,507,499,151,275,490,0,0,0,0,0,0,0
0,0,0,0,0,0,0,0,275,151,151,151,151,151,151,151,275,0,0,0,0,0,0,0,0
0,0,0,0,0,0,0,0,275,151,151,151,151,151,151,151,275,0,0,0,0,0,0,0,0
0,0,0,0,512,492,0,0,275,217,217,217,151,217,217,217,275,0,0,492,512,0,0,0,0
0,0,0,0,275,275,680,0,677,0,0,597,151,597,0,0,664,0,662,275,275,0,0,0,0
0,0,0,0,478,275,492,0,0,674,0,673,31,669,0,666,0,0,492,275,478,0,0,0,0
0,0,0,0,0,320,0,679,0,0,0,0,0,0,0,0,0,663,0,320,0,0,0,0,0
0,0,0,0,0,320,0,0,0,0,0,0,670,0,0,0,0,0,0,320,0,0,0,0,0
0,0,0,0,0,478,512,0,0,0,0,0,0,0,0,0,0,0,512,478,0,0,0,0,0
0,0,0,0,0,0,320,0,0,675,0,0,0,0,0,667,0,0,320,0,0,0,0,0,0
0,0,0,0,0,0,320,32,0,0,0,0,0,0,0,0,0,32,320,0,0,0,0,0,0
0,0,0,0,0,0,478,512,492,676,0,0,671,0,0,668,492,512,478,0,0,0,0,0,0
0,0,0,0,0,0,0,275,678,492,0,0,0,0,0,492,665,275,0,0,0,0,0,0,0
0,0,0,0,0,0,0,275,275,492,0,0,0,0,0,492,275,275,0,0,0,0,0,0,0
0,0,0,0,0,0,0,478,275,492,0,0,108,0,0,492,275,478,0,0,0,0,0,0,0
0,0,0,0,0,0,0,0,531,320,320,320,275,320,320,320,491,0,0,0,0,0,0,0,0
0,0,0,0,0,0,0,0,0,0,0,0,0,0,0,0,0,0,0,0,0,0,0,0,0
0,0,0,0,0,0,0,0,0,0,0,0,0,0,0,0,0,0,0,0,0,0,0,0,0
0,0,0,0,0,0,0,0,0,0,0,0,0,0,0,0,0,0,0,0,0,0,0,0,0
0,0,0,0,0,0,0,0,0,0,0,0,0,0,0,0,0,0,0,0,0,0,0,0,0
0,0,0,0,0,0,0,0,0,0,0,0,672,0,0,0,0,0,0,0,0,0,0,0,0
0,0,0,0,0,0,0,0,0,0,0,0,597,0,0,0,0,0,0,0,0,0,0,0,0
0,0,0,0,0,0,0,0,0,0,0,0,312,0,0,0,0,0,0,0,0,0,0,0,0
0,0,0,0,0,0,0,0,0,0,0,0,312,0,0,0,0,0,0,0,0,0,0,0,0
0,0,0,0,0,0,0,0,0,0,0,0,152,0,0,0,0,0,0,0,0,0,0,0,0
0,0,0,0,0,0,0,0,0,0,0,0,0,0,0,0,0,0,0,0,0,0,0,0,0
0,0,0,0,0,0,0,0,0,0,0,0,0,0,0,0,0,0,0,0,0,0,0,0,0
0,0,0,0,0,0,0,0,0,0,0,0,0,0,0,0,0,0,0,0,0,0,0,0,0
0,0,0,0,0,0,0,320,0,0,0,0,0,0,0,0,0,320,0,0,0,0,0,0,0
0,0,0,0,0,0,0,567,576,320,0,0,0,0,0,320,576,567,0,0,0,0,0,0,0
0,0,0,0,0,0,0,0,0,576,576,576,576,576,576,576,0,0,0,0,0,0,0,0,0
0,0,0,0,0,0,0,0,0,0,0,0,0,0,0,0,0,0,0,0,0,0,0,0,0
0,0,0,0,0,0,0,0,0,0,0,0,0,0,0,0,0,0,0,0,0,0,0,0,0
:endlayer
layer: 18
0,0,0,0,0,0,0,0,0,0,0,0,0,0,0,0,0,0,0,0,0,0,0,0,0
0,0,0,0,0,0,0,0,0,0,0,0,0,0,0,0,0,0,0,0,0,0,0,0,0
0,0,0,0,0,0,0,0,0,0,0,0,0,0,0,0,0,0,0,0,0,0,0,0,0
0,0,0,0,0,0,0,0,0,0,0,0,0,0,0,0,0,0,0,0,0,0,0,0,0
0,0,0,0,0,0,0,0,0,0,0,0,0,0,0,0,0,0,0,0,0,0,0,0,0
0,0,0,0,0,0,0,0,0,0,0,0,0,0,0,0,0,0,0,0,0,0,0,0,0
0,0,0,0,0,0,0,0,0,0,0,0,152,0,0,0,0,0,0,0,0,0,0,0,0
0,0,0,0,0,0,0,0,0,0,0,0,312,0,0,0,0,0,0,0,0,0,0,0,0
0,0,0,0,0,0,0,0,0,0,0,0,312,0,0,0,0,0,0,0,0,0,0,0,0
0,0,0,0,0,0,0,0,275,320,320,320,275,320,320,320,275,0,0,0,0,0,0,0,0
0,0,0,0,0,320,275,320,320,719,0,0,704,0,0,694,320,320,275,320,0,0,0,0,0
0,0,0,0,275,320,478,0,722,0,0,712,31,700,0,0,688,0,478,320,275,0,0,0,0
0,0,0,0,320,732,729,0,0,0,0,713,705,701,0,0,0,0,683,681,320,0,0,0,0
0,0,0,0,275,491,730,0,0,0,0,0,0,0,0,0,0,0,684,531,275,0,0,0,0
0,0,0,0,320,0,0,0,723,0,0,492,492,492,0,0,689,0,0,0,320,0,0,0,0
0,0,0,0,320,733,0,0,0,0,492,275,275,275,492,0,0,0,0,682,320,0,0,0,0
0,0,0,0,320,275,0,0,0,0,275,275,706,275,275,0,0,0,0,275,320,0,0,0,0
0,0,0,0,0,275,0,0,724,0,716,275,707,275,697,0,690,0,0,275,0,0,0,0,0
0,0,0,0,0,275,0,0,275,320,492,275,275,275,492,320,275,0,0,275,0,0,0,0,0
0,0,0,0,0,0,0,0,725,320,492,275,31,275,492,320,691,0,0,0,0,0,0,0,0
0,0,0,0,0,0,0,0,0,320,492,275,275,275,492,320,0,0,0,0,0,0,0,0,0
0,0,0,0,0,0,0,0,0,275,320,320,31,320,320,275,0,0,0,0,0,0,0,0,0
0,0,0,0,0,0,0,0,0,0,0,0,285,0,0,0,0,0,0,0,0,0,0,0,0
0,0,0,0,0,0,0,0,0,0,0,0,0,0,0,0,0,0,0,0,0,0,0,0,0
0,0,0,0,0,0,0,0,0,0,0,0,0,0,0,0,0,0,0,0,0,0,0,0,0
0,0,0,0,0,0,0,0,0,0,0,0,0,0,0,0,0,0,0,0,0,0,0,0,0
0,0,0,0,0,320,320,0,0,0,0,0,0,0,0,0,0,0,320,320,0,0,0,0,0
0,0,0,0,0,320,320,0,0,0,0,0,0,0,0,0,0,0,320,320,0,0,0,0,0
0,0,0,0,0,320,320,0,0,0,0,0,0,0,0,0,0,0,320,320,0,0,0,0,0
0,0,0,0,0,0,0,0,0,0,0,0,0,0,0,0,0,0,0,0,0,0,0,0,0
0,0,0,0,0,0,0,0,0,0,0,0,33,0,0,0,0,0,0,0,0,0,0,0,0
0,0,0,0,0,0,0,0,0,0,0,0,31,0,0,0,0,0,0,0,0,0,0,0,0
0,0,0,0,0,0,0,0,0,0,0,0,0,0,0,0,0,0,0,0,0,0,0,0,0
0,0,0,0,0,0,0,0,0,0,0,0,0,0,0,0,0,0,0,0,0,0,0,0,0
0,0,0,0,0,0,0,0,0,0,0,0,0,0,0,0,0,0,0,0,0,0,0,0,0
0,0,0,0,0,0,0,0,0,0,0,0,0,0,0,0,0,0,0,0,0,0,0,0,0
0,0,0,0,0,0,0,0,0,0,0,0,0,0,0,0,0,0,0,0,0,0,0,0,0
0,0,0,0,0,320,320,0,0,0,0,0,0,0,0,0,0,0,320,320,0,0,0,0,0
0,0,0,0,0,320,320,0,0,0,0,0,0,0,0,0,0,0,320,320,0,0,0,0,0
0,0,0,0,0,0,0,0,0,0,0,0,0,0,0,0,0,0,0,0,0,0,0,0,0
0,0,0,0,0,0,0,0,0,0,0,0,33,0,0,0,0,0,0,0,0,0,0,0,0
0,0,0,0,0,0,0,0,189,320,320,320,31,320,320,320,258,0,0,0,0,0,0,0,0
0,0,0,0,0,0,0,686,2,720,717,0,708,0,698,695,2,686,0,0,0,0,0,0,0
0,0,0,0,0,0,0,320,492,492,0,0,0,0,0,492,492,320,0,0,0,0,0,0,0
0,0,0,0,0,0,0,320,32,0,0,0,709,0,0,0,32,320,0,0,0,0,0,0,0
0,0,0,0,0,0,0,320,726,0,0,0,0,0,0,0,692,320,0,0,0,0,0,0,0
0,0,0,0,0,0,0,76,686,0,0,0,0,0,0,0,686,76,0,0,0,0,0,0,0
0,0,0,0,0,0,0,0,320,0,0,714,710,702,0,0,320,0,0,0,0,0,0,0,0
0,0,0,0,0,0,0,0,275,721,718,715,711,703,699,696,275,0,0,0,0,0,0,0,0
0,0,0,0,0,0,0,0,478,0,0,0,0,0,0,0,478,0,0,0,0,0,0,0,0
0,0,0,0,0,0,0,0,0,0,0,0,33,0,0,0,0,0,0,0,0,0,0,0,0
0,0,0,0,0,32,731,0,0,0,0,0,31,0,0,0,0,0,685,32,0,0,0,0,0
0,0,0,0,0,0,0,0,0,0,0,0,0,0,0,0,0,0,0,0,0,0,0,0,0
0,0,0,0,0,0,0,0,0,0,0,0,0,0,0,0,0,0,0,0,0,0,0,0,0
0,0,0,0,0,0,0,0,0,0,0,0,0,0,0,0,0,0,0,0,0,0,0,0,0
0,0,0,0,0,0,0,0,0,0,0,0,0,0,0,0,0,0,0,0,0,0,0,0,0
0,0,0,0,0,0,0,0,0,0,0,0,0,0,0,0,0,0,0,0,0,0,0,0,0
0,0,0,0,0,0,0,0,0,0,0,0,0,0,0,0,0,0,0,0,0,0,0,0,0
0,0,0,0,0,0,0,728,0,0,0,0,0,0,0,0,0,687,0,0,0,0,0,0,0
0,0,0,0,0,0,0,0,727,0,0,0,0,0,0,0,693,0,0,0,0,0,0,0,0
0,0,0,0,0,0,0,0,320,0,0,0,0,0,0,0,320,0,0,0,0,0,0,0,0
0,0,0,0,0,0,0,0,0,0,32,0,320,0,32,0,0,0,0,0,0,0,0,0,0
0,0,0,0,0,0,0,0,0,0,0,0,0,0,0,0,0,0,0,0,0,0,0,0,0
0,0,0,0,0,0,0,0,0,0,0,0,0,0,0,0,0,0,0,0,0,0,0,0,0
0,0,0,0,0,0,0,0,0,0,0,0,0,0,0,0,0,0,0,0,0,0,0,0,0
0,0,0,0,0,0,0,0,0,0,0,0,0,0,0,0,0,0,0,0,0,0,0,0,0
0,0,0,0,0,0,0,0,0,0,0,0,0,0,0,0,0,0,0,0,0,0,0,0,0
0,0,0,0,0,0,0,0,0,0,0,0,0,0,0,0,0,0,0,0,0,0,0,0,0
0,0,0,0,0,0,0,0,0,0,0,0,0,0,0,0,0,0,0,0,0,0,0,0,0
0,0,0,0,0,0,0,0,0,0,0,0,597,0,0,0,0,0,0,0,0,0,0,0,0
0,0,0,0,0,0,0,0,0,0,0,0,312,0,0,0,0,0,0,0,0,0,0,0,0
0,0,0,0,0,0,0,0,0,0,0,178,312,136,0,0,0,0,0,0,0,0,0,0,0
0,0,0,0,0,0,0,0,0,0,0,0,152,0,0,0,0,0,0,0,0,0,0,0,0
0,0,0,0,0,0,0,0,0,0,0,0,0,0,0,0,0,0,0,0,0,0,0,0,0
0,0,0,0,0,0,0,0,0,0,0,0,0,0,0,0,0,0,0,0,0,0,0,0,0
0,0,0,0,0,0,0,0,0,0,0,0,0,0,0,0,0,0,0,0,0,0,0,0,0
0,0,0,0,0,0,0,567,576,576,320,0,0,0,320,576,576,567,0,0,0,0,0,0,0
0,0,0,0,0,0,0,0,0,0,576,576,576,576,576,0,0,0,0,0,0,0,0,0,0
0,0,0,0,0,0,0,0,0,0,0,0,0,0,0,0,0,0,0,0,0,0,0,0,0
:endlayer
layer: 19
0,0,0,0,0,0,0,0,0,0,0,0,0,0,0,0,0,0,0,0,0,0,0,0,0
0,0,0,0,0,0,0,0,0,0,0,0,0,0,0,0,0,0,0,0,0,0,0,0,0
0,0,0,0,0,0,0,0,0,0,0,0,0,0,0,0,0,0,0,0,0,0,0,0,0
0,0,0,0,0,0,0,0,0,0,0,0,0,0,0,0,0,0,0,0,0,0,0,0,0
0,0,0,0,0,0,0,0,0,0,0,0,152,0,0,0,0,0,0,0,0,0,0,0,0
0,0,0,0,0,0,0,0,0,0,0,0,312,0,0,0,0,0,0,0,0,0,0,0,0
0,0,0,0,0,0,0,0,0,0,0,0,312,0,0,0,0,0,0,0,0,0,0,0,0
0,0,0,0,0,0,0,0,0,0,0,0,597,0,0,0,0,0,0,0,0,0,0,0,0
0,0,0,0,0,0,0,0,0,0,0,0,0,0,0,0,0,0,0,0,0,0,0,0,0
0,0,0,0,0,0,0,0,320,0,32,0,320,0,32,0,320,0,0,0,0,0,0,0,0
0,0,0,0,0,0,0,0,0,0,0,0,0,0,0,0,0,0,0,0,0,0,0,0,0
0,0,0,0,32,0,0,0,0,0,0,0,31,0,0,0,0,0,0,0,32,0,0,0,0
0,0,0,0,0,0,0,0,0,0,0,0,0,0,0,0,0,0,0,0,0,0,0,0,0
0,0,0,0,0,0,0,0,0,0,0,0,0,0,0,0,0,0,0,0,0,0,0,0,0
0,0,0,0,0,0,0,0,0,0,0,0,0,0,0,0,0,0,0,0,0,0,0,0,0
0,0,0,0,0,0,0,0,0,0,740,0,283,0,736,0,0,0,0,0,0,0,0,0,0
0,0,0,0,0,32,0,0,0,0,0,739,515,738,0,0,0,0,0,32,0,0,0,0,0
0,0,0,0,0,512,0,0,0,0,0,0,515,0,0,0,0,0,0,512,0,0,0,0,0
0,0,0,0,0,320,0,0,32,0,0,0,212,0,0,0,32,0,0,320,0,0,0,0,0
0,0,0,0,0,320,0,0,0,0,741,561,31,561,737,0,0,0,0,320,0,0,0,0,0
0,0,0,0,0,0,0,0,0,0,0,0,33,0,0,0,0,0,0,0,0,0,0,0,0
0,0,0,0,0,0,0,0,0,320,0,320,31,320,0,320,0,0,0,0,0,0,0,0,0
0,0,0,0,0,0,0,0,0,0,0,0,275,0,0,0,0,0,0,0,0,0,0,0,0
0,0,0,0,0,0,0,0,0,0,0,0,0,0,0,0,0,0,0,0,0,0,0,0,0
0,0,0,0,0,0,0,0,0,0,0,0,0,0,0,0,0,0,0,0,0,0,0,0,0
0,0,0,0,0,0,0,0,0,0,0,0,0,0,0,0,0,0,0,0,0,0,0,0,0
0,0,0,0,0,0,0,0,0,0,0,0,0,0,0,0,0,0,0,0,0,0,0,0,0
0,0,0,0,0,0,0,0,0,0,0,0,0,0,0,0,0,0,0,0,0,0,0,0,0
0,0,0,0,0,0,320,0,0,0,0,0,0,0,0,0,0,0,320,0,0,0,0,0,0
0,0,0,0,0,0,320,0,0,0,0,0,0,0,0,0,0,0,320,0,0,0,0,0,0
0,0,0,0,0,0,0,0,0,0,0,0,33,0,0,0,0,0,0,0,0,0,0,0,0
0,0,0,0,0,0,0,0,0,0,0,0,31,0,0,0,0,0,0,0,0,0,0,0,0
0,0,0,0,0,0,0,0,0,0,0,0,0,0,0,0,0,0,0,0,0,0,0,0,0
0,0,0,0,0,0,0,0,0,0,0,0,0,0,0,0,0,0,0,0,0,0,0,0,0
0,0,0,0,0,0,0,0,0,0,0,0,0,0,0,0,0,0,0,0,0,0,0,0,0
0,0,0,0,0,0,0,0,0,0,0,0,0,0,0,0,0,0,0,0,0,0,0,0,0
0,0,0,0,0,0,0,0,0,0,0,0,0,0,0,0,0,0,0,0,0,0,0,0,0
0,0,0,0,0,0,0,0,0,0,0,0,0,0,0,0,0,0,0,0,0,0,0,0,0
0,0,0,0,0,0,320,0,0,0,0,0,0,0,0,0,0,0,320,0,0,0,0,0,0
0,0,0,0,0,0,320,0,0,0,0,0,0,0,0,0,0,0,320,0,0,0,0,0,0
0,0,0,0,0,0,0,0,0,0,0,0,33,0,0,0,0,0,0,0,0,0,0,0,0
0,0,0,0,0,0,0,0,0,0,0,0,31,0,0,0,0,0,0,0,0,0,0,0,0
0,0,0,0,0,0,0,0,0,0,0,0,0,0,0,0,0,0,0,0,0,0,0,0,0
0,0,0,0,0,0,0,0,742,0,0,0,0,0,0,0,735,0,0,0,0,0,0,0,0
0,0,0,0,0,0,0,0,0,0,0,0,0,0,0,0,0,0,0,0,0,0,0,0,0
0,0,0,0,0,0,0,0,0,0,0,0,0,0,0,0,0,0,0,0,0,0,0,0,0
0,0,0,0,0,0,0,743,0,0,0,0,0,0,0,0,0,734,0,0,0,0,0,0,0
0,0,0,0,0,0,0,0,0,0,0,0,0,0,0,0,0,0,0,0,0,0,0,0,0
0,0,0,0,0,0,0,0,512,0,0,0,0,0,0,0,512,0,0,0,0,0,0,0,0
0,0,0,0,0,0,0,0,320,0,0,0,0,0,0,0,320,0,0,0,0,0,0,0,0
0,0,0,0,0,0,0,0,320,0,0,0,33,0,0,0,320,0,0,0,0,0,0,0,0
0,0,0,0,0,0,0,0,320,0,0,178,31,136,0,0,320,0,0,0,0,0,0,0,0
0,0,0,0,0,0,0,0,0,0,0,0,112,0,0,0,0,0,0,0,0,0,0,0,0
0,0,0,0,0,0,0,0,0,0,0,0,0,0,0,0,0,0,0,0,0,0,0,0,0
0,0,0,0,0,0,0,0,0,0,0,0,0,0,0,0,0,0,0,0,0,0,0,0,0
0,0,0,0,0,0,0,0,0,0,0,0,0,0,0,0,0,0,0,0,0,0,0,0,0
0,0,0,0,0,0,0,0,0,0,0,0,0,0,0,0,0,0,0,0,0,0,0,0,0
0,0,0,0,0,0,0,0,0,0,0,0,0,0,0,0,0,0,0,0,0,0,0,0,0
0,0,0,0,0,0,0,0,0,0,0,0,0,0,0,0,0,0,0,0,0,0,0,0,0
0,0,0,0,0,0,0,0,0,0,0,0,0,0,0,0,0,0,0,0,0,0,0,0,0
0,0,0,0,0,0,0,0,32,0,0,0,0,0,0,0,32,0,0,0,0,0,0,0,0
0,0,0,0,0,0,0,0,0,0,0,0,32,0,0,0,0,0,0,0,0,0,0,0,0
0,0,0,0,0,0,0,0,0,0,0,0,0,0,0,0,0,0,0,0,0,0,0,0,0
0,0,0,0,0,0,0,0,0,0,0,0,0,0,0,0,0,0,0,0,0,0,0,0,0
0,0,0,0,0,0,0,0,0,0,0,0,0,0,0,0,0,0,0,0,0,0,0,0,0
0,0,0,0,0,0,0,0,0,0,0,0,0,0,0,0,0,0,0,0,0,0,0,0,0
0,0,0,0,0,0,0,0,0,0,0,0,0,0,0,0,0,0,0,0,0,0,0,0,0
0,0,0,0,0,0,0,0,0,0,0,0,0,0,0,0,0,0,0,0,0,0,0,0,0
0,0,0,0,0,0,0,0,0,0,0,0,0,0,0,0,0,0,0,0,0,0,0,0,0
0,0,0,0,0,0,0,0,0,0,0,0,0,0,0,0,0,0,0,0,0,0,0,0,0
0,0,0,0,0,0,0,0,0,0,0,0,274,0,0,0,0,0,0,0,0,0,0,0,0
0,0,0,0,0,0,0,0,0,0,0,0,312,0,0,0,0,0,0,0,0,0,0,0,0
0,0,0,0,0,0,0,0,0,0,0,0,312,0,0,0,0,0,0,0,0,0,0,0,0
0,0,0,0,0,0,0,0,0,0,0,0,312,0,0,0,0,0,0,0,0,0,0,0,0
0,0,0,0,0,0,0,0,0,0,0,0,152,0,0,0,0,0,0,0,0,0,0,0,0
0,0,0,0,0,0,0,0,0,0,0,0,0,0,0,0,0,0,0,0,0,0,0,0,0
0,0,0,0,0,0,0,320,0,0,0,0,0,0,0,0,0,320,0,0,0,0,0,0,0
0,0,0,0,0,0,0,567,567,567,567,567,567,567,567,567,567,567,0,0,0,0,0,0,0
0,0,0,0,0,0,0,0,0,0,0,0,0,0,0,0,0,0,0,0,0,0,0,0,0
:endlayer
layer: 20
0,0,0,0,0,0,0,0,0,0,0,0,0,0,0,0,0,0,0,0,0,0,0,0,0
0,0,0,0,0,0,0,0,0,0,0,0,0,0,0,0,0,0,0,0,0,0,0,0,0
0,0,0,0,0,0,0,0,0,0,0,0,0,0,0,0,0,0,0,0,0,0,0,0,0
0,0,0,0,0,0,0,0,0,0,0,0,0,0,0,0,0,0,0,0,0,0,0,0,0
0,0,0,0,0,0,0,0,0,0,0,0,320,0,0,0,0,0,0,0,0,0,0,0,0
0,0,0,0,0,0,0,0,0,0,0,0,320,0,0,0,0,0,0,0,0,0,0,0,0
0,0,0,0,0,0,0,0,0,0,0,0,0,0,0,0,0,0,0,0,0,0,0,0,0
0,0,0,0,0,0,0,0,0,0,0,0,0,0,0,0,0,0,0,0,0,0,0,0,0
0,0,0,0,0,0,0,0,0,0,0,0,0,0,0,0,0,0,0,0,0,0,0,0,0
0,0,0,0,0,0,0,0,32,0,0,0,320,0,0,0,32,0,0,0,0,0,0,0,0
0,0,0,0,0,0,0,0,0,0,0,0,0,0,0,0,0,0,0,0,0,0,0,0,0
0,0,0,0,0,0,0,0,0,0,0,0,31,0,0,0,0,0,0,0,0,0,0,0,0
0,0,0,0,0,0,0,0,0,0,0,0,0,0,0,0,0,0,0,0,0,0,0,0,0
0,0,0,0,0,0,0,0,0,0,0,0,0,0,0,0,0,0,0,0,0,0,0,0,0
0,0,0,0,0,0,0,0,0,0,0,0,0,0,0,0,0,0,0,0,0,0,0,0,0
0,0,0,0,0,0,0,0,0,0,0,0,0,0,0,0,0,0,0,0,0,0,0,0,0
0,0,0,0,0,745,0,0,0,0,0,0,0,0,0,0,0,0,0,744,0,0,0,0,0
0,0,0,0,0,0,0,0,0,0,0,0,0,0,0,0,0,0,0,0,0,0,0,0,0
0,0,0,0,0,0,0,0,0,0,0,0,0,0,0,0,0,0,0,0,0,0,0,0,0
0,0,0,0,0,320,320,0,0,0,0,0,492,0,0,0,0,0,320,320,0,0,0,0,0
0,0,0,0,0,320,320,0,0,0,0,0,33,0,0,0,0,0,320,320,0,0,0,0,0
0,0,0,0,0,0,0,0,0,32,0,0,31,0,0,32,0,0,0,0,0,0,0,0,0
0,0,0,0,0,0,0,0,0,0,0,0,320,0,0,0,0,0,0,0,0,0,0,0,0
0,0,0,0,0,0,0,0,0,0,0,0,0,0,0,0,0,0,0,0,0,0,0,0,0
0,0,0,0,0,0,0,0,0,0,0,0,0,0,0,0,0,0,0,0,0,0,0,0,0
0,0,0,0,0,0,0,0,0,0,0,0,0,0,0,0,0,0,0,0,0,0,0,0,0
0,0,0,0,0,0,0,0,0,0,0,0,0,0,0,0,0,0,0,0,0,0,0,0,0
0,0,0,0,0,0,0,0,0,0,0,0,0,0,0,0,0,0,0,0,0,0,0,0,0
0,0,0,0,0,0,0,0,0,0,0,0,0,0,0,0,0,0,0,0,0,0,0,0,0
0,0,0,0,0,0,320,0,0,0,0,0,0,0,0,0,0,0,320,0,0,0,0,0,0
0,0,0,0,0,0,320,0,0,0,0,0,33,0,0,0,0,0,320,0,0,0,0,0,0
0,0,0,0,0,0,0,0,0,0,0,0,31,0,0,0,0,0,0,0,0,0,0,0,0
0,0,0,0,0,0,0,0,0,0,0,0,0,0,0,0,0,0,0,0,0,0,0,0,0
0,0,0,0,0,0,0,0,0,0,0,0,0,0,0,0,0,0,0,0,0,0,0,0,0
0,0,0,0,0,0,0,0,0,0,0,0,0,0,0,0,0,0,0,0,0,0,0,0,0
0,0,0,0,0,0,0,0,0,0,0,0,0,0,0,0,0,0,0,0,0,0,0,0,0
0,0,0,0,0,0,0,0,0,0,0,0,0,0,0,0,0,0,0,0,0,0,0,0,0
0,0,0,0,0,0,0,0,0,0,0,0,0,0,0,0,0,0,0,0,0,0,0,0,0
0,0,0,0,0,0,0,0,0,0,0,0,0,0,0,0,0,0,0,0,0,0,0,0,0
0,0,0,0,0,0,320,0,0,0,0,0,0,0,0,0,0,0,320,0,0,0,0,0,0
0,0,0,0,0,0,320,0,0,0,0,0,33,0,0,0,0,0,320,0,0,0,0,0,0
0,0,0,0,0,0,0,0,0,0,0,0,31,0,0,0,0,0,0,0,0,0,0,0,0
0,0,0,0,0,0,0,0,0,0,0,0,0,0,0,0,0,0,0,0,0,0,0,0,0
0,0,0,0,0,0,0,0,0,0,0,0,0,0,0,0,0,0,0,0,0,0,0,0,0
0,0,0,0,0,0,0,0,0,0,0,0,0,0,0,0,0,0,0,0,0,0,0,0,0
0,0,0,0,0,0,0,0,0,0,0,0,0,0,0,0,0,0,0,0,0,0,0,0,0
0,0,0,0,0,0,0,0,0,0,0,0,0,0,0,0,0,0,0,0,0,0,0,0,0
0,0,0,0,0,0,0,0,0,0,0,0,0,0,0,0,0,0,0,0,0,0,0,0,0
0,0,0,0,0,0,0,0,0,0,0,0,0,0,0,0,0,0,0,0,0,0,0,0,0
0,0,0,0,0,0,0,0,0,0,0,0,0,0,0,0,0,0,0,0,0,0,0,0,0
0,0,0,0,0,0,0,0,0,0,0,0,33,0,0,0,0,0,0,0,0,0,0,0,0
0,0,0,0,0,0,0,320,320,0,0,0,31,0,0,0,320,320,0,0,0,0,0,0,0
0,0,0,0,0,0,0,320,0,0,0,0,0,0,0,0,0,320,0,0,0,0,0,0,0
0,0,0,0,0,0,0,320,567,567,567,567,567,567,567,567,567,320,0,0,0,0,0,0,0
0,0,0,0,0,0,0,0,0,0,0,0,0,0,0,0,0,0,0,0,0,0,0,0,0
0,0,0,0,0,0,0,0,0,0,0,0,0,0,0,0,0,0,0,0,0,0,0,0,0
0,0,0,0,0,0,0,0,0,0,0,0,0,0,0,0,0,0,0,0,0,0,0,0,0
0,0,0,0,0,0,0,0,0,0,0,0,0,0,0,0,0,0,0,0,0,0,0,0,0
0,0,0,0,0,0,0,0,0,0,0,0,0,0,0,0,0,0,0,0,0,0,0,0,0
0,0,0,0,0,0,0,0,0,0,0,0,0,0,0,0,0,0,0,0,0,0,0,0,0
0,0,0,0,0,0,0,0,0,0,0,0,0,0,0,0,0,0,0,0,0,0,0,0,0
0,0,0,0,0,0,0,0,0,0,0,0,0,0,0,0,0,0,0,0,0,0,0,0,0
0,0,0,0,0,0,0,0,0,0,0,0,0,0,0,0,0,0,0,0,0,0,0,0,0
0,0,0,0,0,0,0,0,0,0,0,0,0,0,0,0,0,0,0,0,0,0,0,0,0
0,0,0,0,0,0,0,0,0,0,0,0,0,0,0,0,0,0,0,0,0,0,0,0,0
0,0,0,0,0,0,0,0,0,0,0,0,0,0,0,0,0,0,0,0,0,0,0,0,0
0,0,0,0,0,0,0,0,0,0,0,0,0,0,0,0,0,0,0,0,0,0,0,0,0
0,0,0,0,0,0,0,0,0,0,0,0,0,0,0,0,0,0,0,0,0,0,0,0,0
0,0,0,0,0,0,0,0,0,0,0,0,0,0,0,0,0,0,0,0,0,0,0,0,0
0,0,0,0,0,0,0,0,0,0,0,0,320,0,0,0,0,0,0,0,0,0,0,0,0
0,0,0,0,0,0,0,0,0,0,0,0,320,0,0,0,0,0,0,0,0,0,0,0,0
0,0,0,0,0,0,0,0,0,0,0,0,275,0,0,0,0,0,0,0,0,0,0,0,0
0,0,0,0,0,0,0,0,0,0,0,0,478,0,0,0,0,0,0,0,0,0,0,0,0
0,0,0,0,0,0,0,0,0,0,0,0,597,0,0,0,0,0,0,0,0,0,0,0,0
0,0,0,0,0,0,0,0,0,0,0,0,312,0,0,0,0,0,0,0,0,0,0,0,0
0,0,0,0,0,0,0,0,108,0,0,0,312,0,0,0,108,0,0,0,0,0,0,0,0
0,0,0,0,0,0,153,504,504,504,504,504,504,504,504,504,504,504,219,0,0,0,0,0,0
0,0,0,0,0,0,0,0,0,0,0,0,320,0,0,0,0,0,0,0,0,0,0,0,0
0,0,0,0,0,0,0,0,0,0,0,0,0,0,0,0,0,0,0,0,0,0,0,0,0
:endlayer
layer: 21
0,0,0,0,0,0,0,0,0,0,0,0,0,0,0,0,0,0,0,0,0,0,0,0,0
0,0,0,0,0,0,0,0,0,0,0,0,0,0,0,0,0,0,0,0,0,0,0,0,0
0,0,0,0,0,0,0,0,0,0,0,0,0,0,0,0,0,0,0,0,0,0,0,0,0
0,0,0,0,0,0,0,0,0,0,0,0,0,0,0,0,0,0,0,0,0,0,0,0,0
0,0,0,0,0,0,0,0,0,0,0,0,320,0,0,0,0,0,0,0,0,0,0,0,0
0,0,0,0,0,0,0,0,0,0,0,0,32,0,0,0,0,0,0,0,0,0,0,0,0
0,0,0,0,0,0,0,0,0,0,0,0,0,0,0,0,0,0,0,0,0,0,0,0,0
0,0,0,0,0,0,0,0,0,0,0,0,0,0,0,0,0,0,0,0,0,0,0,0,0
0,0,0,0,0,0,0,0,0,0,0,0,0,0,0,0,0,0,0,0,0,0,0,0,0
0,0,0,0,0,0,0,0,0,0,0,0,32,0,0,0,0,0,0,0,0,0,0,0,0
0,0,0,0,0,0,0,0,0,0,0,0,108,0,0,0,0,0,0,0,0,0,0,0,0
0,0,0,0,0,0,0,0,0,0,0,178,31,136,0,0,0,0,0,0,0,0,0,0,0
0,0,0,0,0,0,0,0,0,0,0,0,112,0,0,0,0,0,0,0,0,0,0,0,0
0,0,0,0,0,0,0,0,0,0,0,0,0,0,0,0,0,0,0,0,0,0,0,0,0
0,0,0,0,0,0,0,0,0,0,0,0,0,0,0,0,0,0,0,0,0,0,0,0,0
0,0,0,0,0,0,0,0,0,0,0,0,0,0,0,0,0,0,0,0,0,0,0,0,0
0,0,0,0,0,0,0,0,0,0,0,0,0,0,0,0,0,0,0,0,0,0,0,0,0
0,0,0,0,0,0,0,0,0,0,0,0,0,0,0,0,0,0,0,0,0,0,0,0,0
0,0,0,0,0,0,0,0,0,0,0,0,0,0,0,0,0,0,0,0,0,0,0,0,0
0,0,0,0,0,0,0,0,0,0,0,0,0,0,0,0,0,0,0,0,0,0,0,0,0
0,0,0,0,0,0,320,0,0,0,0,0,33,0,0,0,0,0,320,0,0,0,0,0,0
0,0,0,0,0,0,320,0,0,0,0,178,31,320,0,0,0,0,320,0,0,0,0,0,0
0,0,0,0,0,0,320,0,0,0,0,0,320,320,0,0,0,0,320,0,0,0,0,0,0
0,0,0,0,0,0,0,0,0,0,0,0,0,0,0,0,0,0,0,0,0,0,0,0,0
0,0,0,0,0,0,0,0,0,0,0,0,0,0,0,0,0,0,0,0,0,0,0,0,0
0,0,0,0,0,0,0,0,0,0,0,0,0,0,0,0,0,0,0,0,0,0,0,0,0
0,0,0,0,0,0,0,0,0,0,0,0,0,0,0,0,0,0,0,0,0,0,0,0,0
0,0,0,0,0,0,0,0,0,0,0,0,0,0,0,0,0,0,0,0,0,0,0,0,0
0,0,0,0,0,0,0,0,0,0,0,0,0,0,0,0,0,0,0,0,0,0,0,0,0
0,0,0,0,0,0,0,0,0,0,0,0,0,0,0,0,0,0,0,0,0,0,0,0,0
0,0,0,0,0,0,320,0,0,0,0,0,33,0,0,0,0,0,320,0,0,0,0,0,0
0,0,0,0,0,0,320,0,0,0,0,178,31,136,0,0,0,0,320,0,0,0,0,0,0
0,0,0,0,0,0,320,0,0,0,0,0,112,0,0,0,0,0,320,0,0,0,0,0,0
0,0,0,0,0,0,0,0,0,0,0,0,0,0,0,0,0,0,0,0,0,0,0,0,0
0,0,0,0,0,0,0,0,0,0,0,0,0,0,0,0,0,0,0,0,0,0,0,0,0
0,0,0,0,0,0,0,0,0,0,0,0,0,0,0,0,0,0,0,0,0,0,0,0,0
0,0,0,0,0,0,0,0,0,0,0,0,0,0,0,0,0,0,0,0,0,0,0,0,0
0,0,0,0,0,0,0,0,0,0,0,0,0,0,0,0,0,0,0,0,0,0,0,0,0
0,0,0,0,0,0,0,0,0,0,0,0,0,0,0,0,0,0,0,0,0,0,0,0,0
0,0,0,0,0,0,0,0,0,0,0,0,0,0,0,0,0,0,0,0,0,0,0,0,0
0,0,0,0,0,0,320,0,0,0,0,0,33,0,0,0,0,0,320,0,0,0,0,0,0
0,0,0,0,0,0,320,0,0,0,0,178,31,136,0,0,0,0,320,0,0,0,0,0,0
0,0,0,0,0,0,320,0,0,0,0,0,112,0,0,0,0,0,320,0,0,0,0,0,0
0,0,0,0,0,0,0,0,0,0,0,0,0,0,0,0,0,0,0,0,0,0,0,0,0
0,0,0,0,0,0,0,0,0,0,0,0,0,0,0,0,0,0,0,0,0,0,0,0,0
0,0,0,0,0,0,0,0,0,0,0,0,0,0,0,0,0,0,0,0,0,0,0,0,0
0,0,0,0,0,0,0,0,0,0,0,0,0,0,0,0,0,0,0,0,0,0,0,0,0
0,0,0,0,0,0,0,0,0,0,0,0,0,0,0,0,0,0,0,0,0,0,0,0,0
0,0,0,0,0,0,0,0,0,0,0,0,0,0,0,0,0,0,0,0,0,0,0,0,0
0,0,0,0,0,0,0,0,0,0,0,0,0,0,0,0,0,0,0,0,0,0,0,0,0
0,0,0,0,0,0,0,0,0,0,0,0,33,0,0,0,0,0,0,0,0,0,0,0,0
0,0,0,0,0,0,0,0,0,0,0,0,31,0,0,0,0,0,0,0,0,0,0,0,0
0,0,0,0,0,0,0,0,0,0,0,0,0,0,0,0,0,0,0,0,0,0,0,0,0
0,0,0,0,0,0,0,567,576,576,576,576,576,576,576,576,576,567,0,0,0,0,0,0,0
0,0,0,0,0,0,0,0,0,0,0,0,0,0,0,0,0,0,0,0,0,0,0,0,0
0,0,0,0,0,0,0,0,0,0,0,0,0,0,0,0,0,0,0,0,0,0,0,0,0
0,0,0,0,0,0,0,0,0,0,0,0,0,0,0,0,0,0,0,0,0,0,0,0,0
0,0,0,0,0,0,0,0,0,0,0,0,0,0,0,0,0,0,0,0,0,0,0,0,0
0,0,0,0,0,0,0,0,0,0,0,0,0,0,0,0,0,0,0,0,0,0,0,0,0
0,0,0,0,0,0,0,0,0,0,0,0,0,0,0,0,0,0,0,0,0,0,0,0,0
0,0,0,0,0,0,0,0,0,0,0,0,0,0,0,0,0,0,0,0,0,0,0,0,0
0,0,0,0,0,0,0,0,0,0,0,0,0,0,0,0,0,0,0,0,0,0,0,0,0
0,0,0,0,0,0,0,0,0,0,0,0,0,0,0,0,0,0,0,0,0,0,0,0,0
0,0,0,0,0,0,0,0,0,0,0,0,0,0,0,0,0,0,0,0,0,0,0,0,0
0,0,0,0,0,0,0,0,0,0,0,0,0,0,0,0,0,0,0,0,0,0,0,0,0
0,0,0,0,0,0,0,0,0,0,0,0,0,0,0,0,0,0,0,0,0,0,0,0,0
0,0,0,0,0,0,0,0,0,0,0,0,0,0,0,0,0,0,0,0,0,0,0,0,0
0,0,0,0,0,0,0,0,0,0,0,0,0,0,0,0,0,0,0,0,0,0,0,0,0
0,0,0,0,0,0,0,0,0,0,0,0,320,0,0,0,0,0,0,0,0,0,0,0,0
0,0,0,0,0,0,0,0,0,0,0,0,320,0,0,0,0,0,0,0,0,0,0,0,0
0,0,0,0,0,0,0,0,0,0,0,0,492,0,0,0,0,0,0,0,0,0,0,0,0
0,0,0,0,0,0,0,0,0,0,0,0,492,0,0,0,0,0,0,0,0,0,0,0,0
0,0,0,0,0,0,0,0,0,0,0,0,0,0,0,0,0,0,0,0,0,0,0,0,0
0,0,0,0,0,0,0,0,0,0,0,0,0,0,0,0,0,0,0,0,0,0,0,0,0
0,0,0,0,0,0,0,0,0,0,0,0,0,0,0,0,0,0,0,0,0,0,0,0,0
0,0,0,0,0,0,0,0,0,0,0,0,597,0,0,0,0,0,0,0,0,0,0,0,0
0,0,0,0,0,0,0,0,597,320,320,320,312,320,320,320,597,0,0,0,0,0,0,0,0
0,0,0,0,0,0,0,0,0,0,0,0,217,0,0,0,0,0,0,0,0,0,0,0,0
0,0,0,0,0,0,0,0,0,0,0,0,0,0,0,0,0,0,0,0,0,0,0,0,0
:endlayer
layer: 22
0,0,0,0,0,0,0,0,0,0,0,0,0,0,0,0,0,0,0,0,0,0,0,0,0
0,0,0,0,0,0,0,0,0,0,0,0,0,0,0,0,0,0,0,0,0,0,0,0,0
0,0,0,0,0,0,0,0,0,0,0,0,0,0,0,0,0,0,0,0,0,0,0,0,0
0,0,0,0,0,0,0,0,0,0,0,0,0,320,0,0,0,0,0,0,0,0,0,0,0
0,0,0,0,0,0,0,0,0,0,0,0,320,320,0,0,0,0,0,0,0,0,0,0,0
0,0,0,0,0,0,0,0,0,0,0,0,0,0,0,0,0,0,0,0,0,0,0,0,0
0,0,0,0,0,0,0,0,0,0,0,0,0,0,0,0,0,0,0,0,0,0,0,0,0
0,0,0,0,0,0,0,0,0,0,0,0,0,0,0,0,0,0,0,0,0,0,0,0,0
0,0,0,0,0,0,0,0,0,0,0,0,0,0,0,0,0,0,0,0,0,0,0,0,0
0,0,0,0,0,0,0,0,0,0,0,0,0,0,0,0,0,0,0,0,0,0,0,0,0
0,0,0,0,0,0,0,0,0,0,0,0,0,0,0,0,0,0,0,0,0,0,0,0,0
0,0,0,0,0,0,0,0,0,0,0,0,31,0,0,0,0,0,0,0,0,0,0,0,0
0,0,0,0,0,0,0,0,0,0,0,0,0,0,0,0,0,0,0,0,0,0,0,0,0
0,0,0,0,0,0,0,0,0,0,0,0,0,0,0,0,0,0,0,0,0,0,0,0,0
0,0,0,0,0,0,0,0,0,0,0,0,0,0,0,0,0,0,0,0,0,0,0,0,0
0,0,0,0,0,0,0,0,0,0,0,0,0,0,0,0,0,0,0,0,0,0,0,0,0
0,0,0,0,0,0,0,0,0,0,0,0,0,0,0,0,0,0,0,0,0,0,0,0,0
0,0,0,0,0,0,0,0,0,0,0,0,0,0,0,0,0,0,0,0,0,0,0,0,0
0,0,0,0,0,0,0,0,0,0,0,0,0,0,0,0,0,0,0,0,0,0,0,0,0
0,0,0,0,0,0,0,0,0,0,0,0,0,0,0,0,0,0,0,0,0,0,0,0,0
0,0,0,0,0,0,0,0,0,0,0,0,33,0,0,0,0,0,0,0,0,0,0,0,0
0,0,0,0,0,0,320,0,0,0,0,0,31,320,0,0,0,0,320,0,0,0,0,0,0
0,0,0,0,0,0,567,320,0,0,0,0,0,0,0,0,0,320,567,0,0,0,0,0,0
0,0,0,0,0,0,0,567,567,567,567,567,567,567,567,567,567,567,0,0,0,0,0,0,0
0,0,0,0,0,0,0,0,0,0,0,0,0,0,0,0,0,0,0,0,0,0,0,0,0
0,0,0,0,0,0,0,0,0,0,0,0,0,0,0,0,0,0,0,0,0,0,0,0,0
0,0,0,0,0,0,0,0,0,0,0,0,0,0,0,0,0,0,0,0,0,0,0,0,0
0,0,0,0,0,0,0,0,0,0,0,0,0,0,0,0,0,0,0,0,0,0,0,0,0
0,0,0,0,0,0,0,0,0,0,0,0,0,0,0,0,0,0,0,0,0,0,0,0,0
0,0,0,0,0,0,0,0,0,0,0,0,0,0,0,0,0,0,0,0,0,0,0,0,0
0,0,0,0,0,0,0,0,0,0,0,0,33,0,0,0,0,0,0,0,0,0,0,0,0
